package net.modjam5.makercommunity.common.world.structure;

import java.util.Collections;
import java.util.List;
import java.util.Random;

import javax.annotation.Nullable;

import net.minecraft.block.Block;
import net.minecraft.entity.item.EntityArmorStand;
import net.minecraft.entity.item.EntityItemFrame;
import net.minecraft.entity.monster.EntityWitch;
import net.minecraft.init.Biomes;
import net.minecraft.init.Blocks;
import net.minecraft.init.Enchantments;
import net.minecraft.init.Items;
import net.minecraft.inventory.EntityEquipmentSlot;
import net.minecraft.item.ItemStack;
import net.minecraft.util.EnumFacing;
import net.minecraft.util.math.BlockPos;
import net.minecraft.world.World;
import net.minecraft.world.biome.Biome;
import net.minecraft.world.biome.BiomeProvider;
import net.minecraft.world.chunk.Chunk;
import net.minecraft.world.gen.structure.MapGenStructure;
import net.minecraft.world.gen.structure.StructureBoundingBox;
import net.minecraft.world.gen.structure.StructureStart;
import net.modjam5.makercommunity.common.ItemRegistry;
import net.modjam5.makercommunity.common.Registry;
import net.modjam5.makercommunity.util.EnchantingHelper;
import net.modjam5.makercommunity.util.MapStructureHelper;

/**
 * @author Tim Biesenbeek
 */
public class DeepHouseStructure extends MapGenStructure implements Structure {

	private static final StructureBoundingBox boundingBox = new StructureBoundingBox(new int[]{0, 0, 0, 8, 8, 8});
	private static final List<Biome> ALLOWED_BIOMES = Collections.singletonList(Biomes.DEEP_OCEAN);

	@Override
	public void updateWorld(World world) {
		this.world = world;
	}

	@Override
	public StructureBoundingBox getBoundingBox() {
		return boundingBox;
	}

	@Override
	public String getStructureName() {
		return "DeepHouse";
	}

	@Nullable
	@Override
	public BlockPos getNearestStructurePos(World worldIn, BlockPos pos, boolean findUnexplored) {
		this.world = worldIn;
		BiomeProvider biomeprovider = worldIn.getBiomeProvider();
		return biomeprovider.isFixedBiome() && biomeprovider.getFixedBiome() != Biomes.BEACH ? null
				: findNearestStructurePosBySpacing(worldIn, this, pos, 80, 20, 10387319, true, 100, findUnexplored);
	}

	@Override
	public boolean canSpawnStructureAtCoords(int chunkX, int chunkZ) {
		if (Math.abs(chunkX) < 50 || Math.abs(chunkZ) < 50) {
			return false;
		}
		Random random = this.world.setRandomSeed(2304 * chunkX, 1996 * chunkZ, 997);
		boolean rand = random.nextInt(1000) + 1 <= 1;
		boolean biome = this.world.getBiomeProvider().areBiomesViable(chunkX * 16 + 8, chunkZ * 16 + 8, 1,
			ALLOWED_BIOMES);
		return rand && biome;
	}

	@Override
	protected StructureStart getStructureStart(int chunkX, int chunkZ) {
		return new Start(this, chunkX, chunkZ);
	}

	@SuppressWarnings("deprecation")
	public void generate(World world, Random random, int xPos, int zPos) {
		int i = xPos + random.nextInt(15);
		int k = zPos + random.nextInt(15);

		int chunkX = i >> 4;
		int chunkZ = k >> 4;
		Chunk chunk = world.getChunkFromChunkCoords(chunkX, chunkZ);
		int y;
		for (y = chunk.getHeight(new BlockPos(i & 0xF, 0, k & 0xF)) - 1; y > 10; y--) {
			Block block = chunk.getBlockState(i, y, k).getBlock();
			if (block == Blocks.WATER || block == Blocks.FLOWING_WATER) {
				continue;
			}
			break;
		}

		int j = y;

		BlockPos framePos = new BlockPos(i + 3, j + 0.5, k + 6.5);
		EntityItemFrame entityitemframe = new EntityItemFrame(world, framePos, EnumFacing.EAST);
		// TODO: change type map
		entityitemframe.setDisplayedItem(MapStructureHelper
				.buildMapFor(Registry.structureRegister.byClass(VillageStructure.class), world, framePos));
		world.spawnEntity(entityitemframe);

		EntityArmorStand armorStand = new EntityArmorStand(world, i + 4.5, j + 1, k + 4.5);
		armorStand.setItemStackToSlot(EntityEquipmentSlot.MAINHAND, new ItemStack(ItemRegistry.recorders[5]));
		world.spawnEntity(armorStand);

		EntityWitch witch = new EntityWitch(world);
		witch.setLocationAndAngles(i + 4.5, j + 1, k + 5.5, world.rand.nextFloat() * 360F, 0);
		world.spawnEntity(witch);
		witch.setItemStackToSlot(EntityEquipmentSlot.HEAD,
			EnchantingHelper.withEnchant(new ItemStack(Items.DIAMOND_HELMET), Enchantments.PROTECTION, 3));
		witch.setItemStackToSlot(EntityEquipmentSlot.CHEST,
			EnchantingHelper.withEnchant(new ItemStack(Items.DIAMOND_CHESTPLATE), Enchantments.PROTECTION, 3));
		witch.setItemStackToSlot(EntityEquipmentSlot.LEGS,
			EnchantingHelper.withEnchant(new ItemStack(Items.DIAMOND_LEGGINGS), Enchantments.PROTECTION, 3));
		witch.setItemStackToSlot(EntityEquipmentSlot.FEET,
			EnchantingHelper.withEnchant(new ItemStack(Items.DIAMOND_BOOTS), Enchantments.PROTECTION, 3));
		witch.setDropChance(EntityEquipmentSlot.HEAD, 0f);
		witch.setDropChance(EntityEquipmentSlot.CHEST, 0f);
		witch.setDropChance(EntityEquipmentSlot.LEGS, 0f);
		witch.setDropChance(EntityEquipmentSlot.FEET, 0f);
		witch.setCustomNameTag("Kerman");
		witch.enablePersistence();
		witch.setAlwaysRenderNameTag(false);

		world.setBlockState(new BlockPos(i + 0, j + 0, k + 0), Block.getBlockById(42).getStateFromMeta(0), 3);
		world.setBlockState(new BlockPos(i + 1, j + 0, k + 0), Block.getBlockById(42).getStateFromMeta(0), 3);
		world.setBlockState(new BlockPos(i + 2, j + 0, k + 0), Block.getBlockById(42).getStateFromMeta(0), 3);
		world.setBlockState(new BlockPos(i + 3, j + 0, k + 0), Block.getBlockById(42).getStateFromMeta(0), 3);
		world.setBlockState(new BlockPos(i + 4, j + 0, k + 0), Block.getBlockById(42).getStateFromMeta(0), 3);
		world.setBlockState(new BlockPos(i + 5, j + 0, k + 0), Block.getBlockById(42).getStateFromMeta(0), 3);
		world.setBlockState(new BlockPos(i + 6, j + 0, k + 0), Block.getBlockById(42).getStateFromMeta(0), 3);
		world.setBlockState(new BlockPos(i + 7, j + 0, k + 0), Block.getBlockById(13).getStateFromMeta(0), 3);
		world.setBlockState(new BlockPos(i + 0, j + 0, k + 1), Block.getBlockById(42).getStateFromMeta(0), 3);
		world.setBlockState(new BlockPos(i + 1, j + 0, k + 1), Block.getBlockById(3).getStateFromMeta(0), 3);
		world.setBlockState(new BlockPos(i + 2, j + 0, k + 1), Block.getBlockById(3).getStateFromMeta(0), 3);
		world.setBlockState(new BlockPos(i + 3, j + 0, k + 1), Block.getBlockById(3).getStateFromMeta(0), 3);
		world.setBlockState(new BlockPos(i + 4, j + 0, k + 1), Block.getBlockById(2).getStateFromMeta(0), 3);
		world.setBlockState(new BlockPos(i + 5, j + 0, k + 1), Block.getBlockById(2).getStateFromMeta(0), 3);
		world.setBlockState(new BlockPos(i + 6, j + 0, k + 1), Block.getBlockById(42).getStateFromMeta(0), 3);
		world.setBlockState(new BlockPos(i + 7, j + 0, k + 1), Block.getBlockById(13).getStateFromMeta(0), 3);
		world.setBlockState(new BlockPos(i + 0, j + 0, k + 2), Block.getBlockById(42).getStateFromMeta(0), 3);
		world.setBlockState(new BlockPos(i + 1, j + 0, k + 2), Block.getBlockById(2).getStateFromMeta(0), 3);
		world.setBlockState(new BlockPos(i + 2, j + 0, k + 2), Block.getBlockById(2).getStateFromMeta(0), 3);
		world.setBlockState(new BlockPos(i + 3, j + 0, k + 2), Block.getBlockById(2).getStateFromMeta(0), 3);
		world.setBlockState(new BlockPos(i + 4, j + 0, k + 2), Block.getBlockById(2).getStateFromMeta(0), 3);
		world.setBlockState(new BlockPos(i + 5, j + 0, k + 2), Block.getBlockById(3).getStateFromMeta(0), 3);
		world.setBlockState(new BlockPos(i + 6, j + 0, k + 2), Block.getBlockById(42).getStateFromMeta(0), 3);
		world.setBlockState(new BlockPos(i + 7, j + 0, k + 2), Block.getBlockById(13).getStateFromMeta(0), 3);
		world.setBlockState(new BlockPos(i + 0, j + 0, k + 3), Block.getBlockById(42).getStateFromMeta(0), 3);
		world.setBlockState(new BlockPos(i + 1, j + 0, k + 3), Block.getBlockById(2).getStateFromMeta(0), 3);
		world.setBlockState(new BlockPos(i + 2, j + 0, k + 3), Block.getBlockById(2).getStateFromMeta(0), 3);
		world.setBlockState(new BlockPos(i + 3, j + 0, k + 3), Block.getBlockById(2).getStateFromMeta(0), 3);
		world.setBlockState(new BlockPos(i + 4, j + 0, k + 3), Block.getBlockById(2).getStateFromMeta(0), 3);
		world.setBlockState(new BlockPos(i + 5, j + 0, k + 3), Block.getBlockById(42).getStateFromMeta(0), 3);
		world.setBlockState(new BlockPos(i + 6, j + 0, k + 3), Block.getBlockById(42).getStateFromMeta(0), 3);
		world.setBlockState(new BlockPos(i + 7, j + 0, k + 3), Block.getBlockById(42).getStateFromMeta(0), 3);
		world.setBlockState(new BlockPos(i + 0, j + 0, k + 4), Block.getBlockById(42).getStateFromMeta(0), 3);
		world.setBlockState(new BlockPos(i + 1, j + 0, k + 4), Block.getBlockById(2).getStateFromMeta(0), 3);
		world.setBlockState(new BlockPos(i + 2, j + 0, k + 4), Block.getBlockById(2).getStateFromMeta(0), 3);
		world.setBlockState(new BlockPos(i + 3, j + 0, k + 4), Block.getBlockById(2).getStateFromMeta(0), 3);
		world.setBlockState(new BlockPos(i + 4, j + 0, k + 4), Block.getBlockById(2).getStateFromMeta(0), 3);
		world.setBlockState(new BlockPos(i + 5, j + 0, k + 4), Block.getBlockById(42).getStateFromMeta(0), 3);
		world.setBlockState(new BlockPos(i + 6, j + 0, k + 4), Block.getBlockById(42).getStateFromMeta(0), 3);
		world.setBlockState(new BlockPos(i + 7, j + 0, k + 4), Block.getBlockById(42).getStateFromMeta(0), 3);
		world.setBlockState(new BlockPos(i + 0, j + 0, k + 5), Block.getBlockById(42).getStateFromMeta(0), 3);
		world.setBlockState(new BlockPos(i + 1, j + 0, k + 5), Block.getBlockById(2).getStateFromMeta(0), 3);
		world.setBlockState(new BlockPos(i + 2, j + 0, k + 5), Block.getBlockById(2).getStateFromMeta(0), 3);
		world.setBlockState(new BlockPos(i + 3, j + 0, k + 5), Block.getBlockById(2).getStateFromMeta(0), 3);
		world.setBlockState(new BlockPos(i + 4, j + 0, k + 5), Block.getBlockById(2).getStateFromMeta(0), 3);
		world.setBlockState(new BlockPos(i + 5, j + 0, k + 5), Block.getBlockById(3).getStateFromMeta(0), 3);
		world.setBlockState(new BlockPos(i + 6, j + 0, k + 5), Block.getBlockById(42).getStateFromMeta(0), 3);
		world.setBlockState(new BlockPos(i + 7, j + 0, k + 5), Block.getBlockById(13).getStateFromMeta(0), 3);
		world.setBlockState(new BlockPos(i + 0, j + 0, k + 6), Block.getBlockById(42).getStateFromMeta(0), 3);
		world.setBlockState(new BlockPos(i + 1, j + 0, k + 6), Block.getBlockById(3).getStateFromMeta(0), 3);
		world.setBlockState(new BlockPos(i + 2, j + 0, k + 6), Block.getBlockById(47).getStateFromMeta(0), 3);
		world.setBlockState(new BlockPos(i + 3, j + 0, k + 6), Block.getBlockById(0).getStateFromMeta(0), 3);
		world.setBlockState(new BlockPos(i + 4, j + 0, k + 6), Block.getBlockById(2).getStateFromMeta(0), 3);
		world.setBlockState(new BlockPos(i + 5, j + 0, k + 6), Block.getBlockById(2).getStateFromMeta(0), 3);
		world.setBlockState(new BlockPos(i + 6, j + 0, k + 6), Block.getBlockById(42).getStateFromMeta(0), 3);
		world.setBlockState(new BlockPos(i + 7, j + 0, k + 6), Block.getBlockById(13).getStateFromMeta(0), 3);
		world.setBlockState(new BlockPos(i + 0, j + 0, k + 7), Block.getBlockById(42).getStateFromMeta(0), 3);
		world.setBlockState(new BlockPos(i + 1, j + 0, k + 7), Block.getBlockById(42).getStateFromMeta(0), 3);
		world.setBlockState(new BlockPos(i + 2, j + 0, k + 7), Block.getBlockById(42).getStateFromMeta(0), 3);
		world.setBlockState(new BlockPos(i + 3, j + 0, k + 7), Block.getBlockById(42).getStateFromMeta(0), 3);
		world.setBlockState(new BlockPos(i + 4, j + 0, k + 7), Block.getBlockById(42).getStateFromMeta(0), 3);
		world.setBlockState(new BlockPos(i + 5, j + 0, k + 7), Block.getBlockById(42).getStateFromMeta(0), 3);
		world.setBlockState(new BlockPos(i + 6, j + 0, k + 7), Block.getBlockById(42).getStateFromMeta(0), 3);
		world.setBlockState(new BlockPos(i + 7, j + 0, k + 7), Block.getBlockById(13).getStateFromMeta(0), 3);
		world.setBlockState(new BlockPos(i + 0, j + 1, k + 0), Block.getBlockById(42).getStateFromMeta(0), 3);
		world.setBlockState(new BlockPos(i + 1, j + 1, k + 0), Block.getBlockById(20).getStateFromMeta(0), 3);
		world.setBlockState(new BlockPos(i + 2, j + 1, k + 0), Block.getBlockById(20).getStateFromMeta(0), 3);
		world.setBlockState(new BlockPos(i + 3, j + 1, k + 0), Block.getBlockById(20).getStateFromMeta(0), 3);
		world.setBlockState(new BlockPos(i + 4, j + 1, k + 0), Block.getBlockById(20).getStateFromMeta(0), 3);
		world.setBlockState(new BlockPos(i + 5, j + 1, k + 0), Block.getBlockById(20).getStateFromMeta(0), 3);
		world.setBlockState(new BlockPos(i + 6, j + 1, k + 0), Block.getBlockById(42).getStateFromMeta(0), 3);
		world.setBlockState(new BlockPos(i + 7, j + 1, k + 0), Block.getBlockById(9).getStateFromMeta(0), 3);
		world.setBlockState(new BlockPos(i + 0, j + 1, k + 1), Block.getBlockById(20).getStateFromMeta(0), 3);
		world.setBlockState(new BlockPos(i + 1, j + 1, k + 1), Block.getBlockById(47).getStateFromMeta(0), 3);
		world.setBlockState(new BlockPos(i + 2, j + 1, k + 1), Block.getBlockById(47).getStateFromMeta(0), 3);
		world.setBlockState(new BlockPos(i + 3, j + 1, k + 1), Block.getBlockById(47).getStateFromMeta(0), 3);
		world.setBlockState(new BlockPos(i + 4, j + 1, k + 1), Block.getBlockById(0).getStateFromMeta(0), 3);
		world.setBlockState(new BlockPos(i + 5, j + 1, k + 1), Block.getBlockById(54).getStateFromMeta(4), 3);
		world.setBlockState(new BlockPos(i + 6, j + 1, k + 1), Block.getBlockById(20).getStateFromMeta(0), 3);
		world.setBlockState(new BlockPos(i + 7, j + 1, k + 1), Block.getBlockById(9).getStateFromMeta(0), 3);
		world.setBlockState(new BlockPos(i + 0, j + 1, k + 2), Block.getBlockById(20).getStateFromMeta(0), 3);
		world.setBlockState(new BlockPos(i + 1, j + 1, k + 2), Block.getBlockById(0).getStateFromMeta(0), 3);
		world.setBlockState(new BlockPos(i + 2, j + 1, k + 2), Block.getBlockById(0).getStateFromMeta(0), 3);
		world.setBlockState(new BlockPos(i + 3, j + 1, k + 2), Block.getBlockById(0).getStateFromMeta(0), 3);
		world.setBlockState(new BlockPos(i + 4, j + 1, k + 2), Block.getBlockById(0).getStateFromMeta(0), 3);
		world.setBlockState(new BlockPos(i + 5, j + 1, k + 2), Block.getBlockById(42).getStateFromMeta(0), 3);
		world.setBlockState(new BlockPos(i + 6, j + 1, k + 2), Block.getBlockById(20).getStateFromMeta(0), 3);
		world.setBlockState(new BlockPos(i + 7, j + 1, k + 2), Block.getBlockById(42).getStateFromMeta(0), 3);
		world.setBlockState(new BlockPos(i + 0, j + 1, k + 3), Block.getBlockById(20).getStateFromMeta(0), 3);
		world.setBlockState(new BlockPos(i + 1, j + 1, k + 3), Block.getBlockById(26).getStateFromMeta(9), 3);
		world.setBlockState(new BlockPos(i + 2, j + 1, k + 3), Block.getBlockById(26).getStateFromMeta(1), 3);
		world.setBlockState(new BlockPos(i + 3, j + 1, k + 3), Block.getBlockById(0).getStateFromMeta(0), 3);
		world.setBlockState(new BlockPos(i + 4, j + 1, k + 3), Block.getBlockById(0).getStateFromMeta(0), 3);
		world.setBlockState(new BlockPos(i + 5, j + 1, k + 3), Block.getBlockById(0).getStateFromMeta(0), 3);
		world.setBlockState(new BlockPos(i + 6, j + 1, k + 3), Block.getBlockById(148).getStateFromMeta(0), 3);
		world.setBlockState(new BlockPos(i + 7, j + 1, k + 3), Block.getBlockById(9).getStateFromMeta(0), 3);
		world.setBlockState(new BlockPos(i + 0, j + 1, k + 4), Block.getBlockById(20).getStateFromMeta(0), 3);
		world.setBlockState(new BlockPos(i + 1, j + 1, k + 4), Block.getBlockById(26).getStateFromMeta(9), 3);
		world.setBlockState(new BlockPos(i + 2, j + 1, k + 4), Block.getBlockById(26).getStateFromMeta(1), 3);
		world.setBlockState(new BlockPos(i + 3, j + 1, k + 4), Block.getBlockById(0).getStateFromMeta(0), 3);
		world.setBlockState(new BlockPos(i + 4, j + 1, k + 4), Block.getBlockById(0).getStateFromMeta(0), 3);
		world.setBlockState(new BlockPos(i + 5, j + 1, k + 4), Block.getBlockById(0).getStateFromMeta(0), 3);
		world.setBlockState(new BlockPos(i + 6, j + 1, k + 4), Block.getBlockById(148).getStateFromMeta(0), 3);
		world.setBlockState(new BlockPos(i + 7, j + 1, k + 4), Block.getBlockById(9).getStateFromMeta(0), 3);
		world.setBlockState(new BlockPos(i + 0, j + 1, k + 5), Block.getBlockById(20).getStateFromMeta(0), 3);
		world.setBlockState(new BlockPos(i + 1, j + 1, k + 5), Block.getBlockById(0).getStateFromMeta(0), 3);
		world.setBlockState(new BlockPos(i + 2, j + 1, k + 5), Block.getBlockById(0).getStateFromMeta(0), 3);
		world.setBlockState(new BlockPos(i + 3, j + 1, k + 5), Block.getBlockById(0).getStateFromMeta(0), 3);
		world.setBlockState(new BlockPos(i + 4, j + 1, k + 5), Block.getBlockById(0).getStateFromMeta(0), 3);
		world.setBlockState(new BlockPos(i + 5, j + 1, k + 5), Block.getBlockById(42).getStateFromMeta(0), 3);
		world.setBlockState(new BlockPos(i + 6, j + 1, k + 5), Block.getBlockById(20).getStateFromMeta(0), 3);
		world.setBlockState(new BlockPos(i + 7, j + 1, k + 5), Block.getBlockById(42).getStateFromMeta(0), 3);
		world.setBlockState(new BlockPos(i + 0, j + 1, k + 6), Block.getBlockById(20).getStateFromMeta(0), 3);
		world.setBlockState(new BlockPos(i + 1, j + 1, k + 6), Block.getBlockById(47).getStateFromMeta(0), 3);
		world.setBlockState(new BlockPos(i + 2, j + 1, k + 6), Block.getBlockById(47).getStateFromMeta(0), 3);
		world.setBlockState(new BlockPos(i + 3, j + 1, k + 6), Block.getBlockById(47).getStateFromMeta(0), 3);
		world.setBlockState(new BlockPos(i + 4, j + 1, k + 6), Block.getBlockById(0).getStateFromMeta(0), 3);
		world.setBlockState(new BlockPos(i + 5, j + 1, k + 6), Block.getBlockById(54).getStateFromMeta(4), 3);
		world.setBlockState(new BlockPos(i + 6, j + 1, k + 6), Block.getBlockById(20).getStateFromMeta(0), 3);
		world.setBlockState(new BlockPos(i + 7, j + 1, k + 6), Block.getBlockById(9).getStateFromMeta(0), 3);
		world.setBlockState(new BlockPos(i + 0, j + 1, k + 7), Block.getBlockById(42).getStateFromMeta(0), 3);
		world.setBlockState(new BlockPos(i + 1, j + 1, k + 7), Block.getBlockById(20).getStateFromMeta(0), 3);
		world.setBlockState(new BlockPos(i + 2, j + 1, k + 7), Block.getBlockById(20).getStateFromMeta(0), 3);
		world.setBlockState(new BlockPos(i + 3, j + 1, k + 7), Block.getBlockById(20).getStateFromMeta(0), 3);
		world.setBlockState(new BlockPos(i + 4, j + 1, k + 7), Block.getBlockById(20).getStateFromMeta(0), 3);
		world.setBlockState(new BlockPos(i + 5, j + 1, k + 7), Block.getBlockById(20).getStateFromMeta(0), 3);
		world.setBlockState(new BlockPos(i + 6, j + 1, k + 7), Block.getBlockById(42).getStateFromMeta(0), 3);
		world.setBlockState(new BlockPos(i + 7, j + 1, k + 7), Block.getBlockById(9).getStateFromMeta(0), 3);
		world.setBlockState(new BlockPos(i + 0, j + 2, k + 0), Block.getBlockById(42).getStateFromMeta(0), 3);
		world.setBlockState(new BlockPos(i + 1, j + 2, k + 0), Block.getBlockById(20).getStateFromMeta(0), 3);
		world.setBlockState(new BlockPos(i + 2, j + 2, k + 0), Block.getBlockById(20).getStateFromMeta(0), 3);
		world.setBlockState(new BlockPos(i + 3, j + 2, k + 0), Block.getBlockById(20).getStateFromMeta(0), 3);
		world.setBlockState(new BlockPos(i + 4, j + 2, k + 0), Block.getBlockById(20).getStateFromMeta(0), 3);
		world.setBlockState(new BlockPos(i + 5, j + 2, k + 0), Block.getBlockById(20).getStateFromMeta(0), 3);
		world.setBlockState(new BlockPos(i + 6, j + 2, k + 0), Block.getBlockById(42).getStateFromMeta(0), 3);
		world.setBlockState(new BlockPos(i + 7, j + 2, k + 0), Block.getBlockById(9).getStateFromMeta(0), 3);
		world.setBlockState(new BlockPos(i + 0, j + 2, k + 1), Block.getBlockById(20).getStateFromMeta(0), 3);
		world.setBlockState(new BlockPos(i + 1, j + 2, k + 1), Block.getBlockById(47).getStateFromMeta(0), 3);
		world.setBlockState(new BlockPos(i + 2, j + 2, k + 1), Block.getBlockById(47).getStateFromMeta(0), 3);
		world.setBlockState(new BlockPos(i + 3, j + 2, k + 1), Block.getBlockById(0).getStateFromMeta(0), 3);
		world.setBlockState(new BlockPos(i + 4, j + 2, k + 1), Block.getBlockById(0).getStateFromMeta(0), 3);
		world.setBlockState(new BlockPos(i + 5, j + 2, k + 1), Block.getBlockById(0).getStateFromMeta(0), 3);
		world.setBlockState(new BlockPos(i + 6, j + 2, k + 1), Block.getBlockById(20).getStateFromMeta(0), 3);
		world.setBlockState(new BlockPos(i + 7, j + 2, k + 1), Block.getBlockById(9).getStateFromMeta(0), 3);
		world.setBlockState(new BlockPos(i + 0, j + 2, k + 2), Block.getBlockById(20).getStateFromMeta(0), 3);
		world.setBlockState(new BlockPos(i + 1, j + 2, k + 2), Block.getBlockById(108).getStateFromMeta(7), 3);
		world.setBlockState(new BlockPos(i + 2, j + 2, k + 2), Block.getBlockById(0).getStateFromMeta(0), 3);
		world.setBlockState(new BlockPos(i + 3, j + 2, k + 2), Block.getBlockById(0).getStateFromMeta(0), 3);
		world.setBlockState(new BlockPos(i + 4, j + 2, k + 2), Block.getBlockById(0).getStateFromMeta(0), 3);
		world.setBlockState(new BlockPos(i + 5, j + 2, k + 2), Block.getBlockById(42).getStateFromMeta(0), 3);
		world.setBlockState(new BlockPos(i + 6, j + 2, k + 2), Block.getBlockById(20).getStateFromMeta(0), 3);
		world.setBlockState(new BlockPos(i + 7, j + 2, k + 2), Block.getBlockById(42).getStateFromMeta(0), 3);
		world.setBlockState(new BlockPos(i + 0, j + 2, k + 3), Block.getBlockById(20).getStateFromMeta(0), 3);
		world.setBlockState(new BlockPos(i + 1, j + 2, k + 3), Block.getBlockById(0).getStateFromMeta(0), 3);
		world.setBlockState(new BlockPos(i + 2, j + 2, k + 3), Block.getBlockById(0).getStateFromMeta(0), 3);
		world.setBlockState(new BlockPos(i + 3, j + 2, k + 3), Block.getBlockById(0).getStateFromMeta(0), 3);
		world.setBlockState(new BlockPos(i + 4, j + 2, k + 3), Block.getBlockById(0).getStateFromMeta(0), 3);
		world.setBlockState(new BlockPos(i + 5, j + 2, k + 3), Block.getBlockById(0).getStateFromMeta(0), 3);
		world.setBlockState(new BlockPos(i + 6, j + 2, k + 3), Block.getBlockById(0).getStateFromMeta(0), 3);
		world.setBlockState(new BlockPos(i + 7, j + 2, k + 3), Block.getBlockById(9).getStateFromMeta(1), 3);
		world.setBlockState(new BlockPos(i + 0, j + 2, k + 4), Block.getBlockById(20).getStateFromMeta(0), 3);
		world.setBlockState(new BlockPos(i + 1, j + 2, k + 4), Block.getBlockById(0).getStateFromMeta(0), 3);
		world.setBlockState(new BlockPos(i + 2, j + 2, k + 4), Block.getBlockById(0).getStateFromMeta(0), 3);
		world.setBlockState(new BlockPos(i + 3, j + 2, k + 4), Block.getBlockById(0).getStateFromMeta(0), 3);
		world.setBlockState(new BlockPos(i + 4, j + 2, k + 4), Block.getBlockById(0).getStateFromMeta(0), 3);
		world.setBlockState(new BlockPos(i + 5, j + 2, k + 4), Block.getBlockById(0).getStateFromMeta(0), 3);
		world.setBlockState(new BlockPos(i + 6, j + 2, k + 4), Block.getBlockById(0).getStateFromMeta(0), 3);
		world.setBlockState(new BlockPos(i + 7, j + 2, k + 4), Block.getBlockById(9).getStateFromMeta(1), 3);
		world.setBlockState(new BlockPos(i + 0, j + 2, k + 5), Block.getBlockById(20).getStateFromMeta(0), 3);
		world.setBlockState(new BlockPos(i + 1, j + 2, k + 5), Block.getBlockById(108).getStateFromMeta(6), 3);
		world.setBlockState(new BlockPos(i + 2, j + 2, k + 5), Block.getBlockById(0).getStateFromMeta(0), 3);
		world.setBlockState(new BlockPos(i + 3, j + 2, k + 5), Block.getBlockById(0).getStateFromMeta(0), 3);
		world.setBlockState(new BlockPos(i + 4, j + 2, k + 5), Block.getBlockById(0).getStateFromMeta(0), 3);
		world.setBlockState(new BlockPos(i + 5, j + 2, k + 5), Block.getBlockById(42).getStateFromMeta(0), 3);
		world.setBlockState(new BlockPos(i + 6, j + 2, k + 5), Block.getBlockById(20).getStateFromMeta(0), 3);
		world.setBlockState(new BlockPos(i + 7, j + 2, k + 5), Block.getBlockById(42).getStateFromMeta(0), 3);
		world.setBlockState(new BlockPos(i + 0, j + 2, k + 6), Block.getBlockById(20).getStateFromMeta(0), 3);
		world.setBlockState(new BlockPos(i + 1, j + 2, k + 6), Block.getBlockById(47).getStateFromMeta(0), 3);
		world.setBlockState(new BlockPos(i + 2, j + 2, k + 6), Block.getBlockById(47).getStateFromMeta(0), 3);
		world.setBlockState(new BlockPos(i + 3, j + 2, k + 6), Block.getBlockById(0).getStateFromMeta(0), 3);
		world.setBlockState(new BlockPos(i + 4, j + 2, k + 6), Block.getBlockById(0).getStateFromMeta(0), 3);
		world.setBlockState(new BlockPos(i + 5, j + 2, k + 6), Block.getBlockById(0).getStateFromMeta(0), 3);
		world.setBlockState(new BlockPos(i + 6, j + 2, k + 6), Block.getBlockById(20).getStateFromMeta(0), 3);
		world.setBlockState(new BlockPos(i + 7, j + 2, k + 6), Block.getBlockById(9).getStateFromMeta(0), 3);
		world.setBlockState(new BlockPos(i + 0, j + 2, k + 7), Block.getBlockById(42).getStateFromMeta(0), 3);
		world.setBlockState(new BlockPos(i + 1, j + 2, k + 7), Block.getBlockById(20).getStateFromMeta(0), 3);
		world.setBlockState(new BlockPos(i + 2, j + 2, k + 7), Block.getBlockById(20).getStateFromMeta(0), 3);
		world.setBlockState(new BlockPos(i + 3, j + 2, k + 7), Block.getBlockById(20).getStateFromMeta(0), 3);
		world.setBlockState(new BlockPos(i + 4, j + 2, k + 7), Block.getBlockById(20).getStateFromMeta(0), 3);
		world.setBlockState(new BlockPos(i + 5, j + 2, k + 7), Block.getBlockById(20).getStateFromMeta(0), 3);
		world.setBlockState(new BlockPos(i + 6, j + 2, k + 7), Block.getBlockById(42).getStateFromMeta(0), 3);
		world.setBlockState(new BlockPos(i + 7, j + 2, k + 7), Block.getBlockById(9).getStateFromMeta(0), 3);
		world.setBlockState(new BlockPos(i + 0, j + 3, k + 0), Block.getBlockById(42).getStateFromMeta(0), 3);
		world.setBlockState(new BlockPos(i + 1, j + 3, k + 0), Block.getBlockById(20).getStateFromMeta(0), 3);
		world.setBlockState(new BlockPos(i + 2, j + 3, k + 0), Block.getBlockById(20).getStateFromMeta(0), 3);
		world.setBlockState(new BlockPos(i + 3, j + 3, k + 0), Block.getBlockById(20).getStateFromMeta(0), 3);
		world.setBlockState(new BlockPos(i + 4, j + 3, k + 0), Block.getBlockById(20).getStateFromMeta(0), 3);
		world.setBlockState(new BlockPos(i + 5, j + 3, k + 0), Block.getBlockById(20).getStateFromMeta(0), 3);
		world.setBlockState(new BlockPos(i + 6, j + 3, k + 0), Block.getBlockById(42).getStateFromMeta(0), 3);
		world.setBlockState(new BlockPos(i + 7, j + 3, k + 0), Block.getBlockById(9).getStateFromMeta(0), 3);
		world.setBlockState(new BlockPos(i + 0, j + 3, k + 1), Block.getBlockById(20).getStateFromMeta(0), 3);
		world.setBlockState(new BlockPos(i + 1, j + 3, k + 1), Block.getBlockById(47).getStateFromMeta(0), 3);
		world.setBlockState(new BlockPos(i + 2, j + 3, k + 1), Block.getBlockById(0).getStateFromMeta(0), 3);
		world.setBlockState(new BlockPos(i + 3, j + 3, k + 1), Block.getBlockById(0).getStateFromMeta(0), 3);
		world.setBlockState(new BlockPos(i + 4, j + 3, k + 1), Block.getBlockById(0).getStateFromMeta(0), 3);
		world.setBlockState(new BlockPos(i + 5, j + 3, k + 1), Block.getBlockById(0).getStateFromMeta(0), 3);
		world.setBlockState(new BlockPos(i + 6, j + 3, k + 1), Block.getBlockById(20).getStateFromMeta(0), 3);
		world.setBlockState(new BlockPos(i + 7, j + 3, k + 1), Block.getBlockById(9).getStateFromMeta(0), 3);
		world.setBlockState(new BlockPos(i + 0, j + 3, k + 2), Block.getBlockById(20).getStateFromMeta(0), 3);
		world.setBlockState(new BlockPos(i + 1, j + 3, k + 2), Block.getBlockById(47).getStateFromMeta(0), 3);
		world.setBlockState(new BlockPos(i + 2, j + 3, k + 2), Block.getBlockById(0).getStateFromMeta(0), 3);
		world.setBlockState(new BlockPos(i + 3, j + 3, k + 2), Block.getBlockById(0).getStateFromMeta(0), 3);
		world.setBlockState(new BlockPos(i + 4, j + 3, k + 2), Block.getBlockById(0).getStateFromMeta(0), 3);
		world.setBlockState(new BlockPos(i + 5, j + 3, k + 2), Block.getBlockById(169).getStateFromMeta(0), 3);
		world.setBlockState(new BlockPos(i + 6, j + 3, k + 2), Block.getBlockById(20).getStateFromMeta(0), 3);
		world.setBlockState(new BlockPos(i + 7, j + 3, k + 2), Block.getBlockById(169).getStateFromMeta(0), 3);
		world.setBlockState(new BlockPos(i + 0, j + 3, k + 3), Block.getBlockById(20).getStateFromMeta(0), 3);
		world.setBlockState(new BlockPos(i + 1, j + 3, k + 3), Block.getBlockById(108).getStateFromMeta(7), 3);
		world.setBlockState(new BlockPos(i + 2, j + 3, k + 3), Block.getBlockById(0).getStateFromMeta(0), 3);
		world.setBlockState(new BlockPos(i + 3, j + 3, k + 3), Block.getBlockById(0).getStateFromMeta(0), 3);
		world.setBlockState(new BlockPos(i + 4, j + 3, k + 3), Block.getBlockById(0).getStateFromMeta(0), 3);
		world.setBlockState(new BlockPos(i + 5, j + 3, k + 3), Block.getBlockById(42).getStateFromMeta(0), 3);
		world.setBlockState(new BlockPos(i + 6, j + 3, k + 3), Block.getBlockById(20).getStateFromMeta(0), 3);
		world.setBlockState(new BlockPos(i + 7, j + 3, k + 3), Block.getBlockById(42).getStateFromMeta(0), 3);
		world.setBlockState(new BlockPos(i + 0, j + 3, k + 4), Block.getBlockById(20).getStateFromMeta(0), 3);
		world.setBlockState(new BlockPos(i + 1, j + 3, k + 4), Block.getBlockById(108).getStateFromMeta(6), 3);
		world.setBlockState(new BlockPos(i + 2, j + 3, k + 4), Block.getBlockById(0).getStateFromMeta(0), 3);
		world.setBlockState(new BlockPos(i + 3, j + 3, k + 4), Block.getBlockById(0).getStateFromMeta(0), 3);
		world.setBlockState(new BlockPos(i + 4, j + 3, k + 4), Block.getBlockById(0).getStateFromMeta(0), 3);
		world.setBlockState(new BlockPos(i + 5, j + 3, k + 4), Block.getBlockById(42).getStateFromMeta(0), 3);
		world.setBlockState(new BlockPos(i + 6, j + 3, k + 4), Block.getBlockById(20).getStateFromMeta(0), 3);
		world.setBlockState(new BlockPos(i + 7, j + 3, k + 4), Block.getBlockById(42).getStateFromMeta(0), 3);
		world.setBlockState(new BlockPos(i + 0, j + 3, k + 5), Block.getBlockById(20).getStateFromMeta(0), 3);
		world.setBlockState(new BlockPos(i + 1, j + 3, k + 5), Block.getBlockById(47).getStateFromMeta(0), 3);
		world.setBlockState(new BlockPos(i + 2, j + 3, k + 5), Block.getBlockById(0).getStateFromMeta(0), 3);
		world.setBlockState(new BlockPos(i + 3, j + 3, k + 5), Block.getBlockById(0).getStateFromMeta(0), 3);
		world.setBlockState(new BlockPos(i + 4, j + 3, k + 5), Block.getBlockById(0).getStateFromMeta(0), 3);
		world.setBlockState(new BlockPos(i + 5, j + 3, k + 5), Block.getBlockById(169).getStateFromMeta(0), 3);
		world.setBlockState(new BlockPos(i + 6, j + 3, k + 5), Block.getBlockById(20).getStateFromMeta(0), 3);
		world.setBlockState(new BlockPos(i + 7, j + 3, k + 5), Block.getBlockById(169).getStateFromMeta(0), 3);
		world.setBlockState(new BlockPos(i + 0, j + 3, k + 6), Block.getBlockById(20).getStateFromMeta(0), 3);
		world.setBlockState(new BlockPos(i + 1, j + 3, k + 6), Block.getBlockById(47).getStateFromMeta(0), 3);
		world.setBlockState(new BlockPos(i + 2, j + 3, k + 6), Block.getBlockById(0).getStateFromMeta(0), 3);
		world.setBlockState(new BlockPos(i + 3, j + 3, k + 6), Block.getBlockById(0).getStateFromMeta(0), 3);
		world.setBlockState(new BlockPos(i + 4, j + 3, k + 6), Block.getBlockById(0).getStateFromMeta(0), 3);
		world.setBlockState(new BlockPos(i + 5, j + 3, k + 6), Block.getBlockById(0).getStateFromMeta(0), 3);
		world.setBlockState(new BlockPos(i + 6, j + 3, k + 6), Block.getBlockById(20).getStateFromMeta(0), 3);
		world.setBlockState(new BlockPos(i + 7, j + 3, k + 6), Block.getBlockById(9).getStateFromMeta(0), 3);
		world.setBlockState(new BlockPos(i + 0, j + 3, k + 7), Block.getBlockById(42).getStateFromMeta(0), 3);
		world.setBlockState(new BlockPos(i + 1, j + 3, k + 7), Block.getBlockById(20).getStateFromMeta(0), 3);
		world.setBlockState(new BlockPos(i + 2, j + 3, k + 7), Block.getBlockById(20).getStateFromMeta(0), 3);
		world.setBlockState(new BlockPos(i + 3, j + 3, k + 7), Block.getBlockById(20).getStateFromMeta(0), 3);
		world.setBlockState(new BlockPos(i + 4, j + 3, k + 7), Block.getBlockById(20).getStateFromMeta(0), 3);
		world.setBlockState(new BlockPos(i + 5, j + 3, k + 7), Block.getBlockById(20).getStateFromMeta(0), 3);
		world.setBlockState(new BlockPos(i + 6, j + 3, k + 7), Block.getBlockById(42).getStateFromMeta(0), 3);
		world.setBlockState(new BlockPos(i + 7, j + 3, k + 7), Block.getBlockById(9).getStateFromMeta(0), 3);
		world.setBlockState(new BlockPos(i + 0, j + 4, k + 0), Block.getBlockById(42).getStateFromMeta(0), 3);
		world.setBlockState(new BlockPos(i + 1, j + 4, k + 0), Block.getBlockById(20).getStateFromMeta(0), 3);
		world.setBlockState(new BlockPos(i + 2, j + 4, k + 0), Block.getBlockById(20).getStateFromMeta(0), 3);
		world.setBlockState(new BlockPos(i + 3, j + 4, k + 0), Block.getBlockById(20).getStateFromMeta(0), 3);
		world.setBlockState(new BlockPos(i + 4, j + 4, k + 0), Block.getBlockById(20).getStateFromMeta(0), 3);
		world.setBlockState(new BlockPos(i + 5, j + 4, k + 0), Block.getBlockById(20).getStateFromMeta(0), 3);
		world.setBlockState(new BlockPos(i + 6, j + 4, k + 0), Block.getBlockById(42).getStateFromMeta(0), 3);
		world.setBlockState(new BlockPos(i + 7, j + 4, k + 0), Block.getBlockById(9).getStateFromMeta(0), 3);
		world.setBlockState(new BlockPos(i + 0, j + 4, k + 1), Block.getBlockById(20).getStateFromMeta(0), 3);
		world.setBlockState(new BlockPos(i + 1, j + 4, k + 1), Block.getBlockById(0).getStateFromMeta(0), 3);
		world.setBlockState(new BlockPos(i + 2, j + 4, k + 1), Block.getBlockById(0).getStateFromMeta(0), 3);
		world.setBlockState(new BlockPos(i + 3, j + 4, k + 1), Block.getBlockById(0).getStateFromMeta(0), 3);
		world.setBlockState(new BlockPos(i + 4, j + 4, k + 1), Block.getBlockById(0).getStateFromMeta(0), 3);
		world.setBlockState(new BlockPos(i + 5, j + 4, k + 1), Block.getBlockById(0).getStateFromMeta(0), 3);
		world.setBlockState(new BlockPos(i + 6, j + 4, k + 1), Block.getBlockById(20).getStateFromMeta(0), 3);
		world.setBlockState(new BlockPos(i + 7, j + 4, k + 1), Block.getBlockById(9).getStateFromMeta(0), 3);
		world.setBlockState(new BlockPos(i + 0, j + 4, k + 2), Block.getBlockById(20).getStateFromMeta(0), 3);
		world.setBlockState(new BlockPos(i + 1, j + 4, k + 2), Block.getBlockById(47).getStateFromMeta(0), 3);
		world.setBlockState(new BlockPos(i + 2, j + 4, k + 2), Block.getBlockById(0).getStateFromMeta(0), 3);
		world.setBlockState(new BlockPos(i + 3, j + 4, k + 2), Block.getBlockById(0).getStateFromMeta(0), 3);
		world.setBlockState(new BlockPos(i + 4, j + 4, k + 2), Block.getBlockById(0).getStateFromMeta(0), 3);
		world.setBlockState(new BlockPos(i + 5, j + 4, k + 2), Block.getBlockById(0).getStateFromMeta(0), 3);
		world.setBlockState(new BlockPos(i + 6, j + 4, k + 2), Block.getBlockById(20).getStateFromMeta(0), 3);
		world.setBlockState(new BlockPos(i + 7, j + 4, k + 2), Block.getBlockById(9).getStateFromMeta(0), 3);
		world.setBlockState(new BlockPos(i + 0, j + 4, k + 3), Block.getBlockById(20).getStateFromMeta(0), 3);
		world.setBlockState(new BlockPos(i + 1, j + 4, k + 3), Block.getBlockById(47).getStateFromMeta(0), 3);
		world.setBlockState(new BlockPos(i + 2, j + 4, k + 3), Block.getBlockById(0).getStateFromMeta(0), 3);
		world.setBlockState(new BlockPos(i + 3, j + 4, k + 3), Block.getBlockById(0).getStateFromMeta(0), 3);
		world.setBlockState(new BlockPos(i + 4, j + 4, k + 3), Block.getBlockById(0).getStateFromMeta(0), 3);
		world.setBlockState(new BlockPos(i + 5, j + 4, k + 3), Block.getBlockById(54).getStateFromMeta(4), 3);
		world.setBlockState(new BlockPos(i + 6, j + 4, k + 3), Block.getBlockById(20).getStateFromMeta(0), 3);
		world.setBlockState(new BlockPos(i + 7, j + 4, k + 3), Block.getBlockById(9).getStateFromMeta(0), 3);
		world.setBlockState(new BlockPos(i + 0, j + 4, k + 4), Block.getBlockById(20).getStateFromMeta(0), 3);
		world.setBlockState(new BlockPos(i + 1, j + 4, k + 4), Block.getBlockById(47).getStateFromMeta(0), 3);
		world.setBlockState(new BlockPos(i + 2, j + 4, k + 4), Block.getBlockById(0).getStateFromMeta(0), 3);
		world.setBlockState(new BlockPos(i + 3, j + 4, k + 4), Block.getBlockById(0).getStateFromMeta(0), 3);
		world.setBlockState(new BlockPos(i + 4, j + 4, k + 4), Block.getBlockById(0).getStateFromMeta(0), 3);
		world.setBlockState(new BlockPos(i + 5, j + 4, k + 4), Block.getBlockById(54).getStateFromMeta(4), 3);
		world.setBlockState(new BlockPos(i + 6, j + 4, k + 4), Block.getBlockById(20).getStateFromMeta(0), 3);
		world.setBlockState(new BlockPos(i + 7, j + 4, k + 4), Block.getBlockById(9).getStateFromMeta(0), 3);
		world.setBlockState(new BlockPos(i + 0, j + 4, k + 5), Block.getBlockById(20).getStateFromMeta(0), 3);
		world.setBlockState(new BlockPos(i + 1, j + 4, k + 5), Block.getBlockById(47).getStateFromMeta(0), 3);
		world.setBlockState(new BlockPos(i + 2, j + 4, k + 5), Block.getBlockById(0).getStateFromMeta(0), 3);
		world.setBlockState(new BlockPos(i + 3, j + 4, k + 5), Block.getBlockById(0).getStateFromMeta(0), 3);
		world.setBlockState(new BlockPos(i + 4, j + 4, k + 5), Block.getBlockById(0).getStateFromMeta(0), 3);
		world.setBlockState(new BlockPos(i + 5, j + 4, k + 5), Block.getBlockById(0).getStateFromMeta(0), 3);
		world.setBlockState(new BlockPos(i + 6, j + 4, k + 5), Block.getBlockById(20).getStateFromMeta(0), 3);
		world.setBlockState(new BlockPos(i + 7, j + 4, k + 5), Block.getBlockById(9).getStateFromMeta(0), 3);
		world.setBlockState(new BlockPos(i + 0, j + 4, k + 6), Block.getBlockById(20).getStateFromMeta(0), 3);
		world.setBlockState(new BlockPos(i + 1, j + 4, k + 6), Block.getBlockById(0).getStateFromMeta(0), 3);
		world.setBlockState(new BlockPos(i + 2, j + 4, k + 6), Block.getBlockById(0).getStateFromMeta(0), 3);
		world.setBlockState(new BlockPos(i + 3, j + 4, k + 6), Block.getBlockById(0).getStateFromMeta(0), 3);
		world.setBlockState(new BlockPos(i + 4, j + 4, k + 6), Block.getBlockById(0).getStateFromMeta(0), 3);
		world.setBlockState(new BlockPos(i + 5, j + 4, k + 6), Block.getBlockById(0).getStateFromMeta(0), 3);
		world.setBlockState(new BlockPos(i + 6, j + 4, k + 6), Block.getBlockById(20).getStateFromMeta(0), 3);
		world.setBlockState(new BlockPos(i + 7, j + 4, k + 6), Block.getBlockById(9).getStateFromMeta(0), 3);
		world.setBlockState(new BlockPos(i + 0, j + 4, k + 7), Block.getBlockById(42).getStateFromMeta(0), 3);
		world.setBlockState(new BlockPos(i + 1, j + 4, k + 7), Block.getBlockById(20).getStateFromMeta(0), 3);
		world.setBlockState(new BlockPos(i + 2, j + 4, k + 7), Block.getBlockById(20).getStateFromMeta(0), 3);
		world.setBlockState(new BlockPos(i + 3, j + 4, k + 7), Block.getBlockById(20).getStateFromMeta(0), 3);
		world.setBlockState(new BlockPos(i + 4, j + 4, k + 7), Block.getBlockById(20).getStateFromMeta(0), 3);
		world.setBlockState(new BlockPos(i + 5, j + 4, k + 7), Block.getBlockById(20).getStateFromMeta(0), 3);
		world.setBlockState(new BlockPos(i + 6, j + 4, k + 7), Block.getBlockById(42).getStateFromMeta(0), 3);
		world.setBlockState(new BlockPos(i + 7, j + 4, k + 7), Block.getBlockById(9).getStateFromMeta(0), 3);
		world.setBlockState(new BlockPos(i + 0, j + 5, k + 0), Block.getBlockById(42).getStateFromMeta(0), 3);
		world.setBlockState(new BlockPos(i + 1, j + 5, k + 0), Block.getBlockById(20).getStateFromMeta(0), 3);
		world.setBlockState(new BlockPos(i + 2, j + 5, k + 0), Block.getBlockById(20).getStateFromMeta(0), 3);
		world.setBlockState(new BlockPos(i + 3, j + 5, k + 0), Block.getBlockById(20).getStateFromMeta(0), 3);
		world.setBlockState(new BlockPos(i + 4, j + 5, k + 0), Block.getBlockById(20).getStateFromMeta(0), 3);
		world.setBlockState(new BlockPos(i + 5, j + 5, k + 0), Block.getBlockById(20).getStateFromMeta(0), 3);
		world.setBlockState(new BlockPos(i + 6, j + 5, k + 0), Block.getBlockById(42).getStateFromMeta(0), 3);
		world.setBlockState(new BlockPos(i + 7, j + 5, k + 0), Block.getBlockById(9).getStateFromMeta(0), 3);
		world.setBlockState(new BlockPos(i + 0, j + 5, k + 1), Block.getBlockById(20).getStateFromMeta(0), 3);
		world.setBlockState(new BlockPos(i + 1, j + 5, k + 1), Block.getBlockById(0).getStateFromMeta(0), 3);
		world.setBlockState(new BlockPos(i + 2, j + 5, k + 1), Block.getBlockById(0).getStateFromMeta(0), 3);
		world.setBlockState(new BlockPos(i + 3, j + 5, k + 1), Block.getBlockById(0).getStateFromMeta(0), 3);
		world.setBlockState(new BlockPos(i + 4, j + 5, k + 1), Block.getBlockById(0).getStateFromMeta(0), 3);
		world.setBlockState(new BlockPos(i + 5, j + 5, k + 1), Block.getBlockById(0).getStateFromMeta(0), 3);
		world.setBlockState(new BlockPos(i + 6, j + 5, k + 1), Block.getBlockById(20).getStateFromMeta(0), 3);
		world.setBlockState(new BlockPos(i + 7, j + 5, k + 1), Block.getBlockById(9).getStateFromMeta(0), 3);
		world.setBlockState(new BlockPos(i + 0, j + 5, k + 2), Block.getBlockById(20).getStateFromMeta(0), 3);
		world.setBlockState(new BlockPos(i + 1, j + 5, k + 2), Block.getBlockById(0).getStateFromMeta(0), 3);
		world.setBlockState(new BlockPos(i + 2, j + 5, k + 2), Block.getBlockById(0).getStateFromMeta(0), 3);
		world.setBlockState(new BlockPos(i + 3, j + 5, k + 2), Block.getBlockById(0).getStateFromMeta(0), 3);
		world.setBlockState(new BlockPos(i + 4, j + 5, k + 2), Block.getBlockById(0).getStateFromMeta(0), 3);
		world.setBlockState(new BlockPos(i + 5, j + 5, k + 2), Block.getBlockById(0).getStateFromMeta(0), 3);
		world.setBlockState(new BlockPos(i + 6, j + 5, k + 2), Block.getBlockById(20).getStateFromMeta(0), 3);
		world.setBlockState(new BlockPos(i + 7, j + 5, k + 2), Block.getBlockById(9).getStateFromMeta(0), 3);
		world.setBlockState(new BlockPos(i + 0, j + 5, k + 3), Block.getBlockById(20).getStateFromMeta(0), 3);
		world.setBlockState(new BlockPos(i + 1, j + 5, k + 3), Block.getBlockById(0).getStateFromMeta(0), 3);
		world.setBlockState(new BlockPos(i + 2, j + 5, k + 3), Block.getBlockById(0).getStateFromMeta(0), 3);
		world.setBlockState(new BlockPos(i + 3, j + 5, k + 3), Block.getBlockById(0).getStateFromMeta(0), 3);
		world.setBlockState(new BlockPos(i + 4, j + 5, k + 3), Block.getBlockById(0).getStateFromMeta(0), 3);
		world.setBlockState(new BlockPos(i + 5, j + 5, k + 3), Block.getBlockById(0).getStateFromMeta(0), 3);
		world.setBlockState(new BlockPos(i + 6, j + 5, k + 3), Block.getBlockById(20).getStateFromMeta(0), 3);
		world.setBlockState(new BlockPos(i + 7, j + 5, k + 3), Block.getBlockById(9).getStateFromMeta(0), 3);
		world.setBlockState(new BlockPos(i + 0, j + 5, k + 4), Block.getBlockById(20).getStateFromMeta(0), 3);
		world.setBlockState(new BlockPos(i + 1, j + 5, k + 4), Block.getBlockById(0).getStateFromMeta(0), 3);
		world.setBlockState(new BlockPos(i + 2, j + 5, k + 4), Block.getBlockById(0).getStateFromMeta(0), 3);
		world.setBlockState(new BlockPos(i + 3, j + 5, k + 4), Block.getBlockById(0).getStateFromMeta(0), 3);
		world.setBlockState(new BlockPos(i + 4, j + 5, k + 4), Block.getBlockById(0).getStateFromMeta(0), 3);
		world.setBlockState(new BlockPos(i + 5, j + 5, k + 4), Block.getBlockById(0).getStateFromMeta(0), 3);
		world.setBlockState(new BlockPos(i + 6, j + 5, k + 4), Block.getBlockById(20).getStateFromMeta(0), 3);
		world.setBlockState(new BlockPos(i + 7, j + 5, k + 4), Block.getBlockById(9).getStateFromMeta(0), 3);
		world.setBlockState(new BlockPos(i + 0, j + 5, k + 5), Block.getBlockById(20).getStateFromMeta(0), 3);
		world.setBlockState(new BlockPos(i + 1, j + 5, k + 5), Block.getBlockById(0).getStateFromMeta(0), 3);
		world.setBlockState(new BlockPos(i + 2, j + 5, k + 5), Block.getBlockById(0).getStateFromMeta(0), 3);
		world.setBlockState(new BlockPos(i + 3, j + 5, k + 5), Block.getBlockById(0).getStateFromMeta(0), 3);
		world.setBlockState(new BlockPos(i + 4, j + 5, k + 5), Block.getBlockById(0).getStateFromMeta(0), 3);
		world.setBlockState(new BlockPos(i + 5, j + 5, k + 5), Block.getBlockById(0).getStateFromMeta(0), 3);
		world.setBlockState(new BlockPos(i + 6, j + 5, k + 5), Block.getBlockById(20).getStateFromMeta(0), 3);
		world.setBlockState(new BlockPos(i + 7, j + 5, k + 5), Block.getBlockById(9).getStateFromMeta(0), 3);
		world.setBlockState(new BlockPos(i + 0, j + 5, k + 6), Block.getBlockById(20).getStateFromMeta(0), 3);
		world.setBlockState(new BlockPos(i + 1, j + 5, k + 6), Block.getBlockById(0).getStateFromMeta(0), 3);
		world.setBlockState(new BlockPos(i + 2, j + 5, k + 6), Block.getBlockById(0).getStateFromMeta(0), 3);
		world.setBlockState(new BlockPos(i + 3, j + 5, k + 6), Block.getBlockById(0).getStateFromMeta(0), 3);
		world.setBlockState(new BlockPos(i + 4, j + 5, k + 6), Block.getBlockById(0).getStateFromMeta(0), 3);
		world.setBlockState(new BlockPos(i + 5, j + 5, k + 6), Block.getBlockById(0).getStateFromMeta(0), 3);
		world.setBlockState(new BlockPos(i + 6, j + 5, k + 6), Block.getBlockById(20).getStateFromMeta(0), 3);
		world.setBlockState(new BlockPos(i + 7, j + 5, k + 6), Block.getBlockById(9).getStateFromMeta(0), 3);
		world.setBlockState(new BlockPos(i + 0, j + 5, k + 7), Block.getBlockById(42).getStateFromMeta(0), 3);
		world.setBlockState(new BlockPos(i + 1, j + 5, k + 7), Block.getBlockById(20).getStateFromMeta(0), 3);
		world.setBlockState(new BlockPos(i + 2, j + 5, k + 7), Block.getBlockById(20).getStateFromMeta(0), 3);
		world.setBlockState(new BlockPos(i + 3, j + 5, k + 7), Block.getBlockById(20).getStateFromMeta(0), 3);
		world.setBlockState(new BlockPos(i + 4, j + 5, k + 7), Block.getBlockById(20).getStateFromMeta(0), 3);
		world.setBlockState(new BlockPos(i + 5, j + 5, k + 7), Block.getBlockById(20).getStateFromMeta(0), 3);
		world.setBlockState(new BlockPos(i + 6, j + 5, k + 7), Block.getBlockById(42).getStateFromMeta(0), 3);
		world.setBlockState(new BlockPos(i + 7, j + 5, k + 7), Block.getBlockById(9).getStateFromMeta(0), 3);
		world.setBlockState(new BlockPos(i + 0, j + 6, k + 0), Block.getBlockById(42).getStateFromMeta(0), 3);
		world.setBlockState(new BlockPos(i + 1, j + 6, k + 0), Block.getBlockById(20).getStateFromMeta(0), 3);
		world.setBlockState(new BlockPos(i + 2, j + 6, k + 0), Block.getBlockById(20).getStateFromMeta(0), 3);
		world.setBlockState(new BlockPos(i + 3, j + 6, k + 0), Block.getBlockById(20).getStateFromMeta(0), 3);
		world.setBlockState(new BlockPos(i + 4, j + 6, k + 0), Block.getBlockById(20).getStateFromMeta(0), 3);
		world.setBlockState(new BlockPos(i + 5, j + 6, k + 0), Block.getBlockById(20).getStateFromMeta(0), 3);
		world.setBlockState(new BlockPos(i + 6, j + 6, k + 0), Block.getBlockById(42).getStateFromMeta(0), 3);
		world.setBlockState(new BlockPos(i + 7, j + 6, k + 0), Block.getBlockById(9).getStateFromMeta(0), 3);
		world.setBlockState(new BlockPos(i + 0, j + 6, k + 1), Block.getBlockById(20).getStateFromMeta(0), 3);
		world.setBlockState(new BlockPos(i + 1, j + 6, k + 1), Block.getBlockById(0).getStateFromMeta(0), 3);
		world.setBlockState(new BlockPos(i + 2, j + 6, k + 1), Block.getBlockById(0).getStateFromMeta(0), 3);
		world.setBlockState(new BlockPos(i + 3, j + 6, k + 1), Block.getBlockById(0).getStateFromMeta(0), 3);
		world.setBlockState(new BlockPos(i + 4, j + 6, k + 1), Block.getBlockById(0).getStateFromMeta(0), 3);
		world.setBlockState(new BlockPos(i + 5, j + 6, k + 1), Block.getBlockById(0).getStateFromMeta(0), 3);
		world.setBlockState(new BlockPos(i + 6, j + 6, k + 1), Block.getBlockById(20).getStateFromMeta(0), 3);
		world.setBlockState(new BlockPos(i + 7, j + 6, k + 1), Block.getBlockById(9).getStateFromMeta(0), 3);
		world.setBlockState(new BlockPos(i + 0, j + 6, k + 2), Block.getBlockById(20).getStateFromMeta(0), 3);
		world.setBlockState(new BlockPos(i + 1, j + 6, k + 2), Block.getBlockById(0).getStateFromMeta(0), 3);
		world.setBlockState(new BlockPos(i + 2, j + 6, k + 2), Block.getBlockById(0).getStateFromMeta(0), 3);
		world.setBlockState(new BlockPos(i + 3, j + 6, k + 2), Block.getBlockById(0).getStateFromMeta(0), 3);
		world.setBlockState(new BlockPos(i + 4, j + 6, k + 2), Block.getBlockById(0).getStateFromMeta(0), 3);
		world.setBlockState(new BlockPos(i + 5, j + 6, k + 2), Block.getBlockById(0).getStateFromMeta(0), 3);
		world.setBlockState(new BlockPos(i + 6, j + 6, k + 2), Block.getBlockById(20).getStateFromMeta(0), 3);
		world.setBlockState(new BlockPos(i + 7, j + 6, k + 2), Block.getBlockById(9).getStateFromMeta(0), 3);
		world.setBlockState(new BlockPos(i + 0, j + 6, k + 3), Block.getBlockById(20).getStateFromMeta(0), 3);
		world.setBlockState(new BlockPos(i + 1, j + 6, k + 3), Block.getBlockById(0).getStateFromMeta(0), 3);
		world.setBlockState(new BlockPos(i + 2, j + 6, k + 3), Block.getBlockById(0).getStateFromMeta(0), 3);
		world.setBlockState(new BlockPos(i + 3, j + 6, k + 3), Block.getBlockById(0).getStateFromMeta(0), 3);
		world.setBlockState(new BlockPos(i + 4, j + 6, k + 3), Block.getBlockById(0).getStateFromMeta(0), 3);
		world.setBlockState(new BlockPos(i + 5, j + 6, k + 3), Block.getBlockById(0).getStateFromMeta(0), 3);
		world.setBlockState(new BlockPos(i + 6, j + 6, k + 3), Block.getBlockById(20).getStateFromMeta(0), 3);
		world.setBlockState(new BlockPos(i + 7, j + 6, k + 3), Block.getBlockById(9).getStateFromMeta(0), 3);
		world.setBlockState(new BlockPos(i + 0, j + 6, k + 4), Block.getBlockById(20).getStateFromMeta(0), 3);
		world.setBlockState(new BlockPos(i + 1, j + 6, k + 4), Block.getBlockById(0).getStateFromMeta(0), 3);
		world.setBlockState(new BlockPos(i + 2, j + 6, k + 4), Block.getBlockById(0).getStateFromMeta(0), 3);
		world.setBlockState(new BlockPos(i + 3, j + 6, k + 4), Block.getBlockById(0).getStateFromMeta(0), 3);
		world.setBlockState(new BlockPos(i + 4, j + 6, k + 4), Block.getBlockById(0).getStateFromMeta(0), 3);
		world.setBlockState(new BlockPos(i + 5, j + 6, k + 4), Block.getBlockById(0).getStateFromMeta(0), 3);
		world.setBlockState(new BlockPos(i + 6, j + 6, k + 4), Block.getBlockById(20).getStateFromMeta(0), 3);
		world.setBlockState(new BlockPos(i + 7, j + 6, k + 4), Block.getBlockById(9).getStateFromMeta(0), 3);
		world.setBlockState(new BlockPos(i + 0, j + 6, k + 5), Block.getBlockById(20).getStateFromMeta(0), 3);
		world.setBlockState(new BlockPos(i + 1, j + 6, k + 5), Block.getBlockById(0).getStateFromMeta(0), 3);
		world.setBlockState(new BlockPos(i + 2, j + 6, k + 5), Block.getBlockById(0).getStateFromMeta(0), 3);
		world.setBlockState(new BlockPos(i + 3, j + 6, k + 5), Block.getBlockById(0).getStateFromMeta(0), 3);
		world.setBlockState(new BlockPos(i + 4, j + 6, k + 5), Block.getBlockById(0).getStateFromMeta(0), 3);
		world.setBlockState(new BlockPos(i + 5, j + 6, k + 5), Block.getBlockById(0).getStateFromMeta(0), 3);
		world.setBlockState(new BlockPos(i + 6, j + 6, k + 5), Block.getBlockById(20).getStateFromMeta(0), 3);
		world.setBlockState(new BlockPos(i + 7, j + 6, k + 5), Block.getBlockById(9).getStateFromMeta(0), 3);
		world.setBlockState(new BlockPos(i + 0, j + 6, k + 6), Block.getBlockById(20).getStateFromMeta(0), 3);
		world.setBlockState(new BlockPos(i + 1, j + 6, k + 6), Block.getBlockById(0).getStateFromMeta(0), 3);
		world.setBlockState(new BlockPos(i + 2, j + 6, k + 6), Block.getBlockById(0).getStateFromMeta(0), 3);
		world.setBlockState(new BlockPos(i + 3, j + 6, k + 6), Block.getBlockById(0).getStateFromMeta(0), 3);
		world.setBlockState(new BlockPos(i + 4, j + 6, k + 6), Block.getBlockById(0).getStateFromMeta(0), 3);
		world.setBlockState(new BlockPos(i + 5, j + 6, k + 6), Block.getBlockById(0).getStateFromMeta(0), 3);
		world.setBlockState(new BlockPos(i + 6, j + 6, k + 6), Block.getBlockById(20).getStateFromMeta(0), 3);
		world.setBlockState(new BlockPos(i + 7, j + 6, k + 6), Block.getBlockById(9).getStateFromMeta(0), 3);
		world.setBlockState(new BlockPos(i + 0, j + 6, k + 7), Block.getBlockById(42).getStateFromMeta(0), 3);
		world.setBlockState(new BlockPos(i + 1, j + 6, k + 7), Block.getBlockById(20).getStateFromMeta(0), 3);
		world.setBlockState(new BlockPos(i + 2, j + 6, k + 7), Block.getBlockById(20).getStateFromMeta(0), 3);
		world.setBlockState(new BlockPos(i + 3, j + 6, k + 7), Block.getBlockById(20).getStateFromMeta(0), 3);
		world.setBlockState(new BlockPos(i + 4, j + 6, k + 7), Block.getBlockById(20).getStateFromMeta(0), 3);
		world.setBlockState(new BlockPos(i + 5, j + 6, k + 7), Block.getBlockById(20).getStateFromMeta(0), 3);
		world.setBlockState(new BlockPos(i + 6, j + 6, k + 7), Block.getBlockById(42).getStateFromMeta(0), 3);
		world.setBlockState(new BlockPos(i + 7, j + 6, k + 7), Block.getBlockById(9).getStateFromMeta(0), 3);
		world.setBlockState(new BlockPos(i + 0, j + 7, k + 0), Block.getBlockById(42).getStateFromMeta(0), 3);
		world.setBlockState(new BlockPos(i + 1, j + 7, k + 0), Block.getBlockById(42).getStateFromMeta(0), 3);
		world.setBlockState(new BlockPos(i + 2, j + 7, k + 0), Block.getBlockById(42).getStateFromMeta(0), 3);
		world.setBlockState(new BlockPos(i + 3, j + 7, k + 0), Block.getBlockById(42).getStateFromMeta(0), 3);
		world.setBlockState(new BlockPos(i + 4, j + 7, k + 0), Block.getBlockById(42).getStateFromMeta(0), 3);
		world.setBlockState(new BlockPos(i + 5, j + 7, k + 0), Block.getBlockById(42).getStateFromMeta(0), 3);
		world.setBlockState(new BlockPos(i + 6, j + 7, k + 0), Block.getBlockById(42).getStateFromMeta(0), 3);
		world.setBlockState(new BlockPos(i + 7, j + 7, k + 0), Block.getBlockById(9).getStateFromMeta(0), 3);
		world.setBlockState(new BlockPos(i + 0, j + 7, k + 1), Block.getBlockById(42).getStateFromMeta(0), 3);
		world.setBlockState(new BlockPos(i + 1, j + 7, k + 1), Block.getBlockById(20).getStateFromMeta(0), 3);
		world.setBlockState(new BlockPos(i + 2, j + 7, k + 1), Block.getBlockById(20).getStateFromMeta(0), 3);
		world.setBlockState(new BlockPos(i + 3, j + 7, k + 1), Block.getBlockById(20).getStateFromMeta(0), 3);
		world.setBlockState(new BlockPos(i + 4, j + 7, k + 1), Block.getBlockById(20).getStateFromMeta(0), 3);
		world.setBlockState(new BlockPos(i + 5, j + 7, k + 1), Block.getBlockById(20).getStateFromMeta(0), 3);
		world.setBlockState(new BlockPos(i + 6, j + 7, k + 1), Block.getBlockById(42).getStateFromMeta(0), 3);
		world.setBlockState(new BlockPos(i + 7, j + 7, k + 1), Block.getBlockById(9).getStateFromMeta(0), 3);
		world.setBlockState(new BlockPos(i + 0, j + 7, k + 2), Block.getBlockById(42).getStateFromMeta(0), 3);
		world.setBlockState(new BlockPos(i + 1, j + 7, k + 2), Block.getBlockById(20).getStateFromMeta(0), 3);
		world.setBlockState(new BlockPos(i + 2, j + 7, k + 2), Block.getBlockById(20).getStateFromMeta(0), 3);
		world.setBlockState(new BlockPos(i + 3, j + 7, k + 2), Block.getBlockById(20).getStateFromMeta(0), 3);
		world.setBlockState(new BlockPos(i + 4, j + 7, k + 2), Block.getBlockById(20).getStateFromMeta(0), 3);
		world.setBlockState(new BlockPos(i + 5, j + 7, k + 2), Block.getBlockById(20).getStateFromMeta(0), 3);
		world.setBlockState(new BlockPos(i + 6, j + 7, k + 2), Block.getBlockById(42).getStateFromMeta(0), 3);
		world.setBlockState(new BlockPos(i + 7, j + 7, k + 2), Block.getBlockById(9).getStateFromMeta(0), 3);
		world.setBlockState(new BlockPos(i + 0, j + 7, k + 3), Block.getBlockById(42).getStateFromMeta(0), 3);
		world.setBlockState(new BlockPos(i + 1, j + 7, k + 3), Block.getBlockById(20).getStateFromMeta(0), 3);
		world.setBlockState(new BlockPos(i + 2, j + 7, k + 3), Block.getBlockById(20).getStateFromMeta(0), 3);
		world.setBlockState(new BlockPos(i + 3, j + 7, k + 3), Block.getBlockById(20).getStateFromMeta(0), 3);
		world.setBlockState(new BlockPos(i + 4, j + 7, k + 3), Block.getBlockById(20).getStateFromMeta(0), 3);
		world.setBlockState(new BlockPos(i + 5, j + 7, k + 3), Block.getBlockById(20).getStateFromMeta(0), 3);
		world.setBlockState(new BlockPos(i + 6, j + 7, k + 3), Block.getBlockById(42).getStateFromMeta(0), 3);
		world.setBlockState(new BlockPos(i + 7, j + 7, k + 3), Block.getBlockById(9).getStateFromMeta(0), 3);
		world.setBlockState(new BlockPos(i + 0, j + 7, k + 4), Block.getBlockById(42).getStateFromMeta(0), 3);
		world.setBlockState(new BlockPos(i + 1, j + 7, k + 4), Block.getBlockById(20).getStateFromMeta(0), 3);
		world.setBlockState(new BlockPos(i + 2, j + 7, k + 4), Block.getBlockById(20).getStateFromMeta(0), 3);
		world.setBlockState(new BlockPos(i + 3, j + 7, k + 4), Block.getBlockById(20).getStateFromMeta(0), 3);
		world.setBlockState(new BlockPos(i + 4, j + 7, k + 4), Block.getBlockById(20).getStateFromMeta(0), 3);
		world.setBlockState(new BlockPos(i + 5, j + 7, k + 4), Block.getBlockById(20).getStateFromMeta(0), 3);
		world.setBlockState(new BlockPos(i + 6, j + 7, k + 4), Block.getBlockById(42).getStateFromMeta(0), 3);
		world.setBlockState(new BlockPos(i + 7, j + 7, k + 4), Block.getBlockById(9).getStateFromMeta(0), 3);
		world.setBlockState(new BlockPos(i + 0, j + 7, k + 5), Block.getBlockById(42).getStateFromMeta(0), 3);
		world.setBlockState(new BlockPos(i + 1, j + 7, k + 5), Block.getBlockById(20).getStateFromMeta(0), 3);
		world.setBlockState(new BlockPos(i + 2, j + 7, k + 5), Block.getBlockById(20).getStateFromMeta(0), 3);
		world.setBlockState(new BlockPos(i + 3, j + 7, k + 5), Block.getBlockById(20).getStateFromMeta(0), 3);
		world.setBlockState(new BlockPos(i + 4, j + 7, k + 5), Block.getBlockById(20).getStateFromMeta(0), 3);
		world.setBlockState(new BlockPos(i + 5, j + 7, k + 5), Block.getBlockById(20).getStateFromMeta(0), 3);
		world.setBlockState(new BlockPos(i + 6, j + 7, k + 5), Block.getBlockById(42).getStateFromMeta(0), 3);
		world.setBlockState(new BlockPos(i + 7, j + 7, k + 5), Block.getBlockById(9).getStateFromMeta(0), 3);
		world.setBlockState(new BlockPos(i + 0, j + 7, k + 6), Block.getBlockById(42).getStateFromMeta(0), 3);
		world.setBlockState(new BlockPos(i + 1, j + 7, k + 6), Block.getBlockById(20).getStateFromMeta(0), 3);
		world.setBlockState(new BlockPos(i + 2, j + 7, k + 6), Block.getBlockById(20).getStateFromMeta(0), 3);
		world.setBlockState(new BlockPos(i + 3, j + 7, k + 6), Block.getBlockById(20).getStateFromMeta(0), 3);
		world.setBlockState(new BlockPos(i + 4, j + 7, k + 6), Block.getBlockById(20).getStateFromMeta(0), 3);
		world.setBlockState(new BlockPos(i + 5, j + 7, k + 6), Block.getBlockById(20).getStateFromMeta(0), 3);
		world.setBlockState(new BlockPos(i + 6, j + 7, k + 6), Block.getBlockById(42).getStateFromMeta(0), 3);
		world.setBlockState(new BlockPos(i + 7, j + 7, k + 6), Block.getBlockById(9).getStateFromMeta(0), 3);
		world.setBlockState(new BlockPos(i + 0, j + 7, k + 7), Block.getBlockById(42).getStateFromMeta(0), 3);
		world.setBlockState(new BlockPos(i + 1, j + 7, k + 7), Block.getBlockById(42).getStateFromMeta(0), 3);
		world.setBlockState(new BlockPos(i + 2, j + 7, k + 7), Block.getBlockById(42).getStateFromMeta(0), 3);
		world.setBlockState(new BlockPos(i + 3, j + 7, k + 7), Block.getBlockById(42).getStateFromMeta(0), 3);
		world.setBlockState(new BlockPos(i + 4, j + 7, k + 7), Block.getBlockById(42).getStateFromMeta(0), 3);
		world.setBlockState(new BlockPos(i + 5, j + 7, k + 7), Block.getBlockById(42).getStateFromMeta(0), 3);
		world.setBlockState(new BlockPos(i + 6, j + 7, k + 7), Block.getBlockById(42).getStateFromMeta(0), 3);
		world.setBlockState(new BlockPos(i + 7, j + 7, k + 7), Block.getBlockById(9).getStateFromMeta(0), 3);
	}
}