package net.modjam5.makercommunity.common.world.structure;

import java.util.ArrayList;
import java.util.Collections;
import java.util.List;
import java.util.Random;

import javax.annotation.Nullable;

import net.minecraft.block.Block;
import net.minecraft.enchantment.Enchantment;
import net.minecraft.entity.monster.EntityElderGuardian;
import net.minecraft.entity.monster.EntitySkeleton;
import net.minecraft.init.*;
import net.minecraft.inventory.EntityEquipmentSlot;
import net.minecraft.item.ItemStack;
import net.minecraft.util.EnumHand;
import net.minecraft.util.math.BlockPos;
import net.minecraft.world.World;
import net.minecraft.world.biome.Biome;
import net.minecraft.world.biome.BiomeProvider;
import net.minecraft.world.chunk.Chunk;
import net.minecraft.world.gen.structure.MapGenStructure;
import net.minecraft.world.gen.structure.StructureBoundingBox;
import net.minecraft.world.gen.structure.StructureStart;
import net.modjam5.makercommunity.common.BlockRegistry;
import net.modjam5.makercommunity.common.ItemRegistry;
import net.modjam5.makercommunity.common.entity.EntityTriggerArmorStand;
import net.modjam5.makercommunity.util.EnchantingHelper;
import net.modjam5.makercommunity.util.TippedArrowUtil;

/**
 * @author Tim Biesenbeek
 */
public class EndStructure extends MapGenStructure implements Structure {

	private static final StructureBoundingBox boundingBox = new StructureBoundingBox(new int[]{0, 0, 0, 8, 8, 8});
	private static final List<Biome> ALLOWED_BIOMES = Collections.singletonList(Biomes.DEEP_OCEAN);

	@Override
	public void updateWorld(World world) {
		this.world = world;
	}

	@Override
	public StructureBoundingBox getBoundingBox() {
		return boundingBox;
	}

	@Override
	public String getStructureName() {
		return "SubHouse";
	}

	@Nullable
	@Override
	public BlockPos getNearestStructurePos(World worldIn, BlockPos pos, boolean findUnexplored) {
		updateWorld(worldIn);
		BiomeProvider biomeprovider = worldIn.getBiomeProvider();
		return biomeprovider.isFixedBiome() && biomeprovider.getFixedBiome() != Biomes.BEACH ? null
				: findNearestStructurePosBySpacing(worldIn, this, pos, 80, 20, 10387319, true, 100, findUnexplored);
	}

	@Override
	public boolean canSpawnStructureAtCoords(int chunkX, int chunkZ) {
		return canSpawnStructureAtCoords(world, chunkX, chunkZ);
	}

	public static boolean canSpawnStructureAtCoords(World world, int chunkX, int chunkZ) {
		if (Math.abs(chunkX) < 120 || Math.abs(chunkZ) < 120) {
			return false;
		}
		Random random = world.setRandomSeed(2304 * chunkX, 1996 * chunkZ, 1337);
		boolean rand = random.nextInt(1000) + 1 <= 1;
		boolean biome = world.getBiomeProvider().areBiomesViable(chunkX * 16 + 8, chunkZ * 16 + 8, 1, ALLOWED_BIOMES);
		return rand && biome;
	}

	@Override
	protected StructureStart getStructureStart(int chunkX, int chunkZ) {
		return new Start(this, chunkX, chunkZ);
	}

	@SuppressWarnings("deprecation")
	public void generate(World world, Random random, int xPos, int zPos) {
		int i = xPos + random.nextInt(15);
		int k = zPos + random.nextInt(15);

		int chunkX = i >> 4;
		int chunkZ = k >> 4;
		Chunk chunk = world.getChunkFromChunkCoords(chunkX, chunkZ);
		int height = chunk.getHeight(new BlockPos(i & 0xF, 0, k & 0xF)) - 1;
		int y;
		for (y = chunk.getHeight(new BlockPos(i & 0xF, 0, k & 0xF)) - 1; y > 10; y--) {
			Block block = chunk.getBlockState(i, y, k).getBlock();
			if (block == Blocks.WATER || block == Blocks.FLOWING_WATER) {
				continue;
			}
			break;
		}

		int j = y;

		EntityElderGuardian elder = new EntityElderGuardian(world);
		elder.setLocationAndAngles(i + 4.9987499713897705, j + 2.0, k + 15.293150894955033,
			world.rand.nextFloat() * 360F, 0);
		world.spawnEntity(elder);

		EntitySkeleton skelly = new EntitySkeleton(world);
		skelly.setLocationAndAngles(i + 17.5, j + 2, k + 18.5,
			world.rand.nextFloat() * 360F, 0);
		skelly.setHeldItem(EnumHand.MAIN_HAND, EnchantingHelper.withEnchants(new ItemStack(Items.BOW),
			new Enchantment[]{Enchantments.PUNCH, Enchantments.POWER}, new int[]{5, 5}));
		skelly.setHeldItem(EnumHand.OFF_HAND, TippedArrowUtil.tippedArrow(PotionTypes.LONG_POISON, new ArrayList<>()));
		world.spawnEntity(skelly);
		
		EntityTriggerArmorStand armorStand = new EntityTriggerArmorStand(world, i + 10, j + 6, k + 14);
		armorStand.setSummonOnTrigger(EntityElderGuardian.class);
		armorStand.setTickDelay(1 * 20);
		armorStand.setItemStackToSlot(EntityEquipmentSlot.OFFHAND, new ItemStack(ItemRegistry.recorders[12]));
		armorStand.setItemStackToSlot(EntityEquipmentSlot.HEAD, new ItemStack(ItemRegistry.recorders[13]));
		world.spawnEntity(armorStand);
		

		world.setBlockState(new BlockPos(i + 14, j + 0, k + 0), Block.getBlockById(1).getStateFromMeta(5), 2);
		world.setBlockState(new BlockPos(i + 15, j + 0, k + 0), Block.getBlockById(1).getStateFromMeta(5), 2);
		world.setBlockState(new BlockPos(i + 16, j + 0, k + 0), Block.getBlockById(1).getStateFromMeta(0), 2);
		world.setBlockState(new BlockPos(i + 17, j + 0, k + 0), Block.getBlockById(1).getStateFromMeta(0), 2);
		world.setBlockState(new BlockPos(i + 18, j + 0, k + 0), Block.getBlockById(1).getStateFromMeta(0), 2);
		world.setBlockState(new BlockPos(i + 19, j + 0, k + 0), Block.getBlockById(1).getStateFromMeta(0), 2);
		world.setBlockState(new BlockPos(i + 20, j + 0, k + 0), Block.getBlockById(1).getStateFromMeta(0), 2);
		world.setBlockState(new BlockPos(i + 21, j + 0, k + 0), Block.getBlockById(1).getStateFromMeta(0), 2);
		world.setBlockState(new BlockPos(i + 22, j + 0, k + 0), Block.getBlockById(1).getStateFromMeta(0), 2);
		world.setBlockState(new BlockPos(i + 15, j + 0, k + 1), Block.getBlockById(1).getStateFromMeta(5), 2);
		world.setBlockState(new BlockPos(i + 16, j + 0, k + 1), Block.getBlockById(1).getStateFromMeta(0), 2);
		world.setBlockState(new BlockPos(i + 17, j + 0, k + 1), Block.getBlockById(1).getStateFromMeta(0), 2);
		world.setBlockState(new BlockPos(i + 18, j + 0, k + 1), Block.getBlockById(1).getStateFromMeta(0), 2);
		world.setBlockState(new BlockPos(i + 19, j + 0, k + 1), Block.getBlockById(1).getStateFromMeta(0), 2);
		world.setBlockState(new BlockPos(i + 20, j + 0, k + 1), Block.getBlockById(1).getStateFromMeta(0), 2);
		world.setBlockState(new BlockPos(i + 21, j + 0, k + 1), Block.getBlockById(1).getStateFromMeta(0), 2);
		world.setBlockState(new BlockPos(i + 22, j + 0, k + 1), Block.getBlockById(1).getStateFromMeta(0), 2);
		world.setBlockState(new BlockPos(i + 16, j + 0, k + 2), Block.getBlockById(1).getStateFromMeta(0), 2);
		world.setBlockState(new BlockPos(i + 17, j + 0, k + 2), Block.getBlockById(1).getStateFromMeta(0), 2);
		world.setBlockState(new BlockPos(i + 18, j + 0, k + 2), Block.getBlockById(1).getStateFromMeta(0), 2);
		world.setBlockState(new BlockPos(i + 19, j + 0, k + 2), Block.getBlockById(1).getStateFromMeta(0), 2);
		world.setBlockState(new BlockPos(i + 20, j + 0, k + 2), Block.getBlockById(1).getStateFromMeta(0), 2);
		world.setBlockState(new BlockPos(i + 21, j + 0, k + 2), Block.getBlockById(1).getStateFromMeta(3), 2);
		world.setBlockState(new BlockPos(i + 22, j + 0, k + 2), Block.getBlockById(1).getStateFromMeta(3), 2);
		world.setBlockState(new BlockPos(i + 21, j + 0, k + 3), Block.getBlockById(1).getStateFromMeta(3), 2);
		world.setBlockState(new BlockPos(i + 22, j + 0, k + 3), Block.getBlockById(1).getStateFromMeta(3), 2);
		world.setBlockState(new BlockPos(i + 21, j + 0, k + 4), Block.getBlockById(1).getStateFromMeta(3), 2);
		world.setBlockState(new BlockPos(i + 22, j + 0, k + 4), Block.getBlockById(1).getStateFromMeta(3), 2);
		world.setBlockState(new BlockPos(i + 2, j + 0, k + 22), Block.getBlockById(1).getStateFromMeta(0), 2);
		world.setBlockState(new BlockPos(i + 3, j + 0, k + 22), Block.getBlockById(1).getStateFromMeta(0), 2);
		world.setBlockState(new BlockPos(i + 4, j + 0, k + 22), Block.getBlockById(1).getStateFromMeta(0), 2);
		world.setBlockState(new BlockPos(i + 5, j + 0, k + 22), Block.getBlockById(1).getStateFromMeta(0), 2);
		world.setBlockState(new BlockPos(i + 6, j + 0, k + 22), Block.getBlockById(1).getStateFromMeta(0), 2);
		world.setBlockState(new BlockPos(i + 7, j + 0, k + 22), Block.getBlockById(1).getStateFromMeta(0), 2);
		world.setBlockState(new BlockPos(i + 8, j + 0, k + 22), Block.getBlockById(1).getStateFromMeta(0), 2);
		world.setBlockState(new BlockPos(i + 9, j + 0, k + 22), Block.getBlockById(1).getStateFromMeta(0), 2);
		world.setBlockState(new BlockPos(i + 10, j + 0, k + 22), Block.getBlockById(1).getStateFromMeta(0), 2);
		world.setBlockState(new BlockPos(i + 11, j + 0, k + 22), Block.getBlockById(1).getStateFromMeta(0), 2);
		world.setBlockState(new BlockPos(i + 12, j + 0, k + 22), Block.getBlockById(1).getStateFromMeta(0), 2);
		world.setBlockState(new BlockPos(i + 13, j + 0, k + 22), Block.getBlockById(1).getStateFromMeta(0), 2);
		world.setBlockState(new BlockPos(i + 2, j + 0, k + 23), Block.getBlockById(1).getStateFromMeta(0), 2);
		world.setBlockState(new BlockPos(i + 3, j + 0, k + 23), Block.getBlockById(1).getStateFromMeta(0), 2);
		world.setBlockState(new BlockPos(i + 4, j + 0, k + 23), Block.getBlockById(1).getStateFromMeta(0), 2);
		world.setBlockState(new BlockPos(i + 5, j + 0, k + 23), Block.getBlockById(1).getStateFromMeta(0), 2);
		world.setBlockState(new BlockPos(i + 6, j + 0, k + 23), Block.getBlockById(1).getStateFromMeta(0), 2);
		world.setBlockState(new BlockPos(i + 7, j + 0, k + 23), Block.getBlockById(1).getStateFromMeta(0), 2);
		world.setBlockState(new BlockPos(i + 8, j + 0, k + 23), Block.getBlockById(1).getStateFromMeta(0), 2);
		world.setBlockState(new BlockPos(i + 9, j + 0, k + 23), Block.getBlockById(1).getStateFromMeta(0), 2);
		world.setBlockState(new BlockPos(i + 10, j + 0, k + 23), Block.getBlockById(1).getStateFromMeta(0), 2);
		world.setBlockState(new BlockPos(i + 11, j + 0, k + 23), Block.getBlockById(1).getStateFromMeta(0), 2);
		world.setBlockState(new BlockPos(i + 12, j + 0, k + 23), Block.getBlockById(1).getStateFromMeta(0), 2);
		world.setBlockState(new BlockPos(i + 13, j + 0, k + 23), Block.getBlockById(1).getStateFromMeta(0), 2);
		world.setBlockState(new BlockPos(i + 1, j + 0, k + 24), Block.getBlockById(1).getStateFromMeta(0), 2);
		world.setBlockState(new BlockPos(i + 2, j + 0, k + 24), Block.getBlockById(1).getStateFromMeta(0), 2);
		world.setBlockState(new BlockPos(i + 3, j + 0, k + 24), Block.getBlockById(1).getStateFromMeta(0), 2);
		world.setBlockState(new BlockPos(i + 4, j + 0, k + 24), Block.getBlockById(1).getStateFromMeta(0), 2);
		world.setBlockState(new BlockPos(i + 5, j + 0, k + 24), Block.getBlockById(1).getStateFromMeta(0), 2);
		world.setBlockState(new BlockPos(i + 6, j + 0, k + 24), Block.getBlockById(1).getStateFromMeta(0), 2);
		world.setBlockState(new BlockPos(i + 7, j + 0, k + 24), Block.getBlockById(1).getStateFromMeta(0), 2);
		world.setBlockState(new BlockPos(i + 8, j + 0, k + 24), Block.getBlockById(1).getStateFromMeta(0), 2);
		world.setBlockState(new BlockPos(i + 9, j + 0, k + 24), Block.getBlockById(1).getStateFromMeta(3), 2);
		world.setBlockState(new BlockPos(i + 10, j + 0, k + 24), Block.getBlockById(1).getStateFromMeta(3), 2);
		world.setBlockState(new BlockPos(i + 11, j + 0, k + 24), Block.getBlockById(1).getStateFromMeta(3), 2);
		world.setBlockState(new BlockPos(i + 12, j + 0, k + 24), Block.getBlockById(1).getStateFromMeta(3), 2);
		world.setBlockState(new BlockPos(i + 1, j + 0, k + 25), Block.getBlockById(1).getStateFromMeta(0), 2);
		world.setBlockState(new BlockPos(i + 2, j + 0, k + 25), Block.getBlockById(1).getStateFromMeta(0), 2);
		world.setBlockState(new BlockPos(i + 4, j + 0, k + 25), Block.getBlockById(1).getStateFromMeta(0), 2);
		world.setBlockState(new BlockPos(i + 5, j + 0, k + 25), Block.getBlockById(1).getStateFromMeta(0), 2);
		world.setBlockState(new BlockPos(i + 6, j + 0, k + 25), Block.getBlockById(1).getStateFromMeta(3), 2);
		world.setBlockState(new BlockPos(i + 7, j + 0, k + 25), Block.getBlockById(1).getStateFromMeta(3), 2);
		world.setBlockState(new BlockPos(i + 8, j + 0, k + 25), Block.getBlockById(1).getStateFromMeta(3), 2);
		world.setBlockState(new BlockPos(i + 9, j + 0, k + 25), Block.getBlockById(1).getStateFromMeta(3), 2);
		world.setBlockState(new BlockPos(i + 10, j + 0, k + 25), Block.getBlockById(1).getStateFromMeta(3), 2);
		world.setBlockState(new BlockPos(i + 11, j + 0, k + 25), Block.getBlockById(1).getStateFromMeta(3), 2);
		world.setBlockState(new BlockPos(i + 12, j + 0, k + 25), Block.getBlockById(1).getStateFromMeta(3), 2);
		world.setBlockState(new BlockPos(i + 1, j + 0, k + 26), Block.getBlockById(1).getStateFromMeta(0), 2);
		world.setBlockState(new BlockPos(i + 4, j + 0, k + 26), Block.getBlockById(1).getStateFromMeta(0), 2);
		world.setBlockState(new BlockPos(i + 5, j + 0, k + 26), Block.getBlockById(1).getStateFromMeta(3), 2);
		world.setBlockState(new BlockPos(i + 6, j + 0, k + 26), Block.getBlockById(1).getStateFromMeta(3), 2);
		world.setBlockState(new BlockPos(i + 7, j + 0, k + 26), Block.getBlockById(1).getStateFromMeta(3), 2);
		world.setBlockState(new BlockPos(i + 8, j + 0, k + 26), Block.getBlockById(1).getStateFromMeta(3), 2);
		world.setBlockState(new BlockPos(i + 9, j + 0, k + 26), Block.getBlockById(1).getStateFromMeta(3), 2);
		world.setBlockState(new BlockPos(i + 10, j + 0, k + 26), Block.getBlockById(1).getStateFromMeta(3), 2);
		world.setBlockState(new BlockPos(i + 11, j + 0, k + 26), Block.getBlockById(1).getStateFromMeta(3), 2);
		world.setBlockState(new BlockPos(i + 12, j + 0, k + 26), Block.getBlockById(1).getStateFromMeta(3), 2);
		world.setBlockState(new BlockPos(i + 5, j + 0, k + 27), Block.getBlockById(1).getStateFromMeta(3), 2);
		world.setBlockState(new BlockPos(i + 6, j + 0, k + 27), Block.getBlockById(1).getStateFromMeta(3), 2);
		world.setBlockState(new BlockPos(i + 7, j + 0, k + 27), Block.getBlockById(1).getStateFromMeta(3), 2);
		world.setBlockState(new BlockPos(i + 8, j + 0, k + 27), Block.getBlockById(1).getStateFromMeta(3), 2);
		world.setBlockState(new BlockPos(i + 9, j + 0, k + 27), Block.getBlockById(1).getStateFromMeta(3), 2);
		world.setBlockState(new BlockPos(i + 10, j + 0, k + 27), Block.getBlockById(1).getStateFromMeta(3), 2);
		world.setBlockState(new BlockPos(i + 11, j + 0, k + 27), Block.getBlockById(1).getStateFromMeta(0), 2);
		world.setBlockState(new BlockPos(i + 12, j + 0, k + 27), Block.getBlockById(1).getStateFromMeta(0), 2);
		world.setBlockState(new BlockPos(i + 13, j + 0, k + 27), Block.getBlockById(1).getStateFromMeta(0), 2);
		world.setBlockState(new BlockPos(i + 5, j + 0, k + 28), Block.getBlockById(1).getStateFromMeta(0), 2);
		world.setBlockState(new BlockPos(i + 6, j + 0, k + 28), Block.getBlockById(1).getStateFromMeta(0), 2);
		world.setBlockState(new BlockPos(i + 7, j + 0, k + 28), Block.getBlockById(1).getStateFromMeta(0), 2);
		world.setBlockState(new BlockPos(i + 8, j + 0, k + 28), Block.getBlockById(1).getStateFromMeta(0), 2);
		world.setBlockState(new BlockPos(i + 9, j + 0, k + 28), Block.getBlockById(1).getStateFromMeta(0), 2);
		world.setBlockState(new BlockPos(i + 10, j + 0, k + 28), Block.getBlockById(1).getStateFromMeta(0), 2);
		world.setBlockState(new BlockPos(i + 11, j + 0, k + 28), Block.getBlockById(1).getStateFromMeta(0), 2);
		world.setBlockState(new BlockPos(i + 12, j + 0, k + 28), Block.getBlockById(1).getStateFromMeta(0), 2);
		world.setBlockState(new BlockPos(i + 13, j + 0, k + 28), Block.getBlockById(1).getStateFromMeta(0), 2);
		world.setBlockState(new BlockPos(i + 14, j + 0, k + 28), Block.getBlockById(1).getStateFromMeta(0), 2);
		world.setBlockState(new BlockPos(i + 5, j + 0, k + 29), Block.getBlockById(1).getStateFromMeta(0), 2);
		world.setBlockState(new BlockPos(i + 6, j + 0, k + 29), Block.getBlockById(1).getStateFromMeta(0), 2);
		world.setBlockState(new BlockPos(i + 7, j + 0, k + 29), Block.getBlockById(1).getStateFromMeta(0), 2);
		world.setBlockState(new BlockPos(i + 8, j + 0, k + 29), Block.getBlockById(1).getStateFromMeta(0), 2);
		world.setBlockState(new BlockPos(i + 9, j + 0, k + 29), Block.getBlockById(1).getStateFromMeta(0), 2);
		world.setBlockState(new BlockPos(i + 10, j + 0, k + 29), Block.getBlockById(1).getStateFromMeta(0), 2);
		world.setBlockState(new BlockPos(i + 11, j + 0, k + 29), Block.getBlockById(1).getStateFromMeta(0), 2);
		world.setBlockState(new BlockPos(i + 12, j + 0, k + 29), Block.getBlockById(1).getStateFromMeta(0), 2);
		world.setBlockState(new BlockPos(i + 13, j + 0, k + 29), Block.getBlockById(1).getStateFromMeta(0), 2);
		world.setBlockState(new BlockPos(i + 14, j + 0, k + 29), Block.getBlockById(1).getStateFromMeta(0), 2);
		world.setBlockState(new BlockPos(i + 15, j + 0, k + 29), Block.getBlockById(1).getStateFromMeta(3), 2);
		world.setBlockState(new BlockPos(i + 16, j + 0, k + 29), Block.getBlockById(1).getStateFromMeta(3), 2);
		world.setBlockState(new BlockPos(i + 17, j + 0, k + 29), Block.getBlockById(1).getStateFromMeta(3), 2);
		world.setBlockState(new BlockPos(i + 18, j + 0, k + 29), Block.getBlockById(1).getStateFromMeta(3), 2);
		world.setBlockState(new BlockPos(i + 19, j + 0, k + 29), Block.getBlockById(1).getStateFromMeta(3), 2);
		world.setBlockState(new BlockPos(i + 20, j + 0, k + 29), Block.getBlockById(1).getStateFromMeta(3), 2);
		world.setBlockState(new BlockPos(i + 21, j + 0, k + 29), Block.getBlockById(1).getStateFromMeta(0), 2);
		world.setBlockState(new BlockPos(i + 18, j + 1, k + 0), Block.getBlockById(168).getStateFromMeta(0), 2);
		world.setBlockState(new BlockPos(i + 19, j + 1, k + 0), Block.getBlockById(168).getStateFromMeta(0), 2);
		world.setBlockState(new BlockPos(i + 20, j + 1, k + 0), Block.getBlockById(168).getStateFromMeta(2), 2);
		world.setBlockState(new BlockPos(i + 21, j + 1, k + 0), Block.getBlockById(168).getStateFromMeta(0), 2);
		world.setBlockState(new BlockPos(i + 22, j + 1, k + 0), Block.getBlockById(168).getStateFromMeta(0), 2);
		world.setBlockState(new BlockPos(i + 18, j + 1, k + 1), Block.getBlockById(168).getStateFromMeta(0), 2);
		world.setBlockState(new BlockPos(i + 19, j + 1, k + 1), Block.getBlockById(168).getStateFromMeta(0), 2);
		world.setBlockState(new BlockPos(i + 20, j + 1, k + 1), Block.getBlockById(168).getStateFromMeta(0), 2);
		world.setBlockState(new BlockPos(i + 21, j + 1, k + 1), Block.getBlockById(168).getStateFromMeta(0), 2);
		world.setBlockState(new BlockPos(i + 22, j + 1, k + 1), Block.getBlockById(168).getStateFromMeta(0), 2);
		world.setBlockState(new BlockPos(i + 18, j + 1, k + 2), Block.getBlockById(168).getStateFromMeta(2), 2);
		world.setBlockState(new BlockPos(i + 19, j + 1, k + 2), Block.getBlockById(168).getStateFromMeta(0), 2);
		world.setBlockState(new BlockPos(i + 20, j + 1, k + 2), Block.getBlockById(41).getStateFromMeta(0), 2);
		world.setBlockState(new BlockPos(i + 21, j + 1, k + 2), Block.getBlockById(168).getStateFromMeta(0), 2);
		world.setBlockState(new BlockPos(i + 22, j + 1, k + 2), Block.getBlockById(168).getStateFromMeta(2), 2);
		world.setBlockState(new BlockPos(i + 18, j + 1, k + 3), Block.getBlockById(168).getStateFromMeta(0), 2);
		world.setBlockState(new BlockPos(i + 19, j + 1, k + 3), Block.getBlockById(168).getStateFromMeta(0), 2);
		world.setBlockState(new BlockPos(i + 20, j + 1, k + 3), Block.getBlockById(168).getStateFromMeta(0), 2);
		world.setBlockState(new BlockPos(i + 21, j + 1, k + 3), Block.getBlockById(168).getStateFromMeta(0), 2);
		world.setBlockState(new BlockPos(i + 22, j + 1, k + 3), Block.getBlockById(168).getStateFromMeta(0), 2);
		world.setBlockState(new BlockPos(i + 18, j + 1, k + 4), Block.getBlockById(168).getStateFromMeta(0), 2);
		world.setBlockState(new BlockPos(i + 19, j + 1, k + 4), Block.getBlockById(168).getStateFromMeta(0), 2);
		world.setBlockState(new BlockPos(i + 20, j + 1, k + 4), Block.getBlockById(168).getStateFromMeta(2), 2);
		world.setBlockState(new BlockPos(i + 21, j + 1, k + 4), Block.getBlockById(168).getStateFromMeta(0), 2);
		world.setBlockState(new BlockPos(i + 22, j + 1, k + 4), Block.getBlockById(168).getStateFromMeta(0), 2);
		world.setBlockState(new BlockPos(i + 0, j + 1, k + 7), Block.getBlockById(168).getStateFromMeta(2), 2);
		world.setBlockState(new BlockPos(i + 1, j + 1, k + 7), Block.getBlockById(168).getStateFromMeta(0), 2);
		world.setBlockState(new BlockPos(i + 2, j + 1, k + 7), Block.getBlockById(168).getStateFromMeta(0), 2);
		world.setBlockState(new BlockPos(i + 3, j + 1, k + 7), Block.getBlockById(168).getStateFromMeta(0), 2);
		world.setBlockState(new BlockPos(i + 4, j + 1, k + 7), Block.getBlockById(168).getStateFromMeta(0), 2);
		world.setBlockState(new BlockPos(i + 5, j + 1, k + 7), Block.getBlockById(168).getStateFromMeta(0), 2);
		world.setBlockState(new BlockPos(i + 6, j + 1, k + 7), Block.getBlockById(168).getStateFromMeta(0), 2);
		world.setBlockState(new BlockPos(i + 7, j + 1, k + 7), Block.getBlockById(168).getStateFromMeta(0), 2);
		world.setBlockState(new BlockPos(i + 8, j + 1, k + 7), Block.getBlockById(168).getStateFromMeta(0), 2);
		world.setBlockState(new BlockPos(i + 9, j + 1, k + 7), Block.getBlockById(168).getStateFromMeta(0), 2);
		world.setBlockState(new BlockPos(i + 10, j + 1, k + 7), Block.getBlockById(168).getStateFromMeta(0), 2);
		world.setBlockState(new BlockPos(i + 11, j + 1, k + 7), Block.getBlockById(168).getStateFromMeta(0), 2);
		world.setBlockState(new BlockPos(i + 12, j + 1, k + 7), Block.getBlockById(168).getStateFromMeta(0), 2);
		world.setBlockState(new BlockPos(i + 13, j + 1, k + 7), Block.getBlockById(168).getStateFromMeta(0), 2);
		world.setBlockState(new BlockPos(i + 14, j + 1, k + 7), Block.getBlockById(168).getStateFromMeta(0), 2);
		world.setBlockState(new BlockPos(i + 15, j + 1, k + 7), Block.getBlockById(168).getStateFromMeta(0), 2);
		world.setBlockState(new BlockPos(i + 16, j + 1, k + 7), Block.getBlockById(168).getStateFromMeta(0), 2);
		world.setBlockState(new BlockPos(i + 17, j + 1, k + 7), Block.getBlockById(168).getStateFromMeta(0), 2);
		world.setBlockState(new BlockPos(i + 18, j + 1, k + 7), Block.getBlockById(168).getStateFromMeta(0), 2);
		world.setBlockState(new BlockPos(i + 19, j + 1, k + 7), Block.getBlockById(168).getStateFromMeta(0), 2);
		world.setBlockState(new BlockPos(i + 20, j + 1, k + 7), Block.getBlockById(168).getStateFromMeta(0), 2);
		world.setBlockState(new BlockPos(i + 21, j + 1, k + 7), Block.getBlockById(168).getStateFromMeta(0), 2);
		world.setBlockState(new BlockPos(i + 22, j + 1, k + 7), Block.getBlockById(168).getStateFromMeta(2), 2);
		world.setBlockState(new BlockPos(i + 0, j + 1, k + 8), Block.getBlockById(168).getStateFromMeta(0), 2);
		world.setBlockState(new BlockPos(i + 22, j + 1, k + 8), Block.getBlockById(168).getStateFromMeta(0), 2);
		world.setBlockState(new BlockPos(i + 0, j + 1, k + 9), Block.getBlockById(168).getStateFromMeta(0), 2);
		world.setBlockState(new BlockPos(i + 22, j + 1, k + 9), Block.getBlockById(168).getStateFromMeta(0), 2);
		world.setBlockState(new BlockPos(i + 0, j + 1, k + 10), Block.getBlockById(168).getStateFromMeta(0), 2);
		world.setBlockState(new BlockPos(i + 22, j + 1, k + 10), Block.getBlockById(168).getStateFromMeta(0), 2);
		world.setBlockState(new BlockPos(i + 0, j + 1, k + 11), Block.getBlockById(168).getStateFromMeta(0), 2);
		world.setBlockState(new BlockPos(i + 3, j + 1, k + 11), Block.getBlockById(97).getStateFromMeta(2), 2);
		world.setBlockState(new BlockPos(i + 4, j + 1, k + 11), Block.getBlockById(97).getStateFromMeta(2), 2);
		world.setBlockState(new BlockPos(i + 5, j + 1, k + 11), Block.getBlockById(97).getStateFromMeta(2), 2);
		world.setBlockState(new BlockPos(i + 6, j + 1, k + 11), Block.getBlockById(97).getStateFromMeta(2), 2);
		world.setBlockState(new BlockPos(i + 7, j + 1, k + 11), Block.getBlockById(97).getStateFromMeta(2), 2);
		world.setBlockState(new BlockPos(i + 8, j + 1, k + 11), Block.getBlockById(97).getStateFromMeta(2), 2);
		world.setBlockState(new BlockPos(i + 9, j + 1, k + 11), Block.getBlockById(97).getStateFromMeta(2), 2);
		world.setBlockState(new BlockPos(i + 10, j + 1, k + 11), Block.getBlockById(97).getStateFromMeta(2), 2);
		world.setBlockState(new BlockPos(i + 11, j + 1, k + 11), Block.getBlockById(97).getStateFromMeta(2), 2);
		world.setBlockState(new BlockPos(i + 12, j + 1, k + 11), Block.getBlockById(97).getStateFromMeta(2), 2);
		world.setBlockState(new BlockPos(i + 13, j + 1, k + 11), Block.getBlockById(97).getStateFromMeta(2), 2);
		world.setBlockState(new BlockPos(i + 14, j + 1, k + 11), Block.getBlockById(97).getStateFromMeta(2), 2);
		world.setBlockState(new BlockPos(i + 15, j + 1, k + 11), Block.getBlockById(97).getStateFromMeta(2), 2);
		world.setBlockState(new BlockPos(i + 16, j + 1, k + 11), Block.getBlockById(97).getStateFromMeta(2), 2);
		world.setBlockState(new BlockPos(i + 17, j + 1, k + 11), Block.getBlockById(97).getStateFromMeta(2), 2);
		world.setBlockState(new BlockPos(i + 18, j + 1, k + 11), Block.getBlockById(97).getStateFromMeta(2), 2);
		world.setBlockState(new BlockPos(i + 22, j + 1, k + 11), Block.getBlockById(168).getStateFromMeta(0), 2);
		world.setBlockState(new BlockPos(i + 0, j + 1, k + 12), Block.getBlockById(168).getStateFromMeta(0), 2);
		world.setBlockState(new BlockPos(i + 3, j + 1, k + 12), Block.getBlockById(97).getStateFromMeta(2), 2);
		world.setBlockState(new BlockPos(i + 4, j + 1, k + 12), Block.getBlockById(97).getStateFromMeta(2), 2);
		world.setBlockState(new BlockPos(i + 5, j + 1, k + 12), Block.getBlockById(97).getStateFromMeta(2), 2);
		world.setBlockState(new BlockPos(i + 6, j + 1, k + 12), Block.getBlockById(97).getStateFromMeta(2), 2);
		world.setBlockState(new BlockPos(i + 7, j + 1, k + 12), Block.getBlockById(97).getStateFromMeta(2), 2);
		world.setBlockState(new BlockPos(i + 8, j + 1, k + 12), Block.getBlockById(97).getStateFromMeta(2), 2);
		world.setBlockState(new BlockPos(i + 9, j + 1, k + 12), Block.getBlockById(97).getStateFromMeta(2), 2);
		world.setBlockState(new BlockPos(i + 10, j + 1, k + 12), Block.getBlockById(97).getStateFromMeta(2), 2);
		world.setBlockState(new BlockPos(i + 11, j + 1, k + 12), Block.getBlockById(97).getStateFromMeta(2), 2);
		world.setBlockState(new BlockPos(i + 12, j + 1, k + 12), Block.getBlockById(97).getStateFromMeta(2), 2);
		world.setBlockState(new BlockPos(i + 13, j + 1, k + 12), Block.getBlockById(97).getStateFromMeta(2), 2);
		world.setBlockState(new BlockPos(i + 14, j + 1, k + 12), Block.getBlockById(97).getStateFromMeta(2), 2);
		world.setBlockState(new BlockPos(i + 15, j + 1, k + 12), Block.getBlockById(97).getStateFromMeta(2), 2);
		world.setBlockState(new BlockPos(i + 16, j + 1, k + 12), Block.getBlockById(97).getStateFromMeta(2), 2);
		world.setBlockState(new BlockPos(i + 17, j + 1, k + 12), Block.getBlockById(97).getStateFromMeta(2), 2);
		world.setBlockState(new BlockPos(i + 18, j + 1, k + 12), Block.getBlockById(97).getStateFromMeta(2), 2);
		world.setBlockState(new BlockPos(i + 22, j + 1, k + 12), Block.getBlockById(168).getStateFromMeta(0), 2);
		world.setBlockState(new BlockPos(i + 0, j + 1, k + 13), Block.getBlockById(168).getStateFromMeta(0), 2);
		world.setBlockState(new BlockPos(i + 3, j + 1, k + 13), Block.getBlockById(97).getStateFromMeta(2), 2);
		world.setBlockState(new BlockPos(i + 4, j + 1, k + 13), Block.getBlockById(97).getStateFromMeta(2), 2);
		world.setBlockState(new BlockPos(i + 5, j + 1, k + 13), Block.getBlockById(97).getStateFromMeta(2), 2);
		world.setBlockState(new BlockPos(i + 6, j + 1, k + 13), Block.getBlockById(97).getStateFromMeta(2), 2);
		world.setBlockState(new BlockPos(i + 7, j + 1, k + 13), Block.getBlockById(97).getStateFromMeta(2), 2);
		world.setBlockState(new BlockPos(i + 13, j + 1, k + 13), Block.getBlockById(97).getStateFromMeta(2), 2);
		world.setBlockState(new BlockPos(i + 14, j + 1, k + 13), Block.getBlockById(97).getStateFromMeta(2), 2);
		world.setBlockState(new BlockPos(i + 17, j + 1, k + 13), Block.getBlockById(97).getStateFromMeta(2), 2);
		world.setBlockState(new BlockPos(i + 18, j + 1, k + 13), Block.getBlockById(97).getStateFromMeta(2), 2);
		world.setBlockState(new BlockPos(i + 19, j + 1, k + 13), Block.getBlockById(168).getStateFromMeta(0), 2);
		world.setBlockState(new BlockPos(i + 20, j + 1, k + 13), Block.getBlockById(168).getStateFromMeta(0), 2);
		world.setBlockState(new BlockPos(i + 21, j + 1, k + 13), Block.getBlockById(168).getStateFromMeta(0), 2);
		world.setBlockState(new BlockPos(i + 22, j + 1, k + 13), Block.getBlockById(168).getStateFromMeta(0), 2);
		world.setBlockState(new BlockPos(i + 0, j + 1, k + 14), Block.getBlockById(168).getStateFromMeta(0), 2);
		world.setBlockState(new BlockPos(i + 3, j + 1, k + 14), Block.getBlockById(97).getStateFromMeta(2), 2);
		world.setBlockState(new BlockPos(i + 4, j + 1, k + 14), Block.getBlockById(97).getStateFromMeta(2), 2);
		world.setBlockState(new BlockPos(i + 5, j + 1, k + 14), Block.getBlockById(97).getStateFromMeta(2), 2);
		world.setBlockState(new BlockPos(i + 6, j + 1, k + 14), Block.getBlockById(97).getStateFromMeta(2), 2);
		world.setBlockState(new BlockPos(i + 7, j + 1, k + 14), Block.getBlockById(97).getStateFromMeta(2), 2);
		world.setBlockState(new BlockPos(i + 9, j + 1, k + 14), Block.getBlockById(97).getStateFromMeta(2), 2);
		world.setBlockState(new BlockPos(i + 10, j + 1, k + 14), Block.getBlockById(97).getStateFromMeta(2), 2);
		world.setBlockState(new BlockPos(i + 11, j + 1, k + 14), Block.getBlockById(97).getStateFromMeta(2), 2);
		world.setBlockState(new BlockPos(i + 12, j + 1, k + 14), Block.getBlockById(97).getStateFromMeta(2), 2);
		world.setBlockState(new BlockPos(i + 13, j + 1, k + 14), Block.getBlockById(97).getStateFromMeta(2), 2);
		world.setBlockState(new BlockPos(i + 14, j + 1, k + 14), Block.getBlockById(97).getStateFromMeta(2), 2);
		world.setBlockState(new BlockPos(i + 17, j + 1, k + 14), Block.getBlockById(97).getStateFromMeta(2), 2);
		world.setBlockState(new BlockPos(i + 18, j + 1, k + 14), Block.getBlockById(97).getStateFromMeta(2), 2);
		world.setBlockState(new BlockPos(i + 19, j + 1, k + 14), Block.getBlockById(97).getStateFromMeta(2), 2);
		world.setBlockState(new BlockPos(i + 20, j + 1, k + 14), Block.getBlockById(97).getStateFromMeta(2), 2);
		world.setBlockState(new BlockPos(i + 21, j + 1, k + 14), Block.getBlockById(97).getStateFromMeta(2), 2);
		world.setBlockState(new BlockPos(i + 22, j + 1, k + 14), Block.getBlockById(168).getStateFromMeta(0), 2);
		world.setBlockState(new BlockPos(i + 0, j + 1, k + 15), Block.getBlockById(168).getStateFromMeta(0), 2);
		world.setBlockState(new BlockPos(i + 3, j + 1, k + 15), Block.getBlockById(97).getStateFromMeta(2), 2);
		world.setBlockState(new BlockPos(i + 4, j + 1, k + 15), Block.getBlockById(97).getStateFromMeta(2), 2);
		world.setBlockState(new BlockPos(i + 5, j + 1, k + 15), Block.getBlockById(97).getStateFromMeta(2), 2);
		world.setBlockState(new BlockPos(i + 6, j + 1, k + 15), Block.getBlockById(97).getStateFromMeta(2), 2);
		world.setBlockState(new BlockPos(i + 7, j + 1, k + 15), Block.getBlockById(97).getStateFromMeta(2), 2);
		world.setBlockState(new BlockPos(i + 9, j + 1, k + 15), Block.getBlockById(97).getStateFromMeta(2), 2);
		world.setBlockState(new BlockPos(i + 10, j + 1, k + 15), Block.getBlockById(97).getStateFromMeta(2), 2);
		world.setBlockState(new BlockPos(i + 11, j + 1, k + 15), Block.getBlockById(97).getStateFromMeta(2), 2);
		world.setBlockState(new BlockPos(i + 12, j + 1, k + 15), Block.getBlockById(97).getStateFromMeta(2), 2);
		world.setBlockState(new BlockPos(i + 13, j + 1, k + 15), Block.getBlockById(97).getStateFromMeta(2), 2);
		world.setBlockState(new BlockPos(i + 14, j + 1, k + 15), Block.getBlockById(97).getStateFromMeta(2), 2);
		world.setBlockState(new BlockPos(i + 17, j + 1, k + 15), Block.getBlockById(97).getStateFromMeta(2), 2);
		world.setBlockState(new BlockPos(i + 18, j + 1, k + 15), Block.getBlockById(97).getStateFromMeta(2), 2);
		world.setBlockState(new BlockPos(i + 19, j + 1, k + 15), Block.getBlockById(97).getStateFromMeta(2), 2);
		world.setBlockState(new BlockPos(i + 20, j + 1, k + 15), Block.getBlockById(97).getStateFromMeta(2), 2);
		world.setBlockState(new BlockPos(i + 21, j + 1, k + 15), Block.getBlockById(97).getStateFromMeta(2), 2);
		world.setBlockState(new BlockPos(i + 22, j + 1, k + 15), Block.getBlockById(168).getStateFromMeta(0), 2);
		world.setBlockState(new BlockPos(i + 0, j + 1, k + 16), Block.getBlockById(168).getStateFromMeta(0), 2);
		world.setBlockState(new BlockPos(i + 3, j + 1, k + 16), Block.getBlockById(97).getStateFromMeta(2), 2);
		world.setBlockState(new BlockPos(i + 4, j + 1, k + 16), Block.getBlockById(97).getStateFromMeta(2), 2);
		world.setBlockState(new BlockPos(i + 5, j + 1, k + 16), Block.getBlockById(97).getStateFromMeta(2), 2);
		world.setBlockState(new BlockPos(i + 6, j + 1, k + 16), Block.getBlockById(97).getStateFromMeta(2), 2);
		world.setBlockState(new BlockPos(i + 7, j + 1, k + 16), Block.getBlockById(97).getStateFromMeta(2), 2);
		world.setBlockState(new BlockPos(i + 18, j + 1, k + 16), Block.getBlockById(168).getStateFromMeta(0), 2);
		world.setBlockState(new BlockPos(i + 19, j + 1, k + 16), Block.getBlockById(168).getStateFromMeta(0), 2);
		world.setBlockState(new BlockPos(i + 20, j + 1, k + 16), Block.getBlockById(168).getStateFromMeta(0), 2);
		world.setBlockState(new BlockPos(i + 21, j + 1, k + 16), Block.getBlockById(168).getStateFromMeta(0), 2);
		world.setBlockState(new BlockPos(i + 22, j + 1, k + 16), Block.getBlockById(168).getStateFromMeta(0), 2);
		world.setBlockState(new BlockPos(i + 0, j + 1, k + 17), Block.getBlockById(168).getStateFromMeta(0), 2);
		world.setBlockState(new BlockPos(i + 3, j + 1, k + 17), Block.getBlockById(97).getStateFromMeta(2), 2);
		world.setBlockState(new BlockPos(i + 4, j + 1, k + 17), Block.getBlockById(97).getStateFromMeta(2), 2);
		world.setBlockState(new BlockPos(i + 5, j + 1, k + 17), Block.getBlockById(97).getStateFromMeta(2), 2);
		world.setBlockState(new BlockPos(i + 6, j + 1, k + 17), Block.getBlockById(97).getStateFromMeta(2), 2);
		world.setBlockState(new BlockPos(i + 7, j + 1, k + 17), Block.getBlockById(97).getStateFromMeta(2), 2);
		world.setBlockState(new BlockPos(i + 22, j + 1, k + 17), Block.getBlockById(168).getStateFromMeta(0), 2);
		world.setBlockState(new BlockPos(i + 0, j + 1, k + 18), Block.getBlockById(168).getStateFromMeta(0), 2);
		world.setBlockState(new BlockPos(i + 3, j + 1, k + 18), Block.getBlockById(97).getStateFromMeta(2), 2);
		world.setBlockState(new BlockPos(i + 4, j + 1, k + 18), Block.getBlockById(97).getStateFromMeta(2), 2);
		world.setBlockState(new BlockPos(i + 5, j + 1, k + 18), Block.getBlockById(97).getStateFromMeta(2), 2);
		world.setBlockState(new BlockPos(i + 6, j + 1, k + 18), Block.getBlockById(97).getStateFromMeta(2), 2);
		world.setBlockState(new BlockPos(i + 7, j + 1, k + 18), Block.getBlockById(97).getStateFromMeta(2), 2);
		world.setBlockState(new BlockPos(i + 8, j + 1, k + 18), Block.getBlockById(97).getStateFromMeta(2), 2);
		world.setBlockState(new BlockPos(i + 9, j + 1, k + 18), Block.getBlockById(97).getStateFromMeta(2), 2);
		world.setBlockState(new BlockPos(i + 10, j + 1, k + 18), Block.getBlockById(97).getStateFromMeta(2), 2);
		world.setBlockState(new BlockPos(i + 11, j + 1, k + 18), Block.getBlockById(97).getStateFromMeta(2), 2);
		world.setBlockState(new BlockPos(i + 12, j + 1, k + 18), Block.getBlockById(97).getStateFromMeta(2), 2);
		world.setBlockState(new BlockPos(i + 13, j + 1, k + 18), Block.getBlockById(97).getStateFromMeta(2), 2);
		world.setBlockState(new BlockPos(i + 14, j + 1, k + 18), Block.getBlockById(97).getStateFromMeta(2), 2);
		world.setBlockState(new BlockPos(i + 15, j + 1, k + 18), Block.getBlockById(97).getStateFromMeta(2), 2);
		world.setBlockState(new BlockPos(i + 16, j + 1, k + 18), Block.getBlockById(97).getStateFromMeta(2), 2);
		world.setBlockState(new BlockPos(i + 17, j + 1, k + 18), Block.getBlockById(97).getStateFromMeta(2), 2);
		world.setBlockState(new BlockPos(i + 22, j + 1, k + 18), Block.getBlockById(168).getStateFromMeta(0), 2);
		world.setBlockState(new BlockPos(i + 0, j + 1, k + 19), Block.getBlockById(168).getStateFromMeta(0), 2);
		world.setBlockState(new BlockPos(i + 22, j + 1, k + 19), Block.getBlockById(168).getStateFromMeta(0), 2);
		world.setBlockState(new BlockPos(i + 0, j + 1, k + 20), Block.getBlockById(168).getStateFromMeta(0), 2);
		world.setBlockState(new BlockPos(i + 22, j + 1, k + 20), Block.getBlockById(168).getStateFromMeta(0), 2);
		world.setBlockState(new BlockPos(i + 0, j + 1, k + 21), Block.getBlockById(168).getStateFromMeta(0), 2);
		world.setBlockState(new BlockPos(i + 22, j + 1, k + 21), Block.getBlockById(168).getStateFromMeta(0), 2);
		world.setBlockState(new BlockPos(i + 0, j + 1, k + 22), Block.getBlockById(168).getStateFromMeta(2), 2);
		world.setBlockState(new BlockPos(i + 1, j + 1, k + 22), Block.getBlockById(168).getStateFromMeta(0), 2);
		world.setBlockState(new BlockPos(i + 2, j + 1, k + 22), Block.getBlockById(168).getStateFromMeta(0), 2);
		world.setBlockState(new BlockPos(i + 3, j + 1, k + 22), Block.getBlockById(168).getStateFromMeta(0), 2);
		world.setBlockState(new BlockPos(i + 4, j + 1, k + 22), Block.getBlockById(168).getStateFromMeta(0), 2);
		world.setBlockState(new BlockPos(i + 5, j + 1, k + 22), Block.getBlockById(168).getStateFromMeta(0), 2);
		world.setBlockState(new BlockPos(i + 6, j + 1, k + 22), Block.getBlockById(168).getStateFromMeta(0), 2);
		world.setBlockState(new BlockPos(i + 7, j + 1, k + 22), Block.getBlockById(168).getStateFromMeta(0), 2);
		world.setBlockState(new BlockPos(i + 8, j + 1, k + 22), Block.getBlockById(168).getStateFromMeta(0), 2);
		world.setBlockState(new BlockPos(i + 9, j + 1, k + 22), Block.getBlockById(168).getStateFromMeta(0), 2);
		world.setBlockState(new BlockPos(i + 10, j + 1, k + 22), Block.getBlockById(168).getStateFromMeta(0), 2);
		world.setBlockState(new BlockPos(i + 11, j + 1, k + 22), Block.getBlockById(168).getStateFromMeta(0), 2);
		world.setBlockState(new BlockPos(i + 12, j + 1, k + 22), Block.getBlockById(168).getStateFromMeta(0), 2);
		world.setBlockState(new BlockPos(i + 13, j + 1, k + 22), Block.getBlockById(168).getStateFromMeta(0), 2);
		world.setBlockState(new BlockPos(i + 14, j + 1, k + 22), Block.getBlockById(168).getStateFromMeta(0), 2);
		world.setBlockState(new BlockPos(i + 15, j + 1, k + 22), Block.getBlockById(168).getStateFromMeta(0), 2);
		world.setBlockState(new BlockPos(i + 16, j + 1, k + 22), Block.getBlockById(168).getStateFromMeta(0), 2);
		world.setBlockState(new BlockPos(i + 17, j + 1, k + 22), Block.getBlockById(168).getStateFromMeta(0), 2);
		world.setBlockState(new BlockPos(i + 18, j + 1, k + 22), Block.getBlockById(168).getStateFromMeta(0), 2);
		world.setBlockState(new BlockPos(i + 19, j + 1, k + 22), Block.getBlockById(168).getStateFromMeta(0), 2);
		world.setBlockState(new BlockPos(i + 20, j + 1, k + 22), Block.getBlockById(168).getStateFromMeta(0), 2);
		world.setBlockState(new BlockPos(i + 21, j + 1, k + 22), Block.getBlockById(168).getStateFromMeta(0), 2);
		world.setBlockState(new BlockPos(i + 22, j + 1, k + 22), Block.getBlockById(168).getStateFromMeta(2), 2);
		world.setBlockState(new BlockPos(i + 18, j + 1, k + 25), Block.getBlockById(168).getStateFromMeta(0), 2);
		world.setBlockState(new BlockPos(i + 19, j + 1, k + 25), Block.getBlockById(168).getStateFromMeta(0), 2);
		world.setBlockState(new BlockPos(i + 20, j + 1, k + 25), Block.getBlockById(168).getStateFromMeta(2), 2);
		world.setBlockState(new BlockPos(i + 21, j + 1, k + 25), Block.getBlockById(168).getStateFromMeta(0), 2);
		world.setBlockState(new BlockPos(i + 22, j + 1, k + 25), Block.getBlockById(168).getStateFromMeta(0), 2);
		world.setBlockState(new BlockPos(i + 18, j + 1, k + 26), Block.getBlockById(168).getStateFromMeta(0), 2);
		world.setBlockState(new BlockPos(i + 19, j + 1, k + 26), Block.getBlockById(168).getStateFromMeta(0), 2);
		world.setBlockState(new BlockPos(i + 20, j + 1, k + 26), Block.getBlockById(168).getStateFromMeta(0), 2);
		world.setBlockState(new BlockPos(i + 21, j + 1, k + 26), Block.getBlockById(168).getStateFromMeta(0), 2);
		world.setBlockState(new BlockPos(i + 22, j + 1, k + 26), Block.getBlockById(168).getStateFromMeta(0), 2);
		world.setBlockState(new BlockPos(i + 18, j + 1, k + 27), Block.getBlockById(168).getStateFromMeta(2), 2);
		world.setBlockState(new BlockPos(i + 19, j + 1, k + 27), Block.getBlockById(168).getStateFromMeta(0), 2);
		world.setBlockState(new BlockPos(i + 20, j + 1, k + 27), Block.getBlockById(41).getStateFromMeta(0), 2);
		world.setBlockState(new BlockPos(i + 21, j + 1, k + 27), Block.getBlockById(168).getStateFromMeta(0), 2);
		world.setBlockState(new BlockPos(i + 22, j + 1, k + 27), Block.getBlockById(168).getStateFromMeta(2), 2);
		world.setBlockState(new BlockPos(i + 18, j + 1, k + 28), Block.getBlockById(168).getStateFromMeta(0), 2);
		world.setBlockState(new BlockPos(i + 19, j + 1, k + 28), Block.getBlockById(168).getStateFromMeta(0), 2);
		world.setBlockState(new BlockPos(i + 20, j + 1, k + 28), Block.getBlockById(168).getStateFromMeta(0), 2);
		world.setBlockState(new BlockPos(i + 21, j + 1, k + 28), Block.getBlockById(168).getStateFromMeta(0), 2);
		world.setBlockState(new BlockPos(i + 22, j + 1, k + 28), Block.getBlockById(168).getStateFromMeta(0), 2);
		world.setBlockState(new BlockPos(i + 18, j + 1, k + 29), Block.getBlockById(168).getStateFromMeta(0), 2);
		world.setBlockState(new BlockPos(i + 19, j + 1, k + 29), Block.getBlockById(168).getStateFromMeta(0), 2);
		world.setBlockState(new BlockPos(i + 20, j + 1, k + 29), Block.getBlockById(168).getStateFromMeta(2), 2);
		world.setBlockState(new BlockPos(i + 21, j + 1, k + 29), Block.getBlockById(168).getStateFromMeta(0), 2);
		world.setBlockState(new BlockPos(i + 22, j + 1, k + 29), Block.getBlockById(168).getStateFromMeta(0), 2);
		world.setBlockState(new BlockPos(i + 19, j + 2, k + 1), Block.getBlockById(168).getStateFromMeta(0), 2);
		world.setBlockState(new BlockPos(i + 20, j + 2, k + 1), Block.getBlockById(168).getStateFromMeta(0), 2);
		world.setBlockState(new BlockPos(i + 21, j + 2, k + 1), Block.getBlockById(168).getStateFromMeta(0), 2);
		world.setBlockState(new BlockPos(i + 19, j + 2, k + 2), Block.getBlockById(168).getStateFromMeta(0), 2);
		world.setBlockState(new BlockPos(i + 20, j + 2, k + 2), Block.getBlockById(41).getStateFromMeta(0), 2);
		world.setBlockState(new BlockPos(i + 21, j + 2, k + 2), Block.getBlockById(168).getStateFromMeta(0), 2);
		world.setBlockState(new BlockPos(i + 19, j + 2, k + 3), Block.getBlockById(168).getStateFromMeta(0), 2);
		world.setBlockState(new BlockPos(i + 20, j + 2, k + 3), Block.getBlockById(168).getStateFromMeta(0), 2);
		world.setBlockState(new BlockPos(i + 21, j + 2, k + 3), Block.getBlockById(168).getStateFromMeta(0), 2);
		world.setBlockState(new BlockPos(i + 1, j + 2, k + 8), Block.getBlockById(168).getStateFromMeta(2), 2);
		world.setBlockState(new BlockPos(i + 2, j + 2, k + 8), Block.getBlockById(168).getStateFromMeta(0), 2);
		world.setBlockState(new BlockPos(i + 3, j + 2, k + 8), Block.getBlockById(168).getStateFromMeta(0), 2);
		world.setBlockState(new BlockPos(i + 4, j + 2, k + 8), Block.getBlockById(168).getStateFromMeta(0), 2);
		world.setBlockState(new BlockPos(i + 5, j + 2, k + 8), Block.getBlockById(168).getStateFromMeta(0), 2);
		world.setBlockState(new BlockPos(i + 6, j + 2, k + 8), Block.getBlockById(168).getStateFromMeta(0), 2);
		world.setBlockState(new BlockPos(i + 7, j + 2, k + 8), Block.getBlockById(168).getStateFromMeta(0), 2);
		world.setBlockState(new BlockPos(i + 8, j + 2, k + 8), Block.getBlockById(168).getStateFromMeta(0), 2);
		world.setBlockState(new BlockPos(i + 9, j + 2, k + 8), Block.getBlockById(168).getStateFromMeta(0), 2);
		world.setBlockState(new BlockPos(i + 10, j + 2, k + 8), Block.getBlockById(168).getStateFromMeta(0), 2);
		world.setBlockState(new BlockPos(i + 11, j + 2, k + 8), Block.getBlockById(168).getStateFromMeta(0), 2);
		world.setBlockState(new BlockPos(i + 12, j + 2, k + 8), Block.getBlockById(168).getStateFromMeta(0), 2);
		world.setBlockState(new BlockPos(i + 13, j + 2, k + 8), Block.getBlockById(168).getStateFromMeta(0), 2);
		world.setBlockState(new BlockPos(i + 14, j + 2, k + 8), Block.getBlockById(168).getStateFromMeta(0), 2);
		world.setBlockState(new BlockPos(i + 15, j + 2, k + 8), Block.getBlockById(168).getStateFromMeta(0), 2);
		world.setBlockState(new BlockPos(i + 16, j + 2, k + 8), Block.getBlockById(168).getStateFromMeta(0), 2);
		world.setBlockState(new BlockPos(i + 17, j + 2, k + 8), Block.getBlockById(168).getStateFromMeta(0), 2);
		world.setBlockState(new BlockPos(i + 18, j + 2, k + 8), Block.getBlockById(168).getStateFromMeta(0), 2);
		world.setBlockState(new BlockPos(i + 19, j + 2, k + 8), Block.getBlockById(168).getStateFromMeta(0), 2);
		world.setBlockState(new BlockPos(i + 20, j + 2, k + 8), Block.getBlockById(168).getStateFromMeta(0), 2);
		world.setBlockState(new BlockPos(i + 21, j + 2, k + 8), Block.getBlockById(168).getStateFromMeta(2), 2);
		world.setBlockState(new BlockPos(i + 1, j + 2, k + 9), Block.getBlockById(168).getStateFromMeta(0), 2);
		world.setBlockState(new BlockPos(i + 21, j + 2, k + 9), Block.getBlockById(168).getStateFromMeta(0), 2);
		world.setBlockState(new BlockPos(i + 1, j + 2, k + 10), Block.getBlockById(168).getStateFromMeta(0), 2);
		world.setBlockState(new BlockPos(i + 3, j + 2, k + 10), Block.getBlockById(168).getStateFromMeta(1), 2);
		world.setBlockState(new BlockPos(i + 4, j + 2, k + 10), Block.getBlockById(168).getStateFromMeta(1), 2);
		world.setBlockState(new BlockPos(i + 5, j + 2, k + 10), Block.getBlockById(168).getStateFromMeta(1), 2);
		world.setBlockState(new BlockPos(i + 6, j + 2, k + 10), Block.getBlockById(168).getStateFromMeta(1), 2);
		world.setBlockState(new BlockPos(i + 7, j + 2, k + 10), Block.getBlockById(168).getStateFromMeta(1), 2);
		world.setBlockState(new BlockPos(i + 8, j + 2, k + 10), Block.getBlockById(168).getStateFromMeta(1), 2);
		world.setBlockState(new BlockPos(i + 9, j + 2, k + 10), Block.getBlockById(168).getStateFromMeta(1), 2);
		world.setBlockState(new BlockPos(i + 10, j + 2, k + 10), Block.getBlockById(168).getStateFromMeta(1), 2);
		world.setBlockState(new BlockPos(i + 11, j + 2, k + 10), Block.getBlockById(168).getStateFromMeta(1), 2);
		world.setBlockState(new BlockPos(i + 12, j + 2, k + 10), Block.getBlockById(168).getStateFromMeta(1), 2);
		world.setBlockState(new BlockPos(i + 13, j + 2, k + 10), Block.getBlockById(168).getStateFromMeta(1), 2);
		world.setBlockState(new BlockPos(i + 14, j + 2, k + 10), Block.getBlockById(168).getStateFromMeta(1), 2);
		world.setBlockState(new BlockPos(i + 15, j + 2, k + 10), Block.getBlockById(168).getStateFromMeta(1), 2);
		world.setBlockState(new BlockPos(i + 16, j + 2, k + 10), Block.getBlockById(168).getStateFromMeta(1), 2);
		world.setBlockState(new BlockPos(i + 17, j + 2, k + 10), Block.getBlockById(168).getStateFromMeta(1), 2);
		world.setBlockState(new BlockPos(i + 18, j + 2, k + 10), Block.getBlockById(168).getStateFromMeta(1), 2);
		world.setBlockState(new BlockPos(i + 19, j + 2, k + 10), Block.getBlockById(168).getStateFromMeta(0), 2);
		world.setBlockState(new BlockPos(i + 21, j + 2, k + 10), Block.getBlockById(168).getStateFromMeta(0), 2);
		world.setBlockState(new BlockPos(i + 1, j + 2, k + 11), Block.getBlockById(168).getStateFromMeta(0), 2);
		world.setBlockState(new BlockPos(i + 3, j + 2, k + 11), Block.getBlockById(168).getStateFromMeta(1), 2);
		world.setBlockState(new BlockPos(i + 19, j + 2, k + 11), Block.getBlockById(168).getStateFromMeta(1), 2);
		world.setBlockState(new BlockPos(i + 21, j + 2, k + 11), Block.getBlockById(168).getStateFromMeta(0), 2);
		world.setBlockState(new BlockPos(i + 1, j + 2, k + 12), Block.getBlockById(168).getStateFromMeta(0), 2);
		world.setBlockState(new BlockPos(i + 3, j + 2, k + 12), Block.getBlockById(168).getStateFromMeta(1), 2);
		world.setBlockState(new BlockPos(i + 19, j + 2, k + 12), Block.getBlockById(168).getStateFromMeta(1), 2);
		world.setBlockState(new BlockPos(i + 21, j + 2, k + 12), Block.getBlockById(168).getStateFromMeta(0), 2);
		world.setBlockState(new BlockPos(i + 1, j + 2, k + 13), Block.getBlockById(168).getStateFromMeta(0), 2);
		world.setBlockState(new BlockPos(i + 3, j + 2, k + 13), Block.getBlockById(168).getStateFromMeta(1), 2);
		world.setBlockState(new BlockPos(i + 8, j + 2, k + 13), Block.getBlockById(168).getStateFromMeta(1), 2);
		world.setBlockState(new BlockPos(i + 9, j + 2, k + 13), Block.getBlockById(168).getStateFromMeta(1), 2);
		world.setBlockState(new BlockPos(i + 10, j + 2, k + 13), Block.getBlockById(168).getStateFromMeta(1), 2);
		world.setBlockState(new BlockPos(i + 11, j + 2, k + 13), Block.getBlockById(168).getStateFromMeta(1), 2);
		world.setBlockState(new BlockPos(i + 12, j + 2, k + 13), Block.getBlockById(168).getStateFromMeta(1), 2);
		world.setBlockState(new BlockPos(i + 15, j + 2, k + 13), Block.getBlockById(168).getStateFromMeta(1), 2);
		world.setBlockState(new BlockPos(i + 16, j + 2, k + 13), Block.getBlockById(168).getStateFromMeta(1), 2);
		world.setBlockState(new BlockPos(i + 19, j + 2, k + 13), Block.getBlockById(168).getStateFromMeta(1), 2);
		world.setBlockState(new BlockPos(i + 20, j + 2, k + 13), Block.getBlockById(168).getStateFromMeta(0), 2);
		world.setBlockState(new BlockPos(i + 21, j + 2, k + 13), Block.getBlockById(168).getStateFromMeta(0), 2);
		world.setBlockState(new BlockPos(i + 22, j + 2, k + 13), Block.getBlockById(168).getStateFromMeta(2), 2);
		world.setBlockState(new BlockPos(i + 1, j + 2, k + 14), Block.getBlockById(168).getStateFromMeta(0), 2);
		world.setBlockState(new BlockPos(i + 3, j + 2, k + 14), Block.getBlockById(168).getStateFromMeta(1), 2);
		world.setBlockState(new BlockPos(i + 8, j + 2, k + 14), Block.getBlockById(168).getStateFromMeta(1), 2);
		world.setBlockState(new BlockPos(i + 15, j + 2, k + 14), Block.getBlockById(168).getStateFromMeta(1), 2);
		world.setBlockState(new BlockPos(i + 16, j + 2, k + 14), Block.getBlockById(168).getStateFromMeta(1), 2);
		world.setBlockState(new BlockPos(i + 1, j + 2, k + 15), Block.getBlockById(168).getStateFromMeta(0), 2);
		world.setBlockState(new BlockPos(i + 3, j + 2, k + 15), Block.getBlockById(168).getStateFromMeta(1), 2);
		world.setBlockState(new BlockPos(i + 8, j + 2, k + 15), Block.getBlockById(168).getStateFromMeta(1), 2);
		world.setBlockState(new BlockPos(i + 15, j + 2, k + 15), Block.getBlockById(168).getStateFromMeta(1), 2);
		world.setBlockState(new BlockPos(i + 16, j + 2, k + 15), Block.getBlockById(168).getStateFromMeta(1), 2);
		world.setBlockState(new BlockPos(i + 1, j + 2, k + 16), Block.getBlockById(168).getStateFromMeta(0), 2);
		world.setBlockState(new BlockPos(i + 3, j + 2, k + 16), Block.getBlockById(168).getStateFromMeta(1), 2);
		world.setBlockState(new BlockPos(i + 8, j + 2, k + 16), Block.getBlockById(168).getStateFromMeta(1), 2);
		world.setBlockState(new BlockPos(i + 9, j + 2, k + 16), Block.getBlockById(168).getStateFromMeta(1), 2);
		world.setBlockState(new BlockPos(i + 10, j + 2, k + 16), Block.getBlockById(168).getStateFromMeta(1), 2);
		world.setBlockState(new BlockPos(i + 11, j + 2, k + 16), Block.getBlockById(168).getStateFromMeta(1), 2);
		world.setBlockState(new BlockPos(i + 12, j + 2, k + 16), Block.getBlockById(168).getStateFromMeta(1), 2);
		world.setBlockState(new BlockPos(i + 13, j + 2, k + 16), Block.getBlockById(168).getStateFromMeta(1), 2);
		world.setBlockState(new BlockPos(i + 14, j + 2, k + 16), Block.getBlockById(168).getStateFromMeta(1), 2);
		world.setBlockState(new BlockPos(i + 15, j + 2, k + 16), Block.getBlockById(168).getStateFromMeta(1), 2);
		world.setBlockState(new BlockPos(i + 16, j + 2, k + 16), Block.getBlockById(168).getStateFromMeta(0), 2);
		world.setBlockState(new BlockPos(i + 17, j + 2, k + 16), Block.getBlockById(168).getStateFromMeta(0), 2);
		world.setBlockState(new BlockPos(i + 18, j + 2, k + 16), Block.getBlockById(168).getStateFromMeta(0), 2);
		world.setBlockState(new BlockPos(i + 19, j + 2, k + 16), Block.getBlockById(168).getStateFromMeta(0), 2);
		world.setBlockState(new BlockPos(i + 20, j + 2, k + 16), Block.getBlockById(168).getStateFromMeta(0), 2);
		world.setBlockState(new BlockPos(i + 21, j + 2, k + 16), Block.getBlockById(168).getStateFromMeta(0), 2);
		world.setBlockState(new BlockPos(i + 22, j + 2, k + 16), Block.getBlockById(168).getStateFromMeta(2), 2);
		world.setBlockState(new BlockPos(i + 1, j + 2, k + 17), Block.getBlockById(168).getStateFromMeta(0), 2);
		world.setBlockState(new BlockPos(i + 3, j + 2, k + 17), Block.getBlockById(168).getStateFromMeta(1), 2);
		world.setBlockState(new BlockPos(i + 8, j + 2, k + 17), Block.getBlockById(168).getStateFromMeta(1), 2);
		world.setBlockState(new BlockPos(i + 9, j + 2, k + 17), Block.getBlockById(49).getStateFromMeta(0), 2);
		world.setBlockState(new BlockPos(i + 10, j + 2, k + 17), Block.getBlockById(49).getStateFromMeta(0), 2);
		world.setBlockState(new BlockPos(i + 11, j + 2, k + 17), Block.getBlockById(49).getStateFromMeta(0), 2);
		world.setBlockState(new BlockPos(i + 12, j + 2, k + 17), Block.getBlockById(49).getStateFromMeta(0), 2);
		world.setBlockState(new BlockPos(i + 13, j + 2, k + 17), Block.getBlockById(49).getStateFromMeta(0), 2);
		world.setBlockState(new BlockPos(i + 14, j + 2, k + 17), Block.getBlockById(49).getStateFromMeta(0), 2);
		world.setBlockState(new BlockPos(i + 15, j + 2, k + 17), Block.getBlockById(49).getStateFromMeta(0), 2);
		world.setBlockState(new BlockPos(i + 16, j + 2, k + 17), Block.getBlockById(49).getStateFromMeta(0), 2);
		world.setBlockState(new BlockPos(i + 17, j + 2, k + 17), Block.getBlockById(49).getStateFromMeta(0), 2);
		world.setBlockState(new BlockPos(i + 18, j + 2, k + 17), Block.getBlockById(49).getStateFromMeta(0), 2);
		world.setBlockState(new BlockPos(i + 21, j + 2, k + 17), Block.getBlockById(168).getStateFromMeta(0), 2);
		world.setBlockState(new BlockPos(i + 1, j + 2, k + 18), Block.getBlockById(168).getStateFromMeta(0), 2);
		world.setBlockState(new BlockPos(i + 3, j + 2, k + 18), Block.getBlockById(168).getStateFromMeta(1), 2);
		world.setBlockState(new BlockPos(i + 17, j + 2, k + 18), Block.getBlockById(9).getStateFromMeta(1), 2);
		world.setBlockState(new BlockPos(i + 18, j + 2, k + 18), Block.getBlockById(49).getStateFromMeta(0), 2);
		world.setBlockState(new BlockPos(i + 21, j + 2, k + 18), Block.getBlockById(168).getStateFromMeta(0), 2);
		world.setBlockState(new BlockPos(i + 1, j + 2, k + 19), Block.getBlockById(168).getStateFromMeta(0), 2);
		world.setBlockState(new BlockPos(i + 3, j + 2, k + 19), Block.getBlockById(168).getStateFromMeta(1), 2);
		world.setBlockState(new BlockPos(i + 4, j + 2, k + 19), Block.getBlockById(168).getStateFromMeta(1), 2);
		world.setBlockState(new BlockPos(i + 5, j + 2, k + 19), Block.getBlockById(168).getStateFromMeta(1), 2);
		world.setBlockState(new BlockPos(i + 6, j + 2, k + 19), Block.getBlockById(168).getStateFromMeta(1), 2);
		world.setBlockState(new BlockPos(i + 7, j + 2, k + 19), Block.getBlockById(168).getStateFromMeta(1), 2);
		world.setBlockState(new BlockPos(i + 8, j + 2, k + 19), Block.getBlockById(49).getStateFromMeta(0), 2);
		world.setBlockState(new BlockPos(i + 9, j + 2, k + 19), Block.getBlockById(49).getStateFromMeta(0), 2);
		world.setBlockState(new BlockPos(i + 10, j + 2, k + 19), Block.getBlockById(49).getStateFromMeta(0), 2);
		world.setBlockState(new BlockPos(i + 11, j + 2, k + 19), Block.getBlockById(49).getStateFromMeta(0), 2);
		world.setBlockState(new BlockPos(i + 12, j + 2, k + 19), Block.getBlockById(49).getStateFromMeta(0), 2);
		world.setBlockState(new BlockPos(i + 13, j + 2, k + 19), Block.getBlockById(49).getStateFromMeta(0), 2);
		world.setBlockState(new BlockPos(i + 14, j + 2, k + 19), Block.getBlockById(49).getStateFromMeta(0), 2);
		world.setBlockState(new BlockPos(i + 15, j + 2, k + 19), Block.getBlockById(49).getStateFromMeta(0), 2);
		world.setBlockState(new BlockPos(i + 16, j + 2, k + 19), Block.getBlockById(49).getStateFromMeta(0), 2);
		world.setBlockState(new BlockPos(i + 17, j + 2, k + 19), Block.getBlockById(49).getStateFromMeta(0), 2);
		world.setBlockState(new BlockPos(i + 18, j + 2, k + 19), Block.getBlockById(49).getStateFromMeta(0), 2);
		world.setBlockState(new BlockPos(i + 21, j + 2, k + 19), Block.getBlockById(168).getStateFromMeta(0), 2);
		world.setBlockState(new BlockPos(i + 1, j + 2, k + 20), Block.getBlockById(168).getStateFromMeta(0), 2);
		world.setBlockState(new BlockPos(i + 21, j + 2, k + 20), Block.getBlockById(168).getStateFromMeta(0), 2);
		world.setBlockState(new BlockPos(i + 1, j + 2, k + 21), Block.getBlockById(168).getStateFromMeta(2), 2);
		world.setBlockState(new BlockPos(i + 2, j + 2, k + 21), Block.getBlockById(168).getStateFromMeta(0), 2);
		world.setBlockState(new BlockPos(i + 3, j + 2, k + 21), Block.getBlockById(168).getStateFromMeta(0), 2);
		world.setBlockState(new BlockPos(i + 4, j + 2, k + 21), Block.getBlockById(168).getStateFromMeta(0), 2);
		world.setBlockState(new BlockPos(i + 5, j + 2, k + 21), Block.getBlockById(168).getStateFromMeta(0), 2);
		world.setBlockState(new BlockPos(i + 6, j + 2, k + 21), Block.getBlockById(168).getStateFromMeta(0), 2);
		world.setBlockState(new BlockPos(i + 7, j + 2, k + 21), Block.getBlockById(168).getStateFromMeta(0), 2);
		world.setBlockState(new BlockPos(i + 8, j + 2, k + 21), Block.getBlockById(168).getStateFromMeta(0), 2);
		world.setBlockState(new BlockPos(i + 9, j + 2, k + 21), Block.getBlockById(168).getStateFromMeta(0), 2);
		world.setBlockState(new BlockPos(i + 10, j + 2, k + 21), Block.getBlockById(168).getStateFromMeta(0), 2);
		world.setBlockState(new BlockPos(i + 11, j + 2, k + 21), Block.getBlockById(168).getStateFromMeta(0), 2);
		world.setBlockState(new BlockPos(i + 12, j + 2, k + 21), Block.getBlockById(168).getStateFromMeta(0), 2);
		world.setBlockState(new BlockPos(i + 13, j + 2, k + 21), Block.getBlockById(168).getStateFromMeta(0), 2);
		world.setBlockState(new BlockPos(i + 14, j + 2, k + 21), Block.getBlockById(168).getStateFromMeta(0), 2);
		world.setBlockState(new BlockPos(i + 15, j + 2, k + 21), Block.getBlockById(168).getStateFromMeta(0), 2);
		world.setBlockState(new BlockPos(i + 16, j + 2, k + 21), Block.getBlockById(168).getStateFromMeta(0), 2);
		world.setBlockState(new BlockPos(i + 17, j + 2, k + 21), Block.getBlockById(168).getStateFromMeta(0), 2);
		world.setBlockState(new BlockPos(i + 18, j + 2, k + 21), Block.getBlockById(168).getStateFromMeta(0), 2);
		world.setBlockState(new BlockPos(i + 19, j + 2, k + 21), Block.getBlockById(168).getStateFromMeta(0), 2);
		world.setBlockState(new BlockPos(i + 20, j + 2, k + 21), Block.getBlockById(168).getStateFromMeta(0), 2);
		world.setBlockState(new BlockPos(i + 21, j + 2, k + 21), Block.getBlockById(168).getStateFromMeta(2), 2);
		world.setBlockState(new BlockPos(i + 19, j + 2, k + 26), Block.getBlockById(168).getStateFromMeta(0), 2);
		world.setBlockState(new BlockPos(i + 20, j + 2, k + 26), Block.getBlockById(168).getStateFromMeta(0), 2);
		world.setBlockState(new BlockPos(i + 21, j + 2, k + 26), Block.getBlockById(168).getStateFromMeta(0), 2);
		world.setBlockState(new BlockPos(i + 19, j + 2, k + 27), Block.getBlockById(168).getStateFromMeta(0), 2);
		world.setBlockState(new BlockPos(i + 20, j + 2, k + 27), Block.getBlockById(41).getStateFromMeta(0), 2);
		world.setBlockState(new BlockPos(i + 21, j + 2, k + 27), Block.getBlockById(168).getStateFromMeta(0), 2);
		world.setBlockState(new BlockPos(i + 19, j + 2, k + 28), Block.getBlockById(168).getStateFromMeta(0), 2);
		world.setBlockState(new BlockPos(i + 20, j + 2, k + 28), Block.getBlockById(168).getStateFromMeta(0), 2);
		world.setBlockState(new BlockPos(i + 21, j + 2, k + 28), Block.getBlockById(168).getStateFromMeta(0), 2);
		world.setBlockState(new BlockPos(i + 20, j + 3, k + 1), Block.getBlockById(168).getStateFromMeta(0), 2);
		world.setBlockState(new BlockPos(i + 19, j + 3, k + 2), Block.getBlockById(168).getStateFromMeta(0), 2);
		world.setBlockState(new BlockPos(i + 20, j + 3, k + 2), Block.getBlockById(41).getStateFromMeta(0), 2);
		world.setBlockState(new BlockPos(i + 21, j + 3, k + 2), Block.getBlockById(168).getStateFromMeta(0), 2);
		world.setBlockState(new BlockPos(i + 20, j + 3, k + 3), Block.getBlockById(168).getStateFromMeta(0), 2);
		world.setBlockState(new BlockPos(i + 2, j + 3, k + 9), Block.getBlockById(168).getStateFromMeta(2), 2);
		world.setBlockState(new BlockPos(i + 3, j + 3, k + 9), Block.getBlockById(168).getStateFromMeta(0), 2);
		world.setBlockState(new BlockPos(i + 4, j + 3, k + 9), Block.getBlockById(168).getStateFromMeta(0), 2);
		world.setBlockState(new BlockPos(i + 5, j + 3, k + 9), Block.getBlockById(168).getStateFromMeta(0), 2);
		world.setBlockState(new BlockPos(i + 6, j + 3, k + 9), Block.getBlockById(168).getStateFromMeta(0), 2);
		world.setBlockState(new BlockPos(i + 7, j + 3, k + 9), Block.getBlockById(168).getStateFromMeta(0), 2);
		world.setBlockState(new BlockPos(i + 8, j + 3, k + 9), Block.getBlockById(168).getStateFromMeta(0), 2);
		world.setBlockState(new BlockPos(i + 9, j + 3, k + 9), Block.getBlockById(168).getStateFromMeta(0), 2);
		world.setBlockState(new BlockPos(i + 10, j + 3, k + 9), Block.getBlockById(168).getStateFromMeta(0), 2);
		world.setBlockState(new BlockPos(i + 11, j + 3, k + 9), Block.getBlockById(168).getStateFromMeta(0), 2);
		world.setBlockState(new BlockPos(i + 12, j + 3, k + 9), Block.getBlockById(168).getStateFromMeta(0), 2);
		world.setBlockState(new BlockPos(i + 13, j + 3, k + 9), Block.getBlockById(168).getStateFromMeta(0), 2);
		world.setBlockState(new BlockPos(i + 14, j + 3, k + 9), Block.getBlockById(168).getStateFromMeta(0), 2);
		world.setBlockState(new BlockPos(i + 15, j + 3, k + 9), Block.getBlockById(168).getStateFromMeta(0), 2);
		world.setBlockState(new BlockPos(i + 16, j + 3, k + 9), Block.getBlockById(168).getStateFromMeta(0), 2);
		world.setBlockState(new BlockPos(i + 17, j + 3, k + 9), Block.getBlockById(168).getStateFromMeta(0), 2);
		world.setBlockState(new BlockPos(i + 18, j + 3, k + 9), Block.getBlockById(168).getStateFromMeta(0), 2);
		world.setBlockState(new BlockPos(i + 19, j + 3, k + 9), Block.getBlockById(168).getStateFromMeta(0), 2);
		world.setBlockState(new BlockPos(i + 20, j + 3, k + 9), Block.getBlockById(168).getStateFromMeta(2), 2);
		world.setBlockState(new BlockPos(i + 2, j + 3, k + 10), Block.getBlockById(168).getStateFromMeta(0), 2);
		world.setBlockState(new BlockPos(i + 3, j + 3, k + 10), Block.getBlockById(168).getStateFromMeta(1), 2);
		world.setBlockState(new BlockPos(i + 4, j + 3, k + 10), Block.getBlockById(168).getStateFromMeta(1), 2);
		world.setBlockState(new BlockPos(i + 5, j + 3, k + 10), Block.getBlockById(168).getStateFromMeta(1), 2);
		world.setBlockState(new BlockPos(i + 6, j + 3, k + 10), Block.getBlockById(168).getStateFromMeta(1), 2);
		world.setBlockState(new BlockPos(i + 7, j + 3, k + 10), Block.getBlockById(168).getStateFromMeta(1), 2);
		world.setBlockState(new BlockPos(i + 8, j + 3, k + 10), Block.getBlockById(168).getStateFromMeta(1), 2);
		world.setBlockState(new BlockPos(i + 9, j + 3, k + 10), Block.getBlockById(168).getStateFromMeta(1), 2);
		world.setBlockState(new BlockPos(i + 10, j + 3, k + 10), Block.getBlockById(168).getStateFromMeta(1), 2);
		world.setBlockState(new BlockPos(i + 11, j + 3, k + 10), Block.getBlockById(168).getStateFromMeta(1), 2);
		world.setBlockState(new BlockPos(i + 12, j + 3, k + 10), Block.getBlockById(168).getStateFromMeta(1), 2);
		world.setBlockState(new BlockPos(i + 13, j + 3, k + 10), Block.getBlockById(168).getStateFromMeta(1), 2);
		world.setBlockState(new BlockPos(i + 14, j + 3, k + 10), Block.getBlockById(168).getStateFromMeta(1), 2);
		world.setBlockState(new BlockPos(i + 15, j + 3, k + 10), Block.getBlockById(168).getStateFromMeta(1), 2);
		world.setBlockState(new BlockPos(i + 16, j + 3, k + 10), Block.getBlockById(168).getStateFromMeta(1), 2);
		world.setBlockState(new BlockPos(i + 17, j + 3, k + 10), Block.getBlockById(168).getStateFromMeta(1), 2);
		world.setBlockState(new BlockPos(i + 18, j + 3, k + 10), Block.getBlockById(168).getStateFromMeta(1), 2);
		world.setBlockState(new BlockPos(i + 19, j + 3, k + 10), Block.getBlockById(168).getStateFromMeta(0), 2);
		world.setBlockState(new BlockPos(i + 20, j + 3, k + 10), Block.getBlockById(168).getStateFromMeta(0), 2);
		world.setBlockState(new BlockPos(i + 2, j + 3, k + 11), Block.getBlockById(168).getStateFromMeta(0), 2);
		world.setBlockState(new BlockPos(i + 3, j + 3, k + 11), Block.getBlockById(168).getStateFromMeta(1), 2);
		world.setBlockState(new BlockPos(i + 19, j + 3, k + 11), Block.getBlockById(168).getStateFromMeta(1), 2);
		world.setBlockState(new BlockPos(i + 20, j + 3, k + 11), Block.getBlockById(168).getStateFromMeta(0), 2);
		world.setBlockState(new BlockPos(i + 2, j + 3, k + 12), Block.getBlockById(168).getStateFromMeta(0), 2);
		world.setBlockState(new BlockPos(i + 3, j + 3, k + 12), Block.getBlockById(168).getStateFromMeta(1), 2);
		world.setBlockState(new BlockPos(i + 19, j + 3, k + 12), Block.getBlockById(168).getStateFromMeta(1), 2);
		world.setBlockState(new BlockPos(i + 20, j + 3, k + 12), Block.getBlockById(168).getStateFromMeta(0), 2);
		world.setBlockState(new BlockPos(i + 2, j + 3, k + 13), Block.getBlockById(168).getStateFromMeta(0), 2);
		world.setBlockState(new BlockPos(i + 3, j + 3, k + 13), Block.getBlockById(168).getStateFromMeta(1), 2);
		world.setBlockState(new BlockPos(i + 8, j + 3, k + 13), Block.getBlockById(168).getStateFromMeta(1), 2);
		world.setBlockState(new BlockPos(i + 9, j + 3, k + 13), Block.getBlockById(168).getStateFromMeta(1), 2);
		world.setBlockState(new BlockPos(i + 10, j + 3, k + 13), Block.getBlockById(168).getStateFromMeta(1), 2);
		world.setBlockState(new BlockPos(i + 11, j + 3, k + 13), Block.getBlockById(168).getStateFromMeta(1), 2);
		world.setBlockState(new BlockPos(i + 12, j + 3, k + 13), Block.getBlockById(168).getStateFromMeta(1), 2);
		world.setBlockState(new BlockPos(i + 15, j + 3, k + 13), Block.getBlockById(168).getStateFromMeta(1), 2);
		world.setBlockState(new BlockPos(i + 16, j + 3, k + 13), Block.getBlockById(168).getStateFromMeta(1), 2);
		world.setBlockState(new BlockPos(i + 19, j + 3, k + 13), Block.getBlockById(168).getStateFromMeta(1), 2);
		world.setBlockState(new BlockPos(i + 20, j + 3, k + 13), Block.getBlockById(168).getStateFromMeta(0), 2);
		world.setBlockState(new BlockPos(i + 21, j + 3, k + 13), Block.getBlockById(168).getStateFromMeta(0), 2);
		world.setBlockState(new BlockPos(i + 22, j + 3, k + 13), Block.getBlockById(168).getStateFromMeta(2), 2);
		world.setBlockState(new BlockPos(i + 2, j + 3, k + 14), Block.getBlockById(168).getStateFromMeta(0), 2);
		world.setBlockState(new BlockPos(i + 3, j + 3, k + 14), Block.getBlockById(168).getStateFromMeta(1), 2);
		world.setBlockState(new BlockPos(i + 8, j + 3, k + 14), Block.getBlockById(168).getStateFromMeta(1), 2);
		world.setBlockState(new BlockPos(i + 15, j + 3, k + 14), Block.getBlockById(168).getStateFromMeta(1), 2);
		world.setBlockState(new BlockPos(i + 16, j + 3, k + 14), Block.getBlockById(168).getStateFromMeta(1), 2);
		world.setBlockState(new BlockPos(i + 2, j + 3, k + 15), Block.getBlockById(168).getStateFromMeta(0), 2);
		world.setBlockState(new BlockPos(i + 3, j + 3, k + 15), Block.getBlockById(168).getStateFromMeta(1), 2);
		world.setBlockState(new BlockPos(i + 8, j + 3, k + 15), Block.getBlockById(168).getStateFromMeta(1), 2);
		world.setBlockState(new BlockPos(i + 15, j + 3, k + 15), Block.getBlockById(168).getStateFromMeta(1), 2);
		world.setBlockState(new BlockPos(i + 16, j + 3, k + 15), Block.getBlockById(168).getStateFromMeta(1), 2);
		world.setBlockState(new BlockPos(i + 2, j + 3, k + 16), Block.getBlockById(168).getStateFromMeta(0), 2);
		world.setBlockState(new BlockPos(i + 3, j + 3, k + 16), Block.getBlockById(168).getStateFromMeta(1), 2);
		world.setBlockState(new BlockPos(i + 8, j + 3, k + 16), Block.getBlockById(168).getStateFromMeta(1), 2);
		world.setBlockState(new BlockPos(i + 9, j + 3, k + 16), Block.getBlockById(168).getStateFromMeta(1), 2);
		world.setBlockState(new BlockPos(i + 10, j + 3, k + 16), Block.getBlockById(168).getStateFromMeta(1), 2);
		world.setBlockState(new BlockPos(i + 11, j + 3, k + 16), Block.getBlockById(168).getStateFromMeta(1), 2);
		world.setBlockState(new BlockPos(i + 12, j + 3, k + 16), Block.getBlockById(168).getStateFromMeta(1), 2);
		world.setBlockState(new BlockPos(i + 13, j + 3, k + 16), Block.getBlockById(168).getStateFromMeta(1), 2);
		world.setBlockState(new BlockPos(i + 14, j + 3, k + 16), Block.getBlockById(168).getStateFromMeta(1), 2);
		world.setBlockState(new BlockPos(i + 15, j + 3, k + 16), Block.getBlockById(168).getStateFromMeta(1), 2);
		world.setBlockState(new BlockPos(i + 16, j + 3, k + 16), Block.getBlockById(168).getStateFromMeta(0), 2);
		world.setBlockState(new BlockPos(i + 17, j + 3, k + 16), Block.getBlockById(168).getStateFromMeta(0), 2);
		world.setBlockState(new BlockPos(i + 18, j + 3, k + 16), Block.getBlockById(168).getStateFromMeta(0), 2);
		world.setBlockState(new BlockPos(i + 19, j + 3, k + 16), Block.getBlockById(168).getStateFromMeta(0), 2);
		world.setBlockState(new BlockPos(i + 20, j + 3, k + 16), Block.getBlockById(168).getStateFromMeta(0), 2);
		world.setBlockState(new BlockPos(i + 21, j + 3, k + 16), Block.getBlockById(168).getStateFromMeta(0), 2);
		world.setBlockState(new BlockPos(i + 22, j + 3, k + 16), Block.getBlockById(168).getStateFromMeta(2), 2);
		world.setBlockState(new BlockPos(i + 2, j + 3, k + 17), Block.getBlockById(168).getStateFromMeta(0), 2);
		world.setBlockState(new BlockPos(i + 3, j + 3, k + 17), Block.getBlockById(168).getStateFromMeta(1), 2);
		world.setBlockState(new BlockPos(i + 8, j + 3, k + 17), Block.getBlockById(168).getStateFromMeta(1), 2);
		world.setBlockState(new BlockPos(i + 9, j + 3, k + 17), Block.getBlockById(49).getStateFromMeta(0), 2);
		world.setBlockState(new BlockPos(i + 10, j + 3, k + 17), Block.getBlockById(49).getStateFromMeta(0), 2);
		world.setBlockState(new BlockPos(i + 11, j + 3, k + 17), Block.getBlockById(49).getStateFromMeta(0), 2);
		world.setBlockState(new BlockPos(i + 12, j + 3, k + 17), Block.getBlockById(49).getStateFromMeta(0), 2);
		world.setBlockState(new BlockPos(i + 13, j + 3, k + 17), Block.getBlockById(49).getStateFromMeta(0), 2);
		world.setBlockState(new BlockPos(i + 14, j + 3, k + 17), Block.getBlockById(49).getStateFromMeta(0), 2);
		world.setBlockState(new BlockPos(i + 15, j + 3, k + 17), Block.getBlockById(9).getStateFromMeta(8), 2);
		world.setBlockState(new BlockPos(i + 16, j + 3, k + 17), Block.getBlockById(49).getStateFromMeta(0), 2);
		world.setBlockState(new BlockPos(i + 17, j + 3, k + 17), Block.getBlockById(49).getStateFromMeta(0), 2);
		world.setBlockState(new BlockPos(i + 18, j + 3, k + 17), Block.getBlockById(49).getStateFromMeta(0), 2);
		world.setBlockState(new BlockPos(i + 20, j + 3, k + 17), Block.getBlockById(168).getStateFromMeta(0), 2);
		world.setBlockState(new BlockPos(i + 2, j + 3, k + 18), Block.getBlockById(168).getStateFromMeta(0), 2);
		world.setBlockState(new BlockPos(i + 3, j + 3, k + 18), Block.getBlockById(168).getStateFromMeta(1), 2);
		world.setBlockState(new BlockPos(i + 16, j + 3, k + 18), Block.getBlockById(9).getStateFromMeta(1), 2);
		world.setBlockState(new BlockPos(i + 17, j + 3, k + 18), Block.getBlockById(0).getStateFromMeta(0), 2);
		world.setBlockState(new BlockPos(i + 18, j + 3, k + 18), Block.getBlockById(49).getStateFromMeta(0), 2);
		world.setBlockState(new BlockPos(i + 20, j + 3, k + 18), Block.getBlockById(168).getStateFromMeta(0), 2);
		world.setBlockState(new BlockPos(i + 2, j + 3, k + 19), Block.getBlockById(168).getStateFromMeta(0), 2);
		world.setBlockState(new BlockPos(i + 3, j + 3, k + 19), Block.getBlockById(168).getStateFromMeta(1), 2);
		world.setBlockState(new BlockPos(i + 4, j + 3, k + 19), Block.getBlockById(168).getStateFromMeta(1), 2);
		world.setBlockState(new BlockPos(i + 5, j + 3, k + 19), Block.getBlockById(168).getStateFromMeta(1), 2);
		world.setBlockState(new BlockPos(i + 6, j + 3, k + 19), Block.getBlockById(168).getStateFromMeta(1), 2);
		world.setBlockState(new BlockPos(i + 7, j + 3, k + 19), Block.getBlockById(168).getStateFromMeta(1), 2);
		world.setBlockState(new BlockPos(i + 8, j + 3, k + 19), Block.getBlockById(49).getStateFromMeta(0), 2);
		world.setBlockState(new BlockPos(i + 9, j + 3, k + 19), Block.getBlockById(49).getStateFromMeta(0), 2);
		world.setBlockState(new BlockPos(i + 10, j + 3, k + 19), Block.getBlockById(49).getStateFromMeta(0), 2);
		world.setBlockState(new BlockPos(i + 11, j + 3, k + 19), Block.getBlockById(49).getStateFromMeta(0), 2);
		world.setBlockState(new BlockPos(i + 12, j + 3, k + 19), Block.getBlockById(49).getStateFromMeta(0), 2);
		world.setBlockState(new BlockPos(i + 13, j + 3, k + 19), Block.getBlockById(49).getStateFromMeta(0), 2);
		world.setBlockState(new BlockPos(i + 14, j + 3, k + 19), Block.getBlockById(49).getStateFromMeta(0), 2);
		world.setBlockState(new BlockPos(i + 15, j + 3, k + 19), Block.getBlockById(49).getStateFromMeta(0), 2);
		world.setBlockState(new BlockPos(i + 16, j + 3, k + 19), Block.getBlockById(49).getStateFromMeta(0), 2);
		world.setBlockState(new BlockPos(i + 17, j + 3, k + 19), Block.getBlockById(49).getStateFromMeta(0), 2);
		world.setBlockState(new BlockPos(i + 18, j + 3, k + 19), Block.getBlockById(49).getStateFromMeta(0), 2);
		world.setBlockState(new BlockPos(i + 20, j + 3, k + 19), Block.getBlockById(168).getStateFromMeta(0), 2);
		world.setBlockState(new BlockPos(i + 2, j + 3, k + 20), Block.getBlockById(168).getStateFromMeta(2), 2);
		world.setBlockState(new BlockPos(i + 3, j + 3, k + 20), Block.getBlockById(168).getStateFromMeta(0), 2);
		world.setBlockState(new BlockPos(i + 4, j + 3, k + 20), Block.getBlockById(168).getStateFromMeta(0), 2);
		world.setBlockState(new BlockPos(i + 5, j + 3, k + 20), Block.getBlockById(168).getStateFromMeta(0), 2);
		world.setBlockState(new BlockPos(i + 6, j + 3, k + 20), Block.getBlockById(168).getStateFromMeta(0), 2);
		world.setBlockState(new BlockPos(i + 7, j + 3, k + 20), Block.getBlockById(168).getStateFromMeta(0), 2);
		world.setBlockState(new BlockPos(i + 8, j + 3, k + 20), Block.getBlockById(168).getStateFromMeta(0), 2);
		world.setBlockState(new BlockPos(i + 9, j + 3, k + 20), Block.getBlockById(168).getStateFromMeta(0), 2);
		world.setBlockState(new BlockPos(i + 10, j + 3, k + 20), Block.getBlockById(168).getStateFromMeta(0), 2);
		world.setBlockState(new BlockPos(i + 11, j + 3, k + 20), Block.getBlockById(168).getStateFromMeta(0), 2);
		world.setBlockState(new BlockPos(i + 12, j + 3, k + 20), Block.getBlockById(168).getStateFromMeta(0), 2);
		world.setBlockState(new BlockPos(i + 13, j + 3, k + 20), Block.getBlockById(168).getStateFromMeta(0), 2);
		world.setBlockState(new BlockPos(i + 14, j + 3, k + 20), Block.getBlockById(168).getStateFromMeta(0), 2);
		world.setBlockState(new BlockPos(i + 15, j + 3, k + 20), Block.getBlockById(168).getStateFromMeta(0), 2);
		world.setBlockState(new BlockPos(i + 16, j + 3, k + 20), Block.getBlockById(168).getStateFromMeta(0), 2);
		world.setBlockState(new BlockPos(i + 17, j + 3, k + 20), Block.getBlockById(168).getStateFromMeta(0), 2);
		world.setBlockState(new BlockPos(i + 18, j + 3, k + 20), Block.getBlockById(168).getStateFromMeta(0), 2);
		world.setBlockState(new BlockPos(i + 19, j + 3, k + 20), Block.getBlockById(168).getStateFromMeta(0), 2);
		world.setBlockState(new BlockPos(i + 20, j + 3, k + 20), Block.getBlockById(168).getStateFromMeta(2), 2);
		world.setBlockState(new BlockPos(i + 20, j + 3, k + 26), Block.getBlockById(168).getStateFromMeta(0), 2);
		world.setBlockState(new BlockPos(i + 19, j + 3, k + 27), Block.getBlockById(168).getStateFromMeta(0), 2);
		world.setBlockState(new BlockPos(i + 20, j + 3, k + 27), Block.getBlockById(41).getStateFromMeta(0), 2);
		world.setBlockState(new BlockPos(i + 21, j + 3, k + 27), Block.getBlockById(168).getStateFromMeta(0), 2);
		world.setBlockState(new BlockPos(i + 20, j + 3, k + 28), Block.getBlockById(168).getStateFromMeta(0), 2);
		world.setBlockState(new BlockPos(i + 20, j + 4, k + 1), Block.getBlockById(168).getStateFromMeta(0), 2);
		world.setBlockState(new BlockPos(i + 19, j + 4, k + 2), Block.getBlockById(168).getStateFromMeta(0), 2);
		world.setBlockState(new BlockPos(i + 20, j + 4, k + 2), Block.getBlockById(41).getStateFromMeta(0), 2);
		world.setBlockState(new BlockPos(i + 21, j + 4, k + 2), Block.getBlockById(168).getStateFromMeta(0), 2);
		world.setBlockState(new BlockPos(i + 20, j + 4, k + 3), Block.getBlockById(168).getStateFromMeta(0), 2);
		world.setBlockState(new BlockPos(i + 3, j + 4, k + 10), Block.getBlockById(168).getStateFromMeta(2), 2);
		world.setBlockState(new BlockPos(i + 4, j + 4, k + 10), Block.getBlockById(168).getStateFromMeta(0), 2);
		world.setBlockState(new BlockPos(i + 5, j + 4, k + 10), Block.getBlockById(168).getStateFromMeta(0), 2);
		world.setBlockState(new BlockPos(i + 6, j + 4, k + 10), Block.getBlockById(168).getStateFromMeta(0), 2);
		world.setBlockState(new BlockPos(i + 7, j + 4, k + 10), Block.getBlockById(168).getStateFromMeta(0), 2);
		world.setBlockState(new BlockPos(i + 8, j + 4, k + 10), Block.getBlockById(168).getStateFromMeta(0), 2);
		world.setBlockState(new BlockPos(i + 9, j + 4, k + 10), Block.getBlockById(168).getStateFromMeta(0), 2);
		world.setBlockState(new BlockPos(i + 10, j + 4, k + 10), Block.getBlockById(168).getStateFromMeta(0), 2);
		world.setBlockState(new BlockPos(i + 11, j + 4, k + 10), Block.getBlockById(168).getStateFromMeta(0), 2);
		world.setBlockState(new BlockPos(i + 12, j + 4, k + 10), Block.getBlockById(168).getStateFromMeta(0), 2);
		world.setBlockState(new BlockPos(i + 13, j + 4, k + 10), Block.getBlockById(168).getStateFromMeta(0), 2);
		world.setBlockState(new BlockPos(i + 14, j + 4, k + 10), Block.getBlockById(168).getStateFromMeta(0), 2);
		world.setBlockState(new BlockPos(i + 15, j + 4, k + 10), Block.getBlockById(168).getStateFromMeta(0), 2);
		world.setBlockState(new BlockPos(i + 16, j + 4, k + 10), Block.getBlockById(168).getStateFromMeta(0), 2);
		world.setBlockState(new BlockPos(i + 17, j + 4, k + 10), Block.getBlockById(168).getStateFromMeta(0), 2);
		world.setBlockState(new BlockPos(i + 18, j + 4, k + 10), Block.getBlockById(168).getStateFromMeta(0), 2);
		world.setBlockState(new BlockPos(i + 19, j + 4, k + 10), Block.getBlockById(168).getStateFromMeta(2), 2);
		world.setBlockState(new BlockPos(i + 3, j + 4, k + 11), Block.getBlockById(168).getStateFromMeta(0), 2);
		world.setBlockState(new BlockPos(i + 4, j + 4, k + 11), Block.getBlockById(168).getStateFromMeta(0), 2);
		world.setBlockState(new BlockPos(i + 5, j + 4, k + 11), Block.getBlockById(168).getStateFromMeta(0), 2);
		world.setBlockState(new BlockPos(i + 6, j + 4, k + 11), Block.getBlockById(168).getStateFromMeta(0), 2);
		world.setBlockState(new BlockPos(i + 7, j + 4, k + 11), Block.getBlockById(168).getStateFromMeta(0), 2);
		world.setBlockState(new BlockPos(i + 8, j + 4, k + 11), Block.getBlockById(168).getStateFromMeta(0), 2);
		world.setBlockState(new BlockPos(i + 9, j + 4, k + 11), Block.getBlockById(168).getStateFromMeta(0), 2);
		world.setBlockState(new BlockPos(i + 10, j + 4, k + 11), Block.getBlockById(168).getStateFromMeta(0), 2);
		world.setBlockState(new BlockPos(i + 11, j + 4, k + 11), Block.getBlockById(168).getStateFromMeta(0), 2);
		world.setBlockState(new BlockPos(i + 12, j + 4, k + 11), Block.getBlockById(168).getStateFromMeta(0), 2);
		world.setBlockState(new BlockPos(i + 13, j + 4, k + 11), Block.getBlockById(168).getStateFromMeta(0), 2);
		world.setBlockState(new BlockPos(i + 14, j + 4, k + 11), Block.getBlockById(168).getStateFromMeta(0), 2);
		world.setBlockState(new BlockPos(i + 15, j + 4, k + 11), Block.getBlockById(168).getStateFromMeta(0), 2);
		world.setBlockState(new BlockPos(i + 16, j + 4, k + 11), Block.getBlockById(168).getStateFromMeta(0), 2);
		world.setBlockState(new BlockPos(i + 17, j + 4, k + 11), Block.getBlockById(168).getStateFromMeta(0), 2);
		world.setBlockState(new BlockPos(i + 18, j + 4, k + 11), Block.getBlockById(168).getStateFromMeta(0), 2);
		world.setBlockState(new BlockPos(i + 19, j + 4, k + 11), Block.getBlockById(168).getStateFromMeta(0), 2);
		world.setBlockState(new BlockPos(i + 3, j + 4, k + 12), Block.getBlockById(168).getStateFromMeta(0), 2);
		world.setBlockState(new BlockPos(i + 4, j + 4, k + 12), Block.getBlockById(168).getStateFromMeta(0), 2);
		world.setBlockState(new BlockPos(i + 5, j + 4, k + 12), Block.getBlockById(168).getStateFromMeta(0), 2);
		world.setBlockState(new BlockPos(i + 6, j + 4, k + 12), Block.getBlockById(168).getStateFromMeta(0), 2);
		world.setBlockState(new BlockPos(i + 7, j + 4, k + 12), Block.getBlockById(168).getStateFromMeta(0), 2);
		world.setBlockState(new BlockPos(i + 8, j + 4, k + 12), Block.getBlockById(168).getStateFromMeta(0), 2);
		world.setBlockState(new BlockPos(i + 9, j + 4, k + 12), Block.getBlockById(168).getStateFromMeta(0), 2);
		world.setBlockState(new BlockPos(i + 10, j + 4, k + 12), Block.getBlockById(168).getStateFromMeta(0), 2);
		world.setBlockState(new BlockPos(i + 11, j + 4, k + 12), Block.getBlockById(168).getStateFromMeta(0), 2);
		world.setBlockState(new BlockPos(i + 12, j + 4, k + 12), Block.getBlockById(168).getStateFromMeta(0), 2);
		world.setBlockState(new BlockPos(i + 13, j + 4, k + 12), Block.getBlockById(168).getStateFromMeta(0), 2);
		world.setBlockState(new BlockPos(i + 14, j + 4, k + 12), Block.getBlockById(168).getStateFromMeta(0), 2);
		world.setBlockState(new BlockPos(i + 15, j + 4, k + 12), Block.getBlockById(168).getStateFromMeta(0), 2);
		world.setBlockState(new BlockPos(i + 16, j + 4, k + 12), Block.getBlockById(168).getStateFromMeta(0), 2);
		world.setBlockState(new BlockPos(i + 17, j + 4, k + 12), Block.getBlockById(168).getStateFromMeta(0), 2);
		world.setBlockState(new BlockPos(i + 18, j + 4, k + 12), Block.getBlockById(168).getStateFromMeta(0), 2);
		world.setBlockState(new BlockPos(i + 19, j + 4, k + 12), Block.getBlockById(168).getStateFromMeta(0), 2);
		world.setBlockState(new BlockPos(i + 3, j + 4, k + 13), Block.getBlockById(168).getStateFromMeta(0), 2);
		world.setBlockState(new BlockPos(i + 4, j + 4, k + 13), Block.getBlockById(168).getStateFromMeta(0), 2);
		world.setBlockState(new BlockPos(i + 5, j + 4, k + 13), Block.getBlockById(168).getStateFromMeta(0), 2);
		world.setBlockState(new BlockPos(i + 6, j + 4, k + 13), Block.getBlockById(168).getStateFromMeta(0), 2);
		world.setBlockState(new BlockPos(i + 7, j + 4, k + 13), Block.getBlockById(168).getStateFromMeta(0), 2);
		world.setBlockState(new BlockPos(i + 8, j + 4, k + 13), Block.getBlockById(168).getStateFromMeta(0), 2);
		world.setBlockState(new BlockPos(i + 9, j + 4, k + 13), Block.getBlockById(168).getStateFromMeta(0), 2);
		world.setBlockState(new BlockPos(i + 10, j + 4, k + 13), Block.getBlockById(168).getStateFromMeta(0), 2);
		world.setBlockState(new BlockPos(i + 11, j + 4, k + 13), Block.getBlockById(168).getStateFromMeta(0), 2);
		world.setBlockState(new BlockPos(i + 12, j + 4, k + 13), Block.getBlockById(168).getStateFromMeta(0), 2);
		world.setBlockState(new BlockPos(i + 13, j + 4, k + 13), Block.getBlockById(168).getStateFromMeta(0), 2);
		world.setBlockState(new BlockPos(i + 14, j + 4, k + 13), Block.getBlockById(168).getStateFromMeta(0), 2);
		world.setBlockState(new BlockPos(i + 15, j + 4, k + 13), Block.getBlockById(168).getStateFromMeta(0), 2);
		world.setBlockState(new BlockPos(i + 16, j + 4, k + 13), Block.getBlockById(168).getStateFromMeta(0), 2);
		world.setBlockState(new BlockPos(i + 17, j + 4, k + 13), Block.getBlockById(168).getStateFromMeta(0), 2);
		world.setBlockState(new BlockPos(i + 18, j + 4, k + 13), Block.getBlockById(168).getStateFromMeta(0), 2);
		world.setBlockState(new BlockPos(i + 19, j + 4, k + 13), Block.getBlockById(168).getStateFromMeta(0), 2);
		world.setBlockState(new BlockPos(i + 20, j + 4, k + 13), Block.getBlockById(168).getStateFromMeta(0), 2);
		world.setBlockState(new BlockPos(i + 21, j + 4, k + 13), Block.getBlockById(168).getStateFromMeta(0), 2);
		world.setBlockState(new BlockPos(i + 22, j + 4, k + 13), Block.getBlockById(168).getStateFromMeta(2), 2);
		world.setBlockState(new BlockPos(i + 3, j + 4, k + 14), Block.getBlockById(168).getStateFromMeta(0), 2);
		world.setBlockState(new BlockPos(i + 4, j + 4, k + 14), Block.getBlockById(168).getStateFromMeta(0), 2);
		world.setBlockState(new BlockPos(i + 5, j + 4, k + 14), Block.getBlockById(168).getStateFromMeta(0), 2);
		world.setBlockState(new BlockPos(i + 6, j + 4, k + 14), Block.getBlockById(168).getStateFromMeta(0), 2);
		world.setBlockState(new BlockPos(i + 7, j + 4, k + 14), Block.getBlockById(168).getStateFromMeta(0), 2);
		world.setBlockState(new BlockPos(i + 8, j + 4, k + 14), Block.getBlockById(168).getStateFromMeta(0), 2);
		world.setBlockState(new BlockPos(i + 9, j + 4, k + 14), Block.getBlockById(168).getStateFromMeta(0), 2);
		world.setBlockState(new BlockPos(i + 10, j + 4, k + 14), Block.getBlockById(168).getStateFromMeta(0), 2);
		world.setBlockState(new BlockPos(i + 11, j + 4, k + 14), Block.getBlockById(168).getStateFromMeta(0), 2);
		world.setBlockState(new BlockPos(i + 12, j + 4, k + 14), Block.getBlockById(168).getStateFromMeta(0), 2);
		world.setBlockState(new BlockPos(i + 13, j + 4, k + 14), Block.getBlockById(168).getStateFromMeta(0), 2);
		world.setBlockState(new BlockPos(i + 14, j + 4, k + 14), Block.getBlockById(168).getStateFromMeta(0), 2);
		world.setBlockState(new BlockPos(i + 15, j + 4, k + 14), Block.getBlockById(168).getStateFromMeta(0), 2);
		world.setBlockState(new BlockPos(i + 16, j + 4, k + 14), Block.getBlockById(168).getStateFromMeta(0), 2);
		world.setBlockState(new BlockPos(i + 17, j + 4, k + 14), Block.getBlockById(168).getStateFromMeta(0), 2);
		world.setBlockState(new BlockPos(i + 18, j + 4, k + 14), Block.getBlockById(168).getStateFromMeta(0), 2);
		world.setBlockState(new BlockPos(i + 19, j + 4, k + 14), Block.getBlockById(169).getStateFromMeta(0), 2);
		world.setBlockState(new BlockPos(i + 3, j + 4, k + 15), Block.getBlockById(168).getStateFromMeta(0), 2);
		world.setBlockState(new BlockPos(i + 4, j + 4, k + 15), Block.getBlockById(168).getStateFromMeta(0), 2);
		world.setBlockState(new BlockPos(i + 5, j + 4, k + 15), Block.getBlockById(168).getStateFromMeta(0), 2);
		world.setBlockState(new BlockPos(i + 6, j + 4, k + 15), Block.getBlockById(168).getStateFromMeta(0), 2);
		world.setBlockState(new BlockPos(i + 7, j + 4, k + 15), Block.getBlockById(168).getStateFromMeta(0), 2);
		world.setBlockState(new BlockPos(i + 8, j + 4, k + 15), Block.getBlockById(168).getStateFromMeta(0), 2);
		world.setBlockState(new BlockPos(i + 9, j + 4, k + 15), Block.getBlockById(168).getStateFromMeta(0), 2);
		world.setBlockState(new BlockPos(i + 10, j + 4, k + 15), Block.getBlockById(168).getStateFromMeta(0), 2);
		world.setBlockState(new BlockPos(i + 11, j + 4, k + 15), Block.getBlockById(168).getStateFromMeta(0), 2);
		world.setBlockState(new BlockPos(i + 12, j + 4, k + 15), Block.getBlockById(168).getStateFromMeta(0), 2);
		world.setBlockState(new BlockPos(i + 13, j + 4, k + 15), Block.getBlockById(168).getStateFromMeta(0), 2);
		world.setBlockState(new BlockPos(i + 14, j + 4, k + 15), Block.getBlockById(168).getStateFromMeta(0), 2);
		world.setBlockState(new BlockPos(i + 15, j + 4, k + 15), Block.getBlockById(168).getStateFromMeta(0), 2);
		world.setBlockState(new BlockPos(i + 16, j + 4, k + 15), Block.getBlockById(168).getStateFromMeta(0), 2);
		world.setBlockState(new BlockPos(i + 17, j + 4, k + 15), Block.getBlockById(168).getStateFromMeta(0), 2);
		world.setBlockState(new BlockPos(i + 18, j + 4, k + 15), Block.getBlockById(168).getStateFromMeta(0), 2);
		world.setBlockState(new BlockPos(i + 19, j + 4, k + 15), Block.getBlockById(169).getStateFromMeta(0), 2);
		world.setBlockState(new BlockPos(i + 3, j + 4, k + 16), Block.getBlockById(168).getStateFromMeta(0), 2);
		world.setBlockState(new BlockPos(i + 4, j + 4, k + 16), Block.getBlockById(168).getStateFromMeta(0), 2);
		world.setBlockState(new BlockPos(i + 5, j + 4, k + 16), Block.getBlockById(168).getStateFromMeta(0), 2);
		world.setBlockState(new BlockPos(i + 6, j + 4, k + 16), Block.getBlockById(168).getStateFromMeta(0), 2);
		world.setBlockState(new BlockPos(i + 7, j + 4, k + 16), Block.getBlockById(168).getStateFromMeta(0), 2);
		world.setBlockState(new BlockPos(i + 8, j + 4, k + 16), Block.getBlockById(168).getStateFromMeta(0), 2);
		world.setBlockState(new BlockPos(i + 9, j + 4, k + 16), Block.getBlockById(168).getStateFromMeta(0), 2);
		world.setBlockState(new BlockPos(i + 10, j + 4, k + 16), Block.getBlockById(168).getStateFromMeta(0), 2);
		world.setBlockState(new BlockPos(i + 11, j + 4, k + 16), Block.getBlockById(168).getStateFromMeta(0), 2);
		world.setBlockState(new BlockPos(i + 12, j + 4, k + 16), Block.getBlockById(168).getStateFromMeta(0), 2);
		world.setBlockState(new BlockPos(i + 13, j + 4, k + 16), Block.getBlockById(168).getStateFromMeta(0), 2);
		world.setBlockState(new BlockPos(i + 14, j + 4, k + 16), Block.getBlockById(168).getStateFromMeta(0), 2);
		world.setBlockState(new BlockPos(i + 15, j + 4, k + 16), Block.getBlockById(9).getStateFromMeta(8), 2);
		world.setBlockState(new BlockPos(i + 16, j + 4, k + 16), Block.getBlockById(168).getStateFromMeta(0), 2);
		world.setBlockState(new BlockPos(i + 17, j + 4, k + 16), Block.getBlockById(168).getStateFromMeta(0), 2);
		world.setBlockState(new BlockPos(i + 18, j + 4, k + 16), Block.getBlockById(168).getStateFromMeta(0), 2);
		world.setBlockState(new BlockPos(i + 19, j + 4, k + 16), Block.getBlockById(168).getStateFromMeta(0), 2);
		world.setBlockState(new BlockPos(i + 20, j + 4, k + 16), Block.getBlockById(168).getStateFromMeta(0), 2);
		world.setBlockState(new BlockPos(i + 21, j + 4, k + 16), Block.getBlockById(168).getStateFromMeta(0), 2);
		world.setBlockState(new BlockPos(i + 22, j + 4, k + 16), Block.getBlockById(168).getStateFromMeta(2), 2);
		world.setBlockState(new BlockPos(i + 3, j + 4, k + 17), Block.getBlockById(168).getStateFromMeta(0), 2);
		world.setBlockState(new BlockPos(i + 4, j + 4, k + 17), Block.getBlockById(168).getStateFromMeta(0), 2);
		world.setBlockState(new BlockPos(i + 5, j + 4, k + 17), Block.getBlockById(168).getStateFromMeta(0), 2);
		world.setBlockState(new BlockPos(i + 6, j + 4, k + 17), Block.getBlockById(168).getStateFromMeta(0), 2);
		world.setBlockState(new BlockPos(i + 7, j + 4, k + 17), Block.getBlockById(168).getStateFromMeta(0), 2);
		world.setBlockState(new BlockPos(i + 8, j + 4, k + 17), Block.getBlockById(168).getStateFromMeta(0), 2);
		world.setBlockState(new BlockPos(i + 9, j + 4, k + 17), Block.getBlockById(168).getStateFromMeta(0), 2);
		world.setBlockState(new BlockPos(i + 10, j + 4, k + 17), Block.getBlockById(168).getStateFromMeta(0), 2);
		world.setBlockState(new BlockPos(i + 11, j + 4, k + 17), Block.getBlockById(168).getStateFromMeta(0), 2);
		world.setBlockState(new BlockPos(i + 12, j + 4, k + 17), Block.getBlockById(168).getStateFromMeta(0), 2);
		world.setBlockState(new BlockPos(i + 13, j + 4, k + 17), Block.getBlockById(168).getStateFromMeta(0), 2);
		world.setBlockState(new BlockPos(i + 14, j + 4, k + 17), Block.getBlockById(168).getStateFromMeta(0), 2);
		world.setBlockState(new BlockPos(i + 15, j + 4, k + 17), Block.getBlockById(9).getStateFromMeta(8), 2);
		world.setBlockState(new BlockPos(i + 16, j + 4, k + 17), Block.getBlockById(168).getStateFromMeta(0), 2);
		world.setBlockState(new BlockPos(i + 17, j + 4, k + 17), Block.getBlockById(168).getStateFromMeta(0), 2);
		world.setBlockState(new BlockPos(i + 18, j + 4, k + 17), Block.getBlockById(168).getStateFromMeta(0), 2);
		world.setBlockState(new BlockPos(i + 19, j + 4, k + 17), Block.getBlockById(168).getStateFromMeta(0), 2);
		world.setBlockState(new BlockPos(i + 3, j + 4, k + 18), Block.getBlockById(168).getStateFromMeta(0), 2);
		world.setBlockState(new BlockPos(i + 4, j + 4, k + 18), Block.getBlockById(168).getStateFromMeta(0), 2);
		world.setBlockState(new BlockPos(i + 5, j + 4, k + 18), Block.getBlockById(168).getStateFromMeta(0), 2);
		world.setBlockState(new BlockPos(i + 6, j + 4, k + 18), Block.getBlockById(168).getStateFromMeta(0), 2);
		world.setBlockState(new BlockPos(i + 7, j + 4, k + 18), Block.getBlockById(168).getStateFromMeta(0), 2);
		world.setBlockState(new BlockPos(i + 8, j + 4, k + 18), Block.getBlockById(49).getStateFromMeta(0), 2);
		world.setBlockState(new BlockPos(i + 9, j + 4, k + 18), Block.getBlockById(49).getStateFromMeta(0), 2);
		world.setBlockState(new BlockPos(i + 10, j + 4, k + 18), Block.getBlockById(49).getStateFromMeta(0), 2);
		world.setBlockState(new BlockPos(i + 11, j + 4, k + 18), Block.getBlockById(49).getStateFromMeta(0), 2);
		world.setBlockState(new BlockPos(i + 12, j + 4, k + 18), Block.getBlockById(49).getStateFromMeta(0), 2);
		world.setBlockState(new BlockPos(i + 13, j + 4, k + 18), Block.getBlockById(49).getStateFromMeta(0), 2);
		world.setBlockState(new BlockPos(i + 14, j + 4, k + 18), Block.getBlockById(49).getStateFromMeta(0), 2);
		world.setBlockState(new BlockPos(i + 15, j + 4, k + 18), Block.getBlockById(9).getStateFromMeta(1), 2);
		world.setBlockState(new BlockPos(i + 16, j + 4, k + 18), Block.getBlockById(49).getStateFromMeta(0), 2);
		world.setBlockState(new BlockPos(i + 17, j + 4, k + 18), Block.getBlockById(49).getStateFromMeta(0), 2);
		world.setBlockState(new BlockPos(i + 18, j + 4, k + 18), Block.getBlockById(49).getStateFromMeta(0), 2);
		world.setBlockState(new BlockPos(i + 19, j + 4, k + 18), Block.getBlockById(168).getStateFromMeta(0), 2);
		world.setBlockState(new BlockPos(i + 3, j + 4, k + 19), Block.getBlockById(168).getStateFromMeta(2), 2);
		world.setBlockState(new BlockPos(i + 4, j + 4, k + 19), Block.getBlockById(168).getStateFromMeta(0), 2);
		world.setBlockState(new BlockPos(i + 5, j + 4, k + 19), Block.getBlockById(168).getStateFromMeta(0), 2);
		world.setBlockState(new BlockPos(i + 6, j + 4, k + 19), Block.getBlockById(168).getStateFromMeta(0), 2);
		world.setBlockState(new BlockPos(i + 7, j + 4, k + 19), Block.getBlockById(168).getStateFromMeta(0), 2);
		world.setBlockState(new BlockPos(i + 8, j + 4, k + 19), Block.getBlockById(168).getStateFromMeta(0), 2);
		world.setBlockState(new BlockPos(i + 9, j + 4, k + 19), Block.getBlockById(168).getStateFromMeta(0), 2);
		world.setBlockState(new BlockPos(i + 10, j + 4, k + 19), Block.getBlockById(168).getStateFromMeta(0), 2);
		world.setBlockState(new BlockPos(i + 11, j + 4, k + 19), Block.getBlockById(168).getStateFromMeta(0), 2);
		world.setBlockState(new BlockPos(i + 12, j + 4, k + 19), Block.getBlockById(168).getStateFromMeta(0), 2);
		world.setBlockState(new BlockPos(i + 13, j + 4, k + 19), Block.getBlockById(168).getStateFromMeta(0), 2);
		world.setBlockState(new BlockPos(i + 14, j + 4, k + 19), Block.getBlockById(168).getStateFromMeta(0), 2);
		world.setBlockState(new BlockPos(i + 15, j + 4, k + 19), Block.getBlockById(168).getStateFromMeta(0), 2);
		world.setBlockState(new BlockPos(i + 16, j + 4, k + 19), Block.getBlockById(168).getStateFromMeta(0), 2);
		world.setBlockState(new BlockPos(i + 17, j + 4, k + 19), Block.getBlockById(168).getStateFromMeta(0), 2);
		world.setBlockState(new BlockPos(i + 18, j + 4, k + 19), Block.getBlockById(168).getStateFromMeta(0), 2);
		world.setBlockState(new BlockPos(i + 19, j + 4, k + 19), Block.getBlockById(168).getStateFromMeta(2), 2);
		world.setBlockState(new BlockPos(i + 20, j + 4, k + 26), Block.getBlockById(168).getStateFromMeta(0), 2);
		world.setBlockState(new BlockPos(i + 19, j + 4, k + 27), Block.getBlockById(168).getStateFromMeta(0), 2);
		world.setBlockState(new BlockPos(i + 20, j + 4, k + 27), Block.getBlockById(41).getStateFromMeta(0), 2);
		world.setBlockState(new BlockPos(i + 21, j + 4, k + 27), Block.getBlockById(168).getStateFromMeta(0), 2);
		world.setBlockState(new BlockPos(i + 20, j + 4, k + 28), Block.getBlockById(168).getStateFromMeta(0), 2);
		world.setBlockState(new BlockPos(i + 20, j + 5, k + 1), Block.getBlockById(168).getStateFromMeta(0), 2);
		world.setBlockState(new BlockPos(i + 19, j + 5, k + 2), Block.getBlockById(168).getStateFromMeta(0), 2);
		world.setBlockState(new BlockPos(i + 20, j + 5, k + 2), Block.getBlockById(41).getStateFromMeta(0), 2);
		world.setBlockState(new BlockPos(i + 21, j + 5, k + 2), Block.getBlockById(168).getStateFromMeta(0), 2);
		world.setBlockState(new BlockPos(i + 20, j + 5, k + 3), Block.getBlockById(168).getStateFromMeta(0), 2);
		world.setBlockState(new BlockPos(i + 4, j + 5, k + 11), Block.getBlockById(168).getStateFromMeta(2), 2);
		world.setBlockState(new BlockPos(i + 5, j + 5, k + 11), Block.getBlockById(168).getStateFromMeta(0), 2);
		world.setBlockState(new BlockPos(i + 6, j + 5, k + 11), Block.getBlockById(168).getStateFromMeta(0), 2);
		world.setBlockState(new BlockPos(i + 7, j + 5, k + 11), Block.getBlockById(168).getStateFromMeta(0), 2);
		world.setBlockState(new BlockPos(i + 8, j + 5, k + 11), Block.getBlockById(168).getStateFromMeta(0), 2);
		world.setBlockState(new BlockPos(i + 9, j + 5, k + 11), Block.getBlockById(168).getStateFromMeta(0), 2);
		world.setBlockState(new BlockPos(i + 10, j + 5, k + 11), Block.getBlockById(168).getStateFromMeta(0), 2);
		world.setBlockState(new BlockPos(i + 11, j + 5, k + 11), Block.getBlockById(168).getStateFromMeta(0), 2);
		world.setBlockState(new BlockPos(i + 12, j + 5, k + 11), Block.getBlockById(168).getStateFromMeta(0), 2);
		world.setBlockState(new BlockPos(i + 13, j + 5, k + 11), Block.getBlockById(168).getStateFromMeta(0), 2);
		world.setBlockState(new BlockPos(i + 14, j + 5, k + 11), Block.getBlockById(168).getStateFromMeta(0), 2);
		world.setBlockState(new BlockPos(i + 15, j + 5, k + 11), Block.getBlockById(168).getStateFromMeta(0), 2);
		world.setBlockState(new BlockPos(i + 16, j + 5, k + 11), Block.getBlockById(168).getStateFromMeta(0), 2);
		world.setBlockState(new BlockPos(i + 17, j + 5, k + 11), Block.getBlockById(168).getStateFromMeta(0), 2);
		world.setBlockState(new BlockPos(i + 18, j + 5, k + 11), Block.getBlockById(168).getStateFromMeta(2), 2);
		world.setBlockState(new BlockPos(i + 4, j + 5, k + 12), Block.getBlockById(168).getStateFromMeta(0), 2);
		world.setBlockState(new BlockPos(i + 5, j + 5, k + 12), Block.getBlockById(251).getStateFromMeta(15), 2);
		world.setBlockState(new BlockPos(i + 6, j + 5, k + 12), Block.getBlockById(251).getStateFromMeta(15), 2);
		world.setBlockState(new BlockPos(i + 7, j + 5, k + 12), Block.getBlockById(251).getStateFromMeta(15), 2);
		world.setBlockState(new BlockPos(i + 8, j + 5, k + 12), Block.getBlockById(251).getStateFromMeta(15), 2);
		world.setBlockState(new BlockPos(i + 9, j + 5, k + 12), Block.getBlockById(251).getStateFromMeta(15), 2);
		world.setBlockState(new BlockPos(i + 10, j + 5, k + 12), Block.getBlockById(251).getStateFromMeta(15), 2);
		world.setBlockState(new BlockPos(i + 11, j + 5, k + 12), Block.getBlockById(251).getStateFromMeta(15), 2);
		world.setBlockState(new BlockPos(i + 12, j + 5, k + 12), Block.getBlockById(251).getStateFromMeta(15), 2);
		world.setBlockState(new BlockPos(i + 13, j + 5, k + 12), Block.getBlockById(251).getStateFromMeta(15), 2);
		world.setBlockState(new BlockPos(i + 14, j + 5, k + 12), Block.getBlockById(251).getStateFromMeta(15), 2);
		world.setBlockState(new BlockPos(i + 15, j + 5, k + 12), Block.getBlockById(251).getStateFromMeta(15), 2);
		world.setBlockState(new BlockPos(i + 16, j + 5, k + 12), Block.getBlockById(251).getStateFromMeta(15), 2);
		world.setBlockState(new BlockPos(i + 18, j + 5, k + 12), Block.getBlockById(168).getStateFromMeta(0), 2);
