package net.modjam5.makercommunity.common.world.structure;

import java.util.Collections;
import java.util.List;
import java.util.Random;

import javax.annotation.Nullable;

import net.minecraft.block.Block;
import net.minecraft.enchantment.Enchantment;
import net.minecraft.entity.item.EntityItemFrame;
import net.minecraft.entity.monster.EntitySkeleton;
import net.minecraft.init.*;
import net.minecraft.inventory.EntityEquipmentSlot;
import net.minecraft.item.ItemStack;
import net.minecraft.potion.PotionEffect;
import net.minecraft.util.EnumFacing;
import net.minecraft.util.math.BlockPos;
import net.minecraft.world.World;
import net.minecraft.world.biome.Biome;
import net.minecraft.world.biome.BiomeProvider;
import net.minecraft.world.chunk.Chunk;
import net.minecraft.world.gen.structure.MapGenStructure;
import net.minecraft.world.gen.structure.StructureBoundingBox;
import net.minecraft.world.gen.structure.StructureStart;
import net.modjam5.makercommunity.common.ItemRegistry;
import net.modjam5.makercommunity.common.Registry;
import net.modjam5.makercommunity.util.EnchantingHelper;
import net.modjam5.makercommunity.util.MapStructureHelper;

/**
 * @author Tim Biesenbeek
 */
public class SubHouseStructure extends MapGenStructure implements Structure {

	private static final StructureBoundingBox boundingBox = new StructureBoundingBox(new int[]{0, 0, 0, 8, 8, 8});
	private static final List<Biome> ALLOWED_BIOMES = Collections.singletonList(Biomes.DEEP_OCEAN);

	@Override
	public void updateWorld(World world) {
		this.world = world;
	}

	@Override
	public StructureBoundingBox getBoundingBox() {
		return boundingBox;
	}

	@Override
	public String getStructureName() {
		return "SubHouse";
	}

	@Nullable
	@Override
	public BlockPos getNearestStructurePos(World worldIn, BlockPos pos, boolean findUnexplored) {
		this.world = worldIn;
		BiomeProvider biomeprovider = worldIn.getBiomeProvider();
		return biomeprovider.isFixedBiome() && biomeprovider.getFixedBiome() != Biomes.BEACH ? null
				: findNearestStructurePosBySpacing(worldIn, this, pos, 80, 20, 10387319, true, 100, findUnexplored);
	}

	@Override
	public boolean canSpawnStructureAtCoords(int chunkX, int chunkZ) {
		if (Math.abs(chunkX) < 60 || Math.abs(chunkZ) < 60) {
			return false;
		}
		Random random = this.world.setRandomSeed(2304 * chunkX, 1996 * chunkZ, 811);
		boolean rand = random.nextInt(1000) + 1 <= 1;
		boolean biome = this.world.getBiomeProvider().areBiomesViable(chunkX * 16 + 8, chunkZ * 16 + 8, 1,
			ALLOWED_BIOMES);
		return rand && biome;
	}

	@Override
	protected StructureStart getStructureStart(int chunkX, int chunkZ) {
		return new Start(this, chunkX, chunkZ);
	}

	@SuppressWarnings("deprecation")
	public void generate(World world, Random random, int xPos, int zPos) {
		int i = xPos + random.nextInt(15);
		int k = zPos + random.nextInt(15);

		int chunkX = i >> 4;
		int chunkZ = k >> 4;
		Chunk chunk = world.getChunkFromChunkCoords(chunkX, chunkZ);
		int height = chunk.getHeight(new BlockPos(i & 0xF, 0, k & 0xF)) - 1;
		int y;
		for (y = height; y > 10; y--) {
			Block block = chunk.getBlockState(i, y, k).getBlock();
			if (block == Blocks.WATER || block == Blocks.FLOWING_WATER) {
				continue;
			}
			break;
		}

		int j = (int) (y + ((height - y) / 2D));

		BlockPos framePos = new BlockPos(i + 5.5, j + 2.5, k + 12.96875);
		EntityItemFrame entityitemframe = new EntityItemFrame(world, framePos, EnumFacing.NORTH);
		// TODO: change type map
		entityitemframe.setDisplayedItem(MapStructureHelper
				.buildMapFor(Registry.structureRegister.byClass(VillageStructure.class), world, framePos));
		world.spawnEntity(entityitemframe);

		EntitySkeleton skelly = new EntitySkeleton(world);
		skelly.setLocationAndAngles(i + 5.5, j + 1.0, k + 8.5, world.rand.nextFloat() * 360F, 0);
		world.spawnEntity(skelly);
		skelly.addPotionEffect(new PotionEffect(MobEffects.SLOWNESS, 10));
		skelly.setItemStackToSlot(EntityEquipmentSlot.HEAD, new ItemStack(ItemRegistry.recorders[6]));
		skelly.setItemStackToSlot(EntityEquipmentSlot.CHEST,
			EnchantingHelper.withEnchants(new ItemStack(Items.DIAMOND_CHESTPLATE),
				new Enchantment[]{Enchantments.PROTECTION, Enchantments.THORNS}, new int[]{5, 3}));
		skelly.setItemStackToSlot(EntityEquipmentSlot.LEGS,
			EnchantingHelper.withEnchant(new ItemStack(Items.DIAMOND_LEGGINGS), Enchantments.BLAST_PROTECTION, 5));
		skelly.setItemStackToSlot(EntityEquipmentSlot.FEET,
			EnchantingHelper.withEnchant(new ItemStack(Items.DIAMOND_BOOTS), Enchantments.PROJECTILE_PROTECTION, 5));
		skelly.setItemStackToSlot(EntityEquipmentSlot.MAINHAND,
			EnchantingHelper.withEnchant(new ItemStack(Items.BOW), Enchantments.PUNCH, 10));
		skelly.setItemStackToSlot(EntityEquipmentSlot.OFFHAND,
			new ItemStack(Items.SPECTRAL_ARROW, (int) (Math.random() * 64D)));
		skelly.setDropChance(EntityEquipmentSlot.HEAD, 100f);
		skelly.setDropChance(EntityEquipmentSlot.CHEST, 0f);
		skelly.setDropChance(EntityEquipmentSlot.LEGS, 0f);
		skelly.setDropChance(EntityEquipmentSlot.FEET, 0f);
		skelly.setDropChance(EntityEquipmentSlot.MAINHAND, 0f);
		skelly.setDropChance(EntityEquipmentSlot.OFFHAND, 100f);
		skelly.setCustomNameTag("Dinnerbone");
		skelly.enablePersistence();
		skelly.setAlwaysRenderNameTag(false);

		world.setBlockState(new BlockPos(i + 0, j + 0, k + 0), Block.getBlockById(9).getStateFromMeta(0), 2);
		world.setBlockState(new BlockPos(i + 1, j + 0, k + 0), Block.getBlockById(9).getStateFromMeta(0), 2);
		world.setBlockState(new BlockPos(i + 2, j + 0, k + 0), Block.getBlockById(9).getStateFromMeta(0), 2);
		world.setBlockState(new BlockPos(i + 3, j + 0, k + 0), Block.getBlockById(168).getStateFromMeta(0), 2);
		world.setBlockState(new BlockPos(i + 4, j + 0, k + 0), Block.getBlockById(168).getStateFromMeta(0), 2);
		world.setBlockState(new BlockPos(i + 5, j + 0, k + 0), Block.getBlockById(168).getStateFromMeta(0), 2);
		world.setBlockState(new BlockPos(i + 6, j + 0, k + 0), Block.getBlockById(168).getStateFromMeta(0), 2);
		world.setBlockState(new BlockPos(i + 7, j + 0, k + 0), Block.getBlockById(168).getStateFromMeta(0), 2);
		world.setBlockState(new BlockPos(i + 8, j + 0, k + 0), Block.getBlockById(9).getStateFromMeta(0), 2);
		world.setBlockState(new BlockPos(i + 9, j + 0, k + 0), Block.getBlockById(9).getStateFromMeta(0), 2);
		world.setBlockState(new BlockPos(i + 10, j + 0, k + 0), Block.getBlockById(9).getStateFromMeta(0), 2);
		world.setBlockState(new BlockPos(i + 0, j + 0, k + 1), Block.getBlockById(9).getStateFromMeta(0), 2);
		world.setBlockState(new BlockPos(i + 1, j + 0, k + 1), Block.getBlockById(9).getStateFromMeta(0), 2);
		world.setBlockState(new BlockPos(i + 2, j + 0, k + 1), Block.getBlockById(9).getStateFromMeta(0), 2);
		world.setBlockState(new BlockPos(i + 3, j + 0, k + 1), Block.getBlockById(95).getStateFromMeta(3), 2);
		world.setBlockState(new BlockPos(i + 4, j + 0, k + 1), Block.getBlockById(95).getStateFromMeta(3), 2);
		world.setBlockState(new BlockPos(i + 5, j + 0, k + 1), Block.getBlockById(95).getStateFromMeta(3), 2);
		world.setBlockState(new BlockPos(i + 6, j + 0, k + 1), Block.getBlockById(95).getStateFromMeta(3), 2);
		world.setBlockState(new BlockPos(i + 7, j + 0, k + 1), Block.getBlockById(95).getStateFromMeta(3), 2);
		world.setBlockState(new BlockPos(i + 8, j + 0, k + 1), Block.getBlockById(9).getStateFromMeta(0), 2);
		world.setBlockState(new BlockPos(i + 9, j + 0, k + 1), Block.getBlockById(9).getStateFromMeta(0), 2);
		world.setBlockState(new BlockPos(i + 10, j + 0, k + 1), Block.getBlockById(9).getStateFromMeta(0), 2);
		world.setBlockState(new BlockPos(i + 0, j + 0, k + 2), Block.getBlockById(9).getStateFromMeta(0), 2);
		world.setBlockState(new BlockPos(i + 1, j + 0, k + 2), Block.getBlockById(9).getStateFromMeta(0), 2);
		world.setBlockState(new BlockPos(i + 2, j + 0, k + 2), Block.getBlockById(9).getStateFromMeta(0), 2);
		world.setBlockState(new BlockPos(i + 3, j + 0, k + 2), Block.getBlockById(95).getStateFromMeta(3), 2);
		world.setBlockState(new BlockPos(i + 4, j + 0, k + 2), Block.getBlockById(95).getStateFromMeta(3), 2);
		world.setBlockState(new BlockPos(i + 5, j + 0, k + 2), Block.getBlockById(95).getStateFromMeta(3), 2);
		world.setBlockState(new BlockPos(i + 6, j + 0, k + 2), Block.getBlockById(95).getStateFromMeta(3), 2);
		world.setBlockState(new BlockPos(i + 7, j + 0, k + 2), Block.getBlockById(95).getStateFromMeta(3), 2);
		world.setBlockState(new BlockPos(i + 8, j + 0, k + 2), Block.getBlockById(9).getStateFromMeta(0), 2);
		world.setBlockState(new BlockPos(i + 9, j + 0, k + 2), Block.getBlockById(9).getStateFromMeta(0), 2);
		world.setBlockState(new BlockPos(i + 10, j + 0, k + 2), Block.getBlockById(9).getStateFromMeta(0), 2);
		world.setBlockState(new BlockPos(i + 0, j + 0, k + 3), Block.getBlockById(9).getStateFromMeta(0), 2);
		world.setBlockState(new BlockPos(i + 1, j + 0, k + 3), Block.getBlockById(9).getStateFromMeta(0), 2);
		world.setBlockState(new BlockPos(i + 2, j + 0, k + 3), Block.getBlockById(9).getStateFromMeta(0), 2);
		world.setBlockState(new BlockPos(i + 3, j + 0, k + 3), Block.getBlockById(95).getStateFromMeta(3), 2);
		world.setBlockState(new BlockPos(i + 4, j + 0, k + 3), Block.getBlockById(95).getStateFromMeta(3), 2);
		world.setBlockState(new BlockPos(i + 5, j + 0, k + 3), Block.getBlockById(95).getStateFromMeta(3), 2);
		world.setBlockState(new BlockPos(i + 6, j + 0, k + 3), Block.getBlockById(95).getStateFromMeta(3), 2);
		world.setBlockState(new BlockPos(i + 7, j + 0, k + 3), Block.getBlockById(95).getStateFromMeta(3), 2);
		world.setBlockState(new BlockPos(i + 8, j + 0, k + 3), Block.getBlockById(9).getStateFromMeta(0), 2);
		world.setBlockState(new BlockPos(i + 9, j + 0, k + 3), Block.getBlockById(9).getStateFromMeta(0), 2);
		world.setBlockState(new BlockPos(i + 10, j + 0, k + 3), Block.getBlockById(9).getStateFromMeta(0), 2);
		world.setBlockState(new BlockPos(i + 0, j + 0, k + 4), Block.getBlockById(9).getStateFromMeta(0), 2);
		world.setBlockState(new BlockPos(i + 1, j + 0, k + 4), Block.getBlockById(9).getStateFromMeta(0), 2);
		world.setBlockState(new BlockPos(i + 2, j + 0, k + 4), Block.getBlockById(9).getStateFromMeta(0), 2);
		world.setBlockState(new BlockPos(i + 3, j + 0, k + 4), Block.getBlockById(95).getStateFromMeta(3), 2);
		world.setBlockState(new BlockPos(i + 4, j + 0, k + 4), Block.getBlockById(95).getStateFromMeta(3), 2);
		world.setBlockState(new BlockPos(i + 5, j + 0, k + 4), Block.getBlockById(95).getStateFromMeta(3), 2);
		world.setBlockState(new BlockPos(i + 6, j + 0, k + 4), Block.getBlockById(95).getStateFromMeta(3), 2);
		world.setBlockState(new BlockPos(i + 7, j + 0, k + 4), Block.getBlockById(95).getStateFromMeta(3), 2);
		world.setBlockState(new BlockPos(i + 8, j + 0, k + 4), Block.getBlockById(9).getStateFromMeta(0), 2);
		world.setBlockState(new BlockPos(i + 9, j + 0, k + 4), Block.getBlockById(9).getStateFromMeta(0), 2);
		world.setBlockState(new BlockPos(i + 10, j + 0, k + 4), Block.getBlockById(9).getStateFromMeta(0), 2);
		world.setBlockState(new BlockPos(i + 0, j + 0, k + 5), Block.getBlockById(9).getStateFromMeta(0), 2);
		world.setBlockState(new BlockPos(i + 1, j + 0, k + 5), Block.getBlockById(9).getStateFromMeta(0), 2);
		world.setBlockState(new BlockPos(i + 2, j + 0, k + 5), Block.getBlockById(9).getStateFromMeta(0), 2);
		world.setBlockState(new BlockPos(i + 3, j + 0, k + 5), Block.getBlockById(95).getStateFromMeta(3), 2);
		world.setBlockState(new BlockPos(i + 4, j + 0, k + 5), Block.getBlockById(95).getStateFromMeta(3), 2);
		world.setBlockState(new BlockPos(i + 5, j + 0, k + 5), Block.getBlockById(95).getStateFromMeta(3), 2);
		world.setBlockState(new BlockPos(i + 6, j + 0, k + 5), Block.getBlockById(95).getStateFromMeta(3), 2);
		world.setBlockState(new BlockPos(i + 7, j + 0, k + 5), Block.getBlockById(95).getStateFromMeta(3), 2);
		world.setBlockState(new BlockPos(i + 8, j + 0, k + 5), Block.getBlockById(9).getStateFromMeta(0), 2);
		world.setBlockState(new BlockPos(i + 9, j + 0, k + 5), Block.getBlockById(9).getStateFromMeta(0), 2);
		world.setBlockState(new BlockPos(i + 10, j + 0, k + 5), Block.getBlockById(9).getStateFromMeta(0), 2);
		world.setBlockState(new BlockPos(i + 0, j + 0, k + 6), Block.getBlockById(9).getStateFromMeta(0), 2);
		world.setBlockState(new BlockPos(i + 1, j + 0, k + 6), Block.getBlockById(9).getStateFromMeta(0), 2);
		world.setBlockState(new BlockPos(i + 2, j + 0, k + 6), Block.getBlockById(9).getStateFromMeta(0), 2);
		world.setBlockState(new BlockPos(i + 3, j + 0, k + 6), Block.getBlockById(95).getStateFromMeta(3), 2);
		world.setBlockState(new BlockPos(i + 4, j + 0, k + 6), Block.getBlockById(95).getStateFromMeta(3), 2);
		world.setBlockState(new BlockPos(i + 5, j + 0, k + 6), Block.getBlockById(95).getStateFromMeta(3), 2);
		world.setBlockState(new BlockPos(i + 6, j + 0, k + 6), Block.getBlockById(95).getStateFromMeta(3), 2);
		world.setBlockState(new BlockPos(i + 7, j + 0, k + 6), Block.getBlockById(95).getStateFromMeta(3), 2);
		world.setBlockState(new BlockPos(i + 8, j + 0, k + 6), Block.getBlockById(9).getStateFromMeta(0), 2);
		world.setBlockState(new BlockPos(i + 9, j + 0, k + 6), Block.getBlockById(9).getStateFromMeta(0), 2);
		world.setBlockState(new BlockPos(i + 10, j + 0, k + 6), Block.getBlockById(9).getStateFromMeta(0), 2);
		world.setBlockState(new BlockPos(i + 0, j + 0, k + 7), Block.getBlockById(9).getStateFromMeta(0), 2);
		world.setBlockState(new BlockPos(i + 1, j + 0, k + 7), Block.getBlockById(9).getStateFromMeta(0), 2);
		world.setBlockState(new BlockPos(i + 2, j + 0, k + 7), Block.getBlockById(9).getStateFromMeta(0), 2);
		world.setBlockState(new BlockPos(i + 3, j + 0, k + 7), Block.getBlockById(95).getStateFromMeta(3), 2);
		world.setBlockState(new BlockPos(i + 4, j + 0, k + 7), Block.getBlockById(95).getStateFromMeta(3), 2);
		world.setBlockState(new BlockPos(i + 5, j + 0, k + 7), Block.getBlockById(95).getStateFromMeta(3), 2);
		world.setBlockState(new BlockPos(i + 6, j + 0, k + 7), Block.getBlockById(95).getStateFromMeta(3), 2);
		world.setBlockState(new BlockPos(i + 7, j + 0, k + 7), Block.getBlockById(95).getStateFromMeta(3), 2);
		world.setBlockState(new BlockPos(i + 8, j + 0, k + 7), Block.getBlockById(9).getStateFromMeta(0), 2);
		world.setBlockState(new BlockPos(i + 9, j + 0, k + 7), Block.getBlockById(9).getStateFromMeta(0), 2);
		world.setBlockState(new BlockPos(i + 10, j + 0, k + 7), Block.getBlockById(9).getStateFromMeta(0), 2);
		world.setBlockState(new BlockPos(i + 0, j + 0, k + 8), Block.getBlockById(9).getStateFromMeta(0), 2);
		world.setBlockState(new BlockPos(i + 1, j + 0, k + 8), Block.getBlockById(9).getStateFromMeta(0), 2);
		world.setBlockState(new BlockPos(i + 2, j + 0, k + 8), Block.getBlockById(9).getStateFromMeta(0), 2);
		world.setBlockState(new BlockPos(i + 3, j + 0, k + 8), Block.getBlockById(168).getStateFromMeta(0), 2);
		world.setBlockState(new BlockPos(i + 4, j + 0, k + 8), Block.getBlockById(168).getStateFromMeta(0), 2);
		world.setBlockState(new BlockPos(i + 5, j + 0, k + 8), Block.getBlockById(168).getStateFromMeta(0), 2);
		world.setBlockState(new BlockPos(i + 6, j + 0, k + 8), Block.getBlockById(168).getStateFromMeta(0), 2);
		world.setBlockState(new BlockPos(i + 7, j + 0, k + 8), Block.getBlockById(168).getStateFromMeta(0), 2);
		world.setBlockState(new BlockPos(i + 8, j + 0, k + 8), Block.getBlockById(9).getStateFromMeta(0), 2);
		world.setBlockState(new BlockPos(i + 9, j + 0, k + 8), Block.getBlockById(9).getStateFromMeta(0), 2);
		world.setBlockState(new BlockPos(i + 10, j + 0, k + 8), Block.getBlockById(9).getStateFromMeta(0), 2);
		world.setBlockState(new BlockPos(i + 0, j + 0, k + 9), Block.getBlockById(9).getStateFromMeta(0), 2);
		world.setBlockState(new BlockPos(i + 1, j + 0, k + 9), Block.getBlockById(9).getStateFromMeta(0), 2);
		world.setBlockState(new BlockPos(i + 2, j + 0, k + 9), Block.getBlockById(155).getStateFromMeta(0), 2);
		world.setBlockState(new BlockPos(i + 3, j + 0, k + 9), Block.getBlockById(155).getStateFromMeta(0), 2);
		world.setBlockState(new BlockPos(i + 4, j + 0, k + 9), Block.getBlockById(155).getStateFromMeta(0), 2);
		world.setBlockState(new BlockPos(i + 5, j + 0, k + 9), Block.getBlockById(22).getStateFromMeta(0), 2);
		world.setBlockState(new BlockPos(i + 6, j + 0, k + 9), Block.getBlockById(155).getStateFromMeta(0), 2);
		world.setBlockState(new BlockPos(i + 7, j + 0, k + 9), Block.getBlockById(155).getStateFromMeta(0), 2);
		world.setBlockState(new BlockPos(i + 8, j + 0, k + 9), Block.getBlockById(155).getStateFromMeta(0), 2);
		world.setBlockState(new BlockPos(i + 9, j + 0, k + 9), Block.getBlockById(9).getStateFromMeta(0), 2);
		world.setBlockState(new BlockPos(i + 10, j + 0, k + 9), Block.getBlockById(9).getStateFromMeta(0), 2);
		world.setBlockState(new BlockPos(i + 0, j + 0, k + 10), Block.getBlockById(9).getStateFromMeta(0), 2);
		world.setBlockState(new BlockPos(i + 1, j + 0, k + 10), Block.getBlockById(155).getStateFromMeta(0), 2);
		world.setBlockState(new BlockPos(i + 2, j + 0, k + 10), Block.getBlockById(155).getStateFromMeta(0), 2);
		world.setBlockState(new BlockPos(i + 3, j + 0, k + 10), Block.getBlockById(155).getStateFromMeta(0), 2);
		world.setBlockState(new BlockPos(i + 4, j + 0, k + 10), Block.getBlockById(155).getStateFromMeta(0), 2);
		world.setBlockState(new BlockPos(i + 5, j + 0, k + 10), Block.getBlockById(22).getStateFromMeta(0), 2);
		world.setBlockState(new BlockPos(i + 6, j + 0, k + 10), Block.getBlockById(155).getStateFromMeta(0), 2);
		world.setBlockState(new BlockPos(i + 7, j + 0, k + 10), Block.getBlockById(155).getStateFromMeta(0), 2);
		world.setBlockState(new BlockPos(i + 8, j + 0, k + 10), Block.getBlockById(155).getStateFromMeta(0), 2);
		world.setBlockState(new BlockPos(i + 9, j + 0, k + 10), Block.getBlockById(155).getStateFromMeta(0), 2);
		world.setBlockState(new BlockPos(i + 10, j + 0, k + 10), Block.getBlockById(9).getStateFromMeta(0), 2);
		world.setBlockState(new BlockPos(i + 0, j + 0, k + 11), Block.getBlockById(155).getStateFromMeta(0), 2);
		world.setBlockState(new BlockPos(i + 1, j + 0, k + 11), Block.getBlockById(155).getStateFromMeta(0), 2);
		world.setBlockState(new BlockPos(i + 2, j + 0, k + 11), Block.getBlockById(155).getStateFromMeta(0), 2);
		world.setBlockState(new BlockPos(i + 3, j + 0, k + 11), Block.getBlockById(155).getStateFromMeta(0), 2);
		world.setBlockState(new BlockPos(i + 4, j + 0, k + 11), Block.getBlockById(155).getStateFromMeta(0), 2);
		world.setBlockState(new BlockPos(i + 5, j + 0, k + 11), Block.getBlockById(22).getStateFromMeta(0), 2);
		world.setBlockState(new BlockPos(i + 6, j + 0, k + 11), Block.getBlockById(155).getStateFromMeta(0), 2);
		world.setBlockState(new BlockPos(i + 7, j + 0, k + 11), Block.getBlockById(155).getStateFromMeta(0), 2);
		world.setBlockState(new BlockPos(i + 8, j + 0, k + 11), Block.getBlockById(155).getStateFromMeta(0), 2);
		world.setBlockState(new BlockPos(i + 9, j + 0, k + 11), Block.getBlockById(155).getStateFromMeta(0), 2);
		world.setBlockState(new BlockPos(i + 10, j + 0, k + 11), Block.getBlockById(155).getStateFromMeta(0), 2);
		world.setBlockState(new BlockPos(i + 0, j + 0, k + 12), Block.getBlockById(155).getStateFromMeta(0), 2);
		world.setBlockState(new BlockPos(i + 1, j + 0, k + 12), Block.getBlockById(155).getStateFromMeta(0), 2);
		world.setBlockState(new BlockPos(i + 2, j + 0, k + 12), Block.getBlockById(155).getStateFromMeta(0), 2);
		world.setBlockState(new BlockPos(i + 3, j + 0, k + 12), Block.getBlockById(155).getStateFromMeta(0), 2);
		world.setBlockState(new BlockPos(i + 4, j + 0, k + 12), Block.getBlockById(155).getStateFromMeta(0), 2);
		world.setBlockState(new BlockPos(i + 5, j + 0, k + 12), Block.getBlockById(22).getStateFromMeta(0), 2);
		world.setBlockState(new BlockPos(i + 6, j + 0, k + 12), Block.getBlockById(155).getStateFromMeta(0), 2);
		world.setBlockState(new BlockPos(i + 7, j + 0, k + 12), Block.getBlockById(155).getStateFromMeta(0), 2);
		world.setBlockState(new BlockPos(i + 8, j + 0, k + 12), Block.getBlockById(155).getStateFromMeta(0), 2);
		world.setBlockState(new BlockPos(i + 9, j + 0, k + 12), Block.getBlockById(155).getStateFromMeta(0), 2);
		world.setBlockState(new BlockPos(i + 10, j + 0, k + 12), Block.getBlockById(155).getStateFromMeta(0), 2);
		world.setBlockState(new BlockPos(i + 0, j + 0, k + 13), Block.getBlockById(155).getStateFromMeta(0), 2);
		world.setBlockState(new BlockPos(i + 1, j + 0, k + 13), Block.getBlockById(22).getStateFromMeta(0), 2);
		world.setBlockState(new BlockPos(i + 2, j + 0, k + 13), Block.getBlockById(22).getStateFromMeta(0), 2);
		world.setBlockState(new BlockPos(i + 3, j + 0, k + 13), Block.getBlockById(22).getStateFromMeta(0), 2);
		world.setBlockState(new BlockPos(i + 4, j + 0, k + 13), Block.getBlockById(22).getStateFromMeta(0), 2);
		world.setBlockState(new BlockPos(i + 5, j + 0, k + 13), Block.getBlockById(22).getStateFromMeta(0), 2);
		world.setBlockState(new BlockPos(i + 6, j + 0, k + 13), Block.getBlockById(22).getStateFromMeta(0), 2);
		world.setBlockState(new BlockPos(i + 7, j + 0, k + 13), Block.getBlockById(22).getStateFromMeta(0), 2);
		world.setBlockState(new BlockPos(i + 8, j + 0, k + 13), Block.getBlockById(22).getStateFromMeta(0), 2);
		world.setBlockState(new BlockPos(i + 9, j + 0, k + 13), Block.getBlockById(22).getStateFromMeta(0), 2);
		world.setBlockState(new BlockPos(i + 10, j + 0, k + 13), Block.getBlockById(155).getStateFromMeta(0), 2);
		world.setBlockState(new BlockPos(i + 0, j + 0, k + 14), Block.getBlockById(155).getStateFromMeta(0), 2);
		world.setBlockState(new BlockPos(i + 1, j + 0, k + 14), Block.getBlockById(155).getStateFromMeta(0), 2);
		world.setBlockState(new BlockPos(i + 2, j + 0, k + 14), Block.getBlockById(155).getStateFromMeta(0), 2);
		world.setBlockState(new BlockPos(i + 3, j + 0, k + 14), Block.getBlockById(155).getStateFromMeta(0), 2);
		world.setBlockState(new BlockPos(i + 4, j + 0, k + 14), Block.getBlockById(155).getStateFromMeta(0), 2);
		world.setBlockState(new BlockPos(i + 5, j + 0, k + 14), Block.getBlockById(22).getStateFromMeta(0), 2);
		world.setBlockState(new BlockPos(i + 6, j + 0, k + 14), Block.getBlockById(155).getStateFromMeta(0), 2);
		world.setBlockState(new BlockPos(i + 7, j + 0, k + 14), Block.getBlockById(155).getStateFromMeta(0), 2);
		world.setBlockState(new BlockPos(i + 8, j + 0, k + 14), Block.getBlockById(155).getStateFromMeta(0), 2);
		world.setBlockState(new BlockPos(i + 9, j + 0, k + 14), Block.getBlockById(155).getStateFromMeta(0), 2);
		world.setBlockState(new BlockPos(i + 10, j + 0, k + 14), Block.getBlockById(155).getStateFromMeta(0), 2);
		world.setBlockState(new BlockPos(i + 0, j + 0, k + 15), Block.getBlockById(155).getStateFromMeta(0), 2);
		world.setBlockState(new BlockPos(i + 1, j + 0, k + 15), Block.getBlockById(155).getStateFromMeta(0), 2);
		world.setBlockState(new BlockPos(i + 2, j + 0, k + 15), Block.getBlockById(155).getStateFromMeta(0), 2);
		world.setBlockState(new BlockPos(i + 3, j + 0, k + 15), Block.getBlockById(155).getStateFromMeta(0), 2);
		world.setBlockState(new BlockPos(i + 4, j + 0, k + 15), Block.getBlockById(155).getStateFromMeta(0), 2);
		world.setBlockState(new BlockPos(i + 5, j + 0, k + 15), Block.getBlockById(22).getStateFromMeta(0), 2);
		world.setBlockState(new BlockPos(i + 6, j + 0, k + 15), Block.getBlockById(155).getStateFromMeta(0), 2);
		world.setBlockState(new BlockPos(i + 7, j + 0, k + 15), Block.getBlockById(155).getStateFromMeta(0), 2);
		world.setBlockState(new BlockPos(i + 8, j + 0, k + 15), Block.getBlockById(155).getStateFromMeta(0), 2);
		world.setBlockState(new BlockPos(i + 9, j + 0, k + 15), Block.getBlockById(155).getStateFromMeta(0), 2);
		world.setBlockState(new BlockPos(i + 10, j + 0, k + 15), Block.getBlockById(155).getStateFromMeta(0), 2);
		world.setBlockState(new BlockPos(i + 0, j + 0, k + 16), Block.getBlockById(9).getStateFromMeta(0), 2);
		world.setBlockState(new BlockPos(i + 1, j + 0, k + 16), Block.getBlockById(155).getStateFromMeta(0), 2);
		world.setBlockState(new BlockPos(i + 2, j + 0, k + 16), Block.getBlockById(155).getStateFromMeta(0), 2);
		world.setBlockState(new BlockPos(i + 3, j + 0, k + 16), Block.getBlockById(155).getStateFromMeta(0), 2);
		world.setBlockState(new BlockPos(i + 4, j + 0, k + 16), Block.getBlockById(155).getStateFromMeta(0), 2);
		world.setBlockState(new BlockPos(i + 5, j + 0, k + 16), Block.getBlockById(22).getStateFromMeta(0), 2);
		world.setBlockState(new BlockPos(i + 6, j + 0, k + 16), Block.getBlockById(155).getStateFromMeta(0), 2);
		world.setBlockState(new BlockPos(i + 7, j + 0, k + 16), Block.getBlockById(155).getStateFromMeta(0), 2);
		world.setBlockState(new BlockPos(i + 8, j + 0, k + 16), Block.getBlockById(155).getStateFromMeta(0), 2);
		world.setBlockState(new BlockPos(i + 9, j + 0, k + 16), Block.getBlockById(155).getStateFromMeta(0), 2);
		world.setBlockState(new BlockPos(i + 10, j + 0, k + 16), Block.getBlockById(9).getStateFromMeta(0), 2);
		world.setBlockState(new BlockPos(i + 0, j + 0, k + 17), Block.getBlockById(9).getStateFromMeta(0), 2);
		world.setBlockState(new BlockPos(i + 1, j + 0, k + 17), Block.getBlockById(9).getStateFromMeta(0), 2);
		world.setBlockState(new BlockPos(i + 2, j + 0, k + 17), Block.getBlockById(155).getStateFromMeta(0), 2);
		world.setBlockState(new BlockPos(i + 3, j + 0, k + 17), Block.getBlockById(155).getStateFromMeta(0), 2);
		world.setBlockState(new BlockPos(i + 4, j + 0, k + 17), Block.getBlockById(155).getStateFromMeta(0), 2);
		world.setBlockState(new BlockPos(i + 5, j + 0, k + 17), Block.getBlockById(22).getStateFromMeta(0), 2);
		world.setBlockState(new BlockPos(i + 6, j + 0, k + 17), Block.getBlockById(155).getStateFromMeta(0), 2);
		world.setBlockState(new BlockPos(i + 7, j + 0, k + 17), Block.getBlockById(155).getStateFromMeta(0), 2);
		world.setBlockState(new BlockPos(i + 8, j + 0, k + 17), Block.getBlockById(155).getStateFromMeta(0), 2);
		world.setBlockState(new BlockPos(i + 9, j + 0, k + 17), Block.getBlockById(9).getStateFromMeta(0), 2);
		world.setBlockState(new BlockPos(i + 10, j + 0, k + 17), Block.getBlockById(9).getStateFromMeta(0), 2);
		world.setBlockState(new BlockPos(i + 0, j + 0, k + 18), Block.getBlockById(9).getStateFromMeta(0), 2);
		world.setBlockState(new BlockPos(i + 1, j + 0, k + 18), Block.getBlockById(9).getStateFromMeta(0), 2);
		world.setBlockState(new BlockPos(i + 2, j + 0, k + 18), Block.getBlockById(9).getStateFromMeta(0), 2);
		world.setBlockState(new BlockPos(i + 3, j + 0, k + 18), Block.getBlockById(155).getStateFromMeta(0), 2);
		world.setBlockState(new BlockPos(i + 4, j + 0, k + 18), Block.getBlockById(155).getStateFromMeta(0), 2);
		world.setBlockState(new BlockPos(i + 5, j + 0, k + 18), Block.getBlockById(155).getStateFromMeta(0), 2);
		world.setBlockState(new BlockPos(i + 6, j + 0, k + 18), Block.getBlockById(155).getStateFromMeta(0), 2);
		world.setBlockState(new BlockPos(i + 7, j + 0, k + 18), Block.getBlockById(155).getStateFromMeta(0), 2);
		world.setBlockState(new BlockPos(i + 8, j + 0, k + 18), Block.getBlockById(9).getStateFromMeta(0), 2);
		world.setBlockState(new BlockPos(i + 9, j + 0, k + 18), Block.getBlockById(9).getStateFromMeta(0), 2);
		world.setBlockState(new BlockPos(i + 10, j + 0, k + 18), Block.getBlockById(9).getStateFromMeta(0), 2);
		world.setBlockState(new BlockPos(i + 0, j + 1, k + 0), Block.getBlockById(9).getStateFromMeta(0), 2);
		world.setBlockState(new BlockPos(i + 1, j + 1, k + 0), Block.getBlockById(9).getStateFromMeta(0), 2);
		world.setBlockState(new BlockPos(i + 2, j + 1, k + 0), Block.getBlockById(9).getStateFromMeta(0), 2);
		world.setBlockState(new BlockPos(i + 3, j + 1, k + 0), Block.getBlockById(168).getStateFromMeta(0), 2);
		world.setBlockState(new BlockPos(i + 4, j + 1, k + 0), Block.getBlockById(167).getStateFromMeta(3), 2);
		world.setBlockState(new BlockPos(i + 5, j + 1, k + 0), Block.getBlockById(71).getStateFromMeta(2), 2);
		world.setBlockState(new BlockPos(i + 6, j + 1, k + 0), Block.getBlockById(167).getStateFromMeta(2), 2);
		world.setBlockState(new BlockPos(i + 7, j + 1, k + 0), Block.getBlockById(168).getStateFromMeta(0), 2);
		world.setBlockState(new BlockPos(i + 8, j + 1, k + 0), Block.getBlockById(9).getStateFromMeta(0), 2);
		world.setBlockState(new BlockPos(i + 9, j + 1, k + 0), Block.getBlockById(9).getStateFromMeta(0), 2);
		world.setBlockState(new BlockPos(i + 10, j + 1, k + 0), Block.getBlockById(9).getStateFromMeta(0), 2);
		world.setBlockState(new BlockPos(i + 0, j + 1, k + 1), Block.getBlockById(9).getStateFromMeta(0), 2);
		world.setBlockState(new BlockPos(i + 1, j + 1, k + 1), Block.getBlockById(9).getStateFromMeta(0), 2);
		world.setBlockState(new BlockPos(i + 2, j + 1, k + 1), Block.getBlockById(9).getStateFromMeta(0), 2);
		world.setBlockState(new BlockPos(i + 3, j + 1, k + 1), Block.getBlockById(95).getStateFromMeta(3), 2);
		world.setBlockState(new BlockPos(i + 4, j + 1, k + 1), Block.getBlockById(0).getStateFromMeta(0), 2);
		world.setBlockState(new BlockPos(i + 5, j + 1, k + 1), Block.getBlockById(0).getStateFromMeta(0), 2);
		world.setBlockState(new BlockPos(i + 6, j + 1, k + 1), Block.getBlockById(0).getStateFromMeta(0), 2);
		world.setBlockState(new BlockPos(i + 7, j + 1, k + 1), Block.getBlockById(95).getStateFromMeta(3), 2);
		world.setBlockState(new BlockPos(i + 8, j + 1, k + 1), Block.getBlockById(9).getStateFromMeta(0), 2);
		world.setBlockState(new BlockPos(i + 9, j + 1, k + 1), Block.getBlockById(9).getStateFromMeta(0), 2);
		world.setBlockState(new BlockPos(i + 10, j + 1, k + 1), Block.getBlockById(9).getStateFromMeta(0), 2);
		world.setBlockState(new BlockPos(i + 0, j + 1, k + 2), Block.getBlockById(9).getStateFromMeta(0), 2);
		world.setBlockState(new BlockPos(i + 1, j + 1, k + 2), Block.getBlockById(9).getStateFromMeta(0), 2);
		world.setBlockState(new BlockPos(i + 2, j + 1, k + 2), Block.getBlockById(9).getStateFromMeta(0), 2);
		world.setBlockState(new BlockPos(i + 3, j + 1, k + 2), Block.getBlockById(95).getStateFromMeta(3), 2);
		world.setBlockState(new BlockPos(i + 4, j + 1, k + 2), Block.getBlockById(0).getStateFromMeta(0), 2);
		world.setBlockState(new BlockPos(i + 5, j + 1, k + 2), Block.getBlockById(0).getStateFromMeta(0), 2);
		world.setBlockState(new BlockPos(i + 6, j + 1, k + 2), Block.getBlockById(0).getStateFromMeta(0), 2);
		world.setBlockState(new BlockPos(i + 7, j + 1, k + 2), Block.getBlockById(95).getStateFromMeta(3), 2);
		world.setBlockState(new BlockPos(i + 8, j + 1, k + 2), Block.getBlockById(9).getStateFromMeta(0), 2);
		world.setBlockState(new BlockPos(i + 9, j + 1, k + 2), Block.getBlockById(9).getStateFromMeta(0), 2);
		world.setBlockState(new BlockPos(i + 10, j + 1, k + 2), Block.getBlockById(9).getStateFromMeta(0), 2);
		world.setBlockState(new BlockPos(i + 0, j + 1, k + 3), Block.getBlockById(9).getStateFromMeta(0), 2);
		world.setBlockState(new BlockPos(i + 1, j + 1, k + 3), Block.getBlockById(9).getStateFromMeta(0), 2);
		world.setBlockState(new BlockPos(i + 2, j + 1, k + 3), Block.getBlockById(9).getStateFromMeta(0), 2);
		world.setBlockState(new BlockPos(i + 3, j + 1, k + 3), Block.getBlockById(95).getStateFromMeta(3), 2);
		world.setBlockState(new BlockPos(i + 4, j + 1, k + 3), Block.getBlockById(0).getStateFromMeta(0), 2);
		world.setBlockState(new BlockPos(i + 5, j + 1, k + 3), Block.getBlockById(0).getStateFromMeta(0), 2);
		world.setBlockState(new BlockPos(i + 6, j + 1, k + 3), Block.getBlockById(0).getStateFromMeta(0), 2);
		world.setBlockState(new BlockPos(i + 7, j + 1, k + 3), Block.getBlockById(95).getStateFromMeta(3), 2);
		world.setBlockState(new BlockPos(i + 8, j + 1, k + 3), Block.getBlockById(9).getStateFromMeta(0), 2);
		world.setBlockState(new BlockPos(i + 9, j + 1, k + 3), Block.getBlockById(9).getStateFromMeta(0), 2);
		world.setBlockState(new BlockPos(i + 10, j + 1, k + 3), Block.getBlockById(9).getStateFromMeta(0), 2);
		world.setBlockState(new BlockPos(i + 0, j + 1, k + 4), Block.getBlockById(9).getStateFromMeta(0), 2);
		world.setBlockState(new BlockPos(i + 1, j + 1, k + 4), Block.getBlockById(9).getStateFromMeta(0), 2);
		world.setBlockState(new BlockPos(i + 2, j + 1, k + 4), Block.getBlockById(9).getStateFromMeta(0), 2);
		world.setBlockState(new BlockPos(i + 3, j + 1, k + 4), Block.getBlockById(95).getStateFromMeta(3), 2);
		world.setBlockState(new BlockPos(i + 4, j + 1, k + 4), Block.getBlockById(0).getStateFromMeta(0), 2);
		world.setBlockState(new BlockPos(i + 5, j + 1, k + 4), Block.getBlockById(0).getStateFromMeta(0), 2);
		world.setBlockState(new BlockPos(i + 6, j + 1, k + 4), Block.getBlockById(0).getStateFromMeta(0), 2);
		world.setBlockState(new BlockPos(i + 7, j + 1, k + 4), Block.getBlockById(95).getStateFromMeta(3), 2);
		world.setBlockState(new BlockPos(i + 8, j + 1, k + 4), Block.getBlockById(9).getStateFromMeta(0), 2);
		world.setBlockState(new BlockPos(i + 9, j + 1, k + 4), Block.getBlockById(9).getStateFromMeta(0), 2);
		world.setBlockState(new BlockPos(i + 10, j + 1, k + 4), Block.getBlockById(9).getStateFromMeta(0), 2);
		world.setBlockState(new BlockPos(i + 0, j + 1, k + 5), Block.getBlockById(9).getStateFromMeta(0), 2);
		world.setBlockState(new BlockPos(i + 1, j + 1, k + 5), Block.getBlockById(9).getStateFromMeta(0), 2);
		world.setBlockState(new BlockPos(i + 2, j + 1, k + 5), Block.getBlockById(9).getStateFromMeta(0), 2);
		world.setBlockState(new BlockPos(i + 3, j + 1, k + 5), Block.getBlockById(95).getStateFromMeta(3), 2);
		world.setBlockState(new BlockPos(i + 4, j + 1, k + 5), Block.getBlockById(0).getStateFromMeta(0), 2);
		world.setBlockState(new BlockPos(i + 5, j + 1, k + 5), Block.getBlockById(0).getStateFromMeta(0), 2);
		world.setBlockState(new BlockPos(i + 6, j + 1, k + 5), Block.getBlockById(0).getStateFromMeta(0), 2);
		world.setBlockState(new BlockPos(i + 7, j + 1, k + 5), Block.getBlockById(95).getStateFromMeta(3), 2);
		world.setBlockState(new BlockPos(i + 8, j + 1, k + 5), Block.getBlockById(9).getStateFromMeta(0), 2);
		world.setBlockState(new BlockPos(i + 9, j + 1, k + 5), Block.getBlockById(9).getStateFromMeta(0), 2);
		world.setBlockState(new BlockPos(i + 10, j + 1, k + 5), Block.getBlockById(9).getStateFromMeta(0), 2);
		world.setBlockState(new BlockPos(i + 0, j + 1, k + 6), Block.getBlockById(9).getStateFromMeta(0), 2);
		world.setBlockState(new BlockPos(i + 1, j + 1, k + 6), Block.getBlockById(9).getStateFromMeta(0), 2);
		world.setBlockState(new BlockPos(i + 2, j + 1, k + 6), Block.getBlockById(9).getStateFromMeta(0), 2);
		world.setBlockState(new BlockPos(i + 3, j + 1, k + 6), Block.getBlockById(95).getStateFromMeta(3), 2);
		world.setBlockState(new BlockPos(i + 4, j + 1, k + 6), Block.getBlockById(0).getStateFromMeta(0), 2);
		world.setBlockState(new BlockPos(i + 5, j + 1, k + 6), Block.getBlockById(0).getStateFromMeta(0), 2);
		world.setBlockState(new BlockPos(i + 6, j + 1, k + 6), Block.getBlockById(0).getStateFromMeta(0), 2);
		world.setBlockState(new BlockPos(i + 7, j + 1, k + 6), Block.getBlockById(95).getStateFromMeta(3), 2);
		world.setBlockState(new BlockPos(i + 8, j + 1, k + 6), Block.getBlockById(9).getStateFromMeta(0), 2);
		world.setBlockState(new BlockPos(i + 9, j + 1, k + 6), Block.getBlockById(9).getStateFromMeta(0), 2);
		world.setBlockState(new BlockPos(i + 10, j + 1, k + 6), Block.getBlockById(9).getStateFromMeta(0), 2);
		world.setBlockState(new BlockPos(i + 0, j + 1, k + 7), Block.getBlockById(9).getStateFromMeta(0), 2);
		world.setBlockState(new BlockPos(i + 1, j + 1, k + 7), Block.getBlockById(9).getStateFromMeta(0), 2);
		world.setBlockState(new BlockPos(i + 2, j + 1, k + 7), Block.getBlockById(9).getStateFromMeta(0), 2);
		world.setBlockState(new BlockPos(i + 3, j + 1, k + 7), Block.getBlockById(95).getStateFromMeta(3), 2);
		world.setBlockState(new BlockPos(i + 4, j + 1, k + 7), Block.getBlockById(0).getStateFromMeta(0), 2);
		world.setBlockState(new BlockPos(i + 5, j + 1, k + 7), Block.getBlockById(0).getStateFromMeta(0), 2);
		world.setBlockState(new BlockPos(i + 6, j + 1, k + 7), Block.getBlockById(0).getStateFromMeta(0), 2);
		world.setBlockState(new BlockPos(i + 7, j + 1, k + 7), Block.getBlockById(95).getStateFromMeta(3), 2);
		world.setBlockState(new BlockPos(i + 8, j + 1, k + 7), Block.getBlockById(9).getStateFromMeta(0), 2);
		world.setBlockState(new BlockPos(i + 9, j + 1, k + 7), Block.getBlockById(9).getStateFromMeta(0), 2);
		world.setBlockState(new BlockPos(i + 10, j + 1, k + 7), Block.getBlockById(9).getStateFromMeta(0), 2);
		world.setBlockState(new BlockPos(i + 0, j + 1, k + 8), Block.getBlockById(9).getStateFromMeta(0), 2);
		world.setBlockState(new BlockPos(i + 1, j + 1, k + 8), Block.getBlockById(9).getStateFromMeta(0), 2);
		world.setBlockState(new BlockPos(i + 2, j + 1, k + 8), Block.getBlockById(9).getStateFromMeta(0), 2);
		world.setBlockState(new BlockPos(i + 3, j + 1, k + 8), Block.getBlockById(168).getStateFromMeta(0), 2);
		world.setBlockState(new BlockPos(i + 4, j + 1, k + 8), Block.getBlockById(0).getStateFromMeta(0), 2);
		world.setBlockState(new BlockPos(i + 5, j + 1, k + 8), Block.getBlockById(0).getStateFromMeta(0), 2);
		world.setBlockState(new BlockPos(i + 6, j + 1, k + 8), Block.getBlockById(0).getStateFromMeta(0), 2);
		world.setBlockState(new BlockPos(i + 7, j + 1, k + 8), Block.getBlockById(168).getStateFromMeta(0), 2);
		world.setBlockState(new BlockPos(i + 8, j + 1, k + 8), Block.getBlockById(9).getStateFromMeta(0), 2);
		world.setBlockState(new BlockPos(i + 9, j + 1, k + 8), Block.getBlockById(9).getStateFromMeta(0), 2);
		world.setBlockState(new BlockPos(i + 10, j + 1, k + 8), Block.getBlockById(9).getStateFromMeta(0), 2);
		world.setBlockState(new BlockPos(i + 0, j + 1, k + 9), Block.getBlockById(9).getStateFromMeta(0), 2);
		world.setBlockState(new BlockPos(i + 1, j + 1, k + 9), Block.getBlockById(9).getStateFromMeta(0), 2);
		world.setBlockState(new BlockPos(i + 2, j + 1, k + 9), Block.getBlockById(95).getStateFromMeta(3), 2);
		world.setBlockState(new BlockPos(i + 3, j + 1, k + 9), Block.getBlockById(0).getStateFromMeta(0), 2);
		world.setBlockState(new BlockPos(i + 4, j + 1, k + 9), Block.getBlockById(0).getStateFromMeta(0), 2);
		world.setBlockState(new BlockPos(i + 5, j + 1, k + 9), Block.getBlockById(0).getStateFromMeta(0), 2);
		world.setBlockState(new BlockPos(i + 6, j + 1, k + 9), Block.getBlockById(0).getStateFromMeta(0), 2);
		world.setBlockState(new BlockPos(i + 7, j + 1, k + 9), Block.getBlockById(0).getStateFromMeta(0), 2);
		world.setBlockState(new BlockPos(i + 8, j + 1, k + 9), Block.getBlockById(95).getStateFromMeta(3), 2);
		world.setBlockState(new BlockPos(i + 9, j + 1, k + 9), Block.getBlockById(9).getStateFromMeta(0), 2);
		world.setBlockState(new BlockPos(i + 10, j + 1, k + 9), Block.getBlockById(9).getStateFromMeta(0), 2);
		world.setBlockState(new BlockPos(i + 0, j + 1, k + 10), Block.getBlockById(9).getStateFromMeta(0), 2);
		world.setBlockState(new BlockPos(i + 1, j + 1, k + 10), Block.getBlockById(95).getStateFromMeta(3), 2);
		world.setBlockState(new BlockPos(i + 2, j + 1, k + 10), Block.getBlockById(0).getStateFromMeta(0), 2);
		world.setBlockState(new BlockPos(i + 3, j + 1, k + 10), Block.getBlockById(0).getStateFromMeta(0), 2);
		world.setBlockState(new BlockPos(i + 4, j + 1, k + 10), Block.getBlockById(0).getStateFromMeta(0), 2);
		world.setBlockState(new BlockPos(i + 5, j + 1, k + 10), Block.getBlockById(0).getStateFromMeta(0), 2);
		world.setBlockState(new BlockPos(i + 6, j + 1, k + 10), Block.getBlockById(0).getStateFromMeta(0), 2);
		world.setBlockState(new BlockPos(i + 7, j + 1, k + 10), Block.getBlockById(0).getStateFromMeta(0), 2);
		world.setBlockState(new BlockPos(i + 8, j + 1, k + 10), Block.getBlockById(0).getStateFromMeta(0), 2);
		world.setBlockState(new BlockPos(i + 9, j + 1, k + 10), Block.getBlockById(95).getStateFromMeta(3), 2);
		world.setBlockState(new BlockPos(i + 10, j + 1, k + 10), Block.getBlockById(9).getStateFromMeta(0), 2);
		world.setBlockState(new BlockPos(i + 0, j + 1, k + 11), Block.getBlockById(95).getStateFromMeta(3), 2);
		world.setBlockState(new BlockPos(i + 1, j + 1, k + 11), Block.getBlockById(47).getStateFromMeta(0), 2);
		world.setBlockState(new BlockPos(i + 2, j + 1, k + 11), Block.getBlockById(0).getStateFromMeta(0), 2);
		world.setBlockState(new BlockPos(i + 3, j + 1, k + 11), Block.getBlockById(0).getStateFromMeta(0), 2);
		world.setBlockState(new BlockPos(i + 4, j + 1, k + 11), Block.getBlockById(0).getStateFromMeta(0), 2);
		world.setBlockState(new BlockPos(i + 5, j + 1, k + 11), Block.getBlockById(156).getStateFromMeta(3), 2);
		world.setBlockState(new BlockPos(i + 6, j + 1, k + 11), Block.getBlockById(0).getStateFromMeta(0), 2);
		world.setBlockState(new BlockPos(i + 7, j + 1, k + 11), Block.getBlockById(0).getStateFromMeta(0), 2);
		world.setBlockState(new BlockPos(i + 8, j + 1, k + 11), Block.getBlockById(0).getStateFromMeta(0), 2);
		world.setBlockState(new BlockPos(i + 9, j + 1, k + 11), Block.getBlockById(47).getStateFromMeta(0), 2);
		world.setBlockState(new BlockPos(i + 10, j + 1, k + 11), Block.getBlockById(95).getStateFromMeta(3), 2);
		world.setBlockState(new BlockPos(i + 0, j + 1, k + 12), Block.getBlockById(95).getStateFromMeta(3), 2);
		world.setBlockState(new BlockPos(i + 1, j + 1, k + 12), Block.getBlockById(47).getStateFromMeta(0), 2);
		world.setBlockState(new BlockPos(i + 2, j + 1, k + 12), Block.getBlockById(0).getStateFromMeta(0), 2);
		world.setBlockState(new BlockPos(i + 3, j + 1, k + 12), Block.getBlockById(0).getStateFromMeta(0), 2);
		world.setBlockState(new BlockPos(i + 4, j + 1, k + 12), Block.getBlockById(0).getStateFromMeta(0), 2);
		world.setBlockState(new BlockPos(i + 5, j + 1, k + 12), Block.getBlockById(113).getStateFromMeta(0), 2);
		world.setBlockState(new BlockPos(i + 6, j + 1, k + 12), Block.getBlockById(0).getStateFromMeta(0), 2);
		world.setBlockState(new BlockPos(i + 7, j + 1, k + 12), Block.getBlockById(0).getStateFromMeta(0), 2);
		world.setBlockState(new BlockPos(i + 8, j + 1, k + 12), Block.getBlockById(0).getStateFromMeta(0), 2);
		world.setBlockState(new BlockPos(i + 9, j + 1, k + 12), Block.getBlockById(47).getStateFromMeta(0), 2);
		world.setBlockState(new BlockPos(i + 10, j + 1, k + 12), Block.getBlockById(95).getStateFromMeta(3), 2);
		world.setBlockState(new BlockPos(i + 0, j + 1, k + 13), Block.getBlockById(95).getStateFromMeta(3), 2);
		world.setBlockState(new BlockPos(i + 1, j + 1, k + 13), Block.getBlockById(47).getStateFromMeta(0), 2);
		world.setBlockState(new BlockPos(i + 2, j + 1, k + 13), Block.getBlockById(0).getStateFromMeta(0), 2);
		world.setBlockState(new BlockPos(i + 3, j + 1, k + 13), Block.getBlockById(0).getStateFromMeta(0), 2);
		world.setBlockState(new BlockPos(i + 4, j + 1, k + 13), Block.getBlockById(0).getStateFromMeta(0), 2);
		world.setBlockState(new BlockPos(i + 5, j + 1, k + 13), Block.getBlockById(138).getStateFromMeta(0), 2);
		world.setBlockState(new BlockPos(i + 6, j + 1, k + 13), Block.getBlockById(0).getStateFromMeta(0), 2);
		world.setBlockState(new BlockPos(i + 7, j + 1, k + 13), Block.getBlockById(0).getStateFromMeta(0), 2);
		world.setBlockState(new BlockPos(i + 8, j + 1, k + 13), Block.getBlockById(0).getStateFromMeta(0), 2);
		world.setBlockState(new BlockPos(i + 9, j + 1, k + 13), Block.getBlockById(47).getStateFromMeta(0), 2);
		world.setBlockState(new BlockPos(i + 10, j + 1, k + 13), Block.getBlockById(95).getStateFromMeta(3), 2);
		world.setBlockState(new BlockPos(i + 0, j + 1, k + 14), Block.getBlockById(95).getStateFromMeta(3), 2);
		world.setBlockState(new BlockPos(i + 1, j + 1, k + 14), Block.getBlockById(47).getStateFromMeta(0), 2);
		world.setBlockState(new BlockPos(i + 2, j + 1, k + 14), Block.getBlockById(0).getStateFromMeta(0), 2);
		world.setBlockState(new BlockPos(i + 3, j + 1, k + 14), Block.getBlockById(0).getStateFromMeta(0), 2);
		world.setBlockState(new BlockPos(i + 4, j + 1, k + 14), Block.getBlockById(0).getStateFromMeta(0), 2);
		world.setBlockState(new BlockPos(i + 5, j + 1, k + 14), Block.getBlockById(26).getStateFromMeta(10), 2);
		world.setBlockState(new BlockPos(i + 6, j + 1, k + 14), Block.getBlockById(0).getStateFromMeta(0), 2);
		world.setBlockState(new BlockPos(i + 7, j + 1, k + 14), Block.getBlockById(0).getStateFromMeta(0), 2);
		world.setBlockState(new BlockPos(i + 8, j + 1, k + 14), Block.getBlockById(0).getStateFromMeta(0), 2);
		world.setBlockState(new BlockPos(i + 9, j + 1, k + 14), Block.getBlockById(47).getStateFromMeta(0), 2);
		world.setBlockState(new BlockPos(i + 10, j + 1, k + 14), Block.getBlockById(95).getStateFromMeta(3), 2);
		world.setBlockState(new BlockPos(i + 0, j + 1, k + 15), Block.getBlockById(95).getStateFromMeta(3), 2);
		world.setBlockState(new BlockPos(i + 1, j + 1, k + 15), Block.getBlockById(47).getStateFromMeta(0), 2);
		world.setBlockState(new BlockPos(i + 2, j + 1, k + 15), Block.getBlockById(0).getStateFromMeta(0), 2);
		world.setBlockState(new BlockPos(i + 3, j + 1, k + 15), Block.getBlockById(0).getStateFromMeta(0), 2);
		world.setBlockState(new BlockPos(i + 4, j + 1, k + 15), Block.getBlockById(0).getStateFromMeta(0), 2);
		world.setBlockState(new BlockPos(i + 5, j + 1, k + 15), Block.getBlockById(26).getStateFromMeta(2), 2);
		world.setBlockState(new BlockPos(i + 6, j + 1, k + 15), Block.getBlockById(0).getStateFromMeta(0), 2);
		world.setBlockState(new BlockPos(i + 7, j + 1, k + 15), Block.getBlockById(0).getStateFromMeta(0), 2);
		world.setBlockState(new BlockPos(i + 8, j + 1, k + 15), Block.getBlockById(0).getStateFromMeta(0), 2);
		world.setBlockState(new BlockPos(i + 9, j + 1, k + 15), Block.getBlockById(47).getStateFromMeta(0), 2);
		world.setBlockState(new BlockPos(i + 10, j + 1, k + 15), Block.getBlockById(95).getStateFromMeta(3), 2);
		world.setBlockState(new BlockPos(i + 0, j + 1, k + 16), Block.getBlockById(9).getStateFromMeta(0), 2);
		world.setBlockState(new BlockPos(i + 1, j + 1, k + 16), Block.getBlockById(95).getStateFromMeta(3), 2);
		world.setBlockState(new BlockPos(i + 2, j + 1, k + 16), Block.getBlockById(0).getStateFromMeta(0), 2);
		world.setBlockState(new BlockPos(i + 3, j + 1, k + 16), Block.getBlockById(0).getStateFromMeta(0), 2);
		world.setBlockState(new BlockPos(i + 4, j + 1, k + 16), Block.getBlockById(0).getStateFromMeta(0), 2);
		world.setBlockState(new BlockPos(i + 5, j + 1, k + 16), Block.getBlockById(0).getStateFromMeta(0), 2);
		world.setBlockState(new BlockPos(i + 6, j + 1, k + 16), Block.getBlockById(0).getStateFromMeta(0), 2);
		world.setBlockState(new BlockPos(i + 7, j + 1, k + 16), Block.getBlockById(0).getStateFromMeta(0), 2);
		world.setBlockState(new BlockPos(i + 8, j + 1, k + 16), Block.getBlockById(0).getStateFromMeta(0), 2);
		world.setBlockState(new BlockPos(i + 9, j + 1, k + 16), Block.getBlockById(95).getStateFromMeta(3), 2);
		world.setBlockState(new BlockPos(i + 10, j + 1, k + 16), Block.getBlockById(9).getStateFromMeta(0), 2);
		world.setBlockState(new BlockPos(i + 0, j + 1, k + 17), Block.getBlockById(9).getStateFromMeta(0), 2);
		world.setBlockState(new BlockPos(i + 1, j + 1, k + 17), Block.getBlockById(9).getStateFromMeta(0), 2);
		world.setBlockState(new BlockPos(i + 2, j + 1, k + 17), Block.getBlockById(95).getStateFromMeta(3), 2);
		world.setBlockState(new BlockPos(i + 3, j + 1, k + 17), Block.getBlockById(47).getStateFromMeta(0), 2);
		world.setBlockState(new BlockPos(i + 4, j + 1, k + 17), Block.getBlockById(47).getStateFromMeta(0), 2);
		world.setBlockState(new BlockPos(i + 5, j + 1, k + 17), Block.getBlockById(47).getStateFromMeta(0), 2);
		world.setBlockState(new BlockPos(i + 6, j + 1, k + 17), Block.getBlockById(47).getStateFromMeta(0), 2);
		world.setBlockState(new BlockPos(i + 7, j + 1, k + 17), Block.getBlockById(47).getStateFromMeta(0), 2);
		world.setBlockState(new BlockPos(i + 8, j + 1, k + 17), Block.getBlockById(95).getStateFromMeta(3), 2);
		world.setBlockState(new BlockPos(i + 9, j + 1, k + 17), Block.getBlockById(9).getStateFromMeta(0), 2);
		world.setBlockState(new BlockPos(i + 10, j + 1, k + 17), Block.getBlockById(9).getStateFromMeta(0), 2);
		world.setBlockState(new BlockPos(i + 0, j + 1, k + 18), Block.getBlockById(9).getStateFromMeta(0), 2);
		world.setBlockState(new BlockPos(i + 1, j + 1, k + 18), Block.getBlockById(9).getStateFromMeta(0), 2);
		world.setBlockState(new BlockPos(i + 2, j + 1, k + 18), Block.getBlockById(9).getStateFromMeta(0), 2);
		world.setBlockState(new BlockPos(i + 3, j + 1, k + 18), Block.getBlockById(95).getStateFromMeta(3), 2);
		world.setBlockState(new BlockPos(i + 4, j + 1, k + 18), Block.getBlockById(95).getStateFromMeta(3), 2);
		world.setBlockState(new BlockPos(i + 5, j + 1, k + 18), Block.getBlockById(95).getStateFromMeta(3), 2);
		world.setBlockState(new BlockPos(i + 6, j + 1, k + 18), Block.getBlockById(95).getStateFromMeta(3), 2);
		world.setBlockState(new BlockPos(i + 7, j + 1, k + 18), Block.getBlockById(95).getStateFromMeta(3), 2);
		world.setBlockState(new BlockPos(i + 8, j + 1, k + 18), Block.getBlockById(9).getStateFromMeta(0), 2);
		world.setBlockState(new BlockPos(i + 9, j + 1, k + 18), Block.getBlockById(9).getStateFromMeta(0), 2);
		world.setBlockState(new BlockPos(i + 10, j + 1, k + 18), Block.getBlockById(9).getStateFromMeta(0), 2);
		world.setBlockState(new BlockPos(i + 0, j + 2, k + 0), Block.getBlockById(9).getStateFromMeta(0), 2);
		world.setBlockState(new BlockPos(i + 1, j + 2, k + 0), Block.getBlockById(9).getStateFromMeta(0), 2);
		world.setBlockState(new BlockPos(i + 2, j + 2, k + 0), Block.getBlockById(9).getStateFromMeta(0), 2);
		world.setBlockState(new BlockPos(i + 3, j + 2, k + 0), Block.getBlockById(168).getStateFromMeta(0), 2);
		world.setBlockState(new BlockPos(i + 4, j + 2, k + 0), Block.getBlockById(167).getStateFromMeta(3), 2);
		world.setBlockState(new BlockPos(i + 5, j + 2, k + 0), Block.getBlockById(71).getStateFromMeta(8), 2);
		world.setBlockState(new BlockPos(i + 6, j + 2, k + 0), Block.getBlockById(167).getStateFromMeta(2), 2);
		world.setBlockState(new BlockPos(i + 7, j + 2, k + 0), Block.getBlockById(168).getStateFromMeta(0), 2);
		world.setBlockState(new BlockPos(i + 8, j + 2, k + 0), Block.getBlockById(9).getStateFromMeta(0), 2);
		world.setBlockState(new BlockPos(i + 9, j + 2, k + 0), Block.getBlockById(9).getStateFromMeta(0), 2);
		world.setBlockState(new BlockPos(i + 10, j + 2, k + 0), Block.getBlockById(9).getStateFromMeta(0), 2);
		world.setBlockState(new BlockPos(i + 0, j + 2, k + 1), Block.getBlockById(9).getStateFromMeta(0), 2);
		world.setBlockState(new BlockPos(i + 1, j + 2, k + 1), Block.getBlockById(9).getStateFromMeta(0), 2);
		world.setBlockState(new BlockPos(i + 2, j + 2, k + 1), Block.getBlockById(9).getStateFromMeta(0), 2);
		world.setBlockState(new BlockPos(i + 3, j + 2, k + 1), Block.getBlockById(95).getStateFromMeta(3), 2);
		world.setBlockState(new BlockPos(i + 4, j + 2, k + 1), Block.getBlockById(0).getStateFromMeta(0), 2);
		world.setBlockState(new BlockPos(i + 5, j + 2, k + 1), Block.getBlockById(0).getStateFromMeta(0), 2);
		world.setBlockState(new BlockPos(i + 6, j + 2, k + 1), Block.getBlockById(0).getStateFromMeta(0), 2);
		world.setBlockState(new BlockPos(i + 7, j + 2, k + 1), Block.getBlockById(95).getStateFromMeta(3), 2);
		world.setBlockState(new BlockPos(i + 8, j + 2, k + 1), Block.getBlockById(9).getStateFromMeta(0), 2);
		world.setBlockState(new BlockPos(i + 9, j + 2, k + 1), Block.getBlockById(9).getStateFromMeta(0), 2);
		world.setBlockState(new BlockPos(i + 10, j + 2, k + 1), Block.getBlockById(9).getStateFromMeta(0), 2);
		world.setBlockState(new BlockPos(i + 0, j + 2, k + 2), Block.getBlockById(9).getStateFromMeta(0), 2);
		world.setBlockState(new BlockPos(i + 1, j + 2, k + 2), Block.getBlockById(9).getStateFromMeta(0), 2);
		world.setBlockState(new BlockPos(i + 2, j + 2, k + 2), Block.getBlockById(9).getStateFromMeta(0), 2);
		world.setBlockState(new BlockPos(i + 3, j + 2, k + 2), Block.getBlockById(95).getStateFromMeta(3), 2);
		world.setBlockState(new BlockPos(i + 4, j + 2, k + 2), Block.getBlockById(0).getStateFromMeta(0), 2);
		world.setBlockState(new BlockPos(i + 5, j + 2, k + 2), Block.getBlockById(0).getStateFromMeta(0), 2);
		world.setBlockState(new BlockPos(i + 6, j + 2, k + 2), Block.getBlockById(0).getStateFromMeta(0), 2);
		world.setBlockState(new BlockPos(i + 7, j + 2, k + 2), Block.getBlockById(95).getStateFromMeta(3), 2);
		world.setBlockState(new BlockPos(i + 8, j + 2, k + 2), Block.getBlockById(9).getStateFromMeta(0), 2);
		world.setBlockState(new BlockPos(i + 9, j + 2, k + 2), Block.getBlockById(9).getStateFromMeta(0), 2);
		world.setBlockState(new BlockPos(i + 10, j + 2, k + 2), Block.getBlockById(9).getStateFromMeta(0), 2);
		world.setBlockState(new BlockPos(i + 0, j + 2, k + 3), Block.getBlockById(9).getStateFromMeta(0), 2);
		world.setBlockState(new BlockPos(i + 1, j + 2, k + 3), Block.getBlockById(9).getStateFromMeta(0), 2);
		world.setBlockState(new BlockPos(i + 2, j + 2, k + 3), Block.getBlockById(9).getStateFromMeta(0), 2);
		world.setBlockState(new BlockPos(i + 3, j + 2, k + 3), Block.getBlockById(95).getStateFromMeta(3), 2);
		world.setBlockState(new BlockPos(i + 4, j + 2, k + 3), Block.getBlockById(0).getStateFromMeta(0), 2);
		world.setBlockState(new BlockPos(i + 5, j + 2, k + 3), Block.getBlockById(0).getStateFromMeta(0), 2);
		world.setBlockState(new BlockPos(i + 6, j + 2, k + 3), Block.getBlockById(0).getStateFromMeta(0), 2);
		world.setBlockState(new BlockPos(i + 7, j + 2, k + 3), Block.getBlockById(95).getStateFromMeta(3), 2);
		world.setBlockState(new BlockPos(i + 8, j + 2, k + 3), Block.getBlockById(9).getStateFromMeta(0), 2);
		world.setBlockState(new BlockPos(i + 9, j + 2, k + 3), Block.getBlockById(9).getStateFromMeta(0), 2);
		world.setBlockState(new BlockPos(i + 10, j + 2, k + 3), Block.getBlockById(9).getStateFromMeta(0), 2);
		world.setBlockState(new BlockPos(i + 0, j + 2, k + 4), Block.getBlockById(9).getStateFromMeta(0), 2);
		world.setBlockState(new BlockPos(i + 1, j + 2, k + 4), Block.getBlockById(9).getStateFromMeta(0), 2);
		world.setBlockState(new BlockPos(i + 2, j + 2, k + 4), Block.getBlockById(9).getStateFromMeta(0), 2);
		world.setBlockState(new BlockPos(i + 3, j + 2, k + 4), Block.getBlockById(95).getStateFromMeta(3), 2);
		world.setBlockState(new BlockPos(i + 4, j + 2, k + 4), Block.getBlockById(0).getStateFromMeta(0), 2);
		world.setBlockState(new BlockPos(i + 5, j + 2, k + 4), Block.getBlockById(0).getStateFromMeta(0), 2);
		world.setBlockState(new BlockPos(i + 6, j + 2, k + 4), Block.getBlockById(0).getStateFromMeta(0), 2);
		world.setBlockState(new BlockPos(i + 7, j + 2, k + 4), Block.getBlockById(95).getStateFromMeta(3), 2);
		world.setBlockState(new BlockPos(i + 8, j + 2, k + 4), Block.getBlockById(9).getStateFromMeta(0), 2);
		world.setBlockState(new BlockPos(i + 9, j + 2, k + 4), Block.getBlockById(9).getStateFromMeta(0), 2);
		world.setBlockState(new BlockPos(i + 10, j + 2, k + 4), Block.getBlockById(9).getStateFromMeta(0), 2);
		world.setBlockState(new BlockPos(i + 0, j + 2, k + 5), Block.getBlockById(9).getStateFromMeta(0), 2);
		world.setBlockState(new BlockPos(i + 1, j + 2, k + 5), Block.getBlockById(9).getStateFromMeta(0), 2);
		world.setBlockState(new BlockPos(i + 2, j + 2, k + 5), Block.getBlockById(9).getStateFromMeta(0), 2);
		world.setBlockState(new BlockPos(i + 3, j + 2, k + 5), Block.getBlockById(95).getStateFromMeta(3), 2);
		world.setBlockState(new BlockPos(i + 4, j + 2, k + 5), Block.getBlockById(0).getStateFromMeta(0), 2);
		world.setBlockState(new BlockPos(i + 5, j + 2, k + 5), Block.getBlockById(0).getStateFromMeta(0), 2);
		world.setBlockState(new BlockPos(i + 6, j + 2, k + 5), Block.getBlockById(0).getStateFromMeta(0), 2);
		world.setBlockState(new BlockPos(i + 7, j + 2, k + 5), Block.getBlockById(95).getStateFromMeta(3), 2);
		world.setBlockState(new BlockPos(i + 8, j + 2, k + 5), Block.getBlockById(9).getStateFromMeta(0), 2);
		world.setBlockState(new BlockPos(i + 9, j + 2, k + 5), Block.getBlockById(9).getStateFromMeta(0), 2);
		world.setBlockState(new BlockPos(i + 10, j + 2, k + 5), Block.getBlockById(9).getStateFromMeta(0), 2);
		world.setBlockState(new BlockPos(i + 0, j + 2, k + 6), Block.getBlockById(9).getStateFromMeta(0), 2);
		world.setBlockState(new BlockPos(i + 1, j + 2, k + 6), Block.getBlockById(9).getStateFromMeta(0), 2);
		world.setBlockState(new BlockPos(i + 2, j + 2, k + 6), Block.getBlockById(9).getStateFromMeta(0), 2);
		world.setBlockState(new BlockPos(i + 3, j + 2, k + 6), Block.getBlockById(95).getStateFromMeta(3), 2);
		world.setBlockState(new BlockPos(i + 4, j + 2, k + 6), Block.getBlockById(0).getStateFromMeta(0), 2);
		world.setBlockState(new BlockPos(i + 5, j + 2, k + 6), Block.getBlockById(0).getStateFromMeta(0), 2);
		world.setBlockState(new BlockPos(i + 6, j + 2, k + 6), Block.getBlockById(0).getStateFromMeta(0), 2);
		world.setBlockState(new BlockPos(i + 7, j + 2, k + 6), Block.getBlockById(95).getStateFromMeta(3), 2);
		world.setBlockState(new BlockPos(i + 8, j + 2, k + 6), Block.getBlockById(9).getStateFromMeta(0), 2);
		world.setBlockState(new BlockPos(i + 9, j + 2, k + 6), Block.getBlockById(9).getStateFromMeta(0), 2);
		world.setBlockState(new BlockPos(i + 10, j + 2, k + 6), Block.getBlockById(9).getStateFromMeta(0), 2);
		world.setBlockState(new BlockPos(i + 0, j + 2, k + 7), Block.getBlockById(9).getStateFromMeta(0), 2);
		world.setBlockState(new BlockPos(i + 1, j + 2, k + 7), Block.getBlockById(9).getStateFromMeta(0), 2);
		world.setBlockState(new BlockPos(i + 2, j + 2, k + 7), Block.getBlockById(9).getStateFromMeta(0), 2);
		world.setBlockState(new BlockPos(i + 3, j + 2, k + 7), Block.getBlockById(95).getStateFromMeta(3), 2);
		world.setBlockState(new BlockPos(i + 4, j + 2, k + 7), Block.getBlockById(0).getStateFromMeta(0), 2);
		world.setBlockState(new BlockPos(i + 5, j + 2, k + 7), Block.getBlockById(0).getStateFromMeta(0), 2);
		world.setBlockState(new BlockPos(i + 6, j + 2, k + 7), Block.getBlockById(0).getStateFromMeta(0), 2);
		world.setBlockState(new BlockPos(i + 7, j + 2, k + 7), Block.getBlockById(95).getStateFromMeta(3), 2);
		world.setBlockState(new BlockPos(i + 8, j + 2, k + 7), Block.getBlockById(9).getStateFromMeta(0), 2);
		world.setBlockState(new BlockPos(i + 9, j + 2, k + 7), Block.getBlockById(9).getStateFromMeta(0), 2);
		world.setBlockState(new BlockPos(i + 10, j + 2, k + 7), Block.getBlockById(9).getStateFromMeta(0), 2);
		world.setBlockState(new BlockPos(i + 0, j + 2, k + 8), Block.getBlockById(9).getStateFromMeta(0), 2);
		world.setBlockState(new BlockPos(i + 1, j + 2, k + 8), Block.getBlockById(9).getStateFromMeta(0), 2);
		world.setBlockState(new BlockPos(i + 2, j + 2, k + 8), Block.getBlockById(9).getStateFromMeta(0), 2);
		world.setBlockState(new BlockPos(i + 3, j + 2, k + 8), Block.getBlockById(168).getStateFromMeta(0), 2);
		world.setBlockState(new BlockPos(i + 4, j + 2, k + 8), Block.getBlockById(0).getStateFromMeta(0), 2);
		world.setBlockState(new BlockPos(i + 5, j + 2, k + 8), Block.getBlockById(0).getStateFromMeta(0), 2);
		world.setBlockState(new BlockPos(i + 6, j + 2, k + 8), Block.getBlockById(0).getStateFromMeta(0), 2);
		world.setBlockState(new BlockPos(i + 7, j + 2, k + 8), Block.getBlockById(168).getStateFromMeta(0), 2);
		world.setBlockState(new BlockPos(i + 8, j + 2, k + 8), Block.getBlockById(9).getStateFromMeta(0), 2);
		world.setBlockState(new BlockPos(i + 9, j + 2, k + 8), Block.getBlockById(9).getStateFromMeta(0), 2);
		world.setBlockState(new BlockPos(i + 10, j + 2, k + 8), Block.getBlockById(9).getStateFromMeta(0), 2);
		world.setBlockState(new BlockPos(i + 0, j + 2, k + 9), Block.getBlockById(9).getStateFromMeta(0), 2);
		world.setBlockState(new BlockPos(i + 1, j + 2, k + 9), Block.getBlockById(9).getStateFromMeta(0), 2);
		world.setBlockState(new BlockPos(i + 2, j + 2, k + 9), Block.getBlockById(95).getStateFromMeta(3), 2);
		world.setBlockState(new BlockPos(i + 3, j + 2, k + 9), Block.getBlockById(0).getStateFromMeta(0), 2);
		world.setBlockState(new BlockPos(i + 4, j + 2, k + 9), Block.getBlockById(0).getStateFromMeta(0), 2);
		world.setBlockState(new BlockPos(i + 5, j + 2, k + 9), Block.getBlockById(0).getStateFromMeta(0), 2);
		world.setBlockState(new BlockPos(i + 6, j + 2, k + 9), Block.getBlockById(0).getStateFromMeta(0), 2);
		world.setBlockState(new BlockPos(i + 7, j + 2, k + 9), Block.getBlockById(0).getStateFromMeta(0), 2);
		world.setBlockState(new BlockPos(i + 8, j + 2, k + 9), Block.getBlockById(95).getStateFromMeta(3), 2);
		world.setBlockState(new BlockPos(i + 9, j + 2, k + 9), Block.getBlockById(9).getStateFromMeta(0), 2);
		world.setBlockState(new BlockPos(i + 10, j + 2, k + 9), Block.getBlockById(9).getStateFromMeta(0), 2);
		world.setBlockState(new BlockPos(i + 0, j + 2, k + 10), Block.getBlockById(9).getStateFromMeta(0), 2);
		world.setBlockState(new BlockPos(i + 1, j + 2, k + 10), Block.getBlockById(95).getStateFromMeta(3), 2);
		world.setBlockState(new BlockPos(i + 2, j + 2, k + 10), Block.getBlockById(0).getStateFromMeta(0), 2);
		world.setBlockState(new BlockPos(i + 3, j + 2, k + 10), Block.getBlockById(0).getStateFromMeta(0), 2);
		world.setBlockState(new BlockPos(i + 4, j + 2, k + 10), Block.getBlockById(0).getStateFromMeta(0), 2);
		world.setBlockState(new BlockPos(i + 5, j + 2, k + 10), Block.getBlockById(0).getStateFromMeta(0), 2);
		world.setBlockState(new BlockPos(i + 6, j + 2, k + 10), Block.getBlockById(0).getStateFromMeta(0), 2);
		world.setBlockState(new BlockPos(i + 7, j + 2, k + 10), Block.getBlockById(0).getStateFromMeta(0), 2);
		world.setBlockState(new BlockPos(i + 8, j + 2, k + 10), Block.getBlockById(0).getStateFromMeta(0), 2);
		world.setBlockState(new BlockPos(i + 9, j + 2, k + 10), Block.getBlockById(95).getStateFromMeta(3), 2);
		world.setBlockState(new BlockPos(i + 10, j + 2, k + 10), Block.getBlockById(9).getStateFromMeta(0), 2);
		world.setBlockState(new BlockPos(i + 0, j + 2, k + 11), Block.getBlockById(95).getStateFromMeta(3), 2);
		world.setBlockState(new BlockPos(i + 1, j + 2, k + 11), Block.getBlockById(47).getStateFromMeta(0), 2);
		world.setBlockState(new BlockPos(i + 2, j + 2, k + 11), Block.getBlockById(0).getStateFromMeta(0), 2);
		world.setBlockState(new BlockPos(i + 3, j + 2, k + 11), Block.getBlockById(0).getStateFromMeta(0), 2);
		world.setBlockState(new BlockPos(i + 4, j + 2, k + 11), Block.getBlockById(0).getStateFromMeta(0), 2);
		world.setBlockState(new BlockPos(i + 5, j + 2, k + 11), Block.getBlockById(0).getStateFromMeta(0), 2);
		world.setBlockState(new BlockPos(i + 6, j + 2, k + 11), Block.getBlockById(0).getStateFromMeta(0), 2);
		world.setBlockState(new BlockPos(i + 7, j + 2, k + 11), Block.getBlockById(0).getStateFromMeta(0), 2);
		world.setBlockState(new BlockPos(i + 8, j + 2, k + 11), Block.getBlockById(0).getStateFromMeta(0), 2);
		world.setBlockState(new BlockPos(i + 9, j + 2, k + 11), Block.getBlockById(47).getStateFromMeta(0), 2);
		world.setBlockState(new BlockPos(i + 10, j + 2, k + 11), Block.getBlockById(95).getStateFromMeta(3), 2);
		world.setBlockState(new BlockPos(i + 0, j + 2, k + 12), Block.getBlockById(95).getStateFromMeta(3), 2);
		world.setBlockState(new BlockPos(i + 1, j + 2, k + 12), Block.getBlockById(47).getStateFromMeta(0), 2);
		world.setBlockState(new BlockPos(i + 2, j + 2, k + 12), Block.getBlockById(0).getStateFromMeta(0), 2);
		world.setBlockState(new BlockPos(i + 3, j + 2, k + 12), Block.getBlockById(0).getStateFromMeta(0), 2);
		world.setBlockState(new BlockPos(i + 4, j + 2, k + 12), Block.getBlockById(0).getStateFromMeta(0), 2);
		world.setBlockState(new BlockPos(i + 5, j + 2, k + 12), Block.getBlockById(147).getStateFromMeta(0), 2);
		world.setBlockState(new BlockPos(i + 6, j + 2, k + 12), Block.getBlockById(0).getStateFromMeta(0), 2);
		world.setBlockState(new BlockPos(i + 7, j + 2, k + 12), Block.getBlockById(0).getStateFromMeta(0), 2);
		world.setBlockState(new BlockPos(i + 8, j + 2, k + 12), Block.getBlockById(0).getStateFromMeta(0), 2);
		world.setBlockState(new BlockPos(i + 9, j + 2, k + 12), Block.getBlockById(47).getStateFromMeta(0), 2);
		world.setBlockState(new BlockPos(i + 10, j + 2, k + 12), Block.getBlockById(95).getStateFromMeta(3), 2);
		world.setBlockState(new BlockPos(i + 0, j + 2, k + 13), Block.getBlockById(95).getStateFromMeta(3), 2);
		world.setBlockState(new BlockPos(i + 1, j + 2, k + 13), Block.getBlockById(47).getStateFromMeta(0), 2);
		world.setBlockState(new BlockPos(i + 2, j + 2, k + 13), Block.getBlockById(0).getStateFromMeta(0), 2);
		world.setBlockState(new BlockPos(i + 3, j + 2, k + 13), Block.getBlockById(0).getStateFromMeta(0), 2);
		world.setBlockState(new BlockPos(i + 4, j + 2, k + 13), Block.getBlockById(0).getStateFromMeta(0), 2);
		world.setBlockState(new BlockPos(i + 5, j + 2, k + 13), Block.getBlockById(166).getStateFromMeta(0), 2);
		world.setBlockState(new BlockPos(i + 6, j + 2, k + 13), Block.getBlockById(0).getStateFromMeta(0), 2);
		world.setBlockState(new BlockPos(i + 7, j + 2, k + 13), Block.getBlockById(0).getStateFromMeta(0), 2);
		world.setBlockState(new BlockPos(i + 8, j + 2, k + 13), Block.getBlockById(0).getStateFromMeta(0), 2);
		world.setBlockState(new BlockPos(i + 9, j + 2, k + 13), Block.getBlockById(47).getStateFromMeta(0), 2);
		world.setBlockState(new BlockPos(i + 10, j + 2, k + 13), Block.getBlockById(95).getStateFromMeta(3), 2);
		world.setBlockState(new BlockPos(i + 0, j + 2, k + 14), Block.getBlockById(95).getStateFromMeta(3), 2);
		world.setBlockState(new BlockPos(i + 1, j + 2, k + 14), Block.getBlockById(47).getStateFromMeta(0), 2);
		world.setBlockState(new BlockPos(i + 2, j + 2, k + 14), Block.getBlockById(0).getStateFromMeta(0), 2);
		world.setBlockState(new BlockPos(i + 3, j + 2, k + 14), Block.getBlockById(0).getStateFromMeta(0), 2);
		world.setBlockState(new BlockPos(i + 4, j + 2, k + 14), Block.getBlockById(0).getStateFromMeta(0), 2);
		world.setBlockState(new BlockPos(i + 5, j + 2, k + 14), Block.getBlockById(0).getStateFromMeta(0), 2);
		world.setBlockState(new BlockPos(i + 6, j + 2, k + 14), Block.getBlockById(0).getStateFromMeta(0), 2);
		world.setBlockState(new BlockPos(i + 7, j + 2, k + 14), Block.getBlockById(0).getStateFromMeta(0), 2);
		world.setBlockState(new BlockPos(i + 8, j + 2, k + 14), Block.getBlockById(0).getStateFromMeta(0), 2);
		world.setBlockState(new BlockPos(i + 9, j + 2, k + 14), Block.getBlockById(47).getStateFromMeta(0), 2);
		world.setBlockState(new BlockPos(i + 10, j + 2, k + 14), Block.getBlockById(95).getStateFromMeta(3), 2);
		world.setBlockState(new BlockPos(i + 0, j + 2, k + 15), Block.getBlockById(95).getStateFromMeta(3), 2);
		world.setBlockState(new BlockPos(i + 1, j + 2, k + 15), Block.getBlockById(47).getStateFromMeta(0), 2);
		world.setBlockState(new BlockPos(i + 2, j + 2, k + 15), Block.getBlockById(0).getStateFromMeta(0), 2);
		world.setBlockState(new BlockPos(i + 3, j + 2, k + 15), Block.getBlockById(0).getStateFromMeta(0), 2);
		world.setBlockState(new BlockPos(i + 4, j + 2, k + 15), Block.getBlockById(0).getStateFromMeta(0), 2);
		world.setBlockState(new BlockPos(i + 5, j + 2, k + 15), Block.getBlockById(0).getStateFromMeta(0), 2);
		world.setBlockState(new BlockPos(i + 6, j + 2, k + 15), Block.getBlockById(0).getStateFromMeta(0), 2);
		world.setBlockState(new BlockPos(i + 7, j + 2, k + 15), Block.getBlockById(0).getStateFromMeta(0), 2);
		world.setBlockState(new BlockPos(i + 8, j + 2, k + 15), Block.getBlockById(0).getStateFromMeta(0), 2);
		world.setBlockState(new BlockPos(i + 9, j + 2, k + 15), Block.getBlockById(47).getStateFromMeta(0), 2);
		world.setBlockState(new BlockPos(i + 10, j + 2, k + 15), Block.getBlockById(95).getStateFromMeta(3), 2);
		world.setBlockState(new BlockPos(i + 0, j + 2, k + 16), Block.getBlockById(9).getStateFromMeta(0), 2);
		world.setBlockState(new BlockPos(i + 1, j + 2, k + 16), Block.getBlockById(95).getStateFromMeta(3), 2);
		world.setBlockState(new BlockPos(i + 2, j + 2, k + 16), Block.getBlockById(0).getStateFromMeta(0), 2);
		world.setBlockState(new BlockPos(i + 3, j + 2, k + 16), Block.getBlockById(0).getStateFromMeta(0), 2);
		world.setBlockState(new BlockPos(i + 4, j + 2, k + 16), Block.getBlockById(0).getStateFromMeta(0), 2);
		world.setBlockState(new BlockPos(i + 5, j + 2, k + 16), Block.getBlockById(0).getStateFromMeta(0), 2);
		world.setBlockState(new BlockPos(i + 6, j + 2, k + 16), Block.getBlockById(0).getStateFromMeta(0), 2);
		world.setBlockState(new BlockPos(i + 7, j + 2, k + 16), Block.getBlockById(0).getStateFromMeta(0), 2);
		world.setBlockState(new BlockPos(i + 8, j + 2, k + 16), Block.getBlockById(0).getStateFromMeta(0), 2);
		world.setBlockState(new BlockPos(i + 9, j + 2, k + 16), Block.getBlockById(95).getStateFromMeta(3), 2);
		world.setBlockState(new BlockPos(i + 10, j + 2, k + 16), Block.getBlockById(9).getStateFromMeta(0), 2);
		world.setBlockState(new BlockPos(i + 0, j + 2, k + 17), Block.getBlockById(9).getStateFromMeta(0), 2);
		world.setBlockState(new BlockPos(i + 1, j + 2, k + 17), Block.getBlockById(9).getStateFromMeta(0), 2);
		world.setBlockState(new BlockPos(i + 2, j + 2, k + 17), Block.getBlockById(95).getStateFromMeta(3), 2);
		world.setBlockState(new BlockPos(i + 3, j + 2, k + 17), Block.getBlockById(47).getStateFromMeta(0), 2);
		world.setBlockState(new BlockPos(i + 4, j + 2, k + 17), Block.getBlockById(47).getStateFromMeta(0), 2);
		world.setBlockState(new BlockPos(i + 5, j + 2, k + 17), Block.getBlockById(47).getStateFromMeta(0), 2);
		world.setBlockState(new BlockPos(i + 6, j + 2, k + 17), Block.getBlockById(47).getStateFromMeta(0), 2);
		world.setBlockState(new BlockPos(i + 7, j + 2, k + 17), Block.getBlockById(47).getStateFromMeta(0), 2);
		world.setBlockState(new BlockPos(i + 8, j + 2, k + 17), Block.getBlockById(95).getStateFromMeta(3), 2);
		world.setBlockState(new BlockPos(i + 9, j + 2, k + 17), Block.getBlockById(9).getStateFromMeta(0), 2);
		world.setBlockState(new BlockPos(i + 10, j + 2, k + 17), Block.getBlockById(9).getStateFromMeta(0), 2);
		world.setBlockState(new BlockPos(i + 0, j + 2, k + 18), Block.getBlockById(9).getStateFromMeta(0), 2);
		world.setBlockState(new BlockPos(i + 1, j + 2, k + 18), Block.getBlockById(9).getStateFromMeta(0), 2);
		world.setBlockState(new BlockPos(i + 2, j + 2, k + 18), Block.getBlockById(9).getStateFromMeta(0), 2);
		world.setBlockState(new BlockPos(i + 3, j + 2, k + 18), Block.getBlockById(95).getStateFromMeta(3), 2);
		world.setBlockState(new BlockPos(i + 4, j + 2, k + 18), Block.getBlockById(95).getStateFromMeta(3), 2);
		world.setBlockState(new BlockPos(i + 5, j + 2, k + 18), Block.getBlockById(95).getStateFromMeta(3), 2);
		world.setBlockState(new BlockPos(i + 6, j + 2, k + 18), Block.getBlockById(95).getStateFromMeta(3), 2);
		world.setBlockState(new BlockPos(i + 7, j + 2, k + 18), Block.getBlockById(95).getStateFromMeta(3), 2);
		world.setBlockState(new BlockPos(i + 8, j + 2, k + 18), Block.getBlockById(9).getStateFromMeta(0), 2);
		world.setBlockState(new BlockPos(i + 9, j + 2, k + 18), Block.getBlockById(9).getStateFromMeta(0), 2);
		world.setBlockState(new BlockPos(i + 10, j + 2, k + 18), Block.getBlockById(9).getStateFromMeta(0), 2);
		world.setBlockState(new BlockPos(i + 0, j + 3, k + 0), Block.getBlockById(9).getStateFromMeta(0), 2);
		world.setBlockState(new BlockPos(i + 1, j + 3, k + 0), Block.getBlockById(9).getStateFromMeta(0), 2);
		world.setBlockState(new BlockPos(i + 2, j + 3, k + 0), Block.getBlockById(9).getStateFromMeta(0), 2);
		world.setBlockState(new BlockPos(i + 3, j + 3, k + 0), Block.getBlockById(168).getStateFromMeta(0), 2);
		world.setBlockState(new BlockPos(i + 4, j + 3, k + 0), Block.getBlockById(167).getStateFromMeta(3), 2);
		world.setBlockState(new BlockPos(i + 5, j + 3, k + 0), Block.getBlockById(167).getStateFromMeta(3), 2);
		world.setBlockState(new BlockPos(i + 6, j + 3, k + 0), Block.getBlockById(167).getStateFromMeta(2), 2);
		world.setBlockState(new BlockPos(i + 7, j + 3, k + 0), Block.getBlockById(168).getStateFromMeta(0), 2);
		world.setBlockState(new BlockPos(i + 8, j + 3, k + 0), Block.getBlockById(9).getStateFromMeta(0), 2);
		world.setBlockState(new BlockPos(i + 9, j + 3, k + 0), Block.getBlockById(9).getStateFromMeta(0), 2);
		world.setBlockState(new BlockPos(i + 10, j + 3, k + 0), Block.getBlockById(9).getStateFromMeta(0), 2);
		world.setBlockState(new BlockPos(i + 0, j + 3, k + 1), Block.getBlockById(9).getStateFromMeta(0), 2);
		world.setBlockState(new BlockPos(i + 1, j + 3, k + 1), Block.getBlockById(9).getStateFromMeta(0), 2);
		world.setBlockState(new BlockPos(i + 2, j + 3, k + 1), Block.getBlockById(9).getStateFromMeta(0), 2);
		world.setBlockState(new BlockPos(i + 3, j + 3, k + 1), Block.getBlockById(95).getStateFromMeta(3), 2);
		world.setBlockState(new BlockPos(i + 4, j + 3, k + 1), Block.getBlockById(0).getStateFromMeta(0), 2);
		world.setBlockState(new BlockPos(i + 5, j + 3, k + 1), Block.getBlockById(0).getStateFromMeta(0), 2);
		world.setBlockState(new BlockPos(i + 6, j + 3, k + 1), Block.getBlockById(0).getStateFromMeta(0), 2);
		world.setBlockState(new BlockPos(i + 7, j + 3, k + 1), Block.getBlockById(95).getStateFromMeta(3), 2);
		world.setBlockState(new BlockPos(i + 8, j + 3, k + 1), Block.getBlockById(9).getStateFromMeta(0), 2);
		world.setBlockState(new BlockPos(i + 9, j + 3, k + 1), Block.getBlockById(9).getStateFromMeta(0), 2);
		world.setBlockState(new BlockPos(i + 10, j + 3, k + 1), Block.getBlockById(9).getStateFromMeta(0), 2);
		world.setBlockState(new BlockPos(i + 0, j + 3, k + 2), Block.getBlockById(9).getStateFromMeta(0), 2);
		world.setBlockState(new BlockPos(i + 1, j + 3, k + 2), Block.getBlockById(9).getStateFromMeta(0), 2);
		world.setBlockState(new BlockPos(i + 2, j + 3, k + 2), Block.getBlockById(9).getStateFromMeta(0), 2);
		world.setBlockState(new BlockPos(i + 3, j + 3, k + 2), Block.getBlockById(95).getStateFromMeta(3), 2);
		world.setBlockState(new BlockPos(i + 4, j + 3, k + 2), Block.getBlockById(0).getStateFromMeta(0), 2);
		world.setBlockState(new BlockPos(i + 5, j + 3, k + 2), Block.getBlockById(0).getStateFromMeta(0), 2);
		world.setBlockState(new BlockPos(i + 6, j + 3, k + 2), Block.getBlockById(0).getStateFromMeta(0), 2);
		world.setBlockState(new BlockPos(i + 7, j + 3, k + 2), Block.getBlockById(95).getStateFromMeta(3), 2);
		world.setBlockState(new BlockPos(i + 8, j + 3, k + 2), Block.getBlockById(9).getStateFromMeta(0), 2);
		world.setBlockState(new BlockPos(i + 9, j + 3, k + 2), Block.getBlockById(9).getStateFromMeta(0), 2);
		world.setBlockState(new BlockPos(i + 10, j + 3, k + 2), Block.getBlockById(9).getStateFromMeta(0), 2);
		world.setBlockState(new BlockPos(i + 0, j + 3, k + 3), Block.getBlockById(9).getStateFromMeta(0), 2);
		world.setBlockState(new BlockPos(i + 1, j + 3, k + 3), Block.getBlockById(9).getStateFromMeta(0), 2);
		world.setBlockState(new BlockPos(i + 2, j + 3, k + 3), Block.getBlockById(9).getStateFromMeta(0), 2);
		world.setBlockState(new BlockPos(i + 3, j + 3, k + 3), Block.getBlockById(95).getStateFromMeta(3), 2);
		world.setBlockState(new BlockPos(i + 4, j + 3, k + 3), Block.getBlockById(0).getStateFromMeta(0), 2);
		world.setBlockState(new BlockPos(i + 5, j + 3, k + 3), Block.getBlockById(0).getStateFromMeta(0), 2);
		world.setBlockState(new BlockPos(i + 6, j + 3, k + 3), Block.getBlockById(0).getStateFromMeta(0), 2);
		world.setBlockState(new BlockPos(i + 7, j + 3, k + 3), Block.getBlockById(95).getStateFromMeta(3), 2);
		world.setBlockState(new BlockPos(i + 8, j + 3, k + 3), Block.getBlockById(9).getStateFromMeta(0), 2);
		world.setBlockState(new BlockPos(i + 9, j + 3, k + 3), Block.getBlockById(9).getStateFromMeta(0), 2);
		world.setBlockState(new BlockPos(i + 10, j + 3, k + 3), Block.getBlockById(9).getStateFromMeta(0), 2);
		world.setBlockState(new BlockPos(i + 0, j + 3, k + 4), Block.getBlockById(9).getStateFromMeta(0), 2);
		world.setBlockState(new BlockPos(i + 1, j + 3, k + 4), Block.getBlockById(9).getStateFromMeta(0), 2);
		world.setBlockState(new BlockPos(i + 2, j + 3, k + 4), Block.getBlockById(9).getStateFromMeta(0), 2);
		world.setBlockState(new BlockPos(i + 3, j + 3, k + 4), Block.getBlockById(95).getStateFromMeta(3), 2);
		world.setBlockState(new BlockPos(i + 4, j + 3, k + 4), Block.getBlockById(0).getStateFromMeta(0), 2);
		world.setBlockState(new BlockPos(i + 5, j + 3, k + 4), Block.getBlockById(0).getStateFromMeta(0), 2);
		world.setBlockState(new BlockPos(i + 6, j + 3, k + 4), Block.getBlockById(0).getStateFromMeta(0), 2);
		world.setBlockState(new BlockPos(i + 7, j + 3, k + 4), Block.getBlockById(95).getStateFromMeta(3), 2);
		world.setBlockState(new BlockPos(i + 8, j + 3, k + 4), Block.getBlockById(9).getStateFromMeta(0), 2);
		world.setBlockState(new BlockPos(i + 9, j + 3, k + 4), Block.getBlockById(9).getStateFromMeta(0), 2);
		world.setBlockState(new BlockPos(i + 10, j + 3, k + 4), Block.getBlockById(9).getStateFromMeta(0), 2);
		world.setBlockState(new BlockPos(i + 0, j + 3, k + 5), Block.getBlockById(9).getStateFromMeta(0), 2);
		world.setBlockState(new BlockPos(i + 1, j + 3, k + 5), Block.getBlockById(9).getStateFromMeta(0), 2);
		world.setBlockState(new BlockPos(i + 2, j + 3, k + 5), Block.getBlockById(9).getStateFromMeta(0), 2);
		world.setBlockState(new BlockPos(i + 3, j + 3, k + 5), Block.getBlockById(95).getStateFromMeta(3), 2);
		world.setBlockState(new BlockPos(i + 4, j + 3, k + 5), Block.getBlockById(0).getStateFromMeta(0), 2);
		world.setBlockState(new BlockPos(i + 5, j + 3, k + 5), Block.getBlockById(0).getStateFromMeta(0), 2);
		world.setBlockState(new BlockPos(i + 6, j + 3, k + 5), Block.getBlockById(0).getStateFromMeta(0), 2);
		world.setBlockState(new BlockPos(i + 7, j + 3, k + 5), Block.getBlockById(95).getStateFromMeta(3), 2);
		world.setBlockState(new BlockPos(i + 8, j + 3, k + 5), Block.getBlockById(9).getStateFromMeta(0), 2);
		world.setBlockState(new BlockPos(i + 9, j + 3, k + 5), Block.getBlockById(9).getStateFromMeta(0), 2);
		world.setBlockState(new BlockPos(i + 10, j + 3, k + 5), Block.getBlockById(9).getStateFromMeta(0), 2);
		world.setBlockState(new BlockPos(i + 0, j + 3, k + 6), Block.getBlockById(9).getStateFromMeta(0), 2);
		world.setBlockState(new BlockPos(i + 1, j + 3, k + 6), Block.getBlockById(9).getStateFromMeta(0), 2);
		world.setBlockState(new BlockPos(i + 2, j + 3, k + 6), Block.getBlockById(9).getStateFromMeta(0), 2);
		world.setBlockState(new BlockPos(i + 3, j + 3, k + 6), Block.getBlockById(95).getStateFromMeta(3), 2);
		world.setBlockState(new BlockPos(i + 4, j + 3, k + 6), Block.getBlockById(0).getStateFromMeta(0), 2);
		world.setBlockState(new BlockPos(i + 5, j + 3, k + 6), Block.getBlockById(0).getStateFromMeta(0), 2);
		world.setBlockState(new BlockPos(i + 6, j + 3, k + 6), Block.getBlockById(0).getStateFromMeta(0), 2);
		world.setBlockState(new BlockPos(i + 7, j + 3, k + 6), Block.getBlockById(95).getStateFromMeta(3), 2);
		world.setBlockState(new BlockPos(i + 8, j + 3, k + 6), Block.getBlockById(9).getStateFromMeta(0), 2);
		world.setBlockState(new BlockPos(i + 9, j + 3, k + 6), Block.getBlockById(9).getStateFromMeta(0), 2);
		world.setBlockState(new BlockPos(i + 10, j + 3, k + 6), Block.getBlockById(9).getStateFromMeta(0), 2);
		world.setBlockState(new BlockPos(i + 0, j + 3, k + 7), Block.getBlockById(9).getStateFromMeta(0), 2);
		world.setBlockState(new BlockPos(i + 1, j + 3, k + 7), Block.getBlockById(9).getStateFromMeta(0), 2);
		world.setBlockState(new BlockPos(i + 2, j + 3, k + 7), Block.getBlockById(9).getStateFromMeta(0), 2);
		world.setBlockState(new BlockPos(i + 3, j + 3, k + 7), Block.getBlockById(95).getStateFromMeta(3), 2);
		world.setBlockState(new BlockPos(i + 4, j + 3, k + 7), Block.getBlockById(0).getStateFromMeta(0), 2);
		world.setBlockState(new BlockPos(i + 5, j + 3, k + 7), Block.getBlockById(0).getStateFromMeta(0), 2);
		world.setBlockState(new BlockPos(i + 6, j + 3, k + 7), Block.getBlockById(0).getStateFromMeta(0), 2);
		world.setBlockState(new BlockPos(i + 7, j + 3, k + 7), Block.getBlockById(95).getStateFromMeta(3), 2);
		world.setBlockState(new BlockPos(i + 8, j + 3, k + 7), Block.getBlockById(9).getStateFromMeta(0), 2);
		world.setBlockState(new BlockPos(i + 9, j + 3, k + 7), Block.getBlockById(9).getStateFromMeta(0), 2);
		world.setBlockState(new BlockPos(i + 10, j + 3, k + 7), Block.getBlockById(9).getStateFromMeta(0), 2);
		world.setBlockState(new BlockPos(i + 0, j + 3, k + 8), Block.getBlockById(9).getStateFromMeta(0), 2);
		world.setBlockState(new BlockPos(i + 1, j + 3, k + 8), Block.getBlockById(9).getStateFromMeta(0), 2);
		world.setBlockState(new BlockPos(i + 2, j + 3, k + 8), Block.getBlockById(9).getStateFromMeta(0), 2);
		world.setBlockState(new BlockPos(i + 3, j + 3, k + 8), Block.getBlockById(168).getStateFromMeta(0), 2);
		world.setBlockState(new BlockPos(i + 4, j + 3, k + 8), Block.getBlockById(0).getStateFromMeta(0), 2);
		world.setBlockState(new BlockPos(i + 5, j + 3, k + 8), Block.getBlockById(0).getStateFromMeta(0), 2);
		world.setBlockState(new BlockPos(i + 6, j + 3, k + 8), Block.getBlockById(0).getStateFromMeta(0), 2);
		world.setBlockState(new BlockPos(i + 7, j + 3, k + 8), Block.getBlockById(168).getStateFromMeta(0), 2);
		world.setBlockState(new BlockPos(i + 8, j + 3, k + 8), Block.getBlockById(9).getStateFromMeta(0), 2);
		world.setBlockState(new BlockPos(i + 9, j + 3, k + 8), Block.getBlockById(9).getStateFromMeta(0), 2);
		world.setBlockState(new BlockPos(i + 10, j + 3, k + 8), Block.getBlockById(9).getStateFromMeta(0), 2);
		world.setBlockState(new BlockPos(i + 0, j + 3, k + 9), Block.getBlockById(9).getStateFromMeta(0), 2);
		world.setBlockState(new BlockPos(i + 1, j + 3, k + 9), Block.getBlockById(9).getStateFromMeta(0), 2);
		world.setBlockState(new BlockPos(i + 2, j + 3, k + 9), Block.getBlockById(95).getStateFromMeta(3), 2);
		world.setBlockState(new BlockPos(i + 3, j + 3, k + 9), Block.getBlockById(0).getStateFromMeta(0), 2);
		world.setBlockState(new BlockPos(i + 4, j + 3, k + 9), Block.getBlockById(0).getStateFromMeta(0), 2);
		world.setBlockState(new BlockPos(i + 5, j + 3, k + 9), Block.getBlockById(0).getStateFromMeta(0), 2);
		world.setBlockState(new BlockPos(i + 6, j + 3, k + 9), Block.getBlockById(0).getStateFromMeta(0), 2);
		world.setBlockState(new BlockPos(i + 7, j + 3, k + 9), Block.getBlockById(0).getStateFromMeta(0), 2);
		world.setBlockState(new BlockPos(i + 8, j + 3, k + 9), Block.getBlockById(95).getStateFromMeta(3), 2);
		world.setBlockState(new BlockPos(i + 9, j + 3, k + 9), Block.getBlockById(9).getStateFromMeta(0), 2);
		world.setBlockState(new BlockPos(i + 10, j + 3, k + 9), Block.getBlockById(9).getStateFromMeta(0), 2);
		world.setBlockState(new BlockPos(i + 0, j + 3, k + 10), Block.getBlockById(9).getStateFromMeta(0), 2);
		world.setBlockState(new BlockPos(i + 1, j + 3, k + 10), Block.getBlockById(95).getStateFromMeta(3), 2);
		world.setBlockState(new BlockPos(i + 2, j + 3, k + 10), Block.getBlockById(0).getStateFromMeta(0), 2);
		world.setBlockState(new BlockPos(i + 3, j + 3, k + 10), Block.getBlockById(0).getStateFromMeta(0), 2);
		world.setBlockState(new BlockPos(i + 4, j + 3, k + 10), Block.getBlockById(0).getStateFromMeta(0), 2);
		world.setBlockState(new BlockPos(i + 5, j + 3, k + 10), Block.getBlockById(0).getStateFromMeta(0), 2);
		world.setBlockState(new BlockPos(i + 6, j + 3, k + 10), Block.getBlockById(0).getStateFromMeta(0), 2);
		world.setBlockState(new BlockPos(i + 7, j + 3, k + 10), Block.getBlockById(0).getStateFromMeta(0), 2);
		world.setBlockState(new BlockPos(i + 8, j + 3, k + 10), Block.getBlockById(0).getStateFromMeta(0), 2);
		world.setBlockState(new BlockPos(i + 9, j + 3, k + 10), Block.getBlockById(95).getStateFromMeta(3), 2);
		world.setBlockState(new BlockPos(i + 10, j + 3, k + 10), Block.getBlockById(9).getStateFromMeta(0), 2);
		world.setBlockState(new BlockPos(i + 0, j + 3, k + 11), Block.getBlockById(95).getStateFromMeta(3), 2);
		world.setBlockState(new BlockPos(i + 1, j + 3, k + 11), Block.getBlockById(0).getStateFromMeta(0), 2);
		world.setBlockState(new BlockPos(i + 2, j + 3, k + 11), Block.getBlockById(0).getStateFromMeta(0), 2);
		world.setBlockState(new BlockPos(i + 3, j + 3, k + 11), Block.getBlockById(0).getStateFromMeta(0), 2);
		world.setBlockState(new BlockPos(i + 4, j + 3, k + 11), Block.getBlockById(0).getStateFromMeta(0), 2);
		world.setBlockState(new BlockPos(i + 5, j + 3, k + 11), Block.getBlockById(0).getStateFromMeta(0), 2);
		world.setBlockState(new BlockPos(i + 6, j + 3, k + 11), Block.getBlockById(0).getStateFromMeta(0), 2);
		world.setBlockState(new BlockPos(i + 7, j + 3, k + 11), Block.getBlockById(0).getStateFromMeta(0), 2);
		world.setBlockState(new BlockPos(i + 8, j + 3, k + 11), Block.getBlockById(0).getStateFromMeta(0), 2);
		world.setBlockState(new BlockPos(i + 9, j + 3, k + 11), Block.getBlockById(0).getStateFromMeta(0), 2);
		world.setBlockState(new BlockPos(i + 10, j + 3, k + 11), Block.getBlockById(95).getStateFromMeta(3), 2);
		world.setBlockState(new BlockPos(i + 0, j + 3, k + 12), Block.getBlockById(95).getStateFromMeta(3), 2);
		world.setBlockState(new BlockPos(i + 1, j + 3, k + 12), Block.getBlockById(0).getStateFromMeta(0), 2);
		world.setBlockState(new BlockPos(i + 2, j + 3, k + 12), Block.getBlockById(0).getStateFromMeta(0), 2);
		world.setBlockState(new BlockPos(i + 3, j + 3, k + 12), Block.getBlockById(0).getStateFromMeta(0), 2);
		world.setBlockState(new BlockPos(i + 4, j + 3, k + 12), Block.getBlockById(0).getStateFromMeta(0), 2);
		world.setBlockState(new BlockPos(i + 5, j + 3, k + 12), Block.getBlockById(0).getStateFromMeta(0), 2);
		world.setBlockState(new BlockPos(i + 6, j + 3, k + 12), Block.getBlockById(0).getStateFromMeta(0), 2);
		world.setBlockState(new BlockPos(i + 7, j + 3, k + 12), Block.getBlockById(0).getStateFromMeta(0), 2);
		world.setBlockState(new BlockPos(i + 8, j + 3, k + 12), Block.getBlockById(0).getStateFromMeta(0), 2);
		world.setBlockState(new BlockPos(i + 9, j + 3, k + 12), Block.getBlockById(0).getStateFromMeta(0), 2);
		world.setBlockState(new BlockPos(i + 10, j + 3, k + 12), Block.getBlockById(95).getStateFromMeta(3), 2);
		world.setBlockState(new BlockPos(i + 0, j + 3, k + 13), Block.getBlockById(95).getStateFromMeta(3), 2);
		world.setBlockState(new BlockPos(i + 1, j + 3, k + 13), Block.getBlockById(169).getStateFromMeta(0), 2);
		world.setBlockState(new BlockPos(i + 2, j + 3, k + 13), Block.getBlockById(0).getStateFromMeta(0), 2);
		world.setBlockState(new BlockPos(i + 3, j + 3, k + 13), Block.getBlockById(0).getStateFromMeta(0), 2);
		world.setBlockState(new BlockPos(i + 4, j + 3, k + 13), Block.getBlockById(0).getStateFromMeta(0), 2);
		world.setBlockState(new BlockPos(i + 5, j + 3, k + 13), Block.getBlockById(0).getStateFromMeta(0), 2);
		world.setBlockState(new BlockPos(i + 6, j + 3, k + 13), Block.getBlockById(0).getStateFromMeta(0), 2);
		world.setBlockState(new BlockPos(i + 7, j + 3, k + 13), Block.getBlockById(0).getStateFromMeta(0), 2);
		world.setBlockState(new BlockPos(i + 8, j + 3, k + 13), Block.getBlockById(0).getStateFromMeta(0), 2);
		world.setBlockState(new BlockPos(i + 9, j + 3, k + 13), Block.getBlockById(169).getStateFromMeta(0), 2);
		world.setBlockState(new BlockPos(i + 10, j + 3, k + 13), Block.getBlockById(95).getStateFromMeta(3), 2);
		world.setBlockState(new BlockPos(i + 0, j + 3, k + 14), Block.getBlockById(95).getStateFromMeta(3), 2);
		world.setBlockState(new BlockPos(i + 1, j + 3, k + 14), Block.getBlockById(0).getStateFromMeta(0), 2);
		world.setBlockState(new BlockPos(i + 2, j + 3, k + 14), Block.getBlockById(0).getStateFromMeta(0), 2);
		world.setBlockState(new BlockPos(i + 3, j + 3, k + 14), Block.getBlockById(0).getStateFromMeta(0), 2);
		world.setBlockState(new BlockPos(i + 4, j + 3, k + 14), Block.getBlockById(0).getStateFromMeta(0), 2);
		world.setBlockState(new BlockPos(i + 5, j + 3, k + 14), Block.getBlockById(0).getStateFromMeta(0), 2);
		world.setBlockState(new BlockPos(i + 6, j + 3, k + 14), Block.getBlockById(0).getStateFromMeta(0), 2);
		world.setBlockState(new BlockPos(i + 7, j + 3, k + 14), Block.getBlockById(0).getStateFromMeta(0), 2);
		world.setBlockState(new BlockPos(i + 8, j + 3, k + 14), Block.getBlockById(0).getStateFromMeta(0), 2);
		world.setBlockState(new BlockPos(i + 9, j + 3, k + 14), Block.getBlockById(0).getStateFromMeta(0), 2);
		world.setBlockState(new BlockPos(i + 10, j + 3, k + 14), Block.getBlockById(95).getStateFromMeta(3), 2);
		world.setBlockState(new BlockPos(i + 0, j + 3, k + 15), Block.getBlockById(95).getStateFromMeta(3), 2);
		world.setBlockState(new BlockPos(i + 1, j + 3, k + 15), Block.getBlockById(0).getStateFromMeta(0), 2);
		world.setBlockState(new BlockPos(i + 2, j + 3, k + 15), Block.getBlockById(0).getStateFromMeta(0), 2);
		world.setBlockState(new BlockPos(i + 3, j + 3, k + 15), Block.getBlockById(0).getStateFromMeta(0), 2);
		world.setBlockState(new BlockPos(i + 4, j + 3, k + 15), Block.getBlockById(0).getStateFromMeta(0), 2);
		world.setBlockState(new BlockPos(i + 5, j + 3, k + 15), Block.getBlockById(0).getStateFromMeta(0), 2);
		world.setBlockState(new BlockPos(i + 6, j + 3, k + 15), Block.getBlockById(0).getStateFromMeta(0), 2);
		world.setBlockState(new BlockPos(i + 7, j + 3, k + 15), Block.getBlockById(0).getStateFromMeta(0), 2);
		world.setBlockState(new BlockPos(i + 8, j + 3, k + 15), Block.getBlockById(0).getStateFromMeta(0), 2);
		world.setBlockState(new BlockPos(i + 9, j + 3, k + 15), Block.getBlockById(0).getStateFromMeta(0), 2);
		world.setBlockState(new BlockPos(i + 10, j + 3, k + 15), Block.getBlockById(95).getStateFromMeta(3), 2);
		world.setBlockState(new BlockPos(i + 0, j + 3, k + 16), Block.getBlockById(9).getStateFromMeta(0), 2);
		world.setBlockState(new BlockPos(i + 1, j + 3, k + 16), Block.getBlockById(95).getStateFromMeta(3), 2);
		world.setBlockState(new BlockPos(i + 2, j + 3, k + 16), Block.getBlockById(0).getStateFromMeta(0), 2);
		world.setBlockState(new BlockPos(i + 3, j + 3, k + 16), Block.getBlockById(0).getStateFromMeta(0), 2);
		world.setBlockState(new BlockPos(i + 4, j + 3, k + 16), Block.getBlockById(0).getStateFromMeta(0), 2);
		world.setBlockState(new BlockPos(i + 5, j + 3, k + 16), Block.getBlockById(0).getStateFromMeta(0), 2);
		world.setBlockState(new BlockPos(i + 6, j + 3, k + 16), Block.getBlockById(0).getStateFromMeta(0), 2);
		world.setBlockState(new BlockPos(i + 7, j + 3, k + 16), Block.getBlockById(0).getStateFromMeta(0), 2);
		world.setBlockState(new BlockPos(i + 8, j + 3, k + 16), Block.getBlockById(0).getStateFromMeta(0), 2);
		world.setBlockState(new BlockPos(i + 9, j + 3, k + 16), Block.getBlockById(95).getStateFromMeta(3), 2);
		world.setBlockState(new BlockPos(i + 10, j + 3, k + 16), Block.getBlockById(9).getStateFromMeta(0), 2);
		world.setBlockState(new BlockPos(i + 0, j + 3, k + 17), Block.getBlockById(9).getStateFromMeta(0), 2);
		world.setBlockState(new BlockPos(i + 1, j + 3, k + 17), Block.getBlockById(9).getStateFromMeta(0), 2);
		world.setBlockState(new BlockPos(i + 2, j + 3, k + 17), Block.getBlockById(95).getStateFromMeta(3), 2);
		world.setBlockState(new BlockPos(i + 3, j + 3, k + 17), Block.getBlockById(0).getStateFromMeta(0), 2);
		world.setBlockState(new BlockPos(i + 4, j + 3, k + 17), Block.getBlockById(0).getStateFromMeta(0), 2);
		world.setBlockState(new BlockPos(i + 5, j + 3, k + 17), Block.getBlockById(169).getStateFromMeta(0), 2);
		world.setBlockState(new BlockPos(i + 6, j + 3, k + 17), Block.getBlockById(0).getStateFromMeta(0), 2);
		world.setBlockState(new BlockPos(i + 7, j + 3, k + 17), Block.getBlockById(0).getStateFromMeta(0), 2);
		world.setBlockState(new BlockPos(i + 8, j + 3, k + 17), Block.getBlockById(95).getStateFromMeta(3), 2);
		world.setBlockState(new BlockPos(i + 9, j + 3, k + 17), Block.getBlockById(9).getStateFromMeta(0), 2);
		world.setBlockState(new BlockPos(i + 10, j + 3, k + 17), Block.getBlockById(9).getStateFromMeta(0), 2);
		world.setBlockState(new BlockPos(i + 0, j + 3, k + 18), Block.getBlockById(9).getStateFromMeta(0), 2);
		world.setBlockState(new BlockPos(i + 1, j + 3, k + 18), Block.getBlockById(9).getStateFromMeta(0), 2);
		world.setBlockState(new BlockPos(i + 2, j + 3, k + 18), Block.getBlockById(9).getStateFromMeta(0), 2);
		world.setBlockState(new BlockPos(i + 3, j + 3, k + 18), Block.getBlockById(95).getStateFromMeta(3), 2);
		world.setBlockState(new BlockPos(i + 4, j + 3, k + 18), Block.getBlockById(95).getStateFromMeta(3), 2);
		world.setBlockState(new BlockPos(i + 5, j + 3, k + 18), Block.getBlockById(95).getStateFromMeta(3), 2);
		world.setBlockState(new BlockPos(i + 6, j + 3, k + 18), Block.getBlockById(95).getStateFromMeta(3), 2);
		world.setBlockState(new BlockPos(i + 7, j + 3, k + 18), Block.getBlockById(95).getStateFromMeta(3), 2);
		world.setBlockState(new BlockPos(i + 8, j + 3, k + 18), Block.getBlockById(9).getStateFromMeta(0), 2);
		world.setBlockState(new BlockPos(i + 9, j + 3, k + 18), Block.getBlockById(9).getStateFromMeta(0), 2);
		world.setBlockState(new BlockPos(i + 10, j + 3, k + 18), Block.getBlockById(9).getStateFromMeta(0), 2);
		world.setBlockState(new BlockPos(i + 0, j + 4, k + 0), Block.getBlockById(9).getStateFromMeta(0), 2);
		world.setBlockState(new BlockPos(i + 1, j + 4, k + 0), Block.getBlockById(9).getStateFromMeta(0), 2);
		world.setBlockState(new BlockPos(i + 2, j + 4, k + 0), Block.getBlockById(9).getStateFromMeta(0), 2);
		world.setBlockState(new BlockPos(i + 3, j + 4, k + 0), Block.getBlockById(168).getStateFromMeta(0), 2);
		world.setBlockState(new BlockPos(i + 4, j + 4, k + 0), Block.getBlockById(168).getStateFromMeta(0), 2);
		world.setBlockState(new BlockPos(i + 5, j + 4, k + 0), Block.getBlockById(169).getStateFromMeta(0), 2);
		world.setBlockState(new BlockPos(i + 6, j + 4, k + 0), Block.getBlockById(168).getStateFromMeta(0), 2);
		world.setBlockState(new BlockPos(i + 7, j + 4, k + 0), Block.getBlockById(168).getStateFromMeta(0), 2);
		world.setBlockState(new BlockPos(i + 8, j + 4, k + 0), Block.getBlockById(9).getStateFromMeta(0), 2);
		world.setBlockState(new BlockPos(i + 9, j + 4, k + 0), Block.getBlockById(9).getStateFromMeta(0), 2);
		world.setBlockState(new BlockPos(i + 10, j + 4, k + 0), Block.getBlockById(9).getStateFromMeta(0), 2);
		world.setBlockState(new BlockPos(i + 0, j + 4, k + 1), Block.getBlockById(9).getStateFromMeta(0), 2);
		world.setBlockState(new BlockPos(i + 1, j + 4, k + 1), Block.getBlockById(9).getStateFromMeta(0), 2);
		world.setBlockState(new BlockPos(i + 2, j + 4, k + 1), Block.getBlockById(9).getStateFromMeta(0), 2);
		world.setBlockState(new BlockPos(i + 3, j + 4, k + 1), Block.getBlockById(95).getStateFromMeta(3), 2);
		world.setBlockState(new BlockPos(i + 4, j + 4, k + 1), Block.getBlockById(95).getStateFromMeta(3), 2);
		world.setBlockState(new BlockPos(i + 5, j + 4, k + 1), Block.getBlockById(95).getStateFromMeta(3), 2);
		world.setBlockState(new BlockPos(i + 6, j + 4, k + 1), Block.getBlockById(95).getStateFromMeta(3), 2);
		world.setBlockState(new BlockPos(i + 7, j + 4, k + 1), Block.getBlockById(95).getStateFromMeta(3), 2);
		world.setBlockState(new BlockPos(i + 8, j + 4, k + 1), Block.getBlockById(9).getStateFromMeta(0), 2);
		world.setBlockState(new BlockPos(i + 9, j + 4, k + 1), Block.getBlockById(9).getStateFromMeta(0), 2);
		world.setBlockState(new BlockPos(i + 10, j + 4, k + 1), Block.getBlockById(9).getStateFromMeta(0), 2);
		world.setBlockState(new BlockPos(i + 0, j + 4, k + 2), Block.getBlockById(9).getStateFromMeta(0), 2);
		world.setBlockState(new BlockPos(i + 1, j + 4, k + 2), Block.getBlockById(9).getStateFromMeta(0), 2);
		world.setBlockState(new BlockPos(i + 2, j + 4, k + 2), Block.getBlockById(9).getStateFromMeta(0), 2);
		world.setBlockState(new BlockPos(i + 3, j + 4, k + 2), Block.getBlockById(95).getStateFromMeta(3), 2);
		world.setBlockState(new BlockPos(i + 4, j + 4, k + 2), Block.getBlockById(95).getStateFromMeta(3), 2);
		world.setBlockState(new BlockPos(i + 5, j + 4, k + 2), Block.getBlockById(95).getStateFromMeta(3), 2);
		world.setBlockState(new BlockPos(i + 6, j + 4, k + 2), Block.getBlockById(95).getStateFromMeta(3), 2);
		world.setBlockState(new BlockPos(i + 7, j + 4, k + 2), Block.getBlockById(95).getStateFromMeta(3), 2);
		world.setBlockState(new BlockPos(i + 8, j + 4, k + 2), Block.getBlockById(9).getStateFromMeta(0), 2);
		world.setBlockState(new BlockPos(i + 9, j + 4, k + 2), Block.getBlockById(9).getStateFromMeta(0), 2);
		world.setBlockState(new BlockPos(i + 10, j + 4, k + 2), Block.getBlockById(9).getStateFromMeta(0), 2);
		world.setBlockState(new BlockPos(i + 0, j + 4, k + 3), Block.getBlockById(9).getStateFromMeta(0), 2);
		world.setBlockState(new BlockPos(i + 1, j + 4, k + 3), Block.getBlockById(9).getStateFromMeta(0), 2);
		world.setBlockState(new BlockPos(i + 2, j + 4, k + 3), Block.getBlockById(9).getStateFromMeta(0), 2);
		world.setBlockState(new BlockPos(i + 3, j + 4, k + 3), Block.getBlockById(95).getStateFromMeta(3), 2);
		world.setBlockState(new BlockPos(i + 4, j + 4, k + 3), Block.getBlockById(95).getStateFromMeta(3), 2);
		world.setBlockState(new BlockPos(i + 5, j + 4, k + 3), Block.getBlockById(95).getStateFromMeta(3), 2);
		world.setBlockState(new BlockPos(i + 6, j + 4, k + 3), Block.getBlockById(95).getStateFromMeta(3), 2);
		world.setBlockState(new BlockPos(i + 7, j + 4, k + 3), Block.getBlockById(95).getStateFromMeta(3), 2);
		world.setBlockState(new BlockPos(i + 8, j + 4, k + 3), Block.getBlockById(9).getStateFromMeta(0), 2);
		world.setBlockState(new BlockPos(i + 9, j + 4, k + 3), Block.getBlockById(9).getStateFromMeta(0), 2);
		world.setBlockState(new BlockPos(i + 10, j + 4, k + 3), Block.getBlockById(9).getStateFromMeta(0), 2);
		world.setBlockState(new BlockPos(i + 0, j + 4, k + 4), Block.getBlockById(9).getStateFromMeta(0), 2);
		world.setBlockState(new BlockPos(i + 1, j + 4, k + 4), Block.getBlockById(9).getStateFromMeta(0), 2);
		world.setBlockState(new BlockPos(i + 2, j + 4, k + 4), Block.getBlockById(9).getStateFromMeta(0), 2);
		world.setBlockState(new BlockPos(i + 3, j + 4, k + 4), Block.getBlockById(95).getStateFromMeta(3), 2);
		world.setBlockState(new BlockPos(i + 4, j + 4, k + 4), Block.getBlockById(95).getStateFromMeta(3), 2);
		world.setBlockState(new BlockPos(i + 5, j + 4, k + 4), Block.getBlockById(95).getStateFromMeta(3), 2);
		world.setBlockState(new BlockPos(i + 6, j + 4, k + 4), Block.getBlockById(95).getStateFromMeta(3), 2);
		world.setBlockState(new BlockPos(i + 7, j + 4, k + 4), Block.getBlockById(95).getStateFromMeta(3), 2);
		world.setBlockState(new BlockPos(i + 8, j + 4, k + 4), Block.getBlockById(9).getStateFromMeta(0), 2);
		world.setBlockState(new BlockPos(i + 9, j + 4, k + 4), Block.getBlockById(9).getStateFromMeta(0), 2);
		world.setBlockState(new BlockPos(i + 10, j + 4, k + 4), Block.getBlockById(9).getStateFromMeta(0), 2);
		world.setBlockState(new BlockPos(i + 0, j + 4, k + 5), Block.getBlockById(9).getStateFromMeta(0), 2);
		world.setBlockState(new BlockPos(i + 1, j + 4, k + 5), Block.getBlockById(9).getStateFromMeta(0), 2);
		world.setBlockState(new BlockPos(i + 2, j + 4, k + 5), Block.getBlockById(9).getStateFromMeta(0), 2);
		world.setBlockState(new BlockPos(i + 3, j + 4, k + 5), Block.getBlockById(95).getStateFromMeta(3), 2);
		world.setBlockState(new BlockPos(i + 4, j + 4, k + 5), Block.getBlockById(95).getStateFromMeta(3), 2);
		world.setBlockState(new BlockPos(i + 5, j + 4, k + 5), Block.getBlockById(95).getStateFromMeta(3), 2);
		world.setBlockState(new BlockPos(i + 6, j + 4, k + 5), Block.getBlockById(95).getStateFromMeta(3), 2);
		world.setBlockState(new BlockPos(i + 7, j + 4, k + 5), Block.getBlockById(95).getStateFromMeta(3), 2);
		world.setBlockState(new BlockPos(i + 8, j + 4, k + 5), Block.getBlockById(9).getStateFromMeta(0), 2);
		world.setBlockState(new BlockPos(i + 9, j + 4, k + 5), Block.getBlockById(9).getStateFromMeta(0), 2);
		world.setBlockState(new BlockPos(i + 10, j + 4, k + 5), Block.getBlockById(9).getStateFromMeta(0), 2);
