package net.modjam5.makercommunity.common.world.structure;

import net.minecraft.block.Block;
import net.minecraft.util.math.BlockPos;
import net.minecraft.world.World;

/**
 * @author Tim Biesenbeek
 */
public class VillageStructure1 {

    @SuppressWarnings("deprecation")
    public static void gen(World world, int i, int j, int k){
        world.setBlockState(new BlockPos(i + 10, j + 0, k + 9), Block.getBlockById(160).getStateFromMeta(0), 2);
        world.setBlockState(new BlockPos(i + 9, j + 0, k + 10), Block.getBlockById(160).getStateFromMeta(0), 2);
        world.setBlockState(new BlockPos(i + 8, j + 1, k + 9), Block.getBlockById(160).getStateFromMeta(4), 2);
        world.setBlockState(new BlockPos(i + 9, j + 1, k + 9), Block.getBlockById(160).getStateFromMeta(4), 2);
        world.setBlockState(new BlockPos(i + 8, j + 1, k + 10), Block.getBlockById(160).getStateFromMeta(0), 2);
        world.setBlockState(new BlockPos(i + 9, j + 1, k + 10), Block.getBlockById(95).getStateFromMeta(4), 2);
        world.setBlockState(new BlockPos(i + 10, j + 1, k + 10), Block.getBlockById(160).getStateFromMeta(4), 2);
        world.setBlockState(new BlockPos(i + 9, j + 1, k + 11), Block.getBlockById(160).getStateFromMeta(4), 2);
        world.setBlockState(new BlockPos(i + 8, j + 2, k + 9), Block.getBlockById(160).getStateFromMeta(1), 2);
        world.setBlockState(new BlockPos(i + 9, j + 2, k + 9), Block.getBlockById(160).getStateFromMeta(1), 2);
        world.setBlockState(new BlockPos(i + 10, j + 2, k + 9), Block.getBlockById(160).getStateFromMeta(4), 2);
        world.setBlockState(new BlockPos(i + 7, j + 2, k + 10), Block.getBlockById(160).getStateFromMeta(1), 2);
        world.setBlockState(new BlockPos(i + 8, j + 2, k + 10), Block.getBlockById(95).getStateFromMeta(4), 2);
        world.setBlockState(new BlockPos(i + 9, j + 2, k + 10), Block.getBlockById(95).getStateFromMeta(1), 2);
        world.setBlockState(new BlockPos(i + 10, j + 2, k + 10), Block.getBlockById(160).getStateFromMeta(1), 2);
        world.setBlockState(new BlockPos(i + 8, j + 2, k + 11), Block.getBlockById(160).getStateFromMeta(1), 2);
        world.setBlockState(new BlockPos(i + 9, j + 2, k + 11), Block.getBlockById(95).getStateFromMeta(4), 2);
        world.setBlockState(new BlockPos(i + 9, j + 2, k + 12), Block.getBlockById(160).getStateFromMeta(1), 2);
        world.setBlockState(new BlockPos(i + 4, j + 3, k + 4), Block.getBlockById(1).getStateFromMeta(0), 2);
        world.setBlockState(new BlockPos(i + 7, j + 3, k + 4), Block.getBlockById(1).getStateFromMeta(0), 2);
        world.setBlockState(new BlockPos(i + 8, j + 3, k + 4), Block.getBlockById(1).getStateFromMeta(0), 2);
        world.setBlockState(new BlockPos(i + 3, j + 3, k + 5), Block.getBlockById(1).getStateFromMeta(0), 2);
        world.setBlockState(new BlockPos(i + 6, j + 3, k + 5), Block.getBlockById(1).getStateFromMeta(0), 2);
        world.setBlockState(new BlockPos(i + 10, j + 3, k + 5), Block.getBlockById(1).getStateFromMeta(0), 2);
        world.setBlockState(new BlockPos(i + 12, j + 3, k + 5), Block.getBlockById(1).getStateFromMeta(0), 2);
        world.setBlockState(new BlockPos(i + 4, j + 3, k + 6), Block.getBlockById(1).getStateFromMeta(0), 2);
        world.setBlockState(new BlockPos(i + 8, j + 3, k + 6), Block.getBlockById(1).getStateFromMeta(0), 2);
        world.setBlockState(new BlockPos(i + 13, j + 3, k + 6), Block.getBlockById(1).getStateFromMeta(0), 2);
        world.setBlockState(new BlockPos(i + 14, j + 3, k + 6), Block.getBlockById(1).getStateFromMeta(0), 2);
        world.setBlockState(new BlockPos(i + 3, j + 3, k + 7), Block.getBlockById(1).getStateFromMeta(0), 2);
        world.setBlockState(new BlockPos(i + 10, j + 3, k + 7), Block.getBlockById(160).getStateFromMeta(14), 2);
        world.setBlockState(new BlockPos(i + 2, j + 3, k + 8), Block.getBlockById(1).getStateFromMeta(0), 2);
        world.setBlockState(new BlockPos(i + 4, j + 3, k + 8), Block.getBlockById(1).getStateFromMeta(0), 2);
        world.setBlockState(new BlockPos(i + 10, j + 3, k + 8), Block.getBlockById(95).getStateFromMeta(4), 2);
        world.setBlockState(new BlockPos(i + 11, j + 3, k + 8), Block.getBlockById(160).getStateFromMeta(4), 2);
        world.setBlockState(new BlockPos(i + 15, j + 3, k + 8), Block.getBlockById(1).getStateFromMeta(0), 2);
        world.setBlockState(new BlockPos(i + 2, j + 3, k + 9), Block.getBlockById(1).getStateFromMeta(0), 2);
        world.setBlockState(new BlockPos(i + 3, j + 3, k + 9), Block.getBlockById(1).getStateFromMeta(0), 2);
        world.setBlockState(new BlockPos(i + 7, j + 3, k + 9), Block.getBlockById(160).getStateFromMeta(14), 2);
        world.setBlockState(new BlockPos(i + 8, j + 3, k + 9), Block.getBlockById(95).getStateFromMeta(4), 2);
        world.setBlockState(new BlockPos(i + 9, j + 3, k + 9), Block.getBlockById(95).getStateFromMeta(4), 2);
        world.setBlockState(new BlockPos(i + 10, j + 3, k + 9), Block.getBlockById(95).getStateFromMeta(4), 2);
        world.setBlockState(new BlockPos(i + 11, j + 3, k + 9), Block.getBlockById(160).getStateFromMeta(14), 2);
        world.setBlockState(new BlockPos(i + 13, j + 3, k + 9), Block.getBlockById(1).getStateFromMeta(0), 2);
        world.setBlockState(new BlockPos(i + 16, j + 3, k + 9), Block.getBlockById(1).getStateFromMeta(0), 2);
        world.setBlockState(new BlockPos(i + 3, j + 3, k + 10), Block.getBlockById(1).getStateFromMeta(0), 2);
        world.setBlockState(new BlockPos(i + 7, j + 3, k + 10), Block.getBlockById(160).getStateFromMeta(14), 2);
        world.setBlockState(new BlockPos(i + 8, j + 3, k + 10), Block.getBlockById(95).getStateFromMeta(1), 2);
        world.setBlockState(new BlockPos(i + 10, j + 3, k + 10), Block.getBlockById(95).getStateFromMeta(4), 2);
        world.setBlockState(new BlockPos(i + 8, j + 3, k + 11), Block.getBlockById(95).getStateFromMeta(4), 2);
        world.setBlockState(new BlockPos(i + 9, j + 3, k + 11), Block.getBlockById(95).getStateFromMeta(4), 2);
        world.setBlockState(new BlockPos(i + 10, j + 3, k + 11), Block.getBlockById(95).getStateFromMeta(4), 2);
        world.setBlockState(new BlockPos(i + 11, j + 3, k + 11), Block.getBlockById(160).getStateFromMeta(14), 2);
        world.setBlockState(new BlockPos(i + 14, j + 3, k + 11), Block.getBlockById(1).getStateFromMeta(0), 2);
        world.setBlockState(new BlockPos(i + 15, j + 3, k + 11), Block.getBlockById(1).getStateFromMeta(0), 2);
        world.setBlockState(new BlockPos(i + 4, j + 3, k + 12), Block.getBlockById(1).getStateFromMeta(0), 2);
        world.setBlockState(new BlockPos(i + 14, j + 3, k + 12), Block.getBlockById(1).getStateFromMeta(0), 2);
        world.setBlockState(new BlockPos(i + 3, j + 3, k + 13), Block.getBlockById(1).getStateFromMeta(0), 2);
        world.setBlockState(new BlockPos(i + 14, j + 3, k + 13), Block.getBlockById(1).getStateFromMeta(0), 2);
        world.setBlockState(new BlockPos(i + 3, j + 3, k + 14), Block.getBlockById(1).getStateFromMeta(0), 2);
        world.setBlockState(new BlockPos(i + 14, j + 3, k + 14), Block.getBlockById(1).getStateFromMeta(0), 2);
        world.setBlockState(new BlockPos(i + 5, j + 3, k + 15), Block.getBlockById(1).getStateFromMeta(0), 2);
        world.setBlockState(new BlockPos(i + 8, j + 3, k + 15), Block.getBlockById(1).getStateFromMeta(0), 2);
        world.setBlockState(new BlockPos(i + 12, j + 3, k + 15), Block.getBlockById(1).getStateFromMeta(0), 2);
        world.setBlockState(new BlockPos(i + 7, j + 3, k + 16), Block.getBlockById(1).getStateFromMeta(0), 2);
        world.setBlockState(new BlockPos(i + 9, j + 3, k + 16), Block.getBlockById(1).getStateFromMeta(0), 2);
        world.setBlockState(new BlockPos(i + 6, j + 3, k + 17), Block.getBlockById(1).getStateFromMeta(0), 2);
        world.setBlockState(new BlockPos(i + 7, j + 4, k + 2), Block.getBlockById(1).getStateFromMeta(0), 2);
        world.setBlockState(new BlockPos(i + 4, j + 4, k + 3), Block.getBlockById(1).getStateFromMeta(0), 2);
        world.setBlockState(new BlockPos(i + 5, j + 4, k + 3), Block.getBlockById(1).getStateFromMeta(0), 2);
        world.setBlockState(new BlockPos(i + 6, j + 4, k + 3), Block.getBlockById(1).getStateFromMeta(0), 2);
        world.setBlockState(new BlockPos(i + 7, j + 4, k + 3), Block.getBlockById(1).getStateFromMeta(0), 2);
        world.setBlockState(new BlockPos(i + 8, j + 4, k + 3), Block.getBlockById(1).getStateFromMeta(0), 2);
        world.setBlockState(new BlockPos(i + 3, j + 4, k + 4), Block.getBlockById(1).getStateFromMeta(0), 2);
        world.setBlockState(new BlockPos(i + 4, j + 4, k + 4), Block.getBlockById(1).getStateFromMeta(0), 2);
        world.setBlockState(new BlockPos(i + 6, j + 4, k + 4), Block.getBlockById(1).getStateFromMeta(0), 2);
        world.setBlockState(new BlockPos(i + 7, j + 4, k + 4), Block.getBlockById(1).getStateFromMeta(0), 2);
        world.setBlockState(new BlockPos(i + 8, j + 4, k + 4), Block.getBlockById(1).getStateFromMeta(0), 2);
        world.setBlockState(new BlockPos(i + 9, j + 4, k + 4), Block.getBlockById(1).getStateFromMeta(0), 2);
        world.setBlockState(new BlockPos(i + 10, j + 4, k + 4), Block.getBlockById(1).getStateFromMeta(0), 2);
        world.setBlockState(new BlockPos(i + 11, j + 4, k + 4), Block.getBlockById(1).getStateFromMeta(0), 2);
        world.setBlockState(new BlockPos(i + 12, j + 4, k + 4), Block.getBlockById(1).getStateFromMeta(0), 2);
        world.setBlockState(new BlockPos(i + 3, j + 4, k + 5), Block.getBlockById(1).getStateFromMeta(0), 2);
        world.setBlockState(new BlockPos(i + 4, j + 4, k + 5), Block.getBlockById(1).getStateFromMeta(0), 2);
        world.setBlockState(new BlockPos(i + 6, j + 4, k + 5), Block.getBlockById(1).getStateFromMeta(0), 2);
        world.setBlockState(new BlockPos(i + 7, j + 4, k + 5), Block.getBlockById(1).getStateFromMeta(0), 2);
        world.setBlockState(new BlockPos(i + 8, j + 4, k + 5), Block.getBlockById(1).getStateFromMeta(0), 2);
        world.setBlockState(new BlockPos(i + 9, j + 4, k + 5), Block.getBlockById(1).getStateFromMeta(0), 2);
        world.setBlockState(new BlockPos(i + 10, j + 4, k + 5), Block.getBlockById(1).getStateFromMeta(0), 2);
        world.setBlockState(new BlockPos(i + 11, j + 4, k + 5), Block.getBlockById(1).getStateFromMeta(0), 2);
        world.setBlockState(new BlockPos(i + 12, j + 4, k + 5), Block.getBlockById(1).getStateFromMeta(0), 2);
        world.setBlockState(new BlockPos(i + 13, j + 4, k + 5), Block.getBlockById(1).getStateFromMeta(0), 2);
        world.setBlockState(new BlockPos(i + 2, j + 4, k + 6), Block.getBlockById(1).getStateFromMeta(0), 2);
        world.setBlockState(new BlockPos(i + 3, j + 4, k + 6), Block.getBlockById(1).getStateFromMeta(0), 2);
        world.setBlockState(new BlockPos(i + 4, j + 4, k + 6), Block.getBlockById(1).getStateFromMeta(0), 2);
        world.setBlockState(new BlockPos(i + 5, j + 4, k + 6), Block.getBlockById(1).getStateFromMeta(0), 2);
        world.setBlockState(new BlockPos(i + 6, j + 4, k + 6), Block.getBlockById(1).getStateFromMeta(0), 2);
        world.setBlockState(new BlockPos(i + 7, j + 4, k + 6), Block.getBlockById(1).getStateFromMeta(0), 2);
        world.setBlockState(new BlockPos(i + 8, j + 4, k + 6), Block.getBlockById(1).getStateFromMeta(0), 2);
        world.setBlockState(new BlockPos(i + 10, j + 4, k + 6), Block.getBlockById(1).getStateFromMeta(0), 2);
        world.setBlockState(new BlockPos(i + 11, j + 4, k + 6), Block.getBlockById(1).getStateFromMeta(0), 2);
        world.setBlockState(new BlockPos(i + 12, j + 4, k + 6), Block.getBlockById(1).getStateFromMeta(0), 2);
        world.setBlockState(new BlockPos(i + 13, j + 4, k + 6), Block.getBlockById(1).getStateFromMeta(0), 2);
        world.setBlockState(new BlockPos(i + 14, j + 4, k + 6), Block.getBlockById(1).getStateFromMeta(0), 2);
        world.setBlockState(new BlockPos(i + 15, j + 4, k + 6), Block.getBlockById(1).getStateFromMeta(0), 2);
        world.setBlockState(new BlockPos(i + 2, j + 4, k + 7), Block.getBlockById(1).getStateFromMeta(0), 2);
        world.setBlockState(new BlockPos(i + 3, j + 4, k + 7), Block.getBlockById(1).getStateFromMeta(0), 2);
        world.setBlockState(new BlockPos(i + 4, j + 4, k + 7), Block.getBlockById(1).getStateFromMeta(0), 2);
        world.setBlockState(new BlockPos(i + 5, j + 4, k + 7), Block.getBlockById(1).getStateFromMeta(0), 2);
        world.setBlockState(new BlockPos(i + 10, j + 4, k + 7), Block.getBlockById(95).getStateFromMeta(1), 2);
        world.setBlockState(new BlockPos(i + 14, j + 4, k + 7), Block.getBlockById(1).getStateFromMeta(0), 2);
        world.setBlockState(new BlockPos(i + 15, j + 4, k + 7), Block.getBlockById(1).getStateFromMeta(0), 2);
        world.setBlockState(new BlockPos(i + 2, j + 4, k + 8), Block.getBlockById(1).getStateFromMeta(0), 2);
        world.setBlockState(new BlockPos(i + 3, j + 4, k + 8), Block.getBlockById(1).getStateFromMeta(0), 2);
        world.setBlockState(new BlockPos(i + 4, j + 4, k + 8), Block.getBlockById(1).getStateFromMeta(0), 2);
        world.setBlockState(new BlockPos(i + 5, j + 4, k + 8), Block.getBlockById(1).getStateFromMeta(0), 2);
        world.setBlockState(new BlockPos(i + 9, j + 4, k + 8), Block.getBlockById(95).getStateFromMeta(1), 2);
        world.setBlockState(new BlockPos(i + 10, j + 4, k + 8), Block.getBlockById(95).getStateFromMeta(1), 2);
        world.setBlockState(new BlockPos(i + 11, j + 4, k + 8), Block.getBlockById(160).getStateFromMeta(14), 2);
        world.setBlockState(new BlockPos(i + 13, j + 4, k + 8), Block.getBlockById(1).getStateFromMeta(0), 2);
        world.setBlockState(new BlockPos(i + 14, j + 4, k + 8), Block.getBlockById(1).getStateFromMeta(0), 2);
        world.setBlockState(new BlockPos(i + 15, j + 4, k + 8), Block.getBlockById(1).getStateFromMeta(0), 2);
        world.setBlockState(new BlockPos(i + 2, j + 4, k + 9), Block.getBlockById(1).getStateFromMeta(0), 2);
        world.setBlockState(new BlockPos(i + 3, j + 4, k + 9), Block.getBlockById(1).getStateFromMeta(0), 2);
        world.setBlockState(new BlockPos(i + 4, j + 4, k + 9), Block.getBlockById(1).getStateFromMeta(0), 2);
        world.setBlockState(new BlockPos(i + 7, j + 4, k + 9), Block.getBlockById(95).getStateFromMeta(1), 2);
        world.setBlockState(new BlockPos(i + 8, j + 4, k + 9), Block.getBlockById(95).getStateFromMeta(1), 2);
        world.setBlockState(new BlockPos(i + 9, j + 4, k + 9), Block.getBlockById(95).getStateFromMeta(1), 2);
        world.setBlockState(new BlockPos(i + 10, j + 4, k + 9), Block.getBlockById(95).getStateFromMeta(1), 2);
        world.setBlockState(new BlockPos(i + 11, j + 4, k + 9), Block.getBlockById(95).getStateFromMeta(1), 2);
        world.setBlockState(new BlockPos(i + 13, j + 4, k + 9), Block.getBlockById(1).getStateFromMeta(0), 2);
        world.setBlockState(new BlockPos(i + 14, j + 4, k + 9), Block.getBlockById(1).getStateFromMeta(0), 2);
        world.setBlockState(new BlockPos(i + 15, j + 4, k + 9), Block.getBlockById(1).getStateFromMeta(0), 2);
        world.setBlockState(new BlockPos(i + 2, j + 4, k + 10), Block.getBlockById(1).getStateFromMeta(0), 2);
        world.setBlockState(new BlockPos(i + 3, j + 4, k + 10), Block.getBlockById(1).getStateFromMeta(0), 2);
        world.setBlockState(new BlockPos(i + 4, j + 4, k + 10), Block.getBlockById(1).getStateFromMeta(0), 2);
        world.setBlockState(new BlockPos(i + 7, j + 4, k + 10), Block.getBlockById(95).getStateFromMeta(1), 2);
        world.setBlockState(new BlockPos(i + 8, j + 4, k + 10), Block.getBlockById(95).getStateFromMeta(1), 2);
        world.setBlockState(new BlockPos(i + 9, j + 4, k + 10), Block.getBlockById(95).getStateFromMeta(1), 2);
        world.setBlockState(new BlockPos(i + 10, j + 4, k + 10), Block.getBlockById(95).getStateFromMeta(1), 2);
        world.setBlockState(new BlockPos(i + 11, j + 4, k + 10), Block.getBlockById(95).getStateFromMeta(1), 2);
        world.setBlockState(new BlockPos(i + 14, j + 4, k + 10), Block.getBlockById(1).getStateFromMeta(0), 2);
        world.setBlockState(new BlockPos(i + 15, j + 4, k + 10), Block.getBlockById(1).getStateFromMeta(0), 2);
        world.setBlockState(new BlockPos(i + 3, j + 4, k + 11), Block.getBlockById(1).getStateFromMeta(0), 2);
        world.setBlockState(new BlockPos(i + 4, j + 4, k + 11), Block.getBlockById(1).getStateFromMeta(0), 2);
        world.setBlockState(new BlockPos(i + 8, j + 4, k + 11), Block.getBlockById(95).getStateFromMeta(1), 2);
        world.setBlockState(new BlockPos(i + 9, j + 4, k + 11), Block.getBlockById(95).getStateFromMeta(1), 2);
        world.setBlockState(new BlockPos(i + 10, j + 4, k + 11), Block.getBlockById(95).getStateFromMeta(1), 2);
        world.setBlockState(new BlockPos(i + 11, j + 4, k + 11), Block.getBlockById(160).getStateFromMeta(14), 2);
        world.setBlockState(new BlockPos(i + 14, j + 4, k + 11), Block.getBlockById(1).getStateFromMeta(0), 2);
        world.setBlockState(new BlockPos(i + 15, j + 4, k + 11), Block.getBlockById(1).getStateFromMeta(0), 2);
        world.setBlockState(new BlockPos(i + 3, j + 4, k + 12), Block.getBlockById(1).getStateFromMeta(0), 2);
        world.setBlockState(new BlockPos(i + 4, j + 4, k + 12), Block.getBlockById(1).getStateFromMeta(0), 2);
        world.setBlockState(new BlockPos(i + 9, j + 4, k + 12), Block.getBlockById(160).getStateFromMeta(14), 2);
        world.setBlockState(new BlockPos(i + 13, j + 4, k + 12), Block.getBlockById(1).getStateFromMeta(0), 2);
        world.setBlockState(new BlockPos(i + 14, j + 4, k + 12), Block.getBlockById(1).getStateFromMeta(0), 2);
        world.setBlockState(new BlockPos(i + 15, j + 4, k + 12), Block.getBlockById(1).getStateFromMeta(0), 2);
        world.setBlockState(new BlockPos(i + 2, j + 4, k + 13), Block.getBlockById(1).getStateFromMeta(0), 2);
        world.setBlockState(new BlockPos(i + 3, j + 4, k + 13), Block.getBlockById(1).getStateFromMeta(0), 2);
        world.setBlockState(new BlockPos(i + 4, j + 4, k + 13), Block.getBlockById(1).getStateFromMeta(0), 2);
        world.setBlockState(new BlockPos(i + 12, j + 4, k + 13), Block.getBlockById(1).getStateFromMeta(0), 2);
        world.setBlockState(new BlockPos(i + 14, j + 4, k + 13), Block.getBlockById(1).getStateFromMeta(0), 2);
        world.setBlockState(new BlockPos(i + 15, j + 4, k + 13), Block.getBlockById(1).getStateFromMeta(0), 2);
        world.setBlockState(new BlockPos(i + 16, j + 4, k + 13), Block.getBlockById(1).getStateFromMeta(0), 2);
        world.setBlockState(new BlockPos(i + 2, j + 4, k + 14), Block.getBlockById(1).getStateFromMeta(0), 2);
        world.setBlockState(new BlockPos(i + 3, j + 4, k + 14), Block.getBlockById(1).getStateFromMeta(0), 2);
        world.setBlockState(new BlockPos(i + 4, j + 4, k + 14), Block.getBlockById(1).getStateFromMeta(0), 2);
        world.setBlockState(new BlockPos(i + 5, j + 4, k + 14), Block.getBlockById(1).getStateFromMeta(0), 2);
        world.setBlockState(new BlockPos(i + 7, j + 4, k + 14), Block.getBlockById(1).getStateFromMeta(0), 2);
        world.setBlockState(new BlockPos(i + 8, j + 4, k + 14), Block.getBlockById(1).getStateFromMeta(0), 2);
        world.setBlockState(new BlockPos(i + 11, j + 4, k + 14), Block.getBlockById(1).getStateFromMeta(0), 2);
        world.setBlockState(new BlockPos(i + 13, j + 4, k + 14), Block.getBlockById(1).getStateFromMeta(0), 2);
        world.setBlockState(new BlockPos(i + 14, j + 4, k + 14), Block.getBlockById(1).getStateFromMeta(0), 2);
        world.setBlockState(new BlockPos(i + 15, j + 4, k + 14), Block.getBlockById(1).getStateFromMeta(0), 2);
        world.setBlockState(new BlockPos(i + 3, j + 4, k + 15), Block.getBlockById(1).getStateFromMeta(0), 2);
        world.setBlockState(new BlockPos(i + 4, j + 4, k + 15), Block.getBlockById(1).getStateFromMeta(0), 2);
        world.setBlockState(new BlockPos(i + 5, j + 4, k + 15), Block.getBlockById(1).getStateFromMeta(0), 2);
        world.setBlockState(new BlockPos(i + 7, j + 4, k + 15), Block.getBlockById(1).getStateFromMeta(0), 2);
        world.setBlockState(new BlockPos(i + 8, j + 4, k + 15), Block.getBlockById(1).getStateFromMeta(0), 2);
        world.setBlockState(new BlockPos(i + 9, j + 4, k + 15), Block.getBlockById(1).getStateFromMeta(0), 2);
        world.setBlockState(new BlockPos(i + 11, j + 4, k + 15), Block.getBlockById(1).getStateFromMeta(0), 2);
        world.setBlockState(new BlockPos(i + 12, j + 4, k + 15), Block.getBlockById(1).getStateFromMeta(0), 2);
        world.setBlockState(new BlockPos(i + 13, j + 4, k + 15), Block.getBlockById(1).getStateFromMeta(0), 2);
        world.setBlockState(new BlockPos(i + 14, j + 4, k + 15), Block.getBlockById(1).getStateFromMeta(0), 2);
        world.setBlockState(new BlockPos(i + 15, j + 4, k + 15), Block.getBlockById(1).getStateFromMeta(0), 2);
        world.setBlockState(new BlockPos(i + 7, j + 4, k + 16), Block.getBlockById(1).getStateFromMeta(0), 2);
        world.setBlockState(new BlockPos(i + 8, j + 4, k + 16), Block.getBlockById(1).getStateFromMeta(0), 2);
        world.setBlockState(new BlockPos(i + 9, j + 4, k + 16), Block.getBlockById(1).getStateFromMeta(0), 2);
        world.setBlockState(new BlockPos(i + 10, j + 4, k + 16), Block.getBlockById(1).getStateFromMeta(0), 2);
        world.setBlockState(new BlockPos(i + 12, j + 4, k + 16), Block.getBlockById(1).getStateFromMeta(0), 2);
        world.setBlockState(new BlockPos(i + 13, j + 4, k + 16), Block.getBlockById(1).getStateFromMeta(0), 2);
        world.setBlockState(new BlockPos(i + 5, j + 4, k + 17), Block.getBlockById(1).getStateFromMeta(0), 2);
        world.setBlockState(new BlockPos(i + 9, j + 4, k + 17), Block.getBlockById(1).getStateFromMeta(0), 2);
        world.setBlockState(new BlockPos(i + 10, j + 4, k + 17), Block.getBlockById(1).getStateFromMeta(0), 2);
        world.setBlockState(new BlockPos(i + 11, j + 4, k + 17), Block.getBlockById(1).getStateFromMeta(0), 2);
        world.setBlockState(new BlockPos(i + 12, j + 4, k + 17), Block.getBlockById(1).getStateFromMeta(0), 2);
        world.setBlockState(new BlockPos(i + 6, j + 5, k + 2), Block.getBlockById(1).getStateFromMeta(0), 2);
        world.setBlockState(new BlockPos(i + 7, j + 5, k + 2), Block.getBlockById(1).getStateFromMeta(0), 2);
        world.setBlockState(new BlockPos(i + 3, j + 5, k + 3), Block.getBlockById(1).getStateFromMeta(0), 2);
        world.setBlockState(new BlockPos(i + 4, j + 5, k + 3), Block.getBlockById(1).getStateFromMeta(0), 2);
        world.setBlockState(new BlockPos(i + 5, j + 5, k + 3), Block.getBlockById(1).getStateFromMeta(0), 2);
        world.setBlockState(new BlockPos(i + 6, j + 5, k + 3), Block.getBlockById(1).getStateFromMeta(0), 2);
        world.setBlockState(new BlockPos(i + 7, j + 5, k + 3), Block.getBlockById(1).getStateFromMeta(0), 2);
        world.setBlockState(new BlockPos(i + 8, j + 5, k + 3), Block.getBlockById(1).getStateFromMeta(0), 2);
        world.setBlockState(new BlockPos(i + 9, j + 5, k + 3), Block.getBlockById(1).getStateFromMeta(0), 2);
        world.setBlockState(new BlockPos(i + 10, j + 5, k + 3), Block.getBlockById(1).getStateFromMeta(0), 2);
        world.setBlockState(new BlockPos(i + 11, j + 5, k + 3), Block.getBlockById(1).getStateFromMeta(0), 2);
        world.setBlockState(new BlockPos(i + 12, j + 5, k + 3), Block.getBlockById(1).getStateFromMeta(0), 2);
        world.setBlockState(new BlockPos(i + 3, j + 5, k + 4), Block.getBlockById(1).getStateFromMeta(0), 2);
        world.setBlockState(new BlockPos(i + 4, j + 5, k + 4), Block.getBlockById(1).getStateFromMeta(0), 2);
        world.setBlockState(new BlockPos(i + 5, j + 5, k + 4), Block.getBlockById(1).getStateFromMeta(0), 2);
        world.setBlockState(new BlockPos(i + 6, j + 5, k + 4), Block.getBlockById(1).getStateFromMeta(0), 2);
        world.setBlockState(new BlockPos(i + 7, j + 5, k + 4), Block.getBlockById(1).getStateFromMeta(0), 2);
        world.setBlockState(new BlockPos(i + 8, j + 5, k + 4), Block.getBlockById(1).getStateFromMeta(0), 2);
        world.setBlockState(new BlockPos(i + 9, j + 5, k + 4), Block.getBlockById(1).getStateFromMeta(0), 2);
        world.setBlockState(new BlockPos(i + 10, j + 5, k + 4), Block.getBlockById(1).getStateFromMeta(0), 2);
        world.setBlockState(new BlockPos(i + 11, j + 5, k + 4), Block.getBlockById(1).getStateFromMeta(0), 2);
        world.setBlockState(new BlockPos(i + 12, j + 5, k + 4), Block.getBlockById(1).getStateFromMeta(0), 2);
        world.setBlockState(new BlockPos(i + 2, j + 5, k + 5), Block.getBlockById(1).getStateFromMeta(0), 2);
        world.setBlockState(new BlockPos(i + 3, j + 5, k + 5), Block.getBlockById(1).getStateFromMeta(0), 2);
        world.setBlockState(new BlockPos(i + 4, j + 5, k + 5), Block.getBlockById(1).getStateFromMeta(0), 2);
        world.setBlockState(new BlockPos(i + 5, j + 5, k + 5), Block.getBlockById(1).getStateFromMeta(0), 2);
        world.setBlockState(new BlockPos(i + 6, j + 5, k + 5), Block.getBlockById(1).getStateFromMeta(0), 2);
        world.setBlockState(new BlockPos(i + 7, j + 5, k + 5), Block.getBlockById(1).getStateFromMeta(0), 2);
        world.setBlockState(new BlockPos(i + 8, j + 5, k + 5), Block.getBlockById(1).getStateFromMeta(0), 2);
        world.setBlockState(new BlockPos(i + 9, j + 5, k + 5), Block.getBlockById(1).getStateFromMeta(0), 2);
        world.setBlockState(new BlockPos(i + 10, j + 5, k + 5), Block.getBlockById(1).getStateFromMeta(0), 2);
        world.setBlockState(new BlockPos(i + 11, j + 5, k + 5), Block.getBlockById(1).getStateFromMeta(0), 2);
        world.setBlockState(new BlockPos(i + 12, j + 5, k + 5), Block.getBlockById(1).getStateFromMeta(0), 2);
        world.setBlockState(new BlockPos(i + 13, j + 5, k + 5), Block.getBlockById(1).getStateFromMeta(0), 2);
        world.setBlockState(new BlockPos(i + 14, j + 5, k + 5), Block.getBlockById(1).getStateFromMeta(0), 2);
        world.setBlockState(new BlockPos(i + 15, j + 5, k + 5), Block.getBlockById(1).getStateFromMeta(0), 2);
        world.setBlockState(new BlockPos(i + 2, j + 5, k + 6), Block.getBlockById(1).getStateFromMeta(0), 2);
        world.setBlockState(new BlockPos(i + 3, j + 5, k + 6), Block.getBlockById(1).getStateFromMeta(0), 2);
        world.setBlockState(new BlockPos(i + 4, j + 5, k + 6), Block.getBlockById(1).getStateFromMeta(0), 2);
        world.setBlockState(new BlockPos(i + 5, j + 5, k + 6), Block.getBlockById(1).getStateFromMeta(0), 2);
        world.setBlockState(new BlockPos(i + 6, j + 5, k + 6), Block.getBlockById(1).getStateFromMeta(0), 2);
        world.setBlockState(new BlockPos(i + 7, j + 5, k + 6), Block.getBlockById(1).getStateFromMeta(0), 2);
        world.setBlockState(new BlockPos(i + 8, j + 5, k + 6), Block.getBlockById(1).getStateFromMeta(0), 2);
        world.setBlockState(new BlockPos(i + 9, j + 5, k + 6), Block.getBlockById(1).getStateFromMeta(0), 2);
        world.setBlockState(new BlockPos(i + 10, j + 5, k + 6), Block.getBlockById(1).getStateFromMeta(0), 2);
        world.setBlockState(new BlockPos(i + 11, j + 5, k + 6), Block.getBlockById(1).getStateFromMeta(0), 2);
        world.setBlockState(new BlockPos(i + 12, j + 5, k + 6), Block.getBlockById(1).getStateFromMeta(0), 2);
        world.setBlockState(new BlockPos(i + 13, j + 5, k + 6), Block.getBlockById(1).getStateFromMeta(0), 2);
        world.setBlockState(new BlockPos(i + 14, j + 5, k + 6), Block.getBlockById(1).getStateFromMeta(0), 2);
        world.setBlockState(new BlockPos(i + 15, j + 5, k + 6), Block.getBlockById(1).getStateFromMeta(0), 2);
        world.setBlockState(new BlockPos(i + 2, j + 5, k + 7), Block.getBlockById(1).getStateFromMeta(0), 2);
        world.setBlockState(new BlockPos(i + 3, j + 5, k + 7), Block.getBlockById(1).getStateFromMeta(0), 2);
        world.setBlockState(new BlockPos(i + 4, j + 5, k + 7), Block.getBlockById(1).getStateFromMeta(0), 2);
        world.setBlockState(new BlockPos(i + 5, j + 5, k + 7), Block.getBlockById(1).getStateFromMeta(0), 2);
        world.setBlockState(new BlockPos(i + 6, j + 5, k + 7), Block.getBlockById(1).getStateFromMeta(0), 2);
        world.setBlockState(new BlockPos(i + 8, j + 5, k + 7), Block.getBlockById(44).getStateFromMeta(8), 2);
        world.setBlockState(new BlockPos(i + 9, j + 5, k + 7), Block.getBlockById(44).getStateFromMeta(8), 2);
        world.setBlockState(new BlockPos(i + 10, j + 5, k + 7), Block.getBlockById(44).getStateFromMeta(8), 2);
        world.setBlockState(new BlockPos(i + 12, j + 5, k + 7), Block.getBlockById(1).getStateFromMeta(0), 2);
        world.setBlockState(new BlockPos(i + 13, j + 5, k + 7), Block.getBlockById(1).getStateFromMeta(0), 2);
        world.setBlockState(new BlockPos(i + 14, j + 5, k + 7), Block.getBlockById(1).getStateFromMeta(0), 2);
        world.setBlockState(new BlockPos(i + 15, j + 5, k + 7), Block.getBlockById(1).getStateFromMeta(0), 2);
        world.setBlockState(new BlockPos(i + 1, j + 5, k + 8), Block.getBlockById(1).getStateFromMeta(0), 2);
        world.setBlockState(new BlockPos(i + 2, j + 5, k + 8), Block.getBlockById(1).getStateFromMeta(0), 2);
        world.setBlockState(new BlockPos(i + 3, j + 5, k + 8), Block.getBlockById(1).getStateFromMeta(0), 2);
        world.setBlockState(new BlockPos(i + 4, j + 5, k + 8), Block.getBlockById(1).getStateFromMeta(0), 2);
        world.setBlockState(new BlockPos(i + 5, j + 5, k + 8), Block.getBlockById(1).getStateFromMeta(0), 2);
        world.setBlockState(new BlockPos(i + 7, j + 5, k + 8), Block.getBlockById(44).getStateFromMeta(8), 2);
        world.setBlockState(new BlockPos(i + 8, j + 5, k + 8), Block.getBlockById(160).getStateFromMeta(14), 2);
        world.setBlockState(new BlockPos(i + 9, j + 5, k + 8), Block.getBlockById(95).getStateFromMeta(14), 2);
        world.setBlockState(new BlockPos(i + 10, j + 5, k + 8), Block.getBlockById(95).getStateFromMeta(1), 2);
        world.setBlockState(new BlockPos(i + 11, j + 5, k + 8), Block.getBlockById(44).getStateFromMeta(8), 2);
        world.setBlockState(new BlockPos(i + 13, j + 5, k + 8), Block.getBlockById(1).getStateFromMeta(0), 2);
        world.setBlockState(new BlockPos(i + 14, j + 5, k + 8), Block.getBlockById(1).getStateFromMeta(0), 2);
        world.setBlockState(new BlockPos(i + 15, j + 5, k + 8), Block.getBlockById(1).getStateFromMeta(0), 2);
        world.setBlockState(new BlockPos(i + 16, j + 5, k + 8), Block.getBlockById(1).getStateFromMeta(0), 2);
        world.setBlockState(new BlockPos(i + 2, j + 5, k + 9), Block.getBlockById(1).getStateFromMeta(0), 2);
        world.setBlockState(new BlockPos(i + 3, j + 5, k + 9), Block.getBlockById(1).getStateFromMeta(0), 2);
        world.setBlockState(new BlockPos(i + 4, j + 5, k + 9), Block.getBlockById(1).getStateFromMeta(0), 2);
        world.setBlockState(new BlockPos(i + 5, j + 5, k + 9), Block.getBlockById(1).getStateFromMeta(0), 2);
        world.setBlockState(new BlockPos(i + 6, j + 5, k + 9), Block.getBlockById(44).getStateFromMeta(8), 2);
        world.setBlockState(new BlockPos(i + 7, j + 5, k + 9), Block.getBlockById(95).getStateFromMeta(14), 2);
        world.setBlockState(new BlockPos(i + 8, j + 5, k + 9), Block.getBlockById(95).getStateFromMeta(14), 2);
        world.setBlockState(new BlockPos(i + 9, j + 5, k + 9), Block.getBlockById(95).getStateFromMeta(14), 2);
        world.setBlockState(new BlockPos(i + 10, j + 5, k + 9), Block.getBlockById(95).getStateFromMeta(14), 2);
        world.setBlockState(new BlockPos(i + 11, j + 5, k + 9), Block.getBlockById(95).getStateFromMeta(14), 2);
        world.setBlockState(new BlockPos(i + 12, j + 5, k + 9), Block.getBlockById(44).getStateFromMeta(8), 2);
        world.setBlockState(new BlockPos(i + 13, j + 5, k + 9), Block.getBlockById(1).getStateFromMeta(0), 2);
        world.setBlockState(new BlockPos(i + 14, j + 5, k + 9), Block.getBlockById(1).getStateFromMeta(0), 2);
        world.setBlockState(new BlockPos(i + 15, j + 5, k + 9), Block.getBlockById(1).getStateFromMeta(0), 2);
        world.setBlockState(new BlockPos(i + 16, j + 5, k + 9), Block.getBlockById(1).getStateFromMeta(0), 2);
        world.setBlockState(new BlockPos(i + 1, j + 5, k + 10), Block.getBlockById(1).getStateFromMeta(0), 2);
        world.setBlockState(new BlockPos(i + 2, j + 5, k + 10), Block.getBlockById(1).getStateFromMeta(0), 2);
        world.setBlockState(new BlockPos(i + 3, j + 5, k + 10), Block.getBlockById(1).getStateFromMeta(0), 2);
        world.setBlockState(new BlockPos(i + 4, j + 5, k + 10), Block.getBlockById(1).getStateFromMeta(0), 2);
        world.setBlockState(new BlockPos(i + 6, j + 5, k + 10), Block.getBlockById(44).getStateFromMeta(8), 2);
        world.setBlockState(new BlockPos(i + 7, j + 5, k + 10), Block.getBlockById(95).getStateFromMeta(14), 2);
        world.setBlockState(new BlockPos(i + 8, j + 5, k + 10), Block.getBlockById(95).getStateFromMeta(14), 2);
        world.setBlockState(new BlockPos(i + 9, j + 5, k + 10), Block.getBlockById(95).getStateFromMeta(14), 2);
        world.setBlockState(new BlockPos(i + 10, j + 5, k + 10), Block.getBlockById(95).getStateFromMeta(14), 2);
        world.setBlockState(new BlockPos(i + 11, j + 5, k + 10), Block.getBlockById(95).getStateFromMeta(14), 2);
        world.setBlockState(new BlockPos(i + 12, j + 5, k + 10), Block.getBlockById(44).getStateFromMeta(8), 2);
        world.setBlockState(new BlockPos(i + 14, j + 5, k + 10), Block.getBlockById(1).getStateFromMeta(0), 2);
        world.setBlockState(new BlockPos(i + 15, j + 5, k + 10), Block.getBlockById(1).getStateFromMeta(0), 2);
        world.setBlockState(new BlockPos(i + 16, j + 5, k + 10), Block.getBlockById(1).getStateFromMeta(0), 2);
        world.setBlockState(new BlockPos(i + 3, j + 5, k + 11), Block.getBlockById(1).getStateFromMeta(0), 2);
        world.setBlockState(new BlockPos(i + 4, j + 5, k + 11), Block.getBlockById(1).getStateFromMeta(0), 2);
        world.setBlockState(new BlockPos(i + 6, j + 5, k + 11), Block.getBlockById(44).getStateFromMeta(8), 2);
        world.setBlockState(new BlockPos(i + 7, j + 5, k + 11), Block.getBlockById(160).getStateFromMeta(14), 2);
        world.setBlockState(new BlockPos(i + 8, j + 5, k + 11), Block.getBlockById(95).getStateFromMeta(14), 2);
        world.setBlockState(new BlockPos(i + 9, j + 5, k + 11), Block.getBlockById(95).getStateFromMeta(14), 2);
        world.setBlockState(new BlockPos(i + 10, j + 5, k + 11), Block.getBlockById(95).getStateFromMeta(14), 2);
        world.setBlockState(new BlockPos(i + 11, j + 5, k + 11), Block.getBlockById(95).getStateFromMeta(1), 2);
        world.setBlockState(new BlockPos(i + 12, j + 5, k + 11), Block.getBlockById(44).getStateFromMeta(8), 2);
        world.setBlockState(new BlockPos(i + 13, j + 5, k + 11), Block.getBlockById(1).getStateFromMeta(0), 2);
        world.setBlockState(new BlockPos(i + 14, j + 5, k + 11), Block.getBlockById(1).getStateFromMeta(0), 2);
        world.setBlockState(new BlockPos(i + 15, j + 5, k + 11), Block.getBlockById(1).getStateFromMeta(0), 2);
        world.setBlockState(new BlockPos(i + 16, j + 5, k + 11), Block.getBlockById(1).getStateFromMeta(0), 2);
        world.setBlockState(new BlockPos(i + 2, j + 5, k + 12), Block.getBlockById(1).getStateFromMeta(0), 2);
        world.setBlockState(new BlockPos(i + 3, j + 5, k + 12), Block.getBlockById(1).getStateFromMeta(0), 2);
        world.setBlockState(new BlockPos(i + 4, j + 5, k + 12), Block.getBlockById(1).getStateFromMeta(0), 2);
        world.setBlockState(new BlockPos(i + 5, j + 5, k + 12), Block.getBlockById(1).getStateFromMeta(0), 2);
        world.setBlockState(new BlockPos(i + 7, j + 5, k + 12), Block.getBlockById(44).getStateFromMeta(8), 2);
        world.setBlockState(new BlockPos(i + 8, j + 5, k + 12), Block.getBlockById(95).getStateFromMeta(1), 2);
        world.setBlockState(new BlockPos(i + 9, j + 5, k + 12), Block.getBlockById(95).getStateFromMeta(14), 2);
        world.setBlockState(new BlockPos(i + 10, j + 5, k + 12), Block.getBlockById(95).getStateFromMeta(1), 2);
        world.setBlockState(new BlockPos(i + 11, j + 5, k + 12), Block.getBlockById(44).getStateFromMeta(8), 2);
        world.setBlockState(new BlockPos(i + 13, j + 5, k + 12), Block.getBlockById(1).getStateFromMeta(0), 2);
        world.setBlockState(new BlockPos(i + 14, j + 5, k + 12), Block.getBlockById(1).getStateFromMeta(0), 2);
        world.setBlockState(new BlockPos(i + 15, j + 5, k + 12), Block.getBlockById(1).getStateFromMeta(0), 2);
        world.setBlockState(new BlockPos(i + 16, j + 5, k + 12), Block.getBlockById(1).getStateFromMeta(0), 2);
        world.setBlockState(new BlockPos(i + 2, j + 5, k + 13), Block.getBlockById(1).getStateFromMeta(0), 2);
        world.setBlockState(new BlockPos(i + 3, j + 5, k + 13), Block.getBlockById(1).getStateFromMeta(0), 2);
        world.setBlockState(new BlockPos(i + 4, j + 5, k + 13), Block.getBlockById(1).getStateFromMeta(0), 2);
        world.setBlockState(new BlockPos(i + 5, j + 5, k + 13), Block.getBlockById(1).getStateFromMeta(0), 2);
        world.setBlockState(new BlockPos(i + 8, j + 5, k + 13), Block.getBlockById(44).getStateFromMeta(8), 2);
        world.setBlockState(new BlockPos(i + 9, j + 5, k + 13), Block.getBlockById(44).getStateFromMeta(8), 2);
        world.setBlockState(new BlockPos(i + 10, j + 5, k + 13), Block.getBlockById(44).getStateFromMeta(8), 2);
        world.setBlockState(new BlockPos(i + 12, j + 5, k + 13), Block.getBlockById(1).getStateFromMeta(0), 2);
        world.setBlockState(new BlockPos(i + 13, j + 5, k + 13), Block.getBlockById(1).getStateFromMeta(0), 2);
        world.setBlockState(new BlockPos(i + 14, j + 5, k + 13), Block.getBlockById(1).getStateFromMeta(0), 2);
        world.setBlockState(new BlockPos(i + 15, j + 5, k + 13), Block.getBlockById(1).getStateFromMeta(0), 2);
        world.setBlockState(new BlockPos(i + 16, j + 5, k + 13), Block.getBlockById(1).getStateFromMeta(0), 2);
        world.setBlockState(new BlockPos(i + 1, j + 5, k + 14), Block.getBlockById(1).getStateFromMeta(0), 2);
        world.setBlockState(new BlockPos(i + 2, j + 5, k + 14), Block.getBlockById(1).getStateFromMeta(0), 2);
        world.setBlockState(new BlockPos(i + 3, j + 5, k + 14), Block.getBlockById(1).getStateFromMeta(0), 2);
        world.setBlockState(new BlockPos(i + 4, j + 5, k + 14), Block.getBlockById(1).getStateFromMeta(0), 2);
        world.setBlockState(new BlockPos(i + 5, j + 5, k + 14), Block.getBlockById(1).getStateFromMeta(0), 2);
        world.setBlockState(new BlockPos(i + 6, j + 5, k + 14), Block.getBlockById(1).getStateFromMeta(0), 2);
        world.setBlockState(new BlockPos(i + 7, j + 5, k + 14), Block.getBlockById(1).getStateFromMeta(0), 2);
        world.setBlockState(new BlockPos(i + 8, j + 5, k + 14), Block.getBlockById(1).getStateFromMeta(0), 2);
        world.setBlockState(new BlockPos(i + 11, j + 5, k + 14), Block.getBlockById(1).getStateFromMeta(0), 2);
        world.setBlockState(new BlockPos(i + 12, j + 5, k + 14), Block.getBlockById(1).getStateFromMeta(0), 2);
        world.setBlockState(new BlockPos(i + 13, j + 5, k + 14), Block.getBlockById(1).getStateFromMeta(0), 2);
        world.setBlockState(new BlockPos(i + 14, j + 5, k + 14), Block.getBlockById(1).getStateFromMeta(0), 2);
        world.setBlockState(new BlockPos(i + 15, j + 5, k + 14), Block.getBlockById(1).getStateFromMeta(0), 2);
        world.setBlockState(new BlockPos(i + 16, j + 5, k + 14), Block.getBlockById(1).getStateFromMeta(0), 2);
        world.setBlockState(new BlockPos(i + 2, j + 5, k + 15), Block.getBlockById(1).getStateFromMeta(0), 2);
        world.setBlockState(new BlockPos(i + 3, j + 5, k + 15), Block.getBlockById(1).getStateFromMeta(0), 2);
        world.setBlockState(new BlockPos(i + 4, j + 5, k + 15), Block.getBlockById(1).getStateFromMeta(0), 2);
        world.setBlockState(new BlockPos(i + 5, j + 5, k + 15), Block.getBlockById(1).getStateFromMeta(0), 2);
        world.setBlockState(new BlockPos(i + 6, j + 5, k + 15), Block.getBlockById(1).getStateFromMeta(0), 2);
        world.setBlockState(new BlockPos(i + 7, j + 5, k + 15), Block.getBlockById(1).getStateFromMeta(0), 2);
        world.setBlockState(new BlockPos(i + 8, j + 5, k + 15), Block.getBlockById(1).getStateFromMeta(0), 2);
        world.setBlockState(new BlockPos(i + 9, j + 5, k + 15), Block.getBlockById(1).getStateFromMeta(0), 2);
        world.setBlockState(new BlockPos(i + 10, j + 5, k + 15), Block.getBlockById(1).getStateFromMeta(0), 2);
        world.setBlockState(new BlockPos(i + 11, j + 5, k + 15), Block.getBlockById(1).getStateFromMeta(0), 2);
        world.setBlockState(new BlockPos(i + 12, j + 5, k + 15), Block.getBlockById(1).getStateFromMeta(0), 2);
        world.setBlockState(new BlockPos(i + 13, j + 5, k + 15), Block.getBlockById(1).getStateFromMeta(0), 2);
        world.setBlockState(new BlockPos(i + 14, j + 5, k + 15), Block.getBlockById(1).getStateFromMeta(0), 2);
        world.setBlockState(new BlockPos(i + 15, j + 5, k + 15), Block.getBlockById(1).getStateFromMeta(0), 2);
        world.setBlockState(new BlockPos(i + 16, j + 5, k + 15), Block.getBlockById(1).getStateFromMeta(0), 2);
        world.setBlockState(new BlockPos(i + 4, j + 5, k + 16), Block.getBlockById(1).getStateFromMeta(0), 2);
        world.setBlockState(new BlockPos(i + 6, j + 5, k + 16), Block.getBlockById(1).getStateFromMeta(0), 2);
        world.setBlockState(new BlockPos(i + 7, j + 5, k + 16), Block.getBlockById(1).getStateFromMeta(0), 2);
        world.setBlockState(new BlockPos(i + 8, j + 5, k + 16), Block.getBlockById(1).getStateFromMeta(0), 2);
        world.setBlockState(new BlockPos(i + 9, j + 5, k + 16), Block.getBlockById(1).getStateFromMeta(0), 2);
        world.setBlockState(new BlockPos(i + 10, j + 5, k + 16), Block.getBlockById(1).getStateFromMeta(0), 2);
        world.setBlockState(new BlockPos(i + 11, j + 5, k + 16), Block.getBlockById(1).getStateFromMeta(0), 2);
        world.setBlockState(new BlockPos(i + 12, j + 5, k + 16), Block.getBlockById(1).getStateFromMeta(0), 2);
        world.setBlockState(new BlockPos(i + 13, j + 5, k + 16), Block.getBlockById(1).getStateFromMeta(0), 2);
        world.setBlockState(new BlockPos(i + 14, j + 5, k + 16), Block.getBlockById(1).getStateFromMeta(0), 2);
        world.setBlockState(new BlockPos(i + 4, j + 5, k + 17), Block.getBlockById(1).getStateFromMeta(0), 2);
        world.setBlockState(new BlockPos(i + 5, j + 5, k + 17), Block.getBlockById(1).getStateFromMeta(0), 2);
        world.setBlockState(new BlockPos(i + 6, j + 5, k + 17), Block.getBlockById(1).getStateFromMeta(0), 2);
        world.setBlockState(new BlockPos(i + 7, j + 5, k + 17), Block.getBlockById(1).getStateFromMeta(0), 2);
        world.setBlockState(new BlockPos(i + 8, j + 5, k + 17), Block.getBlockById(1).getStateFromMeta(0), 2);
        world.setBlockState(new BlockPos(i + 9, j + 5, k + 17), Block.getBlockById(1).getStateFromMeta(0), 2);
        world.setBlockState(new BlockPos(i + 10, j + 5, k + 17), Block.getBlockById(1).getStateFromMeta(0), 2);
        world.setBlockState(new BlockPos(i + 11, j + 5, k + 17), Block.getBlockById(1).getStateFromMeta(0), 2);
        world.setBlockState(new BlockPos(i + 12, j + 5, k + 17), Block.getBlockById(1).getStateFromMeta(0), 2);
        world.setBlockState(new BlockPos(i + 13, j + 5, k + 17), Block.getBlockById(1).getStateFromMeta(0), 2);
        world.setBlockState(new BlockPos(i + 4, j + 6, k + 2), Block.getBlockById(1).getStateFromMeta(0), 2);
        world.setBlockState(new BlockPos(i + 5, j + 6, k + 2), Block.getBlockById(1).getStateFromMeta(0), 2);
        world.setBlockState(new BlockPos(i + 6, j + 6, k + 2), Block.getBlockById(1).getStateFromMeta(0), 2);
        world.setBlockState(new BlockPos(i + 7, j + 6, k + 2), Block.getBlockById(1).getStateFromMeta(0), 2);
        world.setBlockState(new BlockPos(i + 8, j + 6, k + 2), Block.getBlockById(1).getStateFromMeta(0), 2);
        world.setBlockState(new BlockPos(i + 9, j + 6, k + 2), Block.getBlockById(1).getStateFromMeta(0), 2);
        world.setBlockState(new BlockPos(i + 10, j + 6, k + 2), Block.getBlockById(1).getStateFromMeta(0), 2);
        world.setBlockState(new BlockPos(i + 11, j + 6, k + 2), Block.getBlockById(1).getStateFromMeta(0), 2);
        world.setBlockState(new BlockPos(i + 2, j + 6, k + 3), Block.getBlockById(1).getStateFromMeta(0), 2);
        world.setBlockState(new BlockPos(i + 3, j + 6, k + 3), Block.getBlockById(1).getStateFromMeta(0), 2);
        world.setBlockState(new BlockPos(i + 4, j + 6, k + 3), Block.getBlockById(1).getStateFromMeta(0), 2);
        world.setBlockState(new BlockPos(i + 5, j + 6, k + 3), Block.getBlockById(1).getStateFromMeta(0), 2);
        world.setBlockState(new BlockPos(i + 6, j + 6, k + 3), Block.getBlockById(1).getStateFromMeta(0), 2);
        world.setBlockState(new BlockPos(i + 7, j + 6, k + 3), Block.getBlockById(1).getStateFromMeta(0), 2);
        world.setBlockState(new BlockPos(i + 8, j + 6, k + 3), Block.getBlockById(1).getStateFromMeta(0), 2);
        world.setBlockState(new BlockPos(i + 9, j + 6, k + 3), Block.getBlockById(1).getStateFromMeta(0), 2);
        world.setBlockState(new BlockPos(i + 10, j + 6, k + 3), Block.getBlockById(1).getStateFromMeta(0), 2);
        world.setBlockState(new BlockPos(i + 11, j + 6, k + 3), Block.getBlockById(1).getStateFromMeta(0), 2);
        world.setBlockState(new BlockPos(i + 12, j + 6, k + 3), Block.getBlockById(1).getStateFromMeta(0), 2);
        world.setBlockState(new BlockPos(i + 2, j + 6, k + 4), Block.getBlockById(1).getStateFromMeta(0), 2);
        world.setBlockState(new BlockPos(i + 3, j + 6, k + 4), Block.getBlockById(1).getStateFromMeta(0), 2);
        world.setBlockState(new BlockPos(i + 4, j + 6, k + 4), Block.getBlockById(1).getStateFromMeta(0), 2);
        world.setBlockState(new BlockPos(i + 5, j + 6, k + 4), Block.getBlockById(1).getStateFromMeta(0), 2);
        world.setBlockState(new BlockPos(i + 6, j + 6, k + 4), Block.getBlockById(1).getStateFromMeta(0), 2);
        world.setBlockState(new BlockPos(i + 7, j + 6, k + 4), Block.getBlockById(1).getStateFromMeta(0), 2);
        world.setBlockState(new BlockPos(i + 8, j + 6, k + 4), Block.getBlockById(1).getStateFromMeta(0), 2);
        world.setBlockState(new BlockPos(i + 9, j + 6, k + 4), Block.getBlockById(1).getStateFromMeta(0), 2);
        world.setBlockState(new BlockPos(i + 10, j + 6, k + 4), Block.getBlockById(1).getStateFromMeta(0), 2);
        world.setBlockState(new BlockPos(i + 11, j + 6, k + 4), Block.getBlockById(1).getStateFromMeta(0), 2);
        world.setBlockState(new BlockPos(i + 12, j + 6, k + 4), Block.getBlockById(1).getStateFromMeta(0), 2);
        world.setBlockState(new BlockPos(i + 13, j + 6, k + 4), Block.getBlockById(1).getStateFromMeta(0), 2);
        world.setBlockState(new BlockPos(i + 14, j + 6, k + 4), Block.getBlockById(1).getStateFromMeta(0), 2);
        world.setBlockState(new BlockPos(i + 1, j + 6, k + 5), Block.getBlockById(1).getStateFromMeta(0), 2);
        world.setBlockState(new BlockPos(i + 2, j + 6, k + 5), Block.getBlockById(1).getStateFromMeta(0), 2);
        world.setBlockState(new BlockPos(i + 3, j + 6, k + 5), Block.getBlockById(1).getStateFromMeta(0), 2);
        world.setBlockState(new BlockPos(i + 4, j + 6, k + 5), Block.getBlockById(1).getStateFromMeta(0), 2);
        world.setBlockState(new BlockPos(i + 5, j + 6, k + 5), Block.getBlockById(1).getStateFromMeta(0), 2);
        world.setBlockState(new BlockPos(i + 6, j + 6, k + 5), Block.getBlockById(1).getStateFromMeta(0), 2);
        world.setBlockState(new BlockPos(i + 7, j + 6, k + 5), Block.getBlockById(1).getStateFromMeta(0), 2);
        world.setBlockState(new BlockPos(i + 8, j + 6, k + 5), Block.getBlockById(1).getStateFromMeta(0), 2);
        world.setBlockState(new BlockPos(i + 9, j + 6, k + 5), Block.getBlockById(1).getStateFromMeta(0), 2);
        world.setBlockState(new BlockPos(i + 10, j + 6, k + 5), Block.getBlockById(1).getStateFromMeta(0), 2);
        world.setBlockState(new BlockPos(i + 11, j + 6, k + 5), Block.getBlockById(1).getStateFromMeta(0), 2);
        world.setBlockState(new BlockPos(i + 12, j + 6, k + 5), Block.getBlockById(1).getStateFromMeta(0), 2);
        world.setBlockState(new BlockPos(i + 13, j + 6, k + 5), Block.getBlockById(1).getStateFromMeta(0), 2);
        world.setBlockState(new BlockPos(i + 14, j + 6, k + 5), Block.getBlockById(1).getStateFromMeta(0), 2);
        world.setBlockState(new BlockPos(i + 15, j + 6, k + 5), Block.getBlockById(1).getStateFromMeta(0), 2);
        world.setBlockState(new BlockPos(i + 1, j + 6, k + 6), Block.getBlockById(1).getStateFromMeta(0), 2);
        world.setBlockState(new BlockPos(i + 2, j + 6, k + 6), Block.getBlockById(1).getStateFromMeta(0), 2);
        world.setBlockState(new BlockPos(i + 3, j + 6, k + 6), Block.getBlockById(1).getStateFromMeta(0), 2);
        world.setBlockState(new BlockPos(i + 4, j + 6, k + 6), Block.getBlockById(1).getStateFromMeta(0), 2);
        world.setBlockState(new BlockPos(i + 5, j + 6, k + 6), Block.getBlockById(1).getStateFromMeta(0), 2);
        world.setBlockState(new BlockPos(i + 6, j + 6, k + 6), Block.getBlockById(1).getStateFromMeta(0), 2);
        world.setBlockState(new BlockPos(i + 7, j + 6, k + 6), Block.getBlockById(1).getStateFromMeta(0), 2);
        world.setBlockState(new BlockPos(i + 8, j + 6, k + 6), Block.getBlockById(1).getStateFromMeta(0), 2);
        world.setBlockState(new BlockPos(i + 9, j + 6, k + 6), Block.getBlockById(1).getStateFromMeta(0), 2);
        world.setBlockState(new BlockPos(i + 10, j + 6, k + 6), Block.getBlockById(1).getStateFromMeta(0), 2);
        world.setBlockState(new BlockPos(i + 11, j + 6, k + 6), Block.getBlockById(1).getStateFromMeta(0), 2);
        world.setBlockState(new BlockPos(i + 12, j + 6, k + 6), Block.getBlockById(1).getStateFromMeta(0), 2);
        world.setBlockState(new BlockPos(i + 13, j + 6, k + 6), Block.getBlockById(1).getStateFromMeta(0), 2);
        world.setBlockState(new BlockPos(i + 14, j + 6, k + 6), Block.getBlockById(1).getStateFromMeta(0), 2);
        world.setBlockState(new BlockPos(i + 15, j + 6, k + 6), Block.getBlockById(1).getStateFromMeta(0), 2);
        world.setBlockState(new BlockPos(i + 16, j + 6, k + 6), Block.getBlockById(1).getStateFromMeta(0), 2);
        world.setBlockState(new BlockPos(i + 1, j + 6, k + 7), Block.getBlockById(1).getStateFromMeta(0), 2);
        world.setBlockState(new BlockPos(i + 2, j + 6, k + 7), Block.getBlockById(1).getStateFromMeta(0), 2);
        world.setBlockState(new BlockPos(i + 3, j + 6, k + 7), Block.getBlockById(1).getStateFromMeta(0), 2);
        world.setBlockState(new BlockPos(i + 4, j + 6, k + 7), Block.getBlockById(1).getStateFromMeta(0), 2);
        world.setBlockState(new BlockPos(i + 5, j + 6, k + 7), Block.getBlockById(1).getStateFromMeta(0), 2);
        world.setBlockState(new BlockPos(i + 6, j + 6, k + 7), Block.getBlockById(1).getStateFromMeta(0), 2);
        world.setBlockState(new BlockPos(i + 7, j + 6, k + 7), Block.getBlockById(1).getStateFromMeta(0), 2);
        world.setBlockState(new BlockPos(i + 8, j + 6, k + 7), Block.getBlockById(159).getStateFromMeta(12), 2);
        world.setBlockState(new BlockPos(i + 9, j + 6, k + 7), Block.getBlockById(159).getStateFromMeta(12), 2);
        world.setBlockState(new BlockPos(i + 10, j + 6, k + 7), Block.getBlockById(159).getStateFromMeta(12), 2);
        world.setBlockState(new BlockPos(i + 11, j + 6, k + 7), Block.getBlockById(1).getStateFromMeta(0), 2);
        world.setBlockState(new BlockPos(i + 12, j + 6, k + 7), Block.getBlockById(1).getStateFromMeta(0), 2);
        world.setBlockState(new BlockPos(i + 13, j + 6, k + 7), Block.getBlockById(1).getStateFromMeta(0), 2);
        world.setBlockState(new BlockPos(i + 14, j + 6, k + 7), Block.getBlockById(1).getStateFromMeta(0), 2);
        world.setBlockState(new BlockPos(i + 15, j + 6, k + 7), Block.getBlockById(1).getStateFromMeta(0), 2);
        world.setBlockState(new BlockPos(i + 16, j + 6, k + 7), Block.getBlockById(1).getStateFromMeta(0), 2);
        world.setBlockState(new BlockPos(i + 1, j + 6, k + 8), Block.getBlockById(1).getStateFromMeta(0), 2);
        world.setBlockState(new BlockPos(i + 2, j + 6, k + 8), Block.getBlockById(1).getStateFromMeta(0), 2);
        world.setBlockState(new BlockPos(i + 3, j + 6, k + 8), Block.getBlockById(1).getStateFromMeta(0), 2);
        world.setBlockState(new BlockPos(i + 4, j + 6, k + 8), Block.getBlockById(1).getStateFromMeta(0), 2);
        world.setBlockState(new BlockPos(i + 5, j + 6, k + 8), Block.getBlockById(1).getStateFromMeta(0), 2);
        world.setBlockState(new BlockPos(i + 6, j + 6, k + 8), Block.getBlockById(1).getStateFromMeta(0), 2);
        world.setBlockState(new BlockPos(i + 7, j + 6, k + 8), Block.getBlockById(159).getStateFromMeta(12), 2);
        world.setBlockState(new BlockPos(i + 8, j + 6, k + 8), Block.getBlockById(159).getStateFromMeta(12), 2);
        world.setBlockState(new BlockPos(i + 9, j + 6, k + 8), Block.getBlockById(159).getStateFromMeta(12), 2);
        world.setBlockState(new BlockPos(i + 10, j + 6, k + 8), Block.getBlockById(159).getStateFromMeta(12), 2);
        world.setBlockState(new BlockPos(i + 11, j + 6, k + 8), Block.getBlockById(159).getStateFromMeta(12), 2);
        world.setBlockState(new BlockPos(i + 12, j + 6, k + 8), Block.getBlockById(1).getStateFromMeta(0), 2);
        world.setBlockState(new BlockPos(i + 13, j + 6, k + 8), Block.getBlockById(1).getStateFromMeta(0), 2);
        world.setBlockState(new BlockPos(i + 14, j + 6, k + 8), Block.getBlockById(1).getStateFromMeta(0), 2);
        world.setBlockState(new BlockPos(i + 15, j + 6, k + 8), Block.getBlockById(1).getStateFromMeta(0), 2);
        world.setBlockState(new BlockPos(i + 16, j + 6, k + 8), Block.getBlockById(1).getStateFromMeta(0), 2);
        world.setBlockState(new BlockPos(i + 1, j + 6, k + 9), Block.getBlockById(1).getStateFromMeta(0), 2);
        world.setBlockState(new BlockPos(i + 2, j + 6, k + 9), Block.getBlockById(1).getStateFromMeta(0), 2);
        world.setBlockState(new BlockPos(i + 3, j + 6, k + 9), Block.getBlockById(1).getStateFromMeta(0), 2);
        world.setBlockState(new BlockPos(i + 4, j + 6, k + 9), Block.getBlockById(1).getStateFromMeta(0), 2);
        world.setBlockState(new BlockPos(i + 5, j + 6, k + 9), Block.getBlockById(1).getStateFromMeta(0), 2);
        world.setBlockState(new BlockPos(i + 6, j + 6, k + 9), Block.getBlockById(159).getStateFromMeta(12), 2);
        world.setBlockState(new BlockPos(i + 7, j + 6, k + 9), Block.getBlockById(159).getStateFromMeta(12), 2);
        world.setBlockState(new BlockPos(i + 8, j + 6, k + 9), Block.getBlockById(159).getStateFromMeta(12), 2);
        world.setBlockState(new BlockPos(i + 9, j + 6, k + 9), Block.getBlockById(159).getStateFromMeta(12), 2);
        world.setBlockState(new BlockPos(i + 10, j + 6, k + 9), Block.getBlockById(159).getStateFromMeta(12), 2);
        world.setBlockState(new BlockPos(i + 11, j + 6, k + 9), Block.getBlockById(159).getStateFromMeta(12), 2);
        world.setBlockState(new BlockPos(i + 12, j + 6, k + 9), Block.getBlockById(159).getStateFromMeta(12), 2);
        world.setBlockState(new BlockPos(i + 13, j + 6, k + 9), Block.getBlockById(1).getStateFromMeta(0), 2);
        world.setBlockState(new BlockPos(i + 14, j + 6, k + 9), Block.getBlockById(1).getStateFromMeta(0), 2);
        world.setBlockState(new BlockPos(i + 15, j + 6, k + 9), Block.getBlockById(1).getStateFromMeta(0), 2);
        world.setBlockState(new BlockPos(i + 16, j + 6, k + 9), Block.getBlockById(1).getStateFromMeta(0), 2);
        world.setBlockState(new BlockPos(i + 1, j + 6, k + 10), Block.getBlockById(1).getStateFromMeta(0), 2);
        world.setBlockState(new BlockPos(i + 2, j + 6, k + 10), Block.getBlockById(1).getStateFromMeta(0), 2);
        world.setBlockState(new BlockPos(i + 3, j + 6, k + 10), Block.getBlockById(1).getStateFromMeta(0), 2);
        world.setBlockState(new BlockPos(i + 4, j + 6, k + 10), Block.getBlockById(1).getStateFromMeta(0), 2);
        world.setBlockState(new BlockPos(i + 5, j + 6, k + 10), Block.getBlockById(1).getStateFromMeta(0), 2);
        world.setBlockState(new BlockPos(i + 6, j + 6, k + 10), Block.getBlockById(159).getStateFromMeta(12), 2);
        world.setBlockState(new BlockPos(i + 7, j + 6, k + 10), Block.getBlockById(159).getStateFromMeta(12), 2);
        world.setBlockState(new BlockPos(i + 8, j + 6, k + 10), Block.getBlockById(159).getStateFromMeta(12), 2);
        world.setBlockState(new BlockPos(i + 9, j + 6, k + 10), Block.getBlockById(159).getStateFromMeta(12), 2);
        world.setBlockState(new BlockPos(i + 10, j + 6, k + 10), Block.getBlockById(159).getStateFromMeta(12), 2);
        world.setBlockState(new BlockPos(i + 11, j + 6, k + 10), Block.getBlockById(159).getStateFromMeta(12), 2);
        world.setBlockState(new BlockPos(i + 12, j + 6, k + 10), Block.getBlockById(159).getStateFromMeta(12), 2);
        world.setBlockState(new BlockPos(i + 13, j + 6, k + 10), Block.getBlockById(1).getStateFromMeta(0), 2);
        world.setBlockState(new BlockPos(i + 14, j + 6, k + 10), Block.getBlockById(1).getStateFromMeta(0), 2);
        world.setBlockState(new BlockPos(i + 15, j + 6, k + 10), Block.getBlockById(1).getStateFromMeta(0), 2);
        world.setBlockState(new BlockPos(i + 16, j + 6, k + 10), Block.getBlockById(1).getStateFromMeta(0), 2);
        world.setBlockState(new BlockPos(i + 1, j + 6, k + 11), Block.getBlockById(1).getStateFromMeta(0), 2);
        world.setBlockState(new BlockPos(i + 2, j + 6, k + 11), Block.getBlockById(1).getStateFromMeta(0), 2);
        world.setBlockState(new BlockPos(i + 3, j + 6, k + 11), Block.getBlockById(1).getStateFromMeta(0), 2);
        world.setBlockState(new BlockPos(i + 4, j + 6, k + 11), Block.getBlockById(1).getStateFromMeta(0), 2);
        world.setBlockState(new BlockPos(i + 5, j + 6, k + 11), Block.getBlockById(1).getStateFromMeta(0), 2);
        world.setBlockState(new BlockPos(i + 6, j + 6, k + 11), Block.getBlockById(159).getStateFromMeta(12), 2);
        world.setBlockState(new BlockPos(i + 7, j + 6, k + 11), Block.getBlockById(159).getStateFromMeta(12), 2);
        world.setBlockState(new BlockPos(i + 8, j + 6, k + 11), Block.getBlockById(159).getStateFromMeta(12), 2);
        world.setBlockState(new BlockPos(i + 9, j + 6, k + 11), Block.getBlockById(159).getStateFromMeta(12), 2);
        world.setBlockState(new BlockPos(i + 10, j + 6, k + 11), Block.getBlockById(159).getStateFromMeta(12), 2);
        world.setBlockState(new BlockPos(i + 11, j + 6, k + 11), Block.getBlockById(159).getStateFromMeta(12), 2);
        world.setBlockState(new BlockPos(i + 12, j + 6, k + 11), Block.getBlockById(159).getStateFromMeta(12), 2);
        world.setBlockState(new BlockPos(i + 13, j + 6, k + 11), Block.getBlockById(1).getStateFromMeta(0), 2);
        world.setBlockState(new BlockPos(i + 14, j + 6, k + 11), Block.getBlockById(1).getStateFromMeta(0), 2);
        world.setBlockState(new BlockPos(i + 15, j + 6, k + 11), Block.getBlockById(1).getStateFromMeta(0), 2);
        world.setBlockState(new BlockPos(i + 16, j + 6, k + 11), Block.getBlockById(1).getStateFromMeta(0), 2);
        world.setBlockState(new BlockPos(i + 1, j + 6, k + 12), Block.getBlockById(1).getStateFromMeta(0), 2);
        world.setBlockState(new BlockPos(i + 2, j + 6, k + 12), Block.getBlockById(1).getStateFromMeta(0), 2);
        world.setBlockState(new BlockPos(i + 3, j + 6, k + 12), Block.getBlockById(1).getStateFromMeta(0), 2);
        world.setBlockState(new BlockPos(i + 4, j + 6, k + 12), Block.getBlockById(1).getStateFromMeta(0), 2);
        world.setBlockState(new BlockPos(i + 5, j + 6, k + 12), Block.getBlockById(1).getStateFromMeta(0), 2);
        world.setBlockState(new BlockPos(i + 6, j + 6, k + 12), Block.getBlockById(1).getStateFromMeta(0), 2);
        world.setBlockState(new BlockPos(i + 7, j + 6, k + 12), Block.getBlockById(159).getStateFromMeta(12), 2);
        world.setBlockState(new BlockPos(i + 8, j + 6, k + 12), Block.getBlockById(159).getStateFromMeta(12), 2);
        world.setBlockState(new BlockPos(i + 9, j + 6, k + 12), Block.getBlockById(159).getStateFromMeta(12), 2);
        world.setBlockState(new BlockPos(i + 10, j + 6, k + 12), Block.getBlockById(159).getStateFromMeta(12), 2);
        world.setBlockState(new BlockPos(i + 11, j + 6, k + 12), Block.getBlockById(159).getStateFromMeta(12), 2);
        world.setBlockState(new BlockPos(i + 12, j + 6, k + 12), Block.getBlockById(1).getStateFromMeta(0), 2);
        world.setBlockState(new BlockPos(i + 13, j + 6, k + 12), Block.getBlockById(1).getStateFromMeta(0), 2);
        world.setBlockState(new BlockPos(i + 14, j + 6, k + 12), Block.getBlockById(1).getStateFromMeta(0), 2);
        world.setBlockState(new BlockPos(i + 15, j + 6, k + 12), Block.getBlockById(1).getStateFromMeta(0), 2);
        world.setBlockState(new BlockPos(i + 16, j + 6, k + 12), Block.getBlockById(1).getStateFromMeta(0), 2);
        world.setBlockState(new BlockPos(i + 1, j + 6, k + 13), Block.getBlockById(1).getStateFromMeta(0), 2);
        world.setBlockState(new BlockPos(i + 2, j + 6, k + 13), Block.getBlockById(1).getStateFromMeta(0), 2);
        world.setBlockState(new BlockPos(i + 3, j + 6, k + 13), Block.getBlockById(1).getStateFromMeta(0), 2);
        world.setBlockState(new BlockPos(i + 4, j + 6, k + 13), Block.getBlockById(1).getStateFromMeta(0), 2);
        world.setBlockState(new BlockPos(i + 5, j + 6, k + 13), Block.getBlockById(1).getStateFromMeta(0), 2);
        world.setBlockState(new BlockPos(i + 6, j + 6, k + 13), Block.getBlockById(1).getStateFromMeta(0), 2);
        world.setBlockState(new BlockPos(i + 7, j + 6, k + 13), Block.getBlockById(1).getStateFromMeta(0), 2);
        world.setBlockState(new BlockPos(i + 8, j + 6, k + 13), Block.getBlockById(159).getStateFromMeta(12), 2);
        world.setBlockState(new BlockPos(i + 9, j + 6, k + 13), Block.getBlockById(159).getStateFromMeta(12), 2);
        world.setBlockState(new BlockPos(i + 10, j + 6, k + 13), Block.getBlockById(159).getStateFromMeta(12), 2);
        world.setBlockState(new BlockPos(i + 11, j + 6, k + 13), Block.getBlockById(1).getStateFromMeta(0), 2);
        world.setBlockState(new BlockPos(i + 12, j + 6, k + 13), Block.getBlockById(1).getStateFromMeta(0), 2);
        world.setBlockState(new BlockPos(i + 13, j + 6, k + 13), Block.getBlockById(1).getStateFromMeta(0), 2);
        world.setBlockState(new BlockPos(i + 14, j + 6, k + 13), Block.getBlockById(1).getStateFromMeta(0), 2);
        world.setBlockState(new BlockPos(i + 15, j + 6, k + 13), Block.getBlockById(1).getStateFromMeta(0), 2);
        world.setBlockState(new BlockPos(i + 16, j + 6, k + 13), Block.getBlockById(1).getStateFromMeta(0), 2);
        world.setBlockState(new BlockPos(i + 1, j + 6, k + 14), Block.getBlockById(1).getStateFromMeta(0), 2);
        world.setBlockState(new BlockPos(i + 2, j + 6, k + 14), Block.getBlockById(1).getStateFromMeta(0), 2);
        world.setBlockState(new BlockPos(i + 3, j + 6, k + 14), Block.getBlockById(1).getStateFromMeta(0), 2);
        world.setBlockState(new BlockPos(i + 4, j + 6, k + 14), Block.getBlockById(1).getStateFromMeta(0), 2);
        world.setBlockState(new BlockPos(i + 5, j + 6, k + 14), Block.getBlockById(1).getStateFromMeta(0), 2);
        world.setBlockState(new BlockPos(i + 6, j + 6, k + 14), Block.getBlockById(1).getStateFromMeta(0), 2);
        world.setBlockState(new BlockPos(i + 7, j + 6, k + 14), Block.getBlockById(1).getStateFromMeta(0), 2);
        world.setBlockState(new BlockPos(i + 8, j + 6, k + 14), Block.getBlockById(1).getStateFromMeta(0), 2);
        world.setBlockState(new BlockPos(i + 9, j + 6, k + 14), Block.getBlockById(1).getStateFromMeta(0), 2);
        world.setBlockState(new BlockPos(i + 10, j + 6, k + 14), Block.getBlockById(1).getStateFromMeta(0), 2);
        world.setBlockState(new BlockPos(i + 11, j + 6, k + 14), Block.getBlockById(1).getStateFromMeta(0), 2);
        world.setBlockState(new BlockPos(i + 12, j + 6, k + 14), Block.getBlockById(1).getStateFromMeta(0), 2);
        world.setBlockState(new BlockPos(i + 13, j + 6, k + 14), Block.getBlockById(1).getStateFromMeta(0), 2);
        world.setBlockState(new BlockPos(i + 14, j + 6, k + 14), Block.getBlockById(1).getStateFromMeta(0), 2);
        world.setBlockState(new BlockPos(i + 15, j + 6, k + 14), Block.getBlockById(1).getStateFromMeta(0), 2);
        world.setBlockState(new BlockPos(i + 16, j + 6, k + 14), Block.getBlockById(1).getStateFromMeta(0), 2);
        world.setBlockState(new BlockPos(i + 2, j + 6, k + 15), Block.getBlockById(1).getStateFromMeta(0), 2);
        world.setBlockState(new BlockPos(i + 3, j + 6, k + 15), Block.getBlockById(1).getStateFromMeta(0), 2);
        world.setBlockState(new BlockPos(i + 4, j + 6, k + 15), Block.getBlockById(1).getStateFromMeta(0), 2);
        world.setBlockState(new BlockPos(i + 5, j + 6, k + 15), Block.getBlockById(1).getStateFromMeta(0), 2);
        world.setBlockState(new BlockPos(i + 6, j + 6, k + 15), Block.getBlockById(1).getStateFromMeta(0), 2);
        world.setBlockState(new BlockPos(i + 7, j + 6, k + 15), Block.getBlockById(1).getStateFromMeta(0), 2);
        world.setBlockState(new BlockPos(i + 8, j + 6, k + 15), Block.getBlockById(1).getStateFromMeta(0), 2);
        world.setBlockState(new BlockPos(i + 9, j + 6, k + 15), Block.getBlockById(1).getStateFromMeta(0), 2);
        world.setBlockState(new BlockPos(i + 10, j + 6, k + 15), Block.getBlockById(1).getStateFromMeta(0), 2);
        world.setBlockState(new BlockPos(i + 11, j + 6, k + 15), Block.getBlockById(1).getStateFromMeta(0), 2);
        world.setBlockState(new BlockPos(i + 12, j + 6, k + 15), Block.getBlockById(1).getStateFromMeta(0), 2);
        world.setBlockState(new BlockPos(i + 13, j + 6, k + 15), Block.getBlockById(1).getStateFromMeta(0), 2);
        world.setBlockState(new BlockPos(i + 14, j + 6, k + 15), Block.getBlockById(1).getStateFromMeta(0), 2);
        world.setBlockState(new BlockPos(i + 15, j + 6, k + 15), Block.getBlockById(1).getStateFromMeta(0), 2);
        world.setBlockState(new BlockPos(i + 16, j + 6, k + 15), Block.getBlockById(1).getStateFromMeta(0), 2);
        world.setBlockState(new BlockPos(i + 3, j + 6, k + 16), Block.getBlockById(1).getStateFromMeta(0), 2);
        world.setBlockState(new BlockPos(i + 4, j + 6, k + 16), Block.getBlockById(1).getStateFromMeta(0), 2);
        world.setBlockState(new BlockPos(i + 5, j + 6, k + 16), Block.getBlockById(1).getStateFromMeta(0), 2);
        world.setBlockState(new BlockPos(i + 6, j + 6, k + 16), Block.getBlockById(1).getStateFromMeta(0), 2);
        world.setBlockState(new BlockPos(i + 7, j + 6, k + 16), Block.getBlockById(1).getStateFromMeta(0), 2);
        world.setBlockState(new BlockPos(i + 8, j + 6, k + 16), Block.getBlockById(1).getStateFromMeta(0), 2);
        world.setBlockState(new BlockPos(i + 9, j + 6, k + 16), Block.getBlockById(1).getStateFromMeta(0), 2);
        world.setBlockState(new BlockPos(i + 10, j + 6, k + 16), Block.getBlockById(1).getStateFromMeta(0), 2);
        world.setBlockState(new BlockPos(i + 11, j + 6, k + 16), Block.getBlockById(1).getStateFromMeta(0), 2);
        world.setBlockState(new BlockPos(i + 12, j + 6, k + 16), Block.getBlockById(1).getStateFromMeta(0), 2);
        world.setBlockState(new BlockPos(i + 13, j + 6, k + 16), Block.getBlockById(1).getStateFromMeta(0), 2);
        world.setBlockState(new BlockPos(i + 14, j + 6, k + 16), Block.getBlockById(1).getStateFromMeta(0), 2);
        world.setBlockState(new BlockPos(i + 15, j + 6, k + 16), Block.getBlockById(1).getStateFromMeta(0), 2);
        world.setBlockState(new BlockPos(i + 4, j + 6, k + 17), Block.getBlockById(1).getStateFromMeta(0), 2);
        world.setBlockState(new BlockPos(i + 5, j + 6, k + 17), Block.getBlockById(1).getStateFromMeta(0), 2);
        world.setBlockState(new BlockPos(i + 6, j + 6, k + 17), Block.getBlockById(1).getStateFromMeta(0), 2);
        world.setBlockState(new BlockPos(i + 7, j + 6, k + 17), Block.getBlockById(1).getStateFromMeta(0), 2);
        world.setBlockState(new BlockPos(i + 8, j + 6, k + 17), Block.getBlockById(1).getStateFromMeta(0), 2);
        world.setBlockState(new BlockPos(i + 9, j + 6, k + 17), Block.getBlockById(1).getStateFromMeta(0), 2);
        world.setBlockState(new BlockPos(i + 10, j + 6, k + 17), Block.getBlockById(1).getStateFromMeta(0), 2);
        world.setBlockState(new BlockPos(i + 11, j + 6, k + 17), Block.getBlockById(1).getStateFromMeta(0), 2);
        world.setBlockState(new BlockPos(i + 12, j + 6, k + 17), Block.getBlockById(1).getStateFromMeta(0), 2);
        world.setBlockState(new BlockPos(i + 13, j + 6, k + 17), Block.getBlockById(1).getStateFromMeta(0), 2);
        world.setBlockState(new BlockPos(i + 7, j + 7, k + 1), Block.getBlockById(1).getStateFromMeta(0), 2);
        world.setBlockState(new BlockPos(i + 8, j + 7, k + 1), Block.getBlockById(1).getStateFromMeta(0), 2);
        world.setBlockState(new BlockPos(i + 9, j + 7, k + 1), Block.getBlockById(1).getStateFromMeta(0), 2);
        world.setBlockState(new BlockPos(i + 2, j + 7, k + 2), Block.getBlockById(1).getStateFromMeta(0), 2);
        world.setBlockState(new BlockPos(i + 3, j + 7, k + 2), Block.getBlockById(1).getStateFromMeta(0), 2);
        world.setBlockState(new BlockPos(i + 4, j + 7, k + 2), Block.getBlockById(1).getStateFromMeta(0), 2);
        world.setBlockState(new BlockPos(i + 5, j + 7, k + 2), Block.getBlockById(1).getStateFromMeta(0), 2);
        world.setBlockState(new BlockPos(i + 6, j + 7, k + 2), Block.getBlockById(1).getStateFromMeta(0), 2);
        world.setBlockState(new BlockPos(i + 7, j + 7, k + 2), Block.getBlockById(1).getStateFromMeta(0), 2);
        world.setBlockState(new BlockPos(i + 8, j + 7, k + 2), Block.getBlockById(1).getStateFromMeta(0), 2);
        world.setBlockState(new BlockPos(i + 9, j + 7, k + 2), Block.getBlockById(1).getStateFromMeta(0), 2);
        world.setBlockState(new BlockPos(i + 10, j + 7, k + 2), Block.getBlockById(1).getStateFromMeta(0), 2);
        world.setBlockState(new BlockPos(i + 11, j + 7, k + 2), Block.getBlockById(1).getStateFromMeta(0), 2);
        world.setBlockState(new BlockPos(i + 12, j + 7, k + 2), Block.getBlockById(1).getStateFromMeta(0), 2);
        world.setBlockState(new BlockPos(i + 2, j + 7, k + 3), Block.getBlockById(1).getStateFromMeta(0), 2);
        world.setBlockState(new BlockPos(i + 3, j + 7, k + 3), Block.getBlockById(1).getStateFromMeta(0), 2);
        world.setBlockState(new BlockPos(i + 4, j + 7, k + 3), Block.getBlockById(1).getStateFromMeta(0), 2);
        world.setBlockState(new BlockPos(i + 5, j + 7, k + 3), Block.getBlockById(1).getStateFromMeta(0), 2);
        world.setBlockState(new BlockPos(i + 6, j + 7, k + 3), Block.getBlockById(1).getStateFromMeta(0), 2);
        world.setBlockState(new BlockPos(i + 7, j + 7, k + 3), Block.getBlockById(1).getStateFromMeta(0), 2);
        world.setBlockState(new BlockPos(i + 8, j + 7, k + 3), Block.getBlockById(1).getStateFromMeta(0), 2);
        world.setBlockState(new BlockPos(i + 9, j + 7, k + 3), Block.getBlockById(1).getStateFromMeta(0), 2);
        world.setBlockState(new BlockPos(i + 10, j + 7, k + 3), Block.getBlockById(1).getStateFromMeta(0), 2);
        world.setBlockState(new BlockPos(i + 11, j + 7, k + 3), Block.getBlockById(1).getStateFromMeta(0), 2);
        world.setBlockState(new BlockPos(i + 12, j + 7, k + 3), Block.getBlockById(1).getStateFromMeta(0), 2);
        world.setBlockState(new BlockPos(i + 13, j + 7, k + 3), Block.getBlockById(1).getStateFromMeta(0), 2);
        world.setBlockState(new BlockPos(i + 14, j + 7, k + 3), Block.getBlockById(1).getStateFromMeta(0), 2);
        world.setBlockState(new BlockPos(i + 1, j + 7, k + 4), Block.getBlockById(1).getStateFromMeta(0), 2);
        world.setBlockState(new BlockPos(i + 2, j + 7, k + 4), Block.getBlockById(1).getStateFromMeta(0), 2);
        world.setBlockState(new BlockPos(i + 3, j + 7, k + 4), Block.getBlockById(1).getStateFromMeta(0), 2);
        world.setBlockState(new BlockPos(i + 4, j + 7, k + 4), Block.getBlockById(1).getStateFromMeta(0), 2);
        world.setBlockState(new BlockPos(i + 5, j + 7, k + 4), Block.getBlockById(1).getStateFromMeta(0), 2);
        world.setBlockState(new BlockPos(i + 6, j + 7, k + 4), Block.getBlockById(1).getStateFromMeta(0), 2);
        world.setBlockState(new BlockPos(i + 7, j + 7, k + 4), Block.getBlockById(1).getStateFromMeta(0), 2);
        world.setBlockState(new BlockPos(i + 8, j + 7, k + 4), Block.getBlockById(1).getStateFromMeta(0), 2);
        world.setBlockState(new BlockPos(i + 9, j + 7, k + 4), Block.getBlockById(1).getStateFromMeta(0), 2);
        world.setBlockState(new BlockPos(i + 10, j + 7, k + 4), Block.getBlockById(1).getStateFromMeta(0), 2);
        world.setBlockState(new BlockPos(i + 11, j + 7, k + 4), Block.getBlockById(1).getStateFromMeta(0), 2);
        world.setBlockState(new BlockPos(i + 12, j + 7, k + 4), Block.getBlockById(1).getStateFromMeta(0), 2);
        world.setBlockState(new BlockPos(i + 13, j + 7, k + 4), Block.getBlockById(1).getStateFromMeta(0), 2);
        world.setBlockState(new BlockPos(i + 14, j + 7, k + 4), Block.getBlockById(1).getStateFromMeta(0), 2);
        world.setBlockState(new BlockPos(i + 15, j + 7, k + 4), Block.getBlockById(1).getStateFromMeta(0), 2);
        world.setBlockState(new BlockPos(i + 1, j + 7, k + 5), Block.getBlockById(1).getStateFromMeta(0), 2);
        world.setBlockState(new BlockPos(i + 2, j + 7, k + 5), Block.getBlockById(1).getStateFromMeta(0), 2);
        world.setBlockState(new BlockPos(i + 3, j + 7, k + 5), Block.getBlockById(1).getStateFromMeta(0), 2);
        world.setBlockState(new BlockPos(i + 4, j + 7, k + 5), Block.getBlockById(1).getStateFromMeta(0), 2);
        world.setBlockState(new BlockPos(i + 5, j + 7, k + 5), Block.getBlockById(1).getStateFromMeta(0), 2);
        world.setBlockState(new BlockPos(i + 6, j + 7, k + 5), Block.getBlockById(1).getStateFromMeta(0), 2);
        world.setBlockState(new BlockPos(i + 7, j + 7, k + 5), Block.getBlockById(1).getStateFromMeta(0), 2);
        world.setBlockState(new BlockPos(i + 8, j + 7, k + 5), Block.getBlockById(1).getStateFromMeta(0), 2);
        world.setBlockState(new BlockPos(i + 9, j + 7, k + 5), Block.getBlockById(1).getStateFromMeta(0), 2);
        world.setBlockState(new BlockPos(i + 10, j + 7, k + 5), Block.getBlockById(1).getStateFromMeta(0), 2);
        world.setBlockState(new BlockPos(i + 11, j + 7, k + 5), Block.getBlockById(1).getStateFromMeta(0), 2);
        world.setBlockState(new BlockPos(i + 12, j + 7, k + 5), Block.getBlockById(1).getStateFromMeta(0), 2);
        world.setBlockState(new BlockPos(i + 13, j + 7, k + 5), Block.getBlockById(1).getStateFromMeta(0), 2);
        world.setBlockState(new BlockPos(i + 14, j + 7, k + 5), Block.getBlockById(1).getStateFromMeta(0), 2);
        world.setBlockState(new BlockPos(i + 15, j + 7, k + 5), Block.getBlockById(1).getStateFromMeta(0), 2);
        world.setBlockState(new BlockPos(i + 16, j + 7, k + 5), Block.getBlockById(1).getStateFromMeta(0), 2);
        world.setBlockState(new BlockPos(i + 1, j + 7, k + 6), Block.getBlockById(1).getStateFromMeta(0), 2);
        world.setBlockState(new BlockPos(i + 2, j + 7, k + 6), Block.getBlockById(1).getStateFromMeta(0), 2);
        world.setBlockState(new BlockPos(i + 3, j + 7, k + 6), Block.getBlockById(1).getStateFromMeta(0), 2);
        world.setBlockState(new BlockPos(i + 4, j + 7, k + 6), Block.getBlockById(1).getStateFromMeta(0), 2);
        world.setBlockState(new BlockPos(i + 5, j + 7, k + 6), Block.getBlockById(1).getStateFromMeta(0), 2);
        world.setBlockState(new BlockPos(i + 6, j + 7, k + 6), Block.getBlockById(1).getStateFromMeta(0), 2);
        world.setBlockState(new BlockPos(i + 7, j + 7, k + 6), Block.getBlockById(1).getStateFromMeta(0), 2);
        world.setBlockState(new BlockPos(i + 8, j + 7, k + 6), Block.getBlockById(1).getStateFromMeta(0), 2);
        world.setBlockState(new BlockPos(i + 9, j + 7, k + 6), Block.getBlockById(1).getStateFromMeta(0), 2);
        world.setBlockState(new BlockPos(i + 10, j + 7, k + 6), Block.getBlockById(1).getStateFromMeta(0), 2);
        world.setBlockState(new BlockPos(i + 11, j + 7, k + 6), Block.getBlockById(1).getStateFromMeta(0), 2);
        world.setBlockState(new BlockPos(i + 12, j + 7, k + 6), Block.getBlockById(1).getStateFromMeta(0), 2);
        world.setBlockState(new BlockPos(i + 13, j + 7, k + 6), Block.getBlockById(1).getStateFromMeta(0), 2);
        world.setBlockState(new BlockPos(i + 14, j + 7, k + 6), Block.getBlockById(1).getStateFromMeta(0), 2);
        world.setBlockState(new BlockPos(i + 15, j + 7, k + 6), Block.getBlockById(1).getStateFromMeta(0), 2);
        world.setBlockState(new BlockPos(i + 16, j + 7, k + 6), Block.getBlockById(1).getStateFromMeta(0), 2);
        world.setBlockState(new BlockPos(i + 1, j + 7, k + 7), Block.getBlockById(1).getStateFromMeta(0), 2);
        world.setBlockState(new BlockPos(i + 2, j + 7, k + 7), Block.getBlockById(1).getStateFromMeta(0), 2);
        world.setBlockState(new BlockPos(i + 3, j + 7, k + 7), Block.getBlockById(1).getStateFromMeta(0), 2);
        world.setBlockState(new BlockPos(i + 4, j + 7, k + 7), Block.getBlockById(1).getStateFromMeta(0), 2);
        world.setBlockState(new BlockPos(i + 5, j + 7, k + 7), Block.getBlockById(1).getStateFromMeta(0), 2);
        world.setBlockState(new BlockPos(i + 6, j + 7, k + 7), Block.getBlockById(1).getStateFromMeta(0), 2);
        world.setBlockState(new BlockPos(i + 7, j + 7, k + 7), Block.getBlockById(1).getStateFromMeta(0), 2);
        world.setBlockState(new BlockPos(i + 8, j + 7, k + 7), Block.getBlockById(1).getStateFromMeta(0), 2);
        world.setBlockState(new BlockPos(i + 9, j + 7, k + 7), Block.getBlockById(1).getStateFromMeta(0), 2);
        world.setBlockState(new BlockPos(i + 10, j + 7, k + 7), Block.getBlockById(1).getStateFromMeta(0), 2);
        world.setBlockState(new BlockPos(i + 11, j + 7, k + 7), Block.getBlockById(1).getStateFromMeta(0), 2);
        world.setBlockState(new BlockPos(i + 12, j + 7, k + 7), Block.getBlockById(1).getStateFromMeta(0), 2);
        world.setBlockState(new BlockPos(i + 13, j + 7, k + 7), Block.getBlockById(1).getStateFromMeta(0), 2);
        world.setBlockState(new BlockPos(i + 14, j + 7, k + 7), Block.getBlockById(1).getStateFromMeta(0), 2);
        world.setBlockState(new BlockPos(i + 15, j + 7, k + 7), Block.getBlockById(1).getStateFromMeta(0), 2);
        world.setBlockState(new BlockPos(i + 16, j + 7, k + 7), Block.getBlockById(1).getStateFromMeta(0), 2);
        world.setBlockState(new BlockPos(i + 1, j + 7, k + 8), Block.getBlockById(1).getStateFromMeta(0), 2);
        world.setBlockState(new BlockPos(i + 2, j + 7, k + 8), Block.getBlockById(1).getStateFromMeta(0), 2);
        world.setBlockState(new BlockPos(i + 3, j + 7, k + 8), Block.getBlockById(1).getStateFromMeta(0), 2);
        world.setBlockState(new BlockPos(i + 4, j + 7, k + 8), Block.getBlockById(1).getStateFromMeta(0), 2);
        world.setBlockState(new BlockPos(i + 5, j + 7, k + 8), Block.getBlockById(1).getStateFromMeta(0), 2);
        world.setBlockState(new BlockPos(i + 6, j + 7, k + 8), Block.getBlockById(1).getStateFromMeta(0), 2);
        world.setBlockState(new BlockPos(i + 7, j + 7, k + 8), Block.getBlockById(1).getStateFromMeta(0), 2);
        world.setBlockState(new BlockPos(i + 8, j + 7, k + 8), Block.getBlockById(1).getStateFromMeta(0), 2);
        world.setBlockState(new BlockPos(i + 9, j + 7, k + 8), Block.getBlockById(1).getStateFromMeta(0), 2);
        world.setBlockState(new BlockPos(i + 10, j + 7, k + 8), Block.getBlockById(1).getStateFromMeta(0), 2);
        world.setBlockState(new BlockPos(i + 11, j + 7, k + 8), Block.getBlockById(1).getStateFromMeta(0), 2);
        world.setBlockState(new BlockPos(i + 12, j + 7, k + 8), Block.getBlockById(1).getStateFromMeta(0), 2);
        world.setBlockState(new BlockPos(i + 13, j + 7, k + 8), Block.getBlockById(1).getStateFromMeta(0), 2);
        world.setBlockState(new BlockPos(i + 14, j + 7, k + 8), Block.getBlockById(1).getStateFromMeta(0), 2);
        world.setBlockState(new BlockPos(i + 15, j + 7, k + 8), Block.getBlockById(1).getStateFromMeta(0), 2);
        world.setBlockState(new BlockPos(i + 16, j + 7, k + 8), Block.getBlockById(1).getStateFromMeta(0), 2);
        world.setBlockState(new BlockPos(i + 1, j + 7, k + 9), Block.getBlockById(1).getStateFromMeta(0), 2);
        world.setBlockState(new BlockPos(i + 2, j + 7, k + 9), Block.getBlockById(1).getStateFromMeta(0), 2);
        world.setBlockState(new BlockPos(i + 3, j + 7, k + 9), Block.getBlockById(1).getStateFromMeta(0), 2);
        world.setBlockState(new BlockPos(i + 4, j + 7, k + 9), Block.getBlockById(1).getStateFromMeta(0), 2);
        world.setBlockState(new BlockPos(i + 5, j + 7, k + 9), Block.getBlockById(1).getStateFromMeta(0), 2);
        world.setBlockState(new BlockPos(i + 6, j + 7, k + 9), Block.getBlockById(1).getStateFromMeta(0), 2);
        world.setBlockState(new BlockPos(i + 7, j + 7, k + 9), Block.getBlockById(1).getStateFromMeta(0), 2);
        world.setBlockState(new BlockPos(i + 8, j + 7, k + 9), Block.getBlockById(1).getStateFromMeta(0), 2);
        world.setBlockState(new BlockPos(i + 9, j + 7, k + 9), Block.getBlockById(1).getStateFromMeta(0), 2);
        world.setBlockState(new BlockPos(i + 10, j + 7, k + 9), Block.getBlockById(1).getStateFromMeta(0), 2);
        world.setBlockState(new BlockPos(i + 11, j + 7, k + 9), Block.getBlockById(1).getStateFromMeta(0), 2);
        world.setBlockState(new BlockPos(i + 12, j + 7, k + 9), Block.getBlockById(1).getStateFromMeta(0), 2);
        world.setBlockState(new BlockPos(i + 13, j + 7, k + 9), Block.getBlockById(1).getStateFromMeta(0), 2);
        world.setBlockState(new BlockPos(i + 14, j + 7, k + 9), Block.getBlockById(1).getStateFromMeta(0), 2);
        world.setBlockState(new BlockPos(i + 15, j + 7, k + 9), Block.getBlockById(1).getStateFromMeta(0), 2);
        world.setBlockState(new BlockPos(i + 16, j + 7, k + 9), Block.getBlockById(1).getStateFromMeta(0), 2);
        world.setBlockState(new BlockPos(i + 17, j + 7, k + 9), Block.getBlockById(1).getStateFromMeta(0), 2);
        world.setBlockState(new BlockPos(i + 1, j + 7, k + 10), Block.getBlockById(1).getStateFromMeta(0), 2);
        world.setBlockState(new BlockPos(i + 2, j + 7, k + 10), Block.getBlockById(1).getStateFromMeta(0), 2);
        world.setBlockState(new BlockPos(i + 3, j + 7, k + 10), Block.getBlockById(1).getStateFromMeta(0), 2);
        world.setBlockState(new BlockPos(i + 4, j + 7, k + 10), Block.getBlockById(1).getStateFromMeta(0), 2);
        world.setBlockState(new BlockPos(i + 5, j + 7, k + 10), Block.getBlockById(1).getStateFromMeta(0), 2);
        world.setBlockState(new BlockPos(i + 6, j + 7, k + 10), Block.getBlockById(1).getStateFromMeta(0), 2);
        world.setBlockState(new BlockPos(i + 7, j + 7, k + 10), Block.getBlockById(1).getStateFromMeta(0), 2);
        world.setBlockState(new BlockPos(i + 8, j + 7, k + 10), Block.getBlockById(1).getStateFromMeta(0), 2);
        world.setBlockState(new BlockPos(i + 9, j + 7, k + 10), Block.getBlockById(1).getStateFromMeta(0), 2);
        world.setBlockState(new BlockPos(i + 10, j + 7, k + 10), Block.getBlockById(1).getStateFromMeta(0), 2);
        world.setBlockState(new BlockPos(i + 11, j + 7, k + 10), Block.getBlockById(1).getStateFromMeta(0), 2);
        world.setBlockState(new BlockPos(i + 12, j + 7, k + 10), Block.getBlockById(1).getStateFromMeta(0), 2);
        world.setBlockState(new BlockPos(i + 13, j + 7, k + 10), Block.getBlockById(1).getStateFromMeta(0), 2);
        world.setBlockState(new BlockPos(i + 14, j + 7, k + 10), Block.getBlockById(1).getStateFromMeta(0), 2);
        world.setBlockState(new BlockPos(i + 15, j + 7, k + 10), Block.getBlockById(1).getStateFromMeta(0), 2);
        world.setBlockState(new BlockPos(i + 16, j + 7, k + 10), Block.getBlockById(1).getStateFromMeta(0), 2);
        world.setBlockState(new BlockPos(i + 17, j + 7, k + 10), Block.getBlockById(1).getStateFromMeta(0), 2);
        world.setBlockState(new BlockPos(i + 1, j + 7, k + 11), Block.getBlockById(1).getStateFromMeta(0), 2);
        world.setBlockState(new BlockPos(i + 2, j + 7, k + 11), Block.getBlockById(1).getStateFromMeta(0), 2);
        world.setBlockState(new BlockPos(i + 3, j + 7, k + 11), Block.getBlockById(1).getStateFromMeta(0), 2);
        world.setBlockState(new BlockPos(i + 4, j + 7, k + 11), Block.getBlockById(1).getStateFromMeta(0), 2);
        world.setBlockState(new BlockPos(i + 5, j + 7, k + 11), Block.getBlockById(1).getStateFromMeta(0), 2);
        world.setBlockState(new BlockPos(i + 6, j + 7, k + 11), Block.getBlockById(1).getStateFromMeta(0), 2);
        world.setBlockState(new BlockPos(i + 7, j + 7, k + 11), Block.getBlockById(1).getStateFromMeta(0), 2);
        world.setBlockState(new BlockPos(i + 8, j + 7, k + 11), Block.getBlockById(1).getStateFromMeta(0), 2);
        world.setBlockState(new BlockPos(i + 9, j + 7, k + 11), Block.getBlockById(1).getStateFromMeta(0), 2);
        world.setBlockState(new BlockPos(i + 10, j + 7, k + 11), Block.getBlockById(1).getStateFromMeta(0), 2);
        world.setBlockState(new BlockPos(i + 11, j + 7, k + 11), Block.getBlockById(1).getStateFromMeta(0), 2);
        world.setBlockState(new BlockPos(i + 12, j + 7, k + 11), Block.getBlockById(1).getStateFromMeta(0), 2);
        world.setBlockState(new BlockPos(i + 13, j + 7, k + 11), Block.getBlockById(1).getStateFromMeta(0), 2);
        world.setBlockState(new BlockPos(i + 14, j + 7, k + 11), Block.getBlockById(1).getStateFromMeta(0), 2);
        world.setBlockState(new BlockPos(i + 15, j + 7, k + 11), Block.getBlockById(1).getStateFromMeta(0), 2);
        world.setBlockState(new BlockPos(i + 16, j + 7, k + 11), Block.getBlockById(1).getStateFromMeta(0), 2);
        world.setBlockState(new BlockPos(i + 1, j + 7, k + 12), Block.getBlockById(1).getStateFromMeta(0), 2);
        world.setBlockState(new BlockPos(i + 2, j + 7, k + 12), Block.getBlockById(1).getStateFromMeta(0), 2);
        world.setBlockState(new BlockPos(i + 3, j + 7, k + 12), Block.getBlockById(1).getStateFromMeta(0), 2);
        world.setBlockState(new BlockPos(i + 4, j + 7, k + 12), Block.getBlockById(1).getStateFromMeta(0), 2);
        world.setBlockState(new BlockPos(i + 5, j + 7, k + 12), Block.getBlockById(1).getStateFromMeta(0), 2);
        world.setBlockState(new BlockPos(i + 6, j + 7, k + 12), Block.getBlockById(1).getStateFromMeta(0), 2);
        world.setBlockState(new BlockPos(i + 7, j + 7, k + 12), Block.getBlockById(1).getStateFromMeta(0), 2);
        world.setBlockState(new BlockPos(i + 8, j + 7, k + 12), Block.getBlockById(1).getStateFromMeta(0), 2);
        world.setBlockState(new BlockPos(i + 9, j + 7, k + 12), Block.getBlockById(1).getStateFromMeta(0), 2);
        world.setBlockState(new BlockPos(i + 10, j + 7, k + 12), Block.getBlockById(1).getStateFromMeta(0), 2);
        world.setBlockState(new BlockPos(i + 11, j + 7, k + 12), Block.getBlockById(1).getStateFromMeta(0), 2);
        world.setBlockState(new BlockPos(i + 12, j + 7, k + 12), Block.getBlockById(1).getStateFromMeta(0), 2);
        world.setBlockState(new BlockPos(i + 13, j + 7, k + 12), Block.getBlockById(1).getStateFromMeta(0), 2);
        world.setBlockState(new BlockPos(i + 14, j + 7, k + 12), Block.getBlockById(1).getStateFromMeta(0), 2);
        world.setBlockState(new BlockPos(i + 15, j + 7, k + 12), Block.getBlockById(1).getStateFromMeta(0), 2);
        world.setBlockState(new BlockPos(i + 16, j + 7, k + 12), Block.getBlockById(1).getStateFromMeta(0), 2);
        world.setBlockState(new BlockPos(i + 1, j + 7, k + 13), Block.getBlockById(1).getStateFromMeta(0), 2);
        world.setBlockState(new BlockPos(i + 2, j + 7, k + 13), Block.getBlockById(1).getStateFromMeta(0), 2);
        world.setBlockState(new BlockPos(i + 3, j + 7, k + 13), Block.getBlockById(1).getStateFromMeta(0), 2);
        world.setBlockState(new BlockPos(i + 4, j + 7, k + 13), Block.getBlockById(1).getStateFromMeta(0), 2);
        world.setBlockState(new BlockPos(i + 5, j + 7, k + 13), Block.getBlockById(1).getStateFromMeta(0), 2);
        world.setBlockState(new BlockPos(i + 6, j + 7, k + 13), Block.getBlockById(1).getStateFromMeta(0), 2);
        world.setBlockState(new BlockPos(i + 7, j + 7, k + 13), Block.getBlockById(1).getStateFromMeta(0), 2);
        world.setBlockState(new BlockPos(i + 8, j + 7, k + 13), Block.getBlockById(1).getStateFromMeta(0), 2);
        world.setBlockState(new BlockPos(i + 9, j + 7, k + 13), Block.getBlockById(1).getStateFromMeta(0), 2);
        world.setBlockState(new BlockPos(i + 10, j + 7, k + 13), Block.getBlockById(1).getStateFromMeta(0), 2);
        world.setBlockState(new BlockPos(i + 11, j + 7, k + 13), Block.getBlockById(1).getStateFromMeta(0), 2);
        world.setBlockState(new BlockPos(i + 12, j + 7, k + 13), Block.getBlockById(1).getStateFromMeta(0), 2);
        world.setBlockState(new BlockPos(i + 13, j + 7, k + 13), Block.getBlockById(1).getStateFromMeta(0), 2);
        world.setBlockState(new BlockPos(i + 14, j + 7, k + 13), Block.getBlockById(1).getStateFromMeta(0), 2);
        world.setBlockState(new BlockPos(i + 15, j + 7, k + 13), Block.getBlockById(1).getStateFromMeta(0), 2);
        world.setBlockState(new BlockPos(i + 16, j + 7, k + 13), Block.getBlockById(1).getStateFromMeta(0), 2);
        world.setBlockState(new BlockPos(i + 1, j + 7, k + 14), Block.getBlockById(1).getStateFromMeta(0), 2);
        world.setBlockState(new BlockPos(i + 2, j + 7, k + 14), Block.getBlockById(1).getStateFromMeta(0), 2);
        world.setBlockState(new BlockPos(i + 3, j + 7, k + 14), Block.getBlockById(1).getStateFromMeta(0), 2);
        world.setBlockState(new BlockPos(i + 4, j + 7, k + 14), Block.getBlockById(1).getStateFromMeta(0), 2);
        world.setBlockState(new BlockPos(i + 5, j + 7, k + 14), Block.getBlockById(1).getStateFromMeta(0), 2);
        world.setBlockState(new BlockPos(i + 6, j + 7, k + 14), Block.getBlockById(1).getStateFromMeta(0), 2);
        world.setBlockState(new BlockPos(i + 7, j + 7, k + 14), Block.getBlockById(1).getStateFromMeta(0), 2);
        world.setBlockState(new BlockPos(i + 8, j + 7, k + 14), Block.getBlockById(1).getStateFromMeta(0), 2);
        world.setBlockState(new BlockPos(i + 9, j + 7, k + 14), Block.getBlockById(1).getStateFromMeta(0), 2);
        world.setBlockState(new BlockPos(i + 10, j + 7, k + 14), Block.getBlockById(1).getStateFromMeta(0), 2);
        world.setBlockState(new BlockPos(i + 11, j + 7, k + 14), Block.getBlockById(1).getStateFromMeta(0), 2);
        world.setBlockState(new BlockPos(i + 12, j + 7, k + 14), Block.getBlockById(1).getStateFromMeta(0), 2);
        world.setBlockState(new BlockPos(i + 13, j + 7, k + 14), Block.getBlockById(1).getStateFromMeta(0), 2);
        world.setBlockState(new BlockPos(i + 14, j + 7, k + 14), Block.getBlockById(1).getStateFromMeta(0), 2);
        world.setBlockState(new BlockPos(i + 15, j + 7, k + 14), Block.getBlockById(1).getStateFromMeta(0), 2);
        world.setBlockState(new BlockPos(i + 16, j + 7, k + 14), Block.getBlockById(1).getStateFromMeta(0), 2);
        world.setBlockState(new BlockPos(i + 2, j + 7, k + 15), Block.getBlockById(1).getStateFromMeta(0), 2);
        world.setBlockState(new BlockPos(i + 3, j + 7, k + 15), Block.getBlockById(1).getStateFromMeta(0), 2);
        world.setBlockState(new BlockPos(i + 4, j + 7, k + 15), Block.getBlockById(1).getStateFromMeta(0), 2);
        world.setBlockState(new BlockPos(i + 5, j + 7, k + 15), Block.getBlockById(1).getStateFromMeta(0), 2);
        world.setBlockState(new BlockPos(i + 6, j + 7, k + 15), Block.getBlockById(1).getStateFromMeta(0), 2);
        world.setBlockState(new BlockPos(i + 7, j + 7, k + 15), Block.getBlockById(1).getStateFromMeta(0), 2);
        world.setBlockState(new BlockPos(i + 8, j + 7, k + 15), Block.getBlockById(1).getStateFromMeta(0), 2);
        world.setBlockState(new BlockPos(i + 9, j + 7, k + 15), Block.getBlockById(1).getStateFromMeta(0), 2);
        world.setBlockState(new BlockPos(i + 10, j + 7, k + 15), Block.getBlockById(1).getStateFromMeta(0), 2);
        world.setBlockState(new BlockPos(i + 11, j + 7, k + 15), Block.getBlockById(1).getStateFromMeta(0), 2);
        world.setBlockState(new BlockPos(i + 12, j + 7, k + 15), Block.getBlockById(1).getStateFromMeta(0), 2);
        world.setBlockState(new BlockPos(i + 13, j + 7, k + 15), Block.getBlockById(1).getStateFromMeta(0), 2);
        world.setBlockState(new BlockPos(i + 14, j + 7, k + 15), Block.getBlockById(1).getStateFromMeta(0), 2);
        world.setBlockState(new BlockPos(i + 15, j + 7, k + 15), Block.getBlockById(1).getStateFromMeta(0), 2);
        world.setBlockState(new BlockPos(i + 16, j + 7, k + 15), Block.getBlockById(1).getStateFromMeta(0), 2);
        world.setBlockState(new BlockPos(i + 2, j + 7, k + 16), Block.getBlockById(1).getStateFromMeta(0), 2);
        world.setBlockState(new BlockPos(i + 3, j + 7, k + 16), Block.getBlockById(1).getStateFromMeta(0), 2);
        world.setBlockState(new BlockPos(i + 4, j + 7, k + 16), Block.getBlockById(1).getStateFromMeta(0), 2);
        world.setBlockState(new BlockPos(i + 5, j + 7, k + 16), Block.getBlockById(1).getStateFromMeta(0), 2);
        world.setBlockState(new BlockPos(i + 6, j + 7, k + 16), Block.getBlockById(1).getStateFromMeta(0), 2);
        world.setBlockState(new BlockPos(i + 7, j + 7, k + 16), Block.getBlockById(1).getStateFromMeta(0), 2);
        world.setBlockState(new BlockPos(i + 8, j + 7, k + 16), Block.getBlockById(1).getStateFromMeta(0), 2);
        world.setBlockState(new BlockPos(i + 9, j + 7, k + 16), Block.getBlockById(1).getStateFromMeta(0), 2);
        world.setBlockState(new BlockPos(i + 10, j + 7, k + 16), Block.getBlockById(1).getStateFromMeta(0), 2);
        world.setBlockState(new BlockPos(i + 11, j + 7, k + 16), Block.getBlockById(1).getStateFromMeta(0), 2);
        world.setBlockState(new BlockPos(i + 12, j + 7, k + 16), Block.getBlockById(1).getStateFromMeta(0), 2);
        world.setBlockState(new BlockPos(i + 13, j + 7, k + 16), Block.getBlockById(1).getStateFromMeta(0), 2);
        world.setBlockState(new BlockPos(i + 14, j + 7, k + 16), Block.getBlockById(1).getStateFromMeta(0), 2);
        world.setBlockState(new BlockPos(i + 15, j + 7, k + 16), Block.getBlockById(1).getStateFromMeta(0), 2);
        world.setBlockState(new BlockPos(i + 3, j + 7, k + 17), Block.getBlockById(1).getStateFromMeta(0), 2);
        world.setBlockState(new BlockPos(i + 4, j + 7, k + 17), Block.getBlockById(1).getStateFromMeta(0), 2);
        world.setBlockState(new BlockPos(i + 5, j + 7, k + 17), Block.getBlockById(1).getStateFromMeta(0), 2);
        world.setBlockState(new BlockPos(i + 6, j + 7, k + 17), Block.getBlockById(1).getStateFromMeta(0), 2);
        world.setBlockState(new BlockPos(i + 7, j + 7, k + 17), Block.getBlockById(1).getStateFromMeta(0), 2);
        world.setBlockState(new BlockPos(i + 8, j + 7, k + 17), Block.getBlockById(1).getStateFromMeta(0), 2);
        world.setBlockState(new BlockPos(i + 9, j + 7, k + 17), Block.getBlockById(1).getStateFromMeta(0), 2);
        world.setBlockState(new BlockPos(i + 10, j + 7, k + 17), Block.getBlockById(1).getStateFromMeta(0), 2);
        world.setBlockState(new BlockPos(i + 11, j + 7, k + 17), Block.getBlockById(1).getStateFromMeta(0), 2);
        world.setBlockState(new BlockPos(i + 12, j + 7, k + 17), Block.getBlockById(1).getStateFromMeta(0), 2);
        world.setBlockState(new BlockPos(i + 13, j + 7, k + 17), Block.getBlockById(1).getStateFromMeta(0), 2);
        world.setBlockState(new BlockPos(i + 8, j + 7, k + 18), Block.getBlockById(1).getStateFromMeta(0), 2);
        world.setBlockState(new BlockPos(i + 7, j + 8, k + 0), Block.getBlockById(3).getStateFromMeta(0), 2);
        world.setBlockState(new BlockPos(i + 8, j + 8, k + 0), Block.getBlockById(3).getStateFromMeta(0), 2);
        world.setBlockState(new BlockPos(i + 6, j + 8, k + 1), Block.getBlockById(3).getStateFromMeta(0), 2);
        world.setBlockState(new BlockPos(i + 7, j + 8, k + 1), Block.getBlockById(3).getStateFromMeta(0), 2);
        world.setBlockState(new BlockPos(i + 8, j + 8, k + 1), Block.getBlockById(3).getStateFromMeta(0), 2);
        world.setBlockState(new BlockPos(i + 9, j + 8, k + 1), Block.getBlockById(3).getStateFromMeta(0), 2);
        world.setBlockState(new BlockPos(i + 10, j + 8, k + 1), Block.getBlockById(3).getStateFromMeta(0), 2);
        world.setBlockState(new BlockPos(i + 2, j + 8, k + 2), Block.getBlockById(2).getStateFromMeta(0), 2);
        world.setBlockState(new BlockPos(i + 3, j + 8, k + 2), Block.getBlockById(3).getStateFromMeta(0), 2);
        world.setBlockState(new BlockPos(i + 4, j + 8, k + 2), Block.getBlockById(3).getStateFromMeta(0), 2);
        world.setBlockState(new BlockPos(i + 5, j + 8, k + 2), Block.getBlockById(3).getStateFromMeta(0), 2);
        world.setBlockState(new BlockPos(i + 6, j + 8, k + 2), Block.getBlockById(3).getStateFromMeta(0), 2);
        world.setBlockState(new BlockPos(i + 7, j + 8, k + 2), Block.getBlockById(3).getStateFromMeta(0), 2);
        world.setBlockState(new BlockPos(i + 8, j + 8, k + 2), Block.getBlockById(3).getStateFromMeta(0), 2);
        world.setBlockState(new BlockPos(i + 9, j + 8, k + 2), Block.getBlockById(3).getStateFromMeta(0), 2);
        world.setBlockState(new BlockPos(i + 10, j + 8, k + 2), Block.getBlockById(3).getStateFromMeta(0), 2);
        world.setBlockState(new BlockPos(i + 11, j + 8, k + 2), Block.getBlockById(3).getStateFromMeta(0), 2);
        world.setBlockState(new BlockPos(i + 12, j + 8, k + 2), Block.getBlockById(3).getStateFromMeta(0), 2);
        world.setBlockState(new BlockPos(i + 2, j + 8, k + 3), Block.getBlockById(3).getStateFromMeta(0), 2);
        world.setBlockState(new BlockPos(i + 3, j + 8, k + 3), Block.getBlockById(3).getStateFromMeta(0), 2);
        world.setBlockState(new BlockPos(i + 4, j + 8, k + 3), Block.getBlockById(3).getStateFromMeta(0), 2);
        world.setBlockState(new BlockPos(i + 5, j + 8, k + 3), Block.getBlockById(3).getStateFromMeta(0), 2);
        world.setBlockState(new BlockPos(i + 6, j + 8, k + 3), Block.getBlockById(3).getStateFromMeta(0), 2);
        world.setBlockState(new BlockPos(i + 7, j + 8, k + 3), Block.getBlockById(3).getStateFromMeta(0), 2);
        world.setBlockState(new BlockPos(i + 8, j + 8, k + 3), Block.getBlockById(3).getStateFromMeta(0), 2);
        world.setBlockState(new BlockPos(i + 9, j + 8, k + 3), Block.getBlockById(3).getStateFromMeta(0), 2);
        world.setBlockState(new BlockPos(i + 10, j + 8, k + 3), Block.getBlockById(3).getStateFromMeta(0), 2);
        world.setBlockState(new BlockPos(i + 11, j + 8, k + 3), Block.getBlockById(3).getStateFromMeta(0), 2);
        world.setBlockState(new BlockPos(i + 12, j + 8, k + 3), Block.getBlockById(3).getStateFromMeta(0), 2);
        world.setBlockState(new BlockPos(i + 13, j + 8, k + 3), Block.getBlockById(3).getStateFromMeta(0), 2);
        world.setBlockState(new BlockPos(i + 14, j + 8, k + 3), Block.getBlockById(3).getStateFromMeta(0), 2);
        world.setBlockState(new BlockPos(i + 15, j + 8, k + 3), Block.getBlockById(3).getStateFromMeta(0), 2);
        world.setBlockState(new BlockPos(i + 1, j + 8, k + 4), Block.getBlockById(2).getStateFromMeta(0), 2);
        world.setBlockState(new BlockPos(i + 2, j + 8, k + 4), Block.getBlockById(3).getStateFromMeta(0), 2);
