package net.modjam5.makercommunity.common.world.structure;

import net.minecraft.block.Block;
import net.minecraft.util.math.BlockPos;
import net.minecraft.world.World;

/**
 * @author Tim Biesenbeek
 */
public class VillageStructure2 {

    @SuppressWarnings("deprecation")
    public static void gen(World world, int i, int j, int k){
        world.setBlockState(new BlockPos(i + 5, j + 9, k + 4), Block.getBlockById(3).getStateFromMeta(0), 3);
        world.setBlockState(new BlockPos(i + 6, j + 9, k + 4), Block.getBlockById(3).getStateFromMeta(0), 3);
        world.setBlockState(new BlockPos(i + 7, j + 9, k + 4), Block.getBlockById(3).getStateFromMeta(0), 3);
        world.setBlockState(new BlockPos(i + 8, j + 9, k + 4), Block.getBlockById(3).getStateFromMeta(0), 3);
        world.setBlockState(new BlockPos(i + 9, j + 9, k + 4), Block.getBlockById(3).getStateFromMeta(0), 3);
        world.setBlockState(new BlockPos(i + 10, j + 9, k + 4), Block.getBlockById(3).getStateFromMeta(0), 3);
        world.setBlockState(new BlockPos(i + 11, j + 9, k + 4), Block.getBlockById(3).getStateFromMeta(0), 3);
        world.setBlockState(new BlockPos(i + 12, j + 9, k + 4), Block.getBlockById(3).getStateFromMeta(0), 3);
        world.setBlockState(new BlockPos(i + 13, j + 9, k + 4), Block.getBlockById(3).getStateFromMeta(0), 3);
        world.setBlockState(new BlockPos(i + 14, j + 9, k + 4), Block.getBlockById(3).getStateFromMeta(0), 3);
        world.setBlockState(new BlockPos(i + 15, j + 9, k + 4), Block.getBlockById(3).getStateFromMeta(0), 3);
        world.setBlockState(new BlockPos(i + 16, j + 9, k + 4), Block.getBlockById(2).getStateFromMeta(0), 3);
        world.setBlockState(new BlockPos(i + 1, j + 9, k + 5), Block.getBlockById(2).getStateFromMeta(0), 3);
        world.setBlockState(new BlockPos(i + 2, j + 9, k + 5), Block.getBlockById(3).getStateFromMeta(0), 3);
        world.setBlockState(new BlockPos(i + 3, j + 9, k + 5), Block.getBlockById(3).getStateFromMeta(0), 3);
        world.setBlockState(new BlockPos(i + 4, j + 9, k + 5), Block.getBlockById(3).getStateFromMeta(0), 3);
        world.setBlockState(new BlockPos(i + 5, j + 9, k + 5), Block.getBlockById(3).getStateFromMeta(0), 3);
        world.setBlockState(new BlockPos(i + 6, j + 9, k + 5), Block.getBlockById(3).getStateFromMeta(0), 3);
        world.setBlockState(new BlockPos(i + 7, j + 9, k + 5), Block.getBlockById(2).getStateFromMeta(0), 3);
        world.setBlockState(new BlockPos(i + 8, j + 9, k + 5), Block.getBlockById(3).getStateFromMeta(0), 3);
        world.setBlockState(new BlockPos(i + 9, j + 9, k + 5), Block.getBlockById(3).getStateFromMeta(0), 3);
        world.setBlockState(new BlockPos(i + 10, j + 9, k + 5), Block.getBlockById(3).getStateFromMeta(0), 3);
        world.setBlockState(new BlockPos(i + 11, j + 9, k + 5), Block.getBlockById(3).getStateFromMeta(0), 3);
        world.setBlockState(new BlockPos(i + 12, j + 9, k + 5), Block.getBlockById(3).getStateFromMeta(0), 3);
        world.setBlockState(new BlockPos(i + 13, j + 9, k + 5), Block.getBlockById(3).getStateFromMeta(0), 3);
        world.setBlockState(new BlockPos(i + 14, j + 9, k + 5), Block.getBlockById(3).getStateFromMeta(0), 3);
        world.setBlockState(new BlockPos(i + 15, j + 9, k + 5), Block.getBlockById(3).getStateFromMeta(0), 3);
        world.setBlockState(new BlockPos(i + 16, j + 9, k + 5), Block.getBlockById(3).getStateFromMeta(0), 3);
        world.setBlockState(new BlockPos(i + 1, j + 9, k + 6), Block.getBlockById(3).getStateFromMeta(0), 3);
        world.setBlockState(new BlockPos(i + 2, j + 9, k + 6), Block.getBlockById(3).getStateFromMeta(0), 3);
        world.setBlockState(new BlockPos(i + 3, j + 9, k + 6), Block.getBlockById(3).getStateFromMeta(0), 3);
        world.setBlockState(new BlockPos(i + 4, j + 9, k + 6), Block.getBlockById(3).getStateFromMeta(0), 3);
        world.setBlockState(new BlockPos(i + 5, j + 9, k + 6), Block.getBlockById(3).getStateFromMeta(0), 3);
        world.setBlockState(new BlockPos(i + 6, j + 9, k + 6), Block.getBlockById(3).getStateFromMeta(0), 3);
        world.setBlockState(new BlockPos(i + 7, j + 9, k + 6), Block.getBlockById(3).getStateFromMeta(0), 3);
        world.setBlockState(new BlockPos(i + 8, j + 9, k + 6), Block.getBlockById(3).getStateFromMeta(0), 3);
        world.setBlockState(new BlockPos(i + 9, j + 9, k + 6), Block.getBlockById(3).getStateFromMeta(0), 3);
        world.setBlockState(new BlockPos(i + 10, j + 9, k + 6), Block.getBlockById(3).getStateFromMeta(0), 3);
        world.setBlockState(new BlockPos(i + 11, j + 9, k + 6), Block.getBlockById(3).getStateFromMeta(0), 3);
        world.setBlockState(new BlockPos(i + 12, j + 9, k + 6), Block.getBlockById(3).getStateFromMeta(0), 3);
        world.setBlockState(new BlockPos(i + 13, j + 9, k + 6), Block.getBlockById(3).getStateFromMeta(0), 3);
        world.setBlockState(new BlockPos(i + 14, j + 9, k + 6), Block.getBlockById(3).getStateFromMeta(0), 3);
        world.setBlockState(new BlockPos(i + 15, j + 9, k + 6), Block.getBlockById(3).getStateFromMeta(0), 3);
        world.setBlockState(new BlockPos(i + 16, j + 9, k + 6), Block.getBlockById(3).getStateFromMeta(0), 3);
        world.setBlockState(new BlockPos(i + 1, j + 9, k + 7), Block.getBlockById(3).getStateFromMeta(0), 3);
        world.setBlockState(new BlockPos(i + 2, j + 9, k + 7), Block.getBlockById(9).getStateFromMeta(0), 3);
        world.setBlockState(new BlockPos(i + 3, j + 9, k + 7), Block.getBlockById(9).getStateFromMeta(0), 3);
        world.setBlockState(new BlockPos(i + 4, j + 9, k + 7), Block.getBlockById(9).getStateFromMeta(0), 3);
        world.setBlockState(new BlockPos(i + 5, j + 9, k + 7), Block.getBlockById(3).getStateFromMeta(0), 3);
        world.setBlockState(new BlockPos(i + 6, j + 9, k + 7), Block.getBlockById(3).getStateFromMeta(0), 3);
        world.setBlockState(new BlockPos(i + 7, j + 9, k + 7), Block.getBlockById(3).getStateFromMeta(0), 3);
        world.setBlockState(new BlockPos(i + 8, j + 9, k + 7), Block.getBlockById(3).getStateFromMeta(0), 3);
        world.setBlockState(new BlockPos(i + 9, j + 9, k + 7), Block.getBlockById(3).getStateFromMeta(0), 3);
        world.setBlockState(new BlockPos(i + 10, j + 9, k + 7), Block.getBlockById(3).getStateFromMeta(0), 3);
        world.setBlockState(new BlockPos(i + 11, j + 9, k + 7), Block.getBlockById(3).getStateFromMeta(0), 3);
        world.setBlockState(new BlockPos(i + 12, j + 9, k + 7), Block.getBlockById(3).getStateFromMeta(0), 3);
        world.setBlockState(new BlockPos(i + 13, j + 9, k + 7), Block.getBlockById(3).getStateFromMeta(0), 3);
        world.setBlockState(new BlockPos(i + 14, j + 9, k + 7), Block.getBlockById(3).getStateFromMeta(0), 3);
        world.setBlockState(new BlockPos(i + 15, j + 9, k + 7), Block.getBlockById(3).getStateFromMeta(0), 3);
        world.setBlockState(new BlockPos(i + 16, j + 9, k + 7), Block.getBlockById(3).getStateFromMeta(0), 3);
        world.setBlockState(new BlockPos(i + 17, j + 9, k + 7), Block.getBlockById(2).getStateFromMeta(0), 3);
        world.setBlockState(new BlockPos(i + 0, j + 9, k + 8), Block.getBlockById(3).getStateFromMeta(0), 3);
        world.setBlockState(new BlockPos(i + 1, j + 9, k + 8), Block.getBlockById(3).getStateFromMeta(0), 3);
        world.setBlockState(new BlockPos(i + 2, j + 9, k + 8), Block.getBlockById(9).getStateFromMeta(0), 3);
        world.setBlockState(new BlockPos(i + 3, j + 9, k + 8), Block.getBlockById(9).getStateFromMeta(0), 3);
        world.setBlockState(new BlockPos(i + 4, j + 9, k + 8), Block.getBlockById(9).getStateFromMeta(0), 3);
        world.setBlockState(new BlockPos(i + 5, j + 9, k + 8), Block.getBlockById(3).getStateFromMeta(0), 3);
        world.setBlockState(new BlockPos(i + 6, j + 9, k + 8), Block.getBlockById(3).getStateFromMeta(0), 3);
        world.setBlockState(new BlockPos(i + 7, j + 9, k + 8), Block.getBlockById(3).getStateFromMeta(0), 3);
        world.setBlockState(new BlockPos(i + 8, j + 9, k + 8), Block.getBlockById(3).getStateFromMeta(0), 3);
        world.setBlockState(new BlockPos(i + 9, j + 9, k + 8), Block.getBlockById(3).getStateFromMeta(0), 3);
        world.setBlockState(new BlockPos(i + 10, j + 9, k + 8), Block.getBlockById(3).getStateFromMeta(0), 3);
        world.setBlockState(new BlockPos(i + 11, j + 9, k + 8), Block.getBlockById(3).getStateFromMeta(0), 3);
        world.setBlockState(new BlockPos(i + 12, j + 9, k + 8), Block.getBlockById(3).getStateFromMeta(0), 3);
        world.setBlockState(new BlockPos(i + 13, j + 9, k + 8), Block.getBlockById(3).getStateFromMeta(0), 3);
        world.setBlockState(new BlockPos(i + 14, j + 9, k + 8), Block.getBlockById(3).getStateFromMeta(0), 3);
        world.setBlockState(new BlockPos(i + 15, j + 9, k + 8), Block.getBlockById(3).getStateFromMeta(0), 3);
        world.setBlockState(new BlockPos(i + 16, j + 9, k + 8), Block.getBlockById(3).getStateFromMeta(0), 3);
        world.setBlockState(new BlockPos(i + 17, j + 9, k + 8), Block.getBlockById(2).getStateFromMeta(0), 3);
        world.setBlockState(new BlockPos(i + 0, j + 9, k + 9), Block.getBlockById(3).getStateFromMeta(0), 3);
        world.setBlockState(new BlockPos(i + 1, j + 9, k + 9), Block.getBlockById(3).getStateFromMeta(0), 3);
        world.setBlockState(new BlockPos(i + 2, j + 9, k + 9), Block.getBlockById(9).getStateFromMeta(0), 3);
        world.setBlockState(new BlockPos(i + 3, j + 9, k + 9), Block.getBlockById(9).getStateFromMeta(0), 3);
        world.setBlockState(new BlockPos(i + 4, j + 9, k + 9), Block.getBlockById(9).getStateFromMeta(0), 3);
        world.setBlockState(new BlockPos(i + 5, j + 9, k + 9), Block.getBlockById(3).getStateFromMeta(0), 3);
        world.setBlockState(new BlockPos(i + 6, j + 9, k + 9), Block.getBlockById(3).getStateFromMeta(0), 3);
        world.setBlockState(new BlockPos(i + 7, j + 9, k + 9), Block.getBlockById(3).getStateFromMeta(0), 3);
        world.setBlockState(new BlockPos(i + 8, j + 9, k + 9), Block.getBlockById(3).getStateFromMeta(0), 3);
        world.setBlockState(new BlockPos(i + 9, j + 9, k + 9), Block.getBlockById(3).getStateFromMeta(0), 3);
        world.setBlockState(new BlockPos(i + 10, j + 9, k + 9), Block.getBlockById(3).getStateFromMeta(0), 3);
        world.setBlockState(new BlockPos(i + 11, j + 9, k + 9), Block.getBlockById(3).getStateFromMeta(0), 3);
        world.setBlockState(new BlockPos(i + 12, j + 9, k + 9), Block.getBlockById(3).getStateFromMeta(0), 3);
        world.setBlockState(new BlockPos(i + 13, j + 9, k + 9), Block.getBlockById(3).getStateFromMeta(0), 3);
        world.setBlockState(new BlockPos(i + 14, j + 9, k + 9), Block.getBlockById(3).getStateFromMeta(0), 3);
        world.setBlockState(new BlockPos(i + 15, j + 9, k + 9), Block.getBlockById(3).getStateFromMeta(0), 3);
        world.setBlockState(new BlockPos(i + 16, j + 9, k + 9), Block.getBlockById(3).getStateFromMeta(0), 3);
        world.setBlockState(new BlockPos(i + 17, j + 9, k + 9), Block.getBlockById(2).getStateFromMeta(0), 3);
        world.setBlockState(new BlockPos(i + 0, j + 9, k + 10), Block.getBlockById(3).getStateFromMeta(0), 3);
        world.setBlockState(new BlockPos(i + 1, j + 9, k + 10), Block.getBlockById(3).getStateFromMeta(0), 3);
        world.setBlockState(new BlockPos(i + 2, j + 9, k + 10), Block.getBlockById(9).getStateFromMeta(0), 3);
        world.setBlockState(new BlockPos(i + 3, j + 9, k + 10), Block.getBlockById(9).getStateFromMeta(0), 3);
        world.setBlockState(new BlockPos(i + 4, j + 9, k + 10), Block.getBlockById(9).getStateFromMeta(0), 3);
        world.setBlockState(new BlockPos(i + 5, j + 9, k + 10), Block.getBlockById(3).getStateFromMeta(0), 3);
        world.setBlockState(new BlockPos(i + 6, j + 9, k + 10), Block.getBlockById(3).getStateFromMeta(0), 3);
        world.setBlockState(new BlockPos(i + 7, j + 9, k + 10), Block.getBlockById(3).getStateFromMeta(0), 3);
        world.setBlockState(new BlockPos(i + 8, j + 9, k + 10), Block.getBlockById(3).getStateFromMeta(0), 3);
        world.setBlockState(new BlockPos(i + 9, j + 9, k + 10), Block.getBlockById(3).getStateFromMeta(0), 3);
        world.setBlockState(new BlockPos(i + 10, j + 9, k + 10), Block.getBlockById(3).getStateFromMeta(0), 3);
        world.setBlockState(new BlockPos(i + 11, j + 9, k + 10), Block.getBlockById(3).getStateFromMeta(0), 3);
        world.setBlockState(new BlockPos(i + 12, j + 9, k + 10), Block.getBlockById(3).getStateFromMeta(0), 3);
        world.setBlockState(new BlockPos(i + 13, j + 9, k + 10), Block.getBlockById(3).getStateFromMeta(0), 3);
        world.setBlockState(new BlockPos(i + 14, j + 9, k + 10), Block.getBlockById(3).getStateFromMeta(0), 3);
        world.setBlockState(new BlockPos(i + 15, j + 9, k + 10), Block.getBlockById(3).getStateFromMeta(0), 3);
        world.setBlockState(new BlockPos(i + 16, j + 9, k + 10), Block.getBlockById(3).getStateFromMeta(0), 3);
        world.setBlockState(new BlockPos(i + 17, j + 9, k + 10), Block.getBlockById(2).getStateFromMeta(0), 3);
        world.setBlockState(new BlockPos(i + 1, j + 9, k + 11), Block.getBlockById(3).getStateFromMeta(0), 3);
        world.setBlockState(new BlockPos(i + 2, j + 9, k + 11), Block.getBlockById(9).getStateFromMeta(0), 3);
        world.setBlockState(new BlockPos(i + 3, j + 9, k + 11), Block.getBlockById(9).getStateFromMeta(0), 3);
        world.setBlockState(new BlockPos(i + 4, j + 9, k + 11), Block.getBlockById(9).getStateFromMeta(0), 3);
        world.setBlockState(new BlockPos(i + 5, j + 9, k + 11), Block.getBlockById(3).getStateFromMeta(0), 3);
        world.setBlockState(new BlockPos(i + 6, j + 9, k + 11), Block.getBlockById(3).getStateFromMeta(0), 3);
        world.setBlockState(new BlockPos(i + 7, j + 9, k + 11), Block.getBlockById(3).getStateFromMeta(0), 3);
        world.setBlockState(new BlockPos(i + 8, j + 9, k + 11), Block.getBlockById(3).getStateFromMeta(0), 3);
        world.setBlockState(new BlockPos(i + 9, j + 9, k + 11), Block.getBlockById(3).getStateFromMeta(0), 3);
        world.setBlockState(new BlockPos(i + 10, j + 9, k + 11), Block.getBlockById(3).getStateFromMeta(0), 3);
        world.setBlockState(new BlockPos(i + 11, j + 9, k + 11), Block.getBlockById(3).getStateFromMeta(0), 3);
        world.setBlockState(new BlockPos(i + 12, j + 9, k + 11), Block.getBlockById(3).getStateFromMeta(0), 3);
        world.setBlockState(new BlockPos(i + 13, j + 9, k + 11), Block.getBlockById(3).getStateFromMeta(0), 3);
        world.setBlockState(new BlockPos(i + 14, j + 9, k + 11), Block.getBlockById(3).getStateFromMeta(0), 3);
        world.setBlockState(new BlockPos(i + 15, j + 9, k + 11), Block.getBlockById(3).getStateFromMeta(0), 3);
        world.setBlockState(new BlockPos(i + 16, j + 9, k + 11), Block.getBlockById(3).getStateFromMeta(0), 3);
        world.setBlockState(new BlockPos(i + 17, j + 9, k + 11), Block.getBlockById(2).getStateFromMeta(0), 3);
        world.setBlockState(new BlockPos(i + 1, j + 9, k + 12), Block.getBlockById(3).getStateFromMeta(0), 3);
        world.setBlockState(new BlockPos(i + 2, j + 9, k + 12), Block.getBlockById(9).getStateFromMeta(0), 3);
        world.setBlockState(new BlockPos(i + 3, j + 9, k + 12), Block.getBlockById(9).getStateFromMeta(0), 3);
        world.setBlockState(new BlockPos(i + 4, j + 9, k + 12), Block.getBlockById(9).getStateFromMeta(0), 3);
        world.setBlockState(new BlockPos(i + 5, j + 9, k + 12), Block.getBlockById(3).getStateFromMeta(0), 3);
        world.setBlockState(new BlockPos(i + 6, j + 9, k + 12), Block.getBlockById(3).getStateFromMeta(0), 3);
        world.setBlockState(new BlockPos(i + 7, j + 9, k + 12), Block.getBlockById(3).getStateFromMeta(0), 3);
        world.setBlockState(new BlockPos(i + 8, j + 9, k + 12), Block.getBlockById(3).getStateFromMeta(0), 3);
        world.setBlockState(new BlockPos(i + 9, j + 9, k + 12), Block.getBlockById(3).getStateFromMeta(0), 3);
        world.setBlockState(new BlockPos(i + 10, j + 9, k + 12), Block.getBlockById(3).getStateFromMeta(0), 3);
        world.setBlockState(new BlockPos(i + 11, j + 9, k + 12), Block.getBlockById(3).getStateFromMeta(0), 3);
        world.setBlockState(new BlockPos(i + 12, j + 9, k + 12), Block.getBlockById(3).getStateFromMeta(0), 3);
        world.setBlockState(new BlockPos(i + 13, j + 9, k + 12), Block.getBlockById(3).getStateFromMeta(0), 3);
        world.setBlockState(new BlockPos(i + 14, j + 9, k + 12), Block.getBlockById(3).getStateFromMeta(0), 3);
        world.setBlockState(new BlockPos(i + 15, j + 9, k + 12), Block.getBlockById(3).getStateFromMeta(0), 3);
        world.setBlockState(new BlockPos(i + 16, j + 9, k + 12), Block.getBlockById(3).getStateFromMeta(0), 3);
        world.setBlockState(new BlockPos(i + 17, j + 9, k + 12), Block.getBlockById(2).getStateFromMeta(0), 3);
        world.setBlockState(new BlockPos(i + 1, j + 9, k + 13), Block.getBlockById(2).getStateFromMeta(0), 3);
        world.setBlockState(new BlockPos(i + 2, j + 9, k + 13), Block.getBlockById(3).getStateFromMeta(0), 3);
        world.setBlockState(new BlockPos(i + 3, j + 9, k + 13), Block.getBlockById(3).getStateFromMeta(0), 3);
        world.setBlockState(new BlockPos(i + 4, j + 9, k + 13), Block.getBlockById(3).getStateFromMeta(0), 3);
        world.setBlockState(new BlockPos(i + 5, j + 9, k + 13), Block.getBlockById(3).getStateFromMeta(0), 3);
        world.setBlockState(new BlockPos(i + 6, j + 9, k + 13), Block.getBlockById(3).getStateFromMeta(0), 3);
        world.setBlockState(new BlockPos(i + 7, j + 9, k + 13), Block.getBlockById(3).getStateFromMeta(0), 3);
        world.setBlockState(new BlockPos(i + 8, j + 9, k + 13), Block.getBlockById(3).getStateFromMeta(0), 3);
        world.setBlockState(new BlockPos(i + 9, j + 9, k + 13), Block.getBlockById(3).getStateFromMeta(0), 3);
        world.setBlockState(new BlockPos(i + 10, j + 9, k + 13), Block.getBlockById(3).getStateFromMeta(0), 3);
        world.setBlockState(new BlockPos(i + 11, j + 9, k + 13), Block.getBlockById(3).getStateFromMeta(0), 3);
        world.setBlockState(new BlockPos(i + 12, j + 9, k + 13), Block.getBlockById(3).getStateFromMeta(0), 3);
        world.setBlockState(new BlockPos(i + 13, j + 9, k + 13), Block.getBlockById(3).getStateFromMeta(0), 3);
        world.setBlockState(new BlockPos(i + 14, j + 9, k + 13), Block.getBlockById(3).getStateFromMeta(0), 3);
        world.setBlockState(new BlockPos(i + 15, j + 9, k + 13), Block.getBlockById(3).getStateFromMeta(0), 3);
        world.setBlockState(new BlockPos(i + 16, j + 9, k + 13), Block.getBlockById(3).getStateFromMeta(0), 3);
        world.setBlockState(new BlockPos(i + 1, j + 9, k + 14), Block.getBlockById(2).getStateFromMeta(0), 3);
        world.setBlockState(new BlockPos(i + 2, j + 9, k + 14), Block.getBlockById(3).getStateFromMeta(0), 3);
        world.setBlockState(new BlockPos(i + 3, j + 9, k + 14), Block.getBlockById(3).getStateFromMeta(0), 3);
        world.setBlockState(new BlockPos(i + 4, j + 9, k + 14), Block.getBlockById(3).getStateFromMeta(0), 3);
        world.setBlockState(new BlockPos(i + 5, j + 9, k + 14), Block.getBlockById(3).getStateFromMeta(0), 3);
        world.setBlockState(new BlockPos(i + 6, j + 9, k + 14), Block.getBlockById(3).getStateFromMeta(0), 3);
        world.setBlockState(new BlockPos(i + 7, j + 9, k + 14), Block.getBlockById(3).getStateFromMeta(0), 3);
        world.setBlockState(new BlockPos(i + 8, j + 9, k + 14), Block.getBlockById(3).getStateFromMeta(0), 3);
        world.setBlockState(new BlockPos(i + 9, j + 9, k + 14), Block.getBlockById(3).getStateFromMeta(0), 3);
        world.setBlockState(new BlockPos(i + 10, j + 9, k + 14), Block.getBlockById(3).getStateFromMeta(0), 3);
        world.setBlockState(new BlockPos(i + 11, j + 9, k + 14), Block.getBlockById(3).getStateFromMeta(0), 3);
        world.setBlockState(new BlockPos(i + 12, j + 9, k + 14), Block.getBlockById(3).getStateFromMeta(0), 3);
        world.setBlockState(new BlockPos(i + 13, j + 9, k + 14), Block.getBlockById(3).getStateFromMeta(0), 3);
        world.setBlockState(new BlockPos(i + 14, j + 9, k + 14), Block.getBlockById(3).getStateFromMeta(0), 3);
        world.setBlockState(new BlockPos(i + 15, j + 9, k + 14), Block.getBlockById(3).getStateFromMeta(0), 3);
        world.setBlockState(new BlockPos(i + 16, j + 9, k + 14), Block.getBlockById(2).getStateFromMeta(0), 3);
        world.setBlockState(new BlockPos(i + 2, j + 9, k + 15), Block.getBlockById(3).getStateFromMeta(0), 3);
        world.setBlockState(new BlockPos(i + 3, j + 9, k + 15), Block.getBlockById(3).getStateFromMeta(0), 3);
        world.setBlockState(new BlockPos(i + 4, j + 9, k + 15), Block.getBlockById(3).getStateFromMeta(0), 3);
        world.setBlockState(new BlockPos(i + 5, j + 9, k + 15), Block.getBlockById(3).getStateFromMeta(0), 3);
        world.setBlockState(new BlockPos(i + 6, j + 9, k + 15), Block.getBlockById(3).getStateFromMeta(0), 3);
        world.setBlockState(new BlockPos(i + 7, j + 9, k + 15), Block.getBlockById(3).getStateFromMeta(0), 3);
        world.setBlockState(new BlockPos(i + 8, j + 9, k + 15), Block.getBlockById(3).getStateFromMeta(0), 3);
        world.setBlockState(new BlockPos(i + 9, j + 9, k + 15), Block.getBlockById(3).getStateFromMeta(0), 3);
        world.setBlockState(new BlockPos(i + 10, j + 9, k + 15), Block.getBlockById(3).getStateFromMeta(0), 3);
        world.setBlockState(new BlockPos(i + 11, j + 9, k + 15), Block.getBlockById(3).getStateFromMeta(0), 3);
        world.setBlockState(new BlockPos(i + 12, j + 9, k + 15), Block.getBlockById(3).getStateFromMeta(0), 3);
        world.setBlockState(new BlockPos(i + 13, j + 9, k + 15), Block.getBlockById(3).getStateFromMeta(0), 3);
        world.setBlockState(new BlockPos(i + 14, j + 9, k + 15), Block.getBlockById(3).getStateFromMeta(0), 3);
        world.setBlockState(new BlockPos(i + 15, j + 9, k + 15), Block.getBlockById(2).getStateFromMeta(0), 3);
        world.setBlockState(new BlockPos(i + 2, j + 9, k + 16), Block.getBlockById(31).getStateFromMeta(1), 3);
        world.setBlockState(new BlockPos(i + 3, j + 9, k + 16), Block.getBlockById(3).getStateFromMeta(0), 3);
        world.setBlockState(new BlockPos(i + 4, j + 9, k + 16), Block.getBlockById(3).getStateFromMeta(0), 3);
        world.setBlockState(new BlockPos(i + 5, j + 9, k + 16), Block.getBlockById(3).getStateFromMeta(0), 3);
        world.setBlockState(new BlockPos(i + 6, j + 9, k + 16), Block.getBlockById(3).getStateFromMeta(0), 3);
        world.setBlockState(new BlockPos(i + 7, j + 9, k + 16), Block.getBlockById(3).getStateFromMeta(0), 3);
        world.setBlockState(new BlockPos(i + 8, j + 9, k + 16), Block.getBlockById(3).getStateFromMeta(0), 3);
        world.setBlockState(new BlockPos(i + 9, j + 9, k + 16), Block.getBlockById(3).getStateFromMeta(0), 3);
        world.setBlockState(new BlockPos(i + 10, j + 9, k + 16), Block.getBlockById(3).getStateFromMeta(0), 3);
        world.setBlockState(new BlockPos(i + 11, j + 9, k + 16), Block.getBlockById(3).getStateFromMeta(0), 3);
        world.setBlockState(new BlockPos(i + 12, j + 9, k + 16), Block.getBlockById(3).getStateFromMeta(0), 3);
        world.setBlockState(new BlockPos(i + 13, j + 9, k + 16), Block.getBlockById(3).getStateFromMeta(0), 3);
        world.setBlockState(new BlockPos(i + 14, j + 9, k + 16), Block.getBlockById(2).getStateFromMeta(0), 3);
        world.setBlockState(new BlockPos(i + 15, j + 9, k + 16), Block.getBlockById(175).getStateFromMeta(2), 3);
        world.setBlockState(new BlockPos(i + 3, j + 9, k + 17), Block.getBlockById(2).getStateFromMeta(0), 3);
        world.setBlockState(new BlockPos(i + 4, j + 9, k + 17), Block.getBlockById(2).getStateFromMeta(0), 3);
        world.setBlockState(new BlockPos(i + 5, j + 9, k + 17), Block.getBlockById(2).getStateFromMeta(0), 3);
        world.setBlockState(new BlockPos(i + 6, j + 9, k + 17), Block.getBlockById(3).getStateFromMeta(0), 3);
        world.setBlockState(new BlockPos(i + 7, j + 9, k + 17), Block.getBlockById(3).getStateFromMeta(0), 3);
        world.setBlockState(new BlockPos(i + 8, j + 9, k + 17), Block.getBlockById(3).getStateFromMeta(0), 3);
        world.setBlockState(new BlockPos(i + 9, j + 9, k + 17), Block.getBlockById(3).getStateFromMeta(0), 3);
        world.setBlockState(new BlockPos(i + 10, j + 9, k + 17), Block.getBlockById(3).getStateFromMeta(0), 3);
        world.setBlockState(new BlockPos(i + 11, j + 9, k + 17), Block.getBlockById(2).getStateFromMeta(0), 3);
        world.setBlockState(new BlockPos(i + 12, j + 9, k + 17), Block.getBlockById(2).getStateFromMeta(0), 3);
        world.setBlockState(new BlockPos(i + 7, j + 9, k + 18), Block.getBlockById(2).getStateFromMeta(0), 3);
        world.setBlockState(new BlockPos(i + 8, j + 9, k + 18), Block.getBlockById(2).getStateFromMeta(0), 3);
        world.setBlockState(new BlockPos(i + 9, j + 9, k + 18), Block.getBlockById(2).getStateFromMeta(0), 3);
        world.setBlockState(new BlockPos(i + 6, j + 10, k + 0), Block.getBlockById(2).getStateFromMeta(0), 3);
        world.setBlockState(new BlockPos(i + 7, j + 10, k + 0), Block.getBlockById(208).getStateFromMeta(0), 3);
        world.setBlockState(new BlockPos(i + 8, j + 10, k + 0), Block.getBlockById(208).getStateFromMeta(0), 3);
        world.setBlockState(new BlockPos(i + 9, j + 10, k + 0), Block.getBlockById(2).getStateFromMeta(0), 3);
        world.setBlockState(new BlockPos(i + 10, j + 10, k + 0), Block.getBlockById(2).getStateFromMeta(0), 3);
        world.setBlockState(new BlockPos(i + 4, j + 10, k + 1), Block.getBlockById(2).getStateFromMeta(0), 3);
        world.setBlockState(new BlockPos(i + 5, j + 10, k + 1), Block.getBlockById(2).getStateFromMeta(0), 3);
        world.setBlockState(new BlockPos(i + 6, j + 10, k + 1), Block.getBlockById(2).getStateFromMeta(0), 3);
        world.setBlockState(new BlockPos(i + 7, j + 10, k + 1), Block.getBlockById(208).getStateFromMeta(0), 3);
        world.setBlockState(new BlockPos(i + 8, j + 10, k + 1), Block.getBlockById(208).getStateFromMeta(0), 3);
        world.setBlockState(new BlockPos(i + 9, j + 10, k + 1), Block.getBlockById(2).getStateFromMeta(0), 3);
        world.setBlockState(new BlockPos(i + 10, j + 10, k + 1), Block.getBlockById(2).getStateFromMeta(0), 3);
        world.setBlockState(new BlockPos(i + 11, j + 10, k + 1), Block.getBlockById(2).getStateFromMeta(0), 3);
        world.setBlockState(new BlockPos(i + 12, j + 10, k + 1), Block.getBlockById(2).getStateFromMeta(0), 3);
        world.setBlockState(new BlockPos(i + 3, j + 10, k + 2), Block.getBlockById(2).getStateFromMeta(0), 3);
        world.setBlockState(new BlockPos(i + 4, j + 10, k + 2), Block.getBlockById(2).getStateFromMeta(0), 3);
        world.setBlockState(new BlockPos(i + 5, j + 10, k + 2), Block.getBlockById(2).getStateFromMeta(0), 3);
        world.setBlockState(new BlockPos(i + 6, j + 10, k + 2), Block.getBlockById(2).getStateFromMeta(0), 3);
        world.setBlockState(new BlockPos(i + 7, j + 10, k + 2), Block.getBlockById(208).getStateFromMeta(0), 3);
        world.setBlockState(new BlockPos(i + 8, j + 10, k + 2), Block.getBlockById(208).getStateFromMeta(0), 3);
        world.setBlockState(new BlockPos(i + 9, j + 10, k + 2), Block.getBlockById(2).getStateFromMeta(0), 3);
        world.setBlockState(new BlockPos(i + 10, j + 10, k + 2), Block.getBlockById(2).getStateFromMeta(0), 3);
        world.setBlockState(new BlockPos(i + 11, j + 10, k + 2), Block.getBlockById(2).getStateFromMeta(0), 3);
        world.setBlockState(new BlockPos(i + 12, j + 10, k + 2), Block.getBlockById(2).getStateFromMeta(0), 3);
        world.setBlockState(new BlockPos(i + 13, j + 10, k + 2), Block.getBlockById(2).getStateFromMeta(0), 3);
        world.setBlockState(new BlockPos(i + 2, j + 10, k + 3), Block.getBlockById(31).getStateFromMeta(1), 3);
        world.setBlockState(new BlockPos(i + 3, j + 10, k + 3), Block.getBlockById(2).getStateFromMeta(0), 3);
        world.setBlockState(new BlockPos(i + 4, j + 10, k + 3), Block.getBlockById(2).getStateFromMeta(0), 3);
        world.setBlockState(new BlockPos(i + 5, j + 10, k + 3), Block.getBlockById(2).getStateFromMeta(0), 3);
        world.setBlockState(new BlockPos(i + 6, j + 10, k + 3), Block.getBlockById(2).getStateFromMeta(0), 3);
        world.setBlockState(new BlockPos(i + 7, j + 10, k + 3), Block.getBlockById(208).getStateFromMeta(0), 3);
        world.setBlockState(new BlockPos(i + 8, j + 10, k + 3), Block.getBlockById(208).getStateFromMeta(0), 3);
        world.setBlockState(new BlockPos(i + 9, j + 10, k + 3), Block.getBlockById(2).getStateFromMeta(0), 3);
        world.setBlockState(new BlockPos(i + 10, j + 10, k + 3), Block.getBlockById(2).getStateFromMeta(0), 3);
        world.setBlockState(new BlockPos(i + 11, j + 10, k + 3), Block.getBlockById(2).getStateFromMeta(0), 3);
        world.setBlockState(new BlockPos(i + 12, j + 10, k + 3), Block.getBlockById(2).getStateFromMeta(0), 3);
        world.setBlockState(new BlockPos(i + 13, j + 10, k + 3), Block.getBlockById(2).getStateFromMeta(0), 3);
        world.setBlockState(new BlockPos(i + 14, j + 10, k + 3), Block.getBlockById(2).getStateFromMeta(0), 3);
        world.setBlockState(new BlockPos(i + 2, j + 10, k + 4), Block.getBlockById(2).getStateFromMeta(0), 3);
        world.setBlockState(new BlockPos(i + 3, j + 10, k + 4), Block.getBlockById(2).getStateFromMeta(0), 3);
        world.setBlockState(new BlockPos(i + 4, j + 10, k + 4), Block.getBlockById(2).getStateFromMeta(0), 3);
        world.setBlockState(new BlockPos(i + 5, j + 10, k + 4), Block.getBlockById(2).getStateFromMeta(0), 3);
        world.setBlockState(new BlockPos(i + 6, j + 10, k + 4), Block.getBlockById(2).getStateFromMeta(0), 3);
        world.setBlockState(new BlockPos(i + 7, j + 10, k + 4), Block.getBlockById(208).getStateFromMeta(0), 3);
        world.setBlockState(new BlockPos(i + 8, j + 10, k + 4), Block.getBlockById(208).getStateFromMeta(0), 3);
        world.setBlockState(new BlockPos(i + 9, j + 10, k + 4), Block.getBlockById(2).getStateFromMeta(0), 3);
        world.setBlockState(new BlockPos(i + 10, j + 10, k + 4), Block.getBlockById(2).getStateFromMeta(0), 3);
        world.setBlockState(new BlockPos(i + 11, j + 10, k + 4), Block.getBlockById(2).getStateFromMeta(0), 3);
        world.setBlockState(new BlockPos(i + 12, j + 10, k + 4), Block.getBlockById(2).getStateFromMeta(0), 3);
        world.setBlockState(new BlockPos(i + 13, j + 10, k + 4), Block.getBlockById(2).getStateFromMeta(0), 3);
        world.setBlockState(new BlockPos(i + 14, j + 10, k + 4), Block.getBlockById(2).getStateFromMeta(0), 3);
        world.setBlockState(new BlockPos(i + 15, j + 10, k + 4), Block.getBlockById(2).getStateFromMeta(0), 3);
        world.setBlockState(new BlockPos(i + 1, j + 10, k + 5), Block.getBlockById(31).getStateFromMeta(1), 3);
        world.setBlockState(new BlockPos(i + 2, j + 10, k + 5), Block.getBlockById(2).getStateFromMeta(0), 3);
        world.setBlockState(new BlockPos(i + 3, j + 10, k + 5), Block.getBlockById(2).getStateFromMeta(0), 3);
        world.setBlockState(new BlockPos(i + 4, j + 10, k + 5), Block.getBlockById(3).getStateFromMeta(0), 3);
        world.setBlockState(new BlockPos(i + 5, j + 10, k + 5), Block.getBlockById(2).getStateFromMeta(0), 3);
        world.setBlockState(new BlockPos(i + 6, j + 10, k + 5), Block.getBlockById(2).getStateFromMeta(0), 3);
        world.setBlockState(new BlockPos(i + 7, j + 10, k + 5), Block.getBlockById(208).getStateFromMeta(0), 3);
        world.setBlockState(new BlockPos(i + 8, j + 10, k + 5), Block.getBlockById(208).getStateFromMeta(0), 3);
        world.setBlockState(new BlockPos(i + 9, j + 10, k + 5), Block.getBlockById(2).getStateFromMeta(0), 3);
        world.setBlockState(new BlockPos(i + 10, j + 10, k + 5), Block.getBlockById(2).getStateFromMeta(0), 3);
        world.setBlockState(new BlockPos(i + 11, j + 10, k + 5), Block.getBlockById(2).getStateFromMeta(0), 3);
        world.setBlockState(new BlockPos(i + 12, j + 10, k + 5), Block.getBlockById(2).getStateFromMeta(0), 3);
        world.setBlockState(new BlockPos(i + 13, j + 10, k + 5), Block.getBlockById(2).getStateFromMeta(0), 3);
        world.setBlockState(new BlockPos(i + 14, j + 10, k + 5), Block.getBlockById(2).getStateFromMeta(0), 3);
        world.setBlockState(new BlockPos(i + 15, j + 10, k + 5), Block.getBlockById(2).getStateFromMeta(0), 3);
        world.setBlockState(new BlockPos(i + 16, j + 10, k + 5), Block.getBlockById(2).getStateFromMeta(0), 3);
        world.setBlockState(new BlockPos(i + 1, j + 10, k + 6), Block.getBlockById(2).getStateFromMeta(0), 3);
        world.setBlockState(new BlockPos(i + 2, j + 10, k + 6), Block.getBlockById(2).getStateFromMeta(0), 3);
        world.setBlockState(new BlockPos(i + 3, j + 10, k + 6), Block.getBlockById(2).getStateFromMeta(0), 3);
        world.setBlockState(new BlockPos(i + 4, j + 10, k + 6), Block.getBlockById(2).getStateFromMeta(0), 3);
        world.setBlockState(new BlockPos(i + 5, j + 10, k + 6), Block.getBlockById(2).getStateFromMeta(0), 3);
        world.setBlockState(new BlockPos(i + 6, j + 10, k + 6), Block.getBlockById(2).getStateFromMeta(0), 3);
        world.setBlockState(new BlockPos(i + 7, j + 10, k + 6), Block.getBlockById(208).getStateFromMeta(0), 3);
        world.setBlockState(new BlockPos(i + 8, j + 10, k + 6), Block.getBlockById(208).getStateFromMeta(0), 3);
        world.setBlockState(new BlockPos(i + 9, j + 10, k + 6), Block.getBlockById(2).getStateFromMeta(0), 3);
        world.setBlockState(new BlockPos(i + 10, j + 10, k + 6), Block.getBlockById(2).getStateFromMeta(0), 3);
        world.setBlockState(new BlockPos(i + 11, j + 10, k + 6), Block.getBlockById(2).getStateFromMeta(0), 3);
        world.setBlockState(new BlockPos(i + 12, j + 10, k + 6), Block.getBlockById(2).getStateFromMeta(0), 3);
        world.setBlockState(new BlockPos(i + 13, j + 10, k + 6), Block.getBlockById(2).getStateFromMeta(0), 3);
        world.setBlockState(new BlockPos(i + 14, j + 10, k + 6), Block.getBlockById(2).getStateFromMeta(0), 3);
        world.setBlockState(new BlockPos(i + 15, j + 10, k + 6), Block.getBlockById(2).getStateFromMeta(0), 3);
        world.setBlockState(new BlockPos(i + 16, j + 10, k + 6), Block.getBlockById(2).getStateFromMeta(0), 3);
        world.setBlockState(new BlockPos(i + 0, j + 10, k + 7), Block.getBlockById(2).getStateFromMeta(0), 3);
        world.setBlockState(new BlockPos(i + 1, j + 10, k + 7), Block.getBlockById(2).getStateFromMeta(0), 3);
        world.setBlockState(new BlockPos(i + 2, j + 10, k + 7), Block.getBlockById(9).getStateFromMeta(0), 3);
        world.setBlockState(new BlockPos(i + 3, j + 10, k + 7), Block.getBlockById(9).getStateFromMeta(0), 3);
        world.setBlockState(new BlockPos(i + 4, j + 10, k + 7), Block.getBlockById(9).getStateFromMeta(0), 3);
        world.setBlockState(new BlockPos(i + 5, j + 10, k + 7), Block.getBlockById(2).getStateFromMeta(0), 3);
        world.setBlockState(new BlockPos(i + 6, j + 10, k + 7), Block.getBlockById(2).getStateFromMeta(0), 3);
        world.setBlockState(new BlockPos(i + 7, j + 10, k + 7), Block.getBlockById(208).getStateFromMeta(0), 3);
        world.setBlockState(new BlockPos(i + 8, j + 10, k + 7), Block.getBlockById(208).getStateFromMeta(0), 3);
        world.setBlockState(new BlockPos(i + 9, j + 10, k + 7), Block.getBlockById(2).getStateFromMeta(0), 3);
        world.setBlockState(new BlockPos(i + 10, j + 10, k + 7), Block.getBlockById(3).getStateFromMeta(0), 3);
        world.setBlockState(new BlockPos(i + 11, j + 10, k + 7), Block.getBlockById(3).getStateFromMeta(0), 3);
        world.setBlockState(new BlockPos(i + 12, j + 10, k + 7), Block.getBlockById(3).getStateFromMeta(0), 3);
        world.setBlockState(new BlockPos(i + 13, j + 10, k + 7), Block.getBlockById(3).getStateFromMeta(0), 3);
        world.setBlockState(new BlockPos(i + 14, j + 10, k + 7), Block.getBlockById(3).getStateFromMeta(0), 3);
        world.setBlockState(new BlockPos(i + 15, j + 10, k + 7), Block.getBlockById(2).getStateFromMeta(0), 3);
        world.setBlockState(new BlockPos(i + 16, j + 10, k + 7), Block.getBlockById(2).getStateFromMeta(0), 3);
        world.setBlockState(new BlockPos(i + 17, j + 10, k + 7), Block.getBlockById(31).getStateFromMeta(1), 3);
        world.setBlockState(new BlockPos(i + 0, j + 10, k + 8), Block.getBlockById(2).getStateFromMeta(0), 3);
        world.setBlockState(new BlockPos(i + 1, j + 10, k + 8), Block.getBlockById(2).getStateFromMeta(0), 3);
        world.setBlockState(new BlockPos(i + 2, j + 10, k + 8), Block.getBlockById(9).getStateFromMeta(0), 3);
        world.setBlockState(new BlockPos(i + 3, j + 10, k + 8), Block.getBlockById(9).getStateFromMeta(0), 3);
        world.setBlockState(new BlockPos(i + 4, j + 10, k + 8), Block.getBlockById(9).getStateFromMeta(0), 3);
        world.setBlockState(new BlockPos(i + 5, j + 10, k + 8), Block.getBlockById(2).getStateFromMeta(0), 3);
        world.setBlockState(new BlockPos(i + 6, j + 10, k + 8), Block.getBlockById(2).getStateFromMeta(0), 3);
        world.setBlockState(new BlockPos(i + 7, j + 10, k + 8), Block.getBlockById(208).getStateFromMeta(0), 3);
        world.setBlockState(new BlockPos(i + 8, j + 10, k + 8), Block.getBlockById(208).getStateFromMeta(0), 3);
        world.setBlockState(new BlockPos(i + 9, j + 10, k + 8), Block.getBlockById(2).getStateFromMeta(0), 3);
        world.setBlockState(new BlockPos(i + 10, j + 10, k + 8), Block.getBlockById(3).getStateFromMeta(0), 3);
        world.setBlockState(new BlockPos(i + 11, j + 10, k + 8), Block.getBlockById(251).getStateFromMeta(0), 3);
        world.setBlockState(new BlockPos(i + 12, j + 10, k + 8), Block.getBlockById(251).getStateFromMeta(0), 3);
        world.setBlockState(new BlockPos(i + 13, j + 10, k + 8), Block.getBlockById(251).getStateFromMeta(0), 3);
        world.setBlockState(new BlockPos(i + 14, j + 10, k + 8), Block.getBlockById(3).getStateFromMeta(0), 3);
        world.setBlockState(new BlockPos(i + 15, j + 10, k + 8), Block.getBlockById(2).getStateFromMeta(0), 3);
        world.setBlockState(new BlockPos(i + 16, j + 10, k + 8), Block.getBlockById(2).getStateFromMeta(0), 3);
        world.setBlockState(new BlockPos(i + 0, j + 10, k + 9), Block.getBlockById(2).getStateFromMeta(0), 3);
        world.setBlockState(new BlockPos(i + 1, j + 10, k + 9), Block.getBlockById(2).getStateFromMeta(0), 3);
        world.setBlockState(new BlockPos(i + 2, j + 10, k + 9), Block.getBlockById(9).getStateFromMeta(0), 3);
        world.setBlockState(new BlockPos(i + 3, j + 10, k + 9), Block.getBlockById(9).getStateFromMeta(0), 3);
        world.setBlockState(new BlockPos(i + 4, j + 10, k + 9), Block.getBlockById(9).getStateFromMeta(0), 3);
        world.setBlockState(new BlockPos(i + 5, j + 10, k + 9), Block.getBlockById(2).getStateFromMeta(0), 3);
        world.setBlockState(new BlockPos(i + 6, j + 10, k + 9), Block.getBlockById(2).getStateFromMeta(0), 3);
        world.setBlockState(new BlockPos(i + 7, j + 10, k + 9), Block.getBlockById(208).getStateFromMeta(0), 3);
        world.setBlockState(new BlockPos(i + 8, j + 10, k + 9), Block.getBlockById(208).getStateFromMeta(0), 3);
        world.setBlockState(new BlockPos(i + 9, j + 10, k + 9), Block.getBlockById(208).getStateFromMeta(0), 3);
        world.setBlockState(new BlockPos(i + 10, j + 10, k + 9), Block.getBlockById(251).getStateFromMeta(0), 3);
        world.setBlockState(new BlockPos(i + 11, j + 10, k + 9), Block.getBlockById(251).getStateFromMeta(0), 3);
        world.setBlockState(new BlockPos(i + 12, j + 10, k + 9), Block.getBlockById(251).getStateFromMeta(0), 3);
        world.setBlockState(new BlockPos(i + 13, j + 10, k + 9), Block.getBlockById(251).getStateFromMeta(0), 3);
        world.setBlockState(new BlockPos(i + 14, j + 10, k + 9), Block.getBlockById(3).getStateFromMeta(0), 3);
        world.setBlockState(new BlockPos(i + 15, j + 10, k + 9), Block.getBlockById(2).getStateFromMeta(0), 3);
        world.setBlockState(new BlockPos(i + 16, j + 10, k + 9), Block.getBlockById(2).getStateFromMeta(0), 3);
        world.setBlockState(new BlockPos(i + 17, j + 10, k + 9), Block.getBlockById(31).getStateFromMeta(1), 3);
        world.setBlockState(new BlockPos(i + 0, j + 10, k + 10), Block.getBlockById(2).getStateFromMeta(0), 3);
        world.setBlockState(new BlockPos(i + 1, j + 10, k + 10), Block.getBlockById(2).getStateFromMeta(0), 3);
        world.setBlockState(new BlockPos(i + 2, j + 10, k + 10), Block.getBlockById(9).getStateFromMeta(0), 3);
        world.setBlockState(new BlockPos(i + 3, j + 10, k + 10), Block.getBlockById(9).getStateFromMeta(0), 3);
        world.setBlockState(new BlockPos(i + 4, j + 10, k + 10), Block.getBlockById(9).getStateFromMeta(0), 3);
        world.setBlockState(new BlockPos(i + 5, j + 10, k + 10), Block.getBlockById(2).getStateFromMeta(0), 3);
        world.setBlockState(new BlockPos(i + 6, j + 10, k + 10), Block.getBlockById(2).getStateFromMeta(0), 3);
        world.setBlockState(new BlockPos(i + 7, j + 10, k + 10), Block.getBlockById(2).getStateFromMeta(0), 3);
        world.setBlockState(new BlockPos(i + 8, j + 10, k + 10), Block.getBlockById(2).getStateFromMeta(0), 3);
        world.setBlockState(new BlockPos(i + 9, j + 10, k + 10), Block.getBlockById(2).getStateFromMeta(0), 3);
        world.setBlockState(new BlockPos(i + 10, j + 10, k + 10), Block.getBlockById(3).getStateFromMeta(0), 3);
        world.setBlockState(new BlockPos(i + 11, j + 10, k + 10), Block.getBlockById(251).getStateFromMeta(0), 3);
        world.setBlockState(new BlockPos(i + 12, j + 10, k + 10), Block.getBlockById(251).getStateFromMeta(0), 3);
        world.setBlockState(new BlockPos(i + 13, j + 10, k + 10), Block.getBlockById(251).getStateFromMeta(0), 3);
        world.setBlockState(new BlockPos(i + 14, j + 10, k + 10), Block.getBlockById(3).getStateFromMeta(0), 3);
        world.setBlockState(new BlockPos(i + 15, j + 10, k + 10), Block.getBlockById(2).getStateFromMeta(0), 3);
        world.setBlockState(new BlockPos(i + 16, j + 10, k + 10), Block.getBlockById(2).getStateFromMeta(0), 3);
        world.setBlockState(new BlockPos(i + 0, j + 10, k + 11), Block.getBlockById(2).getStateFromMeta(0), 3);
        world.setBlockState(new BlockPos(i + 1, j + 10, k + 11), Block.getBlockById(2).getStateFromMeta(0), 3);
        world.setBlockState(new BlockPos(i + 2, j + 10, k + 11), Block.getBlockById(9).getStateFromMeta(0), 3);
        world.setBlockState(new BlockPos(i + 3, j + 10, k + 11), Block.getBlockById(9).getStateFromMeta(0), 3);
        world.setBlockState(new BlockPos(i + 4, j + 10, k + 11), Block.getBlockById(9).getStateFromMeta(0), 3);
        world.setBlockState(new BlockPos(i + 5, j + 10, k + 11), Block.getBlockById(2).getStateFromMeta(0), 3);
        world.setBlockState(new BlockPos(i + 6, j + 10, k + 11), Block.getBlockById(3).getStateFromMeta(0), 3);
        world.setBlockState(new BlockPos(i + 7, j + 10, k + 11), Block.getBlockById(3).getStateFromMeta(0), 3);
        world.setBlockState(new BlockPos(i + 8, j + 10, k + 11), Block.getBlockById(3).getStateFromMeta(0), 3);
        world.setBlockState(new BlockPos(i + 9, j + 10, k + 11), Block.getBlockById(3).getStateFromMeta(0), 3);
        world.setBlockState(new BlockPos(i + 11, j + 10, k + 11), Block.getBlockById(251).getStateFromMeta(0), 3);
        world.setBlockState(new BlockPos(i + 12, j + 10, k + 11), Block.getBlockById(251).getStateFromMeta(0), 3);
        world.setBlockState(new BlockPos(i + 13, j + 10, k + 11), Block.getBlockById(251).getStateFromMeta(0), 3);
        world.setBlockState(new BlockPos(i + 14, j + 10, k + 11), Block.getBlockById(3).getStateFromMeta(0), 3);
        world.setBlockState(new BlockPos(i + 15, j + 10, k + 11), Block.getBlockById(2).getStateFromMeta(0), 3);
        world.setBlockState(new BlockPos(i + 16, j + 10, k + 11), Block.getBlockById(2).getStateFromMeta(0), 3);
        world.setBlockState(new BlockPos(i + 17, j + 10, k + 11), Block.getBlockById(31).getStateFromMeta(1), 3);
        world.setBlockState(new BlockPos(i + 1, j + 10, k + 12), Block.getBlockById(2).getStateFromMeta(0), 3);
        world.setBlockState(new BlockPos(i + 2, j + 10, k + 12), Block.getBlockById(9).getStateFromMeta(0), 3);
        world.setBlockState(new BlockPos(i + 3, j + 10, k + 12), Block.getBlockById(9).getStateFromMeta(0), 3);
        world.setBlockState(new BlockPos(i + 4, j + 10, k + 12), Block.getBlockById(9).getStateFromMeta(0), 3);
        world.setBlockState(new BlockPos(i + 5, j + 10, k + 12), Block.getBlockById(2).getStateFromMeta(0), 3);
        world.setBlockState(new BlockPos(i + 6, j + 10, k + 12), Block.getBlockById(3).getStateFromMeta(0), 3);
        world.setBlockState(new BlockPos(i + 7, j + 10, k + 12), Block.getBlockById(251).getStateFromMeta(0), 3);
        world.setBlockState(new BlockPos(i + 8, j + 10, k + 12), Block.getBlockById(251).getStateFromMeta(0), 3);
        world.setBlockState(new BlockPos(i + 9, j + 10, k + 12), Block.getBlockById(251).getStateFromMeta(0), 3);
        world.setBlockState(new BlockPos(i + 10, j + 10, k + 12), Block.getBlockById(251).getStateFromMeta(0), 3);
        world.setBlockState(new BlockPos(i + 11, j + 10, k + 12), Block.getBlockById(251).getStateFromMeta(0), 3);
        world.setBlockState(new BlockPos(i + 12, j + 10, k + 12), Block.getBlockById(251).getStateFromMeta(0), 3);
        world.setBlockState(new BlockPos(i + 13, j + 10, k + 12), Block.getBlockById(251).getStateFromMeta(0), 3);
        world.setBlockState(new BlockPos(i + 14, j + 10, k + 12), Block.getBlockById(3).getStateFromMeta(0), 3);
        world.setBlockState(new BlockPos(i + 15, j + 10, k + 12), Block.getBlockById(2).getStateFromMeta(0), 3);
        world.setBlockState(new BlockPos(i + 16, j + 10, k + 12), Block.getBlockById(2).getStateFromMeta(0), 3);
        world.setBlockState(new BlockPos(i + 1, j + 10, k + 13), Block.getBlockById(31).getStateFromMeta(1), 3);
        world.setBlockState(new BlockPos(i + 2, j + 10, k + 13), Block.getBlockById(2).getStateFromMeta(0), 3);
        world.setBlockState(new BlockPos(i + 3, j + 10, k + 13), Block.getBlockById(2).getStateFromMeta(0), 3);
        world.setBlockState(new BlockPos(i + 4, j + 10, k + 13), Block.getBlockById(2).getStateFromMeta(0), 3);
        world.setBlockState(new BlockPos(i + 5, j + 10, k + 13), Block.getBlockById(2).getStateFromMeta(0), 3);
        world.setBlockState(new BlockPos(i + 6, j + 10, k + 13), Block.getBlockById(3).getStateFromMeta(0), 3);
        world.setBlockState(new BlockPos(i + 7, j + 10, k + 13), Block.getBlockById(251).getStateFromMeta(0), 3);
        world.setBlockState(new BlockPos(i + 8, j + 10, k + 13), Block.getBlockById(251).getStateFromMeta(0), 3);
        world.setBlockState(new BlockPos(i + 9, j + 10, k + 13), Block.getBlockById(251).getStateFromMeta(0), 3);
        world.setBlockState(new BlockPos(i + 10, j + 10, k + 13), Block.getBlockById(251).getStateFromMeta(0), 3);
        world.setBlockState(new BlockPos(i + 11, j + 10, k + 13), Block.getBlockById(251).getStateFromMeta(0), 3);
        world.setBlockState(new BlockPos(i + 12, j + 10, k + 13), Block.getBlockById(251).getStateFromMeta(0), 3);
        world.setBlockState(new BlockPos(i + 13, j + 10, k + 13), Block.getBlockById(251).getStateFromMeta(0), 3);
        world.setBlockState(new BlockPos(i + 14, j + 10, k + 13), Block.getBlockById(3).getStateFromMeta(0), 3);
        world.setBlockState(new BlockPos(i + 15, j + 10, k + 13), Block.getBlockById(2).getStateFromMeta(0), 3);
        world.setBlockState(new BlockPos(i + 16, j + 10, k + 13), Block.getBlockById(2).getStateFromMeta(0), 3);
        world.setBlockState(new BlockPos(i + 1, j + 10, k + 14), Block.getBlockById(31).getStateFromMeta(1), 3);
        world.setBlockState(new BlockPos(i + 2, j + 10, k + 14), Block.getBlockById(2).getStateFromMeta(0), 3);
        world.setBlockState(new BlockPos(i + 3, j + 10, k + 14), Block.getBlockById(2).getStateFromMeta(0), 3);
        world.setBlockState(new BlockPos(i + 4, j + 10, k + 14), Block.getBlockById(2).getStateFromMeta(0), 3);
        world.setBlockState(new BlockPos(i + 5, j + 10, k + 14), Block.getBlockById(2).getStateFromMeta(0), 3);
        world.setBlockState(new BlockPos(i + 6, j + 10, k + 14), Block.getBlockById(3).getStateFromMeta(0), 3);
        world.setBlockState(new BlockPos(i + 7, j + 10, k + 14), Block.getBlockById(251).getStateFromMeta(0), 3);
        world.setBlockState(new BlockPos(i + 8, j + 10, k + 14), Block.getBlockById(251).getStateFromMeta(0), 3);
        world.setBlockState(new BlockPos(i + 9, j + 10, k + 14), Block.getBlockById(251).getStateFromMeta(0), 3);
        world.setBlockState(new BlockPos(i + 10, j + 10, k + 14), Block.getBlockById(251).getStateFromMeta(0), 3);
        world.setBlockState(new BlockPos(i + 11, j + 10, k + 14), Block.getBlockById(251).getStateFromMeta(0), 3);
        world.setBlockState(new BlockPos(i + 12, j + 10, k + 14), Block.getBlockById(251).getStateFromMeta(0), 3);
        world.setBlockState(new BlockPos(i + 13, j + 10, k + 14), Block.getBlockById(251).getStateFromMeta(0), 3);
        world.setBlockState(new BlockPos(i + 14, j + 10, k + 14), Block.getBlockById(3).getStateFromMeta(0), 3);
        world.setBlockState(new BlockPos(i + 15, j + 10, k + 14), Block.getBlockById(2).getStateFromMeta(0), 3);
        world.setBlockState(new BlockPos(i + 16, j + 10, k + 14), Block.getBlockById(31).getStateFromMeta(1), 3);
        world.setBlockState(new BlockPos(i + 2, j + 10, k + 15), Block.getBlockById(2).getStateFromMeta(0), 3);
        world.setBlockState(new BlockPos(i + 3, j + 10, k + 15), Block.getBlockById(2).getStateFromMeta(0), 3);
        world.setBlockState(new BlockPos(i + 4, j + 10, k + 15), Block.getBlockById(2).getStateFromMeta(0), 3);
        world.setBlockState(new BlockPos(i + 5, j + 10, k + 15), Block.getBlockById(2).getStateFromMeta(0), 3);
        world.setBlockState(new BlockPos(i + 6, j + 10, k + 15), Block.getBlockById(3).getStateFromMeta(0), 3);
        world.setBlockState(new BlockPos(i + 7, j + 10, k + 15), Block.getBlockById(3).getStateFromMeta(0), 3);
        world.setBlockState(new BlockPos(i + 8, j + 10, k + 15), Block.getBlockById(3).getStateFromMeta(0), 3);
        world.setBlockState(new BlockPos(i + 9, j + 10, k + 15), Block.getBlockById(3).getStateFromMeta(0), 3);
        world.setBlockState(new BlockPos(i + 10, j + 10, k + 15), Block.getBlockById(3).getStateFromMeta(0), 3);
        world.setBlockState(new BlockPos(i + 11, j + 10, k + 15), Block.getBlockById(3).getStateFromMeta(0), 3);
        world.setBlockState(new BlockPos(i + 12, j + 10, k + 15), Block.getBlockById(3).getStateFromMeta(0), 3);
        world.setBlockState(new BlockPos(i + 13, j + 10, k + 15), Block.getBlockById(3).getStateFromMeta(0), 3);
        world.setBlockState(new BlockPos(i + 14, j + 10, k + 15), Block.getBlockById(17).getStateFromMeta(1), 3);
        world.setBlockState(new BlockPos(i + 15, j + 10, k + 15), Block.getBlockById(18).getStateFromMeta(7), 3);
        world.setBlockState(new BlockPos(i + 3, j + 10, k + 16), Block.getBlockById(2).getStateFromMeta(0), 3);
        world.setBlockState(new BlockPos(i + 4, j + 10, k + 16), Block.getBlockById(2).getStateFromMeta(0), 3);
        world.setBlockState(new BlockPos(i + 5, j + 10, k + 16), Block.getBlockById(2).getStateFromMeta(0), 3);
        world.setBlockState(new BlockPos(i + 6, j + 10, k + 16), Block.getBlockById(2).getStateFromMeta(0), 3);
        world.setBlockState(new BlockPos(i + 7, j + 10, k + 16), Block.getBlockById(2).getStateFromMeta(0), 3);
        world.setBlockState(new BlockPos(i + 8, j + 10, k + 16), Block.getBlockById(2).getStateFromMeta(0), 3);
        world.setBlockState(new BlockPos(i + 9, j + 10, k + 16), Block.getBlockById(2).getStateFromMeta(0), 3);
        world.setBlockState(new BlockPos(i + 10, j + 10, k + 16), Block.getBlockById(2).getStateFromMeta(0), 3);
        world.setBlockState(new BlockPos(i + 11, j + 10, k + 16), Block.getBlockById(2).getStateFromMeta(0), 3);
        world.setBlockState(new BlockPos(i + 12, j + 10, k + 16), Block.getBlockById(2).getStateFromMeta(0), 3);
        world.setBlockState(new BlockPos(i + 13, j + 10, k + 16), Block.getBlockById(2).getStateFromMeta(0), 3);
        world.setBlockState(new BlockPos(i + 14, j + 10, k + 16), Block.getBlockById(18).getStateFromMeta(7), 3);
        world.setBlockState(new BlockPos(i + 15, j + 10, k + 16), Block.getBlockById(175).getStateFromMeta(11), 3);
        world.setBlockState(new BlockPos(i + 4, j + 10, k + 17), Block.getBlockById(31).getStateFromMeta(1), 3);
        world.setBlockState(new BlockPos(i + 5, j + 10, k + 17), Block.getBlockById(31).getStateFromMeta(1), 3);
        world.setBlockState(new BlockPos(i + 6, j + 10, k + 17), Block.getBlockById(2).getStateFromMeta(0), 3);
        world.setBlockState(new BlockPos(i + 7, j + 10, k + 17), Block.getBlockById(2).getStateFromMeta(0), 3);
        world.setBlockState(new BlockPos(i + 8, j + 10, k + 17), Block.getBlockById(2).getStateFromMeta(0), 3);
        world.setBlockState(new BlockPos(i + 9, j + 10, k + 17), Block.getBlockById(2).getStateFromMeta(0), 3);
        world.setBlockState(new BlockPos(i + 10, j + 10, k + 17), Block.getBlockById(2).getStateFromMeta(0), 3);
        world.setBlockState(new BlockPos(i + 12, j + 10, k + 17), Block.getBlockById(31).getStateFromMeta(1), 3);
        world.setBlockState(new BlockPos(i + 4, j + 11, k + 1), Block.getBlockById(175).getStateFromMeta(2), 3);
        world.setBlockState(new BlockPos(i + 6, j + 11, k + 1), Block.getBlockById(175).getStateFromMeta(2), 3);
        world.setBlockState(new BlockPos(i + 3, j + 11, k + 2), Block.getBlockById(175).getStateFromMeta(2), 3);
        world.setBlockState(new BlockPos(i + 5, j + 11, k + 2), Block.getBlockById(31).getStateFromMeta(1), 3);
        world.setBlockState(new BlockPos(i + 9, j + 11, k + 2), Block.getBlockById(175).getStateFromMeta(2), 3);
        world.setBlockState(new BlockPos(i + 12, j + 11, k + 2), Block.getBlockById(175).getStateFromMeta(2), 3);
        world.setBlockState(new BlockPos(i + 3, j + 11, k + 3), Block.getBlockById(31).getStateFromMeta(1), 3);
        world.setBlockState(new BlockPos(i + 5, j + 11, k + 3), Block.getBlockById(31).getStateFromMeta(1), 3);
        world.setBlockState(new BlockPos(i + 6, j + 11, k + 3), Block.getBlockById(31).getStateFromMeta(1), 3);
        world.setBlockState(new BlockPos(i + 11, j + 11, k + 3), Block.getBlockById(175).getStateFromMeta(2), 3);
        world.setBlockState(new BlockPos(i + 2, j + 11, k + 4), Block.getBlockById(31).getStateFromMeta(1), 3);
        world.setBlockState(new BlockPos(i + 4, j + 11, k + 4), Block.getBlockById(175).getStateFromMeta(2), 3);
        world.setBlockState(new BlockPos(i + 6, j + 11, k + 4), Block.getBlockById(31).getStateFromMeta(1), 3);
        world.setBlockState(new BlockPos(i + 9, j + 11, k + 4), Block.getBlockById(31).getStateFromMeta(1), 3);
        world.setBlockState(new BlockPos(i + 10, j + 11, k + 4), Block.getBlockById(31).getStateFromMeta(1), 3);
        world.setBlockState(new BlockPos(i + 12, j + 11, k + 4), Block.getBlockById(175).getStateFromMeta(2), 3);
        world.setBlockState(new BlockPos(i + 2, j + 11, k + 5), Block.getBlockById(31).getStateFromMeta(1), 3);
        world.setBlockState(new BlockPos(i + 4, j + 11, k + 5), Block.getBlockById(17).getStateFromMeta(3), 3);
        world.setBlockState(new BlockPos(i + 11, j + 11, k + 5), Block.getBlockById(18).getStateFromMeta(7), 3);
        world.setBlockState(new BlockPos(i + 12, j + 11, k + 5), Block.getBlockById(18).getStateFromMeta(7), 3);
        world.setBlockState(new BlockPos(i + 14, j + 11, k + 5), Block.getBlockById(175).getStateFromMeta(2), 3);
        world.setBlockState(new BlockPos(i + 16, j + 11, k + 5), Block.getBlockById(31).getStateFromMeta(1), 3);
        world.setBlockState(new BlockPos(i + 1, j + 11, k + 6), Block.getBlockById(31).getStateFromMeta(1), 3);
        world.setBlockState(new BlockPos(i + 5, j + 11, k + 6), Block.getBlockById(175).getStateFromMeta(2), 3);
        world.setBlockState(new BlockPos(i + 6, j + 11, k + 6), Block.getBlockById(175).getStateFromMeta(2), 3);
        world.setBlockState(new BlockPos(i + 9, j + 11, k + 6), Block.getBlockById(31).getStateFromMeta(1), 3);
        world.setBlockState(new BlockPos(i + 10, j + 11, k + 6), Block.getBlockById(18).getStateFromMeta(7), 3);
        world.setBlockState(new BlockPos(i + 11, j + 11, k + 6), Block.getBlockById(18).getStateFromMeta(7), 3);
        world.setBlockState(new BlockPos(i + 12, j + 11, k + 6), Block.getBlockById(18).getStateFromMeta(15), 3);
        world.setBlockState(new BlockPos(i + 13, j + 11, k + 6), Block.getBlockById(18).getStateFromMeta(7), 3);
        world.setBlockState(new BlockPos(i + 14, j + 11, k + 6), Block.getBlockById(31).getStateFromMeta(1), 3);
        world.setBlockState(new BlockPos(i + 16, j + 11, k + 6), Block.getBlockById(31).getStateFromMeta(1), 3);
        world.setBlockState(new BlockPos(i + 1, j + 11, k + 7), Block.getBlockById(31).getStateFromMeta(1), 3);
        world.setBlockState(new BlockPos(i + 4, j + 11, k + 7), Block.getBlockById(111).getStateFromMeta(0), 3);
        world.setBlockState(new BlockPos(i + 10, j + 11, k + 7), Block.getBlockById(17).getStateFromMeta(1), 3);
        world.setBlockState(new BlockPos(i + 11, j + 11, k + 7), Block.getBlockById(251).getStateFromMeta(0), 3);
        world.setBlockState(new BlockPos(i + 12, j + 11, k + 7), Block.getBlockById(251).getStateFromMeta(0), 3);
        world.setBlockState(new BlockPos(i + 13, j + 11, k + 7), Block.getBlockById(251).getStateFromMeta(0), 3);
        world.setBlockState(new BlockPos(i + 14, j + 11, k + 7), Block.getBlockById(17).getStateFromMeta(1), 3);
        world.setBlockState(new BlockPos(i + 15, j + 11, k + 7), Block.getBlockById(175).getStateFromMeta(2), 3);
        world.setBlockState(new BlockPos(i + 1, j + 11, k + 8), Block.getBlockById(31).getStateFromMeta(1), 3);
        world.setBlockState(new BlockPos(i + 5, j + 11, k + 8), Block.getBlockById(175).getStateFromMeta(2), 3);
        world.setBlockState(new BlockPos(i + 9, j + 11, k + 8), Block.getBlockById(175).getStateFromMeta(2), 3);
        world.setBlockState(new BlockPos(i + 10, j + 11, k + 8), Block.getBlockById(251).getStateFromMeta(0), 3);
        world.setBlockState(new BlockPos(i + 13, j + 11, k + 8), Block.getBlockById(134).getStateFromMeta(3), 3);
        world.setBlockState(new BlockPos(i + 14, j + 11, k + 8), Block.getBlockById(251).getStateFromMeta(0), 3);
        world.setBlockState(new BlockPos(i + 1, j + 11, k + 9), Block.getBlockById(31).getStateFromMeta(1), 3);
        world.setBlockState(new BlockPos(i + 3, j + 11, k + 9), Block.getBlockById(111).getStateFromMeta(0), 3);
        world.setBlockState(new BlockPos(i + 6, j + 11, k + 9), Block.getBlockById(175).getStateFromMeta(2), 3);
        world.setBlockState(new BlockPos(i + 10, j + 11, k + 9), Block.getBlockById(71).getStateFromMeta(0), 3);
        world.setBlockState(new BlockPos(i + 11, j + 11, k + 9), Block.getBlockById(70).getStateFromMeta(0), 3);
        world.setBlockState(new BlockPos(i + 13, j + 11, k + 9), Block.getBlockById(134).getStateFromMeta(0), 3);
        world.setBlockState(new BlockPos(i + 14, j + 11, k + 9), Block.getBlockById(251).getStateFromMeta(0), 3);
        world.setBlockState(new BlockPos(i + 15, j + 11, k + 9), Block.getBlockById(18).getStateFromMeta(7), 3);
        world.setBlockState(new BlockPos(i + 16, j + 11, k + 9), Block.getBlockById(175).getStateFromMeta(2), 3);
        world.setBlockState(new BlockPos(i + 1, j + 11, k + 10), Block.getBlockById(31).getStateFromMeta(1), 3);
        world.setBlockState(new BlockPos(i + 7, j + 11, k + 10), Block.getBlockById(175).getStateFromMeta(2), 3);
        world.setBlockState(new BlockPos(i + 8, j + 11, k + 10), Block.getBlockById(18).getStateFromMeta(7), 3);
        world.setBlockState(new BlockPos(i + 9, j + 11, k + 10), Block.getBlockById(18).getStateFromMeta(7), 3);
        world.setBlockState(new BlockPos(i + 10, j + 11, k + 10), Block.getBlockById(251).getStateFromMeta(0), 3);
        world.setBlockState(new BlockPos(i + 13, j + 11, k + 10), Block.getBlockById(134).getStateFromMeta(2), 3);
        world.setBlockState(new BlockPos(i + 14, j + 11, k + 10), Block.getBlockById(251).getStateFromMeta(0), 3);
        world.setBlockState(new BlockPos(i + 15, j + 11, k + 10), Block.getBlockById(18).getStateFromMeta(15), 3);
        world.setBlockState(new BlockPos(i + 1, j + 11, k + 11), Block.getBlockById(31).getStateFromMeta(1), 3);
        world.setBlockState(new BlockPos(i + 3, j + 11, k + 11), Block.getBlockById(111).getStateFromMeta(0), 3);
        world.setBlockState(new BlockPos(i + 6, j + 11, k + 11), Block.getBlockById(17).getStateFromMeta(1), 3);
        world.setBlockState(new BlockPos(i + 7, j + 11, k + 11), Block.getBlockById(251).getStateFromMeta(0), 3);
        world.setBlockState(new BlockPos(i + 8, j + 11, k + 11), Block.getBlockById(251).getStateFromMeta(0), 3);
        world.setBlockState(new BlockPos(i + 9, j + 11, k + 11), Block.getBlockById(251).getStateFromMeta(0), 3);
        world.setBlockState(new BlockPos(i + 10, j + 11, k + 11), Block.getBlockById(17).getStateFromMeta(1), 3);
        world.setBlockState(new BlockPos(i + 14, j + 11, k + 11), Block.getBlockById(17).getStateFromMeta(1), 3);
        world.setBlockState(new BlockPos(i + 15, j + 11, k + 11), Block.getBlockById(175).getStateFromMeta(2), 3);
        world.setBlockState(new BlockPos(i + 2, j + 11, k + 12), Block.getBlockById(111).getStateFromMeta(0), 3);
        world.setBlockState(new BlockPos(i + 5, j + 11, k + 12), Block.getBlockById(175).getStateFromMeta(2), 3);
        world.setBlockState(new BlockPos(i + 6, j + 11, k + 12), Block.getBlockById(251).getStateFromMeta(0), 3);
        world.setBlockState(new BlockPos(i + 14, j + 11, k + 12), Block.getBlockById(251).getStateFromMeta(0), 3);
        world.setBlockState(new BlockPos(i + 15, j + 11, k + 12), Block.getBlockById(18).getStateFromMeta(7), 3);
        world.setBlockState(new BlockPos(i + 16, j + 11, k + 12), Block.getBlockById(175).getStateFromMeta(2), 3);
        world.setBlockState(new BlockPos(i + 2, j + 11, k + 13), Block.getBlockById(175).getStateFromMeta(2), 3);
        world.setBlockState(new BlockPos(i + 3, j + 11, k + 13), Block.getBlockById(175).getStateFromMeta(2), 3);
        world.setBlockState(new BlockPos(i + 5, j + 11, k + 13), Block.getBlockById(18).getStateFromMeta(7), 3);
        world.setBlockState(new BlockPos(i + 6, j + 11, k + 13), Block.getBlockById(251).getStateFromMeta(0), 3);
        world.setBlockState(new BlockPos(i + 7, j + 11, k + 13), Block.getBlockById(65).getStateFromMeta(5), 3);
        world.setBlockState(new BlockPos(i + 13, j + 11, k + 13), Block.getBlockById(134).getStateFromMeta(3), 3);
        world.setBlockState(new BlockPos(i + 14, j + 11, k + 13), Block.getBlockById(251).getStateFromMeta(0), 3);
        world.setBlockState(new BlockPos(i + 15, j + 11, k + 13), Block.getBlockById(18).getStateFromMeta(7), 3);
        world.setBlockState(new BlockPos(i + 3, j + 11, k + 14), Block.getBlockById(85).getStateFromMeta(0), 3);
        world.setBlockState(new BlockPos(i + 5, j + 11, k + 14), Block.getBlockById(18).getStateFromMeta(7), 3);
        world.setBlockState(new BlockPos(i + 6, j + 11, k + 14), Block.getBlockById(251).getStateFromMeta(0), 3);
        world.setBlockState(new BlockPos(i + 8, j + 11, k + 14), Block.getBlockById(85).getStateFromMeta(0), 3);
        world.setBlockState(new BlockPos(i + 9, j + 11, k + 14), Block.getBlockById(85).getStateFromMeta(0), 3);
        world.setBlockState(new BlockPos(i + 11, j + 11, k + 14), Block.getBlockById(134).getStateFromMeta(1), 3);
        world.setBlockState(new BlockPos(i + 12, j + 11, k + 14), Block.getBlockById(134).getStateFromMeta(2), 3);
        world.setBlockState(new BlockPos(i + 13, j + 11, k + 14), Block.getBlockById(134).getStateFromMeta(0), 3);
        world.setBlockState(new BlockPos(i + 14, j + 11, k + 14), Block.getBlockById(251).getStateFromMeta(0), 3);
        world.setBlockState(new BlockPos(i + 15, j + 11, k + 14), Block.getBlockById(175).getStateFromMeta(2), 3);
        world.setBlockState(new BlockPos(i + 2, j + 11, k + 15), Block.getBlockById(31).getStateFromMeta(1), 3);
        world.setBlockState(new BlockPos(i + 4, j + 11, k + 15), Block.getBlockById(175).getStateFromMeta(2), 3);
        world.setBlockState(new BlockPos(i + 5, j + 11, k + 15), Block.getBlockById(18).getStateFromMeta(7), 3);
        world.setBlockState(new BlockPos(i + 6, j + 11, k + 15), Block.getBlockById(17).getStateFromMeta(1), 3);
        world.setBlockState(new BlockPos(i + 7, j + 11, k + 15), Block.getBlockById(251).getStateFromMeta(0), 3);
        world.setBlockState(new BlockPos(i + 8, j + 11, k + 15), Block.getBlockById(251).getStateFromMeta(0), 3);
        world.setBlockState(new BlockPos(i + 9, j + 11, k + 15), Block.getBlockById(251).getStateFromMeta(0), 3);
        world.setBlockState(new BlockPos(i + 10, j + 11, k + 15), Block.getBlockById(17).getStateFromMeta(1), 3);
        world.setBlockState(new BlockPos(i + 11, j + 11, k + 15), Block.getBlockById(251).getStateFromMeta(0), 3);
        world.setBlockState(new BlockPos(i + 12, j + 11, k + 15), Block.getBlockById(251).getStateFromMeta(0), 3);
        world.setBlockState(new BlockPos(i + 13, j + 11, k + 15), Block.getBlockById(251).getStateFromMeta(0), 3);
        world.setBlockState(new BlockPos(i + 14, j + 11, k + 15), Block.getBlockById(17).getStateFromMeta(1), 3);
        world.setBlockState(new BlockPos(i + 15, j + 11, k + 15), Block.getBlockById(18).getStateFromMeta(7), 3);
        world.setBlockState(new BlockPos(i + 3, j + 11, k + 16), Block.getBlockById(31).getStateFromMeta(1), 3);
        world.setBlockState(new BlockPos(i + 4, j + 11, k + 16), Block.getBlockById(31).getStateFromMeta(1), 3);
        world.setBlockState(new BlockPos(i + 6, j + 11, k + 16), Block.getBlockById(175).getStateFromMeta(2), 3);
        world.setBlockState(new BlockPos(i + 7, j + 11, k + 16), Block.getBlockById(18).getStateFromMeta(7), 3);
        world.setBlockState(new BlockPos(i + 8, j + 11, k + 16), Block.getBlockById(18).getStateFromMeta(7), 3);
        world.setBlockState(new BlockPos(i + 9, j + 11, k + 16), Block.getBlockById(175).getStateFromMeta(2), 3);
        world.setBlockState(new BlockPos(i + 11, j + 11, k + 16), Block.getBlockById(175).getStateFromMeta(2), 3);
        world.setBlockState(new BlockPos(i + 13, j + 11, k + 16), Block.getBlockById(175).getStateFromMeta(2), 3);
        world.setBlockState(new BlockPos(i + 14, j + 11, k + 16), Block.getBlockById(18).getStateFromMeta(7), 3);
        world.setBlockState(new BlockPos(i + 6, j + 11, k + 17), Block.getBlockById(31).getStateFromMeta(1), 3);
        world.setBlockState(new BlockPos(i + 8, j + 11, k + 17), Block.getBlockById(175).getStateFromMeta(2), 3);
        world.setBlockState(new BlockPos(i + 9, j + 11, k + 17), Block.getBlockById(31).getStateFromMeta(1), 3);
        world.setBlockState(new BlockPos(i + 10, j + 11, k + 17), Block.getBlockById(175).getStateFromMeta(2), 3);
        world.setBlockState(new BlockPos(i + 4, j + 12, k + 1), Block.getBlockById(175).getStateFromMeta(11), 3);
        world.setBlockState(new BlockPos(i + 6, j + 12, k + 1), Block.getBlockById(175).getStateFromMeta(11), 3);
        world.setBlockState(new BlockPos(i + 3, j + 12, k + 2), Block.getBlockById(175).getStateFromMeta(11), 3);
        world.setBlockState(new BlockPos(i + 9, j + 12, k + 2), Block.getBlockById(175).getStateFromMeta(11), 3);
        world.setBlockState(new BlockPos(i + 12, j + 12, k + 2), Block.getBlockById(175).getStateFromMeta(11), 3);
        world.setBlockState(new BlockPos(i + 11, j + 12, k + 3), Block.getBlockById(175).getStateFromMeta(11), 3);
        world.setBlockState(new BlockPos(i + 4, j + 12, k + 4), Block.getBlockById(175).getStateFromMeta(11), 3);
        world.setBlockState(new BlockPos(i + 12, j + 12, k + 4), Block.getBlockById(175).getStateFromMeta(11), 3);
        world.setBlockState(new BlockPos(i + 4, j + 12, k + 5), Block.getBlockById(17).getStateFromMeta(3), 3);
        world.setBlockState(new BlockPos(i + 14, j + 12, k + 5), Block.getBlockById(175).getStateFromMeta(11), 3);
        world.setBlockState(new BlockPos(i + 5, j + 12, k + 6), Block.getBlockById(175).getStateFromMeta(11), 3);
        world.setBlockState(new BlockPos(i + 6, j + 12, k + 6), Block.getBlockById(175).getStateFromMeta(11), 3);
        world.setBlockState(new BlockPos(i + 12, j + 12, k + 6), Block.getBlockById(18).getStateFromMeta(15), 3);
        world.setBlockState(new BlockPos(i + 10, j + 12, k + 7), Block.getBlockById(17).getStateFromMeta(1), 3);
        world.setBlockState(new BlockPos(i + 11, j + 12, k + 7), Block.getBlockById(251).getStateFromMeta(0), 3);
        world.setBlockState(new BlockPos(i + 12, j + 12, k + 7), Block.getBlockById(101).getStateFromMeta(0), 3);
        world.setBlockState(new BlockPos(i + 13, j + 12, k + 7), Block.getBlockById(251).getStateFromMeta(0), 3);
        world.setBlockState(new BlockPos(i + 14, j + 12, k + 7), Block.getBlockById(17).getStateFromMeta(1), 3);
        world.setBlockState(new BlockPos(i + 15, j + 12, k + 7), Block.getBlockById(175).getStateFromMeta(11), 3);
        world.setBlockState(new BlockPos(i + 5, j + 12, k + 8), Block.getBlockById(175).getStateFromMeta(11), 3);
        world.setBlockState(new BlockPos(i + 9, j + 12, k + 8), Block.getBlockById(175).getStateFromMeta(11), 3);
        world.setBlockState(new BlockPos(i + 10, j + 12, k + 8), Block.getBlockById(251).getStateFromMeta(0), 3);
        world.setBlockState(new BlockPos(i + 14, j + 12, k + 8), Block.getBlockById(251).getStateFromMeta(0), 3);
        world.setBlockState(new BlockPos(i + 6, j + 12, k + 9), Block.getBlockById(175).getStateFromMeta(11), 3);
        world.setBlockState(new BlockPos(i + 10, j + 12, k + 9), Block.getBlockById(71).getStateFromMeta(8), 3);
        world.setBlockState(new BlockPos(i + 14, j + 12, k + 9), Block.getBlockById(101).getStateFromMeta(0), 3);
        world.setBlockState(new BlockPos(i + 16, j + 12, k + 9), Block.getBlockById(175).getStateFromMeta(11), 3);
        world.setBlockState(new BlockPos(i + 7, j + 12, k + 10), Block.getBlockById(175).getStateFromMeta(11), 3);
        world.setBlockState(new BlockPos(i + 9, j + 12, k + 10), Block.getBlockById(77).getStateFromMeta(2), 3);
        world.setBlockState(new BlockPos(i + 10, j + 12, k + 10), Block.getBlockById(251).getStateFromMeta(0), 3);
        world.setBlockState(new BlockPos(i + 14, j + 12, k + 10), Block.getBlockById(251).getStateFromMeta(0), 3);
        world.setBlockState(new BlockPos(i + 15, j + 12, k + 10), Block.getBlockById(18).getStateFromMeta(15), 3);
        world.setBlockState(new BlockPos(i + 6, j + 12, k + 11), Block.getBlockById(17).getStateFromMeta(1), 3);
        world.setBlockState(new BlockPos(i + 7, j + 12, k + 11), Block.getBlockById(251).getStateFromMeta(0), 3);
        world.setBlockState(new BlockPos(i + 8, j + 12, k + 11), Block.getBlockById(101).getStateFromMeta(0), 3);
        world.setBlockState(new BlockPos(i + 9, j + 12, k + 11), Block.getBlockById(251).getStateFromMeta(0), 3);
        world.setBlockState(new BlockPos(i + 10, j + 12, k + 11), Block.getBlockById(17).getStateFromMeta(1), 3);
        world.setBlockState(new BlockPos(i + 14, j + 12, k + 11), Block.getBlockById(17).getStateFromMeta(1), 3);
        world.setBlockState(new BlockPos(i + 15, j + 12, k + 11), Block.getBlockById(175).getStateFromMeta(11), 3);
        world.setBlockState(new BlockPos(i + 5, j + 12, k + 12), Block.getBlockById(175).getStateFromMeta(11), 3);
        world.setBlockState(new BlockPos(i + 6, j + 12, k + 12), Block.getBlockById(251).getStateFromMeta(0), 3);
        world.setBlockState(new BlockPos(i + 14, j + 12, k + 12), Block.getBlockById(251).getStateFromMeta(0), 3);
        world.setBlockState(new BlockPos(i + 16, j + 12, k + 12), Block.getBlockById(175).getStateFromMeta(11), 3);
        world.setBlockState(new BlockPos(i + 2, j + 12, k + 13), Block.getBlockById(175).getStateFromMeta(11), 3);
        world.setBlockState(new BlockPos(i + 3, j + 12, k + 13), Block.getBlockById(175).getStateFromMeta(11), 3);
        world.setBlockState(new BlockPos(i + 6, j + 12, k + 13), Block.getBlockById(251).getStateFromMeta(0), 3);
        world.setBlockState(new BlockPos(i + 7, j + 12, k + 13), Block.getBlockById(65).getStateFromMeta(5), 3);
        world.setBlockState(new BlockPos(i + 14, j + 12, k + 13), Block.getBlockById(101).getStateFromMeta(0), 3);
        world.setBlockState(new BlockPos(i + 15, j + 12, k + 13), Block.getBlockById(18).getStateFromMeta(7), 3);
        world.setBlockState(new BlockPos(i + 3, j + 12, k + 14), Block.getBlockById(85).getStateFromMeta(0), 3);
        world.setBlockState(new BlockPos(i + 5, j + 12, k + 14), Block.getBlockById(18).getStateFromMeta(7), 3);
        world.setBlockState(new BlockPos(i + 6, j + 12, k + 14), Block.getBlockById(251).getStateFromMeta(0), 3);
        world.setBlockState(new BlockPos(i + 8, j + 12, k + 14), Block.getBlockById(72).getStateFromMeta(0), 3);
        world.setBlockState(new BlockPos(i + 9, j + 12, k + 14), Block.getBlockById(72).getStateFromMeta(0), 3);
        world.setBlockState(new BlockPos(i + 14, j + 12, k + 14), Block.getBlockById(251).getStateFromMeta(0), 3);
        world.setBlockState(new BlockPos(i + 15, j + 12, k + 14), Block.getBlockById(175).getStateFromMeta(11), 3);
        world.setBlockState(new BlockPos(i + 4, j + 12, k + 15), Block.getBlockById(175).getStateFromMeta(11), 3);
        world.setBlockState(new BlockPos(i + 6, j + 12, k + 15), Block.getBlockById(17).getStateFromMeta(1), 3);
        world.setBlockState(new BlockPos(i + 7, j + 12, k + 15), Block.getBlockById(251).getStateFromMeta(0), 3);
        world.setBlockState(new BlockPos(i + 8, j + 12, k + 15), Block.getBlockById(101).getStateFromMeta(0), 3);
        world.setBlockState(new BlockPos(i + 9, j + 12, k + 15), Block.getBlockById(251).getStateFromMeta(0), 3);
        world.setBlockState(new BlockPos(i + 10, j + 12, k + 15), Block.getBlockById(17).getStateFromMeta(1), 3);
        world.setBlockState(new BlockPos(i + 11, j + 12, k + 15), Block.getBlockById(251).getStateFromMeta(0), 3);
        world.setBlockState(new BlockPos(i + 12, j + 12, k + 15), Block.getBlockById(101).getStateFromMeta(0), 3);
        world.setBlockState(new BlockPos(i + 13, j + 12, k + 15), Block.getBlockById(251).getStateFromMeta(0), 3);
        world.setBlockState(new BlockPos(i + 14, j + 12, k + 15), Block.getBlockById(17).getStateFromMeta(1), 3);
        world.setBlockState(new BlockPos(i + 6, j + 12, k + 16), Block.getBlockById(175).getStateFromMeta(11), 3);
        world.setBlockState(new BlockPos(i + 8, j + 12, k + 16), Block.getBlockById(18).getStateFromMeta(7), 3);
        world.setBlockState(new BlockPos(i + 9, j + 12, k + 16), Block.getBlockById(175).getStateFromMeta(11), 3);
        world.setBlockState(new BlockPos(i + 11, j + 12, k + 16), Block.getBlockById(175).getStateFromMeta(11), 3);
        world.setBlockState(new BlockPos(i + 13, j + 12, k + 16), Block.getBlockById(175).getStateFromMeta(11), 3);
        world.setBlockState(new BlockPos(i + 8, j + 12, k + 17), Block.getBlockById(175).getStateFromMeta(11), 3);
        world.setBlockState(new BlockPos(i + 10, j + 12, k + 17), Block.getBlockById(175).getStateFromMeta(11), 3);
        world.setBlockState(new BlockPos(i + 4, j + 13, k + 5), Block.getBlockById(17).getStateFromMeta(3), 3);
        world.setBlockState(new BlockPos(i + 5, j + 13, k + 5), Block.getBlockById(106).getStateFromMeta(2), 3);
        world.setBlockState(new BlockPos(i + 12, j + 13, k + 6), Block.getBlockById(106).getStateFromMeta(1), 3);
        world.setBlockState(new BlockPos(i + 14, j + 13, k + 6), Block.getBlockById(106).getStateFromMeta(1), 3);
        world.setBlockState(new BlockPos(i + 10, j + 13, k + 7), Block.getBlockById(17).getStateFromMeta(1), 3);
        world.setBlockState(new BlockPos(i + 11, j + 13, k + 7), Block.getBlockById(251).getStateFromMeta(0), 3);
        world.setBlockState(new BlockPos(i + 12, j + 13, k + 7), Block.getBlockById(101).getStateFromMeta(0), 3);
        world.setBlockState(new BlockPos(i + 13, j + 13, k + 7), Block.getBlockById(251).getStateFromMeta(0), 3);
        world.setBlockState(new BlockPos(i + 14, j + 13, k + 7), Block.getBlockById(17).getStateFromMeta(1), 3);
        world.setBlockState(new BlockPos(i + 15, j + 13, k + 7), Block.getBlockById(106).getStateFromMeta(2), 3);
        world.setBlockState(new BlockPos(i + 9, j + 13, k + 8), Block.getBlockById(106).getStateFromMeta(8), 3);
        world.setBlockState(new BlockPos(i + 10, j + 13, k + 8), Block.getBlockById(251).getStateFromMeta(0), 3);
        world.setBlockState(new BlockPos(i + 14, j + 13, k + 8), Block.getBlockById(251).getStateFromMeta(0), 3);
        world.setBlockState(new BlockPos(i + 9, j + 13, k + 9), Block.getBlockById(106).getStateFromMeta(8), 3);
        world.setBlockState(new BlockPos(i + 10, j + 13, k + 9), Block.getBlockById(251).getStateFromMeta(0), 3);
        world.setBlockState(new BlockPos(i + 14, j + 13, k + 9), Block.getBlockById(101).getStateFromMeta(0), 3);
        world.setBlockState(new BlockPos(i + 9, j + 13, k + 10), Block.getBlockById(106).getStateFromMeta(1), 3);
        world.setBlockState(new BlockPos(i + 10, j + 13, k + 10), Block.getBlockById(251).getStateFromMeta(0), 3);
        world.setBlockState(new BlockPos(i + 14, j + 13, k + 10), Block.getBlockById(251).getStateFromMeta(0), 3);
        world.setBlockState(new BlockPos(i + 6, j + 13, k + 11), Block.getBlockById(17).getStateFromMeta(1), 3);
        world.setBlockState(new BlockPos(i + 7, j + 13, k + 11), Block.getBlockById(251).getStateFromMeta(0), 3);
        world.setBlockState(new BlockPos(i + 8, j + 13, k + 11), Block.getBlockById(101).getStateFromMeta(0), 3);
        world.setBlockState(new BlockPos(i + 9, j + 13, k + 11), Block.getBlockById(251).getStateFromMeta(0), 3);
        world.setBlockState(new BlockPos(i + 10, j + 13, k + 11), Block.getBlockById(17).getStateFromMeta(1), 3);
        world.setBlockState(new BlockPos(i + 14, j + 13, k + 11), Block.getBlockById(17).getStateFromMeta(1), 3);
        world.setBlockState(new BlockPos(i + 6, j + 13, k + 12), Block.getBlockById(251).getStateFromMeta(0), 3);
        world.setBlockState(new BlockPos(i + 14, j + 13, k + 12), Block.getBlockById(251).getStateFromMeta(0), 3);
        world.setBlockState(new BlockPos(i + 15, j + 13, k + 12), Block.getBlockById(106).getStateFromMeta(2), 3);
        world.setBlockState(new BlockPos(i + 2, j + 13, k + 13), Block.getBlockById(132).getStateFromMeta(0), 3);
        world.setBlockState(new BlockPos(i + 3, j + 13, k + 13), Block.getBlockById(132).getStateFromMeta(0), 3);
        world.setBlockState(new BlockPos(i + 4, j + 13, k + 13), Block.getBlockById(132).getStateFromMeta(0), 3);
        world.setBlockState(new BlockPos(i + 6, j + 13, k + 13), Block.getBlockById(251).getStateFromMeta(0), 3);
        world.setBlockState(new BlockPos(i + 7, j + 13, k + 13), Block.getBlockById(65).getStateFromMeta(5), 3);
        world.setBlockState(new BlockPos(i + 14, j + 13, k + 13), Block.getBlockById(101).getStateFromMeta(0), 3);
        world.setBlockState(new BlockPos(i + 2, j + 13, k + 14), Block.getBlockById(132).getStateFromMeta(0), 3);
        world.setBlockState(new BlockPos(i + 3, j + 13, k + 14), Block.getBlockById(85).getStateFromMeta(0), 3);
        world.setBlockState(new BlockPos(i + 4, j + 13, k + 14), Block.getBlockById(132).getStateFromMeta(0), 3);
        world.setBlockState(new BlockPos(i + 6, j + 13, k + 14), Block.getBlockById(251).getStateFromMeta(0), 3);
        world.setBlockState(new BlockPos(i + 14, j + 13, k + 14), Block.getBlockById(251).getStateFromMeta(0), 3);
        world.setBlockState(new BlockPos(i + 2, j + 13, k + 15), Block.getBlockById(132).getStateFromMeta(0), 3);
        world.setBlockState(new BlockPos(i + 3, j + 13, k + 15), Block.getBlockById(132).getStateFromMeta(0), 3);
        world.setBlockState(new BlockPos(i + 4, j + 13, k + 15), Block.getBlockById(132).getStateFromMeta(0), 3);
        world.setBlockState(new BlockPos(i + 6, j + 13, k + 15), Block.getBlockById(17).getStateFromMeta(1), 3);
        world.setBlockState(new BlockPos(i + 7, j + 13, k + 15), Block.getBlockById(251).getStateFromMeta(0), 3);
        world.setBlockState(new BlockPos(i + 8, j + 13, k + 15), Block.getBlockById(101).getStateFromMeta(0), 3);
        world.setBlockState(new BlockPos(i + 9, j + 13, k + 15), Block.getBlockById(251).getStateFromMeta(0), 3);
        world.setBlockState(new BlockPos(i + 10, j + 13, k + 15), Block.getBlockById(17).getStateFromMeta(1), 3);
        world.setBlockState(new BlockPos(i + 11, j + 13, k + 15), Block.getBlockById(251).getStateFromMeta(0), 3);
        world.setBlockState(new BlockPos(i + 12, j + 13, k + 15), Block.getBlockById(101).getStateFromMeta(0), 3);
        world.setBlockState(new BlockPos(i + 13, j + 13, k + 15), Block.getBlockById(251).getStateFromMeta(0), 3);
        world.setBlockState(new BlockPos(i + 14, j + 13, k + 15), Block.getBlockById(17).getStateFromMeta(1), 3);
        world.setBlockState(new BlockPos(i + 5, j + 13, k + 16), Block.getBlockById(106).getStateFromMeta(8), 3);
        world.setBlockState(new BlockPos(i + 9, j + 13, k + 16), Block.getBlockById(106).getStateFromMeta(4), 3);
        world.setBlockState(new BlockPos(i + 10, j + 13, k + 16), Block.getBlockById(106).getStateFromMeta(4), 3);
        world.setBlockState(new BlockPos(i + 13, j + 13, k + 16), Block.getBlockById(106).getStateFromMeta(4), 3);
        world.setBlockState(new BlockPos(i + 4, j + 14, k + 5), Block.getBlockById(106).getStateFromMeta(1), 3);
        world.setBlockState(new BlockPos(i + 4, j + 14, k + 6), Block.getBlockById(17).getStateFromMeta(3), 3);
        world.setBlockState(new BlockPos(i + 12, j + 14, k + 6), Block.getBlockById(106).getStateFromMeta(1), 3);
        world.setBlockState(new BlockPos(i + 13, j + 14, k + 6), Block.getBlockById(106).getStateFromMeta(1), 3);
        world.setBlockState(new BlockPos(i + 10, j + 14, k + 7), Block.getBlockById(17).getStateFromMeta(1), 3);
        world.setBlockState(new BlockPos(i + 11, j + 14, k + 7), Block.getBlockById(251).getStateFromMeta(0), 3);
        world.setBlockState(new BlockPos(i + 12, j + 14, k + 7), Block.getBlockById(251).getStateFromMeta(0), 3);
        world.setBlockState(new BlockPos(i + 13, j + 14, k + 7), Block.getBlockById(251).getStateFromMeta(0), 3);
        world.setBlockState(new BlockPos(i + 14, j + 14, k + 7), Block.getBlockById(17).getStateFromMeta(1), 3);
        world.setBlockState(new BlockPos(i + 9, j + 14, k + 8), Block.getBlockById(106).getStateFromMeta(8), 3);
        world.setBlockState(new BlockPos(i + 10, j + 14, k + 8), Block.getBlockById(251).getStateFromMeta(0), 3);
        world.setBlockState(new BlockPos(i + 14, j + 14, k + 8), Block.getBlockById(251).getStateFromMeta(0), 3);
        world.setBlockState(new BlockPos(i + 15, j + 14, k + 8), Block.getBlockById(106).getStateFromMeta(4), 3);
        world.setBlockState(new BlockPos(i + 9, j + 14, k + 9), Block.getBlockById(106).getStateFromMeta(8), 3);
        world.setBlockState(new BlockPos(i + 10, j + 14, k + 9), Block.getBlockById(251).getStateFromMeta(0), 3);
        world.setBlockState(new BlockPos(i + 14, j + 14, k + 9), Block.getBlockById(251).getStateFromMeta(0), 3);
        world.setBlockState(new BlockPos(i + 8, j + 14, k + 10), Block.getBlockById(106).getStateFromMeta(1), 3);
        world.setBlockState(new BlockPos(i + 10, j + 14, k + 10), Block.getBlockById(251).getStateFromMeta(0), 3);
        world.setBlockState(new BlockPos(i + 14, j + 14, k + 10), Block.getBlockById(251).getStateFromMeta(0), 3);
        world.setBlockState(new BlockPos(i + 6, j + 14, k + 11), Block.getBlockById(17).getStateFromMeta(1), 3);
        world.setBlockState(new BlockPos(i + 7, j + 14, k + 11), Block.getBlockById(251).getStateFromMeta(0), 3);
        world.setBlockState(new BlockPos(i + 8, j + 14, k + 11), Block.getBlockById(251).getStateFromMeta(0), 3);
        world.setBlockState(new BlockPos(i + 9, j + 14, k + 11), Block.getBlockById(251).getStateFromMeta(0), 3);
        world.setBlockState(new BlockPos(i + 10, j + 14, k + 11), Block.getBlockById(17).getStateFromMeta(1), 3);
        world.setBlockState(new BlockPos(i + 14, j + 14, k + 11), Block.getBlockById(17).getStateFromMeta(1), 3);
        world.setBlockState(new BlockPos(i + 6, j + 14, k + 12), Block.getBlockById(251).getStateFromMeta(0), 3);
        world.setBlockState(new BlockPos(i + 14, j + 14, k + 12), Block.getBlockById(251).getStateFromMeta(0), 3);
        world.setBlockState(new BlockPos(i + 2, j + 14, k + 13), Block.getBlockById(171).getStateFromMeta(3), 3);
        world.setBlockState(new BlockPos(i + 3, j + 14, k + 13), Block.getBlockById(171).getStateFromMeta(0), 3);
        world.setBlockState(new BlockPos(i + 4, j + 14, k + 13), Block.getBlockById(171).getStateFromMeta(3), 3);
        world.setBlockState(new BlockPos(i + 5, j + 14, k + 13), Block.getBlockById(106).getStateFromMeta(8), 3);
        world.setBlockState(new BlockPos(i + 6, j + 14, k + 13), Block.getBlockById(251).getStateFromMeta(0), 3);
        world.setBlockState(new BlockPos(i + 7, j + 14, k + 13), Block.getBlockById(65).getStateFromMeta(5), 3);
        world.setBlockState(new BlockPos(i + 14, j + 14, k + 13), Block.getBlockById(251).getStateFromMeta(0), 3);
        world.setBlockState(new BlockPos(i + 15, j + 14, k + 13), Block.getBlockById(106).getStateFromMeta(2), 3);
        world.setBlockState(new BlockPos(i + 2, j + 14, k + 14), Block.getBlockById(171).getStateFromMeta(0), 3);
        world.setBlockState(new BlockPos(i + 3, j + 14, k + 14), Block.getBlockById(35).getStateFromMeta(3), 3);
        world.setBlockState(new BlockPos(i + 4, j + 14, k + 14), Block.getBlockById(171).getStateFromMeta(0), 3);
        world.setBlockState(new BlockPos(i + 6, j + 14, k + 14), Block.getBlockById(251).getStateFromMeta(0), 3);
        world.setBlockState(new BlockPos(i + 14, j + 14, k + 14), Block.getBlockById(251).getStateFromMeta(0), 3);
        world.setBlockState(new BlockPos(i + 2, j + 14, k + 15), Block.getBlockById(171).getStateFromMeta(3), 3);
        world.setBlockState(new BlockPos(i + 3, j + 14, k + 15), Block.getBlockById(171).getStateFromMeta(0), 3);
        world.setBlockState(new BlockPos(i + 4, j + 14, k + 15), Block.getBlockById(171).getStateFromMeta(3), 3);
        world.setBlockState(new BlockPos(i + 6, j + 14, k + 15), Block.getBlockById(17).getStateFromMeta(1), 3);
        world.setBlockState(new BlockPos(i + 7, j + 14, k + 15), Block.getBlockById(251).getStateFromMeta(0), 3);
        world.setBlockState(new BlockPos(i + 8, j + 14, k + 15), Block.getBlockById(251).getStateFromMeta(0), 3);
        world.setBlockState(new BlockPos(i + 9, j + 14, k + 15), Block.getBlockById(251).getStateFromMeta(0), 3);
        world.setBlockState(new BlockPos(i + 10, j + 14, k + 15), Block.getBlockById(17).getStateFromMeta(1), 3);
        world.setBlockState(new BlockPos(i + 11, j + 14, k + 15), Block.getBlockById(251).getStateFromMeta(0), 3);
        world.setBlockState(new BlockPos(i + 12, j + 14, k + 15), Block.getBlockById(251).getStateFromMeta(0), 3);
        world.setBlockState(new BlockPos(i + 13, j + 14, k + 15), Block.getBlockById(251).getStateFromMeta(0), 3);
        world.setBlockState(new BlockPos(i + 14, j + 14, k + 15), Block.getBlockById(17).getStateFromMeta(1), 3);
        world.setBlockState(new BlockPos(i + 5, j + 14, k + 16), Block.getBlockById(106).getStateFromMeta(8), 3);
        world.setBlockState(new BlockPos(i + 11, j + 14, k + 16), Block.getBlockById(106).getStateFromMeta(4), 3);
        world.setBlockState(new BlockPos(i + 13, j + 14, k + 16), Block.getBlockById(106).getStateFromMeta(4), 3);
        world.setBlockState(new BlockPos(i + 4, j + 15, k + 4), Block.getBlockById(18).getStateFromMeta(15), 3);
        world.setBlockState(new BlockPos(i + 0, j + 15, k + 5), Block.getBlockById(18).getStateFromMeta(15), 3);
        world.setBlockState(new BlockPos(i + 1, j + 15, k + 5), Block.getBlockById(18).getStateFromMeta(15), 3);
        world.setBlockState(new BlockPos(i + 10, j + 15, k + 5), Block.getBlockById(77).getStateFromMeta(4), 3);
        world.setBlockState(new BlockPos(i + 14, j + 15, k + 5), Block.getBlockById(77).getStateFromMeta(4), 3);
        world.setBlockState(new BlockPos(i + 3, j + 15, k + 6), Block.getBlockById(17).getStateFromMeta(3), 3);
        world.setBlockState(new BlockPos(i + 4, j + 15, k + 6), Block.getBlockById(17).getStateFromMeta(3), 3);
        world.setBlockState(new BlockPos(i + 5, j + 15, k + 6), Block.getBlockById(18).getStateFromMeta(15), 3);
        world.setBlockState(new BlockPos(i + 10, j + 15, k + 6), Block.getBlockById(17).getStateFromMeta(9), 3);
        world.setBlockState(new BlockPos(i + 12, j + 15, k + 6), Block.getBlockById(106).getStateFromMeta(1), 3);
        world.setBlockState(new BlockPos(i + 14, j + 15, k + 6), Block.getBlockById(17).getStateFromMeta(9), 3);
        world.setBlockState(new BlockPos(i + 8, j + 15, k + 7), Block.getBlockById(77).getStateFromMeta(2), 3);
        world.setBlockState(new BlockPos(i + 9, j + 15, k + 7), Block.getBlockById(17).getStateFromMeta(5), 3);
        world.setBlockState(new BlockPos(i + 10, j + 15, k + 7), Block.getBlockById(17).getStateFromMeta(1), 3);
        world.setBlockState(new BlockPos(i + 11, j + 15, k + 7), Block.getBlockById(17).getStateFromMeta(5), 3);
        world.setBlockState(new BlockPos(i + 12, j + 15, k + 7), Block.getBlockById(17).getStateFromMeta(5), 3);
        world.setBlockState(new BlockPos(i + 13, j + 15, k + 7), Block.getBlockById(17).getStateFromMeta(5), 3);
        world.setBlockState(new BlockPos(i + 14, j + 15, k + 7), Block.getBlockById(17).getStateFromMeta(1), 3);
        world.setBlockState(new BlockPos(i + 15, j + 15, k + 7), Block.getBlockById(17).getStateFromMeta(5), 3);
        world.setBlockState(new BlockPos(i + 16, j + 15, k + 7), Block.getBlockById(77).getStateFromMeta(1), 3);
        world.setBlockState(new BlockPos(i + 1, j + 15, k + 8), Block.getBlockById(18).getStateFromMeta(15), 3);
        world.setBlockState(new BlockPos(i + 5, j + 15, k + 8), Block.getBlockById(106).getStateFromMeta(1), 3);
        world.setBlockState(new BlockPos(i + 9, j + 15, k + 8), Block.getBlockById(106).getStateFromMeta(8), 3);
        world.setBlockState(new BlockPos(i + 10, j + 15, k + 8), Block.getBlockById(17).getStateFromMeta(9), 3);
        world.setBlockState(new BlockPos(i + 11, j + 15, k + 8), Block.getBlockById(251).getStateFromMeta(0), 3);
        world.setBlockState(new BlockPos(i + 12, j + 15, k + 8), Block.getBlockById(251).getStateFromMeta(0), 3);
        world.setBlockState(new BlockPos(i + 13, j + 15, k + 8), Block.getBlockById(251).getStateFromMeta(0), 3);
        world.setBlockState(new BlockPos(i + 14, j + 15, k + 8), Block.getBlockById(17).getStateFromMeta(9), 3);
        world.setBlockState(new BlockPos(i + 15, j + 15, k + 8), Block.getBlockById(106).getStateFromMeta(4), 3);
        world.setBlockState(new BlockPos(i + 0, j + 15, k + 9), Block.getBlockById(18).getStateFromMeta(15), 3);
        world.setBlockState(new BlockPos(i + 5, j + 15, k + 9), Block.getBlockById(18).getStateFromMeta(15), 3);
        world.setBlockState(new BlockPos(i + 6, j + 15, k + 9), Block.getBlockById(77).getStateFromMeta(4), 3);
        world.setBlockState(new BlockPos(i + 9, j + 15, k + 9), Block.getBlockById(106).getStateFromMeta(8), 3);
        world.setBlockState(new BlockPos(i + 10, j + 15, k + 9), Block.getBlockById(17).getStateFromMeta(9), 3);
        world.setBlockState(new BlockPos(i + 11, j + 15, k + 9), Block.getBlockById(251).getStateFromMeta(0), 3);
        world.setBlockState(new BlockPos(i + 12, j + 15, k + 9), Block.getBlockById(251).getStateFromMeta(0), 3);
        world.setBlockState(new BlockPos(i + 13, j + 15, k + 9), Block.getBlockById(251).getStateFromMeta(0), 3);
        world.setBlockState(new BlockPos(i + 14, j + 15, k + 9), Block.getBlockById(17).getStateFromMeta(9), 3);
        world.setBlockState(new BlockPos(i + 15, j + 15, k + 9), Block.getBlockById(106).getStateFromMeta(2), 3);
        world.setBlockState(new BlockPos(i + 6, j + 15, k + 10), Block.getBlockById(17).getStateFromMeta(9), 3);
        world.setBlockState(new BlockPos(i + 8, j + 15, k + 10), Block.getBlockById(106).getStateFromMeta(1), 3);
        world.setBlockState(new BlockPos(i + 10, j + 15, k + 10), Block.getBlockById(17).getStateFromMeta(9), 3);
        world.setBlockState(new BlockPos(i + 11, j + 15, k + 10), Block.getBlockById(251).getStateFromMeta(0), 3);
        world.setBlockState(new BlockPos(i + 12, j + 15, k + 10), Block.getBlockById(251).getStateFromMeta(0), 3);
        world.setBlockState(new BlockPos(i + 13, j + 15, k + 10), Block.getBlockById(251).getStateFromMeta(0), 3);
        world.setBlockState(new BlockPos(i + 14, j + 15, k + 10), Block.getBlockById(17).getStateFromMeta(9), 3);
        world.setBlockState(new BlockPos(i + 4, j + 15, k + 11), Block.getBlockById(77).getStateFromMeta(2), 3);
        world.setBlockState(new BlockPos(i + 5, j + 15, k + 11), Block.getBlockById(17).getStateFromMeta(5), 3);
        world.setBlockState(new BlockPos(i + 6, j + 15, k + 11), Block.getBlockById(17).getStateFromMeta(1), 3);
        world.setBlockState(new BlockPos(i + 7, j + 15, k + 11), Block.getBlockById(17).getStateFromMeta(5), 3);
        world.setBlockState(new BlockPos(i + 8, j + 15, k + 11), Block.getBlockById(17).getStateFromMeta(5), 3);
        world.setBlockState(new BlockPos(i + 9, j + 15, k + 11), Block.getBlockById(17).getStateFromMeta(5), 3);
        world.setBlockState(new BlockPos(i + 10, j + 15, k + 11), Block.getBlockById(17).getStateFromMeta(1), 3);
        world.setBlockState(new BlockPos(i + 11, j + 15, k + 11), Block.getBlockById(251).getStateFromMeta(0), 3);
        world.setBlockState(new BlockPos(i + 12, j + 15, k + 11), Block.getBlockById(251).getStateFromMeta(0), 3);
        world.setBlockState(new BlockPos(i + 13, j + 15, k + 11), Block.getBlockById(251).getStateFromMeta(0), 3);
        world.setBlockState(new BlockPos(i + 14, j + 15, k + 11), Block.getBlockById(17).getStateFromMeta(1), 3);
        world.setBlockState(new BlockPos(i + 15, j + 15, k + 11), Block.getBlockById(17).getStateFromMeta(5), 3);
        world.setBlockState(new BlockPos(i + 16, j + 15, k + 11), Block.getBlockById(77).getStateFromMeta(1), 3);
        world.setBlockState(new BlockPos(i + 6, j + 15, k + 12), Block.getBlockById(17).getStateFromMeta(9), 3);
        world.setBlockState(new BlockPos(i + 7, j + 15, k + 12), Block.getBlockById(251).getStateFromMeta(0), 3);
        world.setBlockState(new BlockPos(i + 8, j + 15, k + 12), Block.getBlockById(251).getStateFromMeta(0), 3);
        world.setBlockState(new BlockPos(i + 9, j + 15, k + 12), Block.getBlockById(251).getStateFromMeta(0), 3);
        world.setBlockState(new BlockPos(i + 10, j + 15, k + 12), Block.getBlockById(251).getStateFromMeta(0), 3);
        world.setBlockState(new BlockPos(i + 11, j + 15, k + 12), Block.getBlockById(251).getStateFromMeta(0), 3);
        world.setBlockState(new BlockPos(i + 12, j + 15, k + 12), Block.getBlockById(251).getStateFromMeta(0), 3);
        world.setBlockState(new BlockPos(i + 13, j + 15, k + 12), Block.getBlockById(251).getStateFromMeta(0), 3);
        world.setBlockState(new BlockPos(i + 14, j + 15, k + 12), Block.getBlockById(17).getStateFromMeta(9), 3);
        world.setBlockState(new BlockPos(i + 5, j + 15, k + 13), Block.getBlockById(106).getStateFromMeta(8), 3);
        world.setBlockState(new BlockPos(i + 6, j + 15, k + 13), Block.getBlockById(17).getStateFromMeta(9), 3);
        world.setBlockState(new BlockPos(i + 7, j + 15, k + 13), Block.getBlockById(65).getStateFromMeta(5), 3);
        world.setBlockState(new BlockPos(i + 8, j + 15, k + 13), Block.getBlockById(251).getStateFromMeta(0), 3);
        world.setBlockState(new BlockPos(i + 9, j + 15, k + 13), Block.getBlockById(251).getStateFromMeta(0), 3);
        world.setBlockState(new BlockPos(i + 10, j + 15, k + 13), Block.getBlockById(251).getStateFromMeta(0), 3);
        world.setBlockState(new BlockPos(i + 11, j + 15, k + 13), Block.getBlockById(251).getStateFromMeta(0), 3);
        world.setBlockState(new BlockPos(i + 12, j + 15, k + 13), Block.getBlockById(251).getStateFromMeta(0), 3);
        world.setBlockState(new BlockPos(i + 13, j + 15, k + 13), Block.getBlockById(251).getStateFromMeta(0), 3);
        world.setBlockState(new BlockPos(i + 14, j + 15, k + 13), Block.getBlockById(17).getStateFromMeta(9), 3);
        world.setBlockState(new BlockPos(i + 15, j + 15, k + 13), Block.getBlockById(106).getStateFromMeta(2), 3);
        world.setBlockState(new BlockPos(i + 6, j + 15, k + 14), Block.getBlockById(17).getStateFromMeta(9), 3);
        world.setBlockState(new BlockPos(i + 7, j + 15, k + 14), Block.getBlockById(251).getStateFromMeta(0), 3);
        world.setBlockState(new BlockPos(i + 8, j + 15, k + 14), Block.getBlockById(251).getStateFromMeta(0), 3);
        world.setBlockState(new BlockPos(i + 9, j + 15, k + 14), Block.getBlockById(251).getStateFromMeta(0), 3);
        world.setBlockState(new BlockPos(i + 10, j + 15, k + 14), Block.getBlockById(251).getStateFromMeta(0), 3);
        world.setBlockState(new BlockPos(i + 11, j + 15, k + 14), Block.getBlockById(251).getStateFromMeta(0), 3);
        world.setBlockState(new BlockPos(i + 12, j + 15, k + 14), Block.getBlockById(251).getStateFromMeta(0), 3);
        world.setBlockState(new BlockPos(i + 13, j + 15, k + 14), Block.getBlockById(251).getStateFromMeta(0), 3);
        world.setBlockState(new BlockPos(i + 14, j + 15, k + 14), Block.getBlockById(17).getStateFromMeta(9), 3);
        world.setBlockState(new BlockPos(i + 4, j + 15, k + 15), Block.getBlockById(77).getStateFromMeta(2), 3);
        world.setBlockState(new BlockPos(i + 5, j + 15, k + 15), Block.getBlockById(17).getStateFromMeta(5), 3);
        world.setBlockState(new BlockPos(i + 6, j + 15, k + 15), Block.getBlockById(17).getStateFromMeta(1), 3);
        world.setBlockState(new BlockPos(i + 7, j + 15, k + 15), Block.getBlockById(17).getStateFromMeta(5), 3);
        world.setBlockState(new BlockPos(i + 8, j + 15, k + 15), Block.getBlockById(17).getStateFromMeta(5), 3);
        world.setBlockState(new BlockPos(i + 9, j + 15, k + 15), Block.getBlockById(17).getStateFromMeta(5), 3);
        world.setBlockState(new BlockPos(i + 10, j + 15, k + 15), Block.getBlockById(17).getStateFromMeta(1), 3);
        world.setBlockState(new BlockPos(i + 11, j + 15, k + 15), Block.getBlockById(17).getStateFromMeta(5), 3);
        world.setBlockState(new BlockPos(i + 12, j + 15, k + 15), Block.getBlockById(17).getStateFromMeta(5), 3);
        world.setBlockState(new BlockPos(i + 13, j + 15, k + 15), Block.getBlockById(17).getStateFromMeta(5), 3);
        world.setBlockState(new BlockPos(i + 14, j + 15, k + 15), Block.getBlockById(17).getStateFromMeta(1), 3);
        world.setBlockState(new BlockPos(i + 15, j + 15, k + 15), Block.getBlockById(17).getStateFromMeta(5), 3);
        world.setBlockState(new BlockPos(i + 16, j + 15, k + 15), Block.getBlockById(77).getStateFromMeta(1), 3);
        world.setBlockState(new BlockPos(i + 5, j + 15, k + 16), Block.getBlockById(106).getStateFromMeta(8), 3);
        world.setBlockState(new BlockPos(i + 6, j + 15, k + 16), Block.getBlockById(17).getStateFromMeta(9), 3);
